
-- Baobab Trees
local L = {name = "baobab:leaves"}
local M = {name = "baobab:leaves", prob = 230}
local T = {name = "baobab:trunk", force_place = true}

baobab_1 = {size = {x = 15, y = 29, z = 15}, data = {
_,_,_,_,_,_,_,_,_,_,_,_,_,_,_,
_,_,_,_,_,_,_,_,_,_,_,_,_,_,_,
_,_,_,_,_,_,_,_,_,_,_,_,_,_,_,
_,_,_,_,_,_,_,_,_,_,_,_,_,_,_,
_,_,_,_,_,_,_,_,_,_,_,_,_,_,_,
_,_,_,_,_,_,_,_,_,_,_,_,_,_,_,
_,_,_,_,_,_,_,_,_,_,_,_,_,_,_,
_,_,_,_,_,_,_,_,_,_,_,_,_,_,_,
_,_,_,_,_,_,_,_,_,_,_,_,_,_,_,
_,_,_,_,_,_,_,_,_,_,_,_,_,_,_,
_,_,_,_,_,_,_,_,_,_,_,_,_,_,_,
_,_,_,_,_,_,_,_,_,_,_,_,_,_,_,
_,_,_,_,_,_,_,_,_,_,_,_,_,_,_,
_,_,_,_,_,_,_,_,_,_,_,_,_,_,_,
_,_,_,_,_,_,_,_,_,_,_,_,_,_,_,
_,_,_,_,_,_,_,_,_,_,_,_,_,_,_,
_,_,_,_,_,_,_,_,_,_,_,_,_,_,_,
_,_,_,_,_,_,_,_,_,_,_,_,_,_,_,
_,_,_,_,_,_,_,_,_,_,_,_,_,_,_,
_,_,_,_,_,_,_,_,_,_,_,_,_,_,_,
_,_,_,_,_,_,_,_,_,_,_,_,_,_,_,
_,_,_,_,_,_,_,_,_,_,_,_,_,_,_,
_,_,_,_,_,_,_,_,_,_,_,_,_,_,_,
_,_,_,_,_,_,_,_,_,_,_,_,_,_,_,
_,_,_,_,_,_,_,_,_,_,_,_,_,_,_,
_,_,L,L,L,_,_,_,_,_,_,_,_,_,_,
_,_,_,_,_,_,_,L,L,L,_,_,_,_,_,
_,_,_,_,_,_,_,_,_,_,_,_,_,_,_,
_,_,_,_,_,_,_,_,_,_,_,_,_,_,_,

_,_,_,_,_,_,_,_,_,_,_,_,_,_,_,
_,_,_,_,_,_,_,_,_,_,_,_,_,_,_,
_,_,_,_,_,_,_,_,_,_,_,_,_,_,_,
_,_,_,_,_,_,_,_,_,_,_,_,_,_,_,
_,_,_,_,_,_,_,_,_,_,_,_,_,_,_,
_,_,_,_,_,_,_,_,_,_,_,_,_,_,_,
_,_,_,_,_,_,_,_,_,_,_,_,_,_,_,
_,_,_,_,_,_,_,_,_,_,_,_,_,_,_,
_,_,_,_,_,_,_,_,_,_,_,_,_,_,_,
_,_,_,_,_,_,_,_,_,_,_,_,_,_,_,
_,_,_,_,_,_,_,_,_,_,_,_,_,_,_,
_,_,_,_,_,_,_,_,_,_,_,_,_,_,_,
_,_,_,_,_,_,_,_,_,_,_,_,_,_,_,
_,_,_,_,_,_,_,_,_,_,_,_,_,_,_,
_,_,_,_,_,_,_,_,_,_,_,_,_,_,_,
_,_,_,_,_,_,_,_,_,_,_,_,_,_,_,
_,_,_,_,_,_,_,_,_,_,_,_,_,_,_,
_,_,_,_,_,_,_,_,_,_,_,_,_,_,_,
_,_,_,_,_,_,_,_,_,_,_,_,_,_,_,
_,_,_,_,_,_,_,_,_,_,_,_,_,_,_,
_,_,_,_,_,_,_,_,_,_,_,_,_,_,_,
_,_,_,_,_,_,_,_,_,_,_,_,_,_,_,
_,_,_,_,_,_,_,_,_,_,_,_,_,_,_,
_,_,_,_,_,_,_,_,_,_,_,_,_,_,_,
_,_,_,_,_,_,_,_,_,_,_,_,_,_,_,
_,L,L,L,L,L,_,_,_,_,_,_,_,_,_,
_,_,M,L,M,_,L,L,L,L,L,_,_,_,_,
_,_,_,_,_,_,_,M,L,M,_,_,_,_,_,
_,_,_,_,_,_,_,_,_,_,_,_,_,_,_,

_,_,_,_,_,_,_,_,_,_,_,_,_,_,_,
_,_,_,_,_,_,_,_,_,_,_,_,_,_,_,
_,_,_,_,_,_,_,_,_,_,_,_,_,_,_,
_,_,_,_,_,_,_,_,_,_,_,_,_,_,_,
_,_,_,_,_,_,_,_,_,_,_,_,_,_,_,
_,_,_,_,_,_,_,_,_,_,_,_,_,_,_,
_,_,_,_,_,_,_,_,_,_,_,_,_,_,_,
_,_,_,_,_,_,_,_,_,_,_,_,_,_,_,
_,_,_,_,_,_,_,_,_,_,_,_,_,_,_,
_,_,_,_,_,_,_,_,_,_,_,_,_,_,_,
_,_,_,_,_,_,_,_,_,_,_,_,_,_,_,
_,_,_,_,_,_,_,_,_,_,_,_,_,_,_,
_,_,_,_,_,_,_,_,_,_,_,_,_,_,_,
_,_,_,_,_,_,_,_,_,_,_,_,_,_,_,
_,_,_,_,_,_,_,_,_,_,_,_,_,_,_,
_,_,_,_,_,_,_,_,_,_,_,_,_,_,_,
_,_,_,_,_,_,_,_,_,_,_,_,_,_,_,
_,_,_,_,_,_,_,_,_,_,_,_,_,_,_,
_,_,_,_,_,_,_,_,_,_,_,_,_,_,_,
_,_,_,_,_,_,_,_,_,_,_,_,_,_,_,
_,_,_,_,_,_,_,_,_,_,_,_,_,_,_,
_,_,_,_,_,_,_,_,_,_,_,_,_,_,_,
_,_,_,_,_,_,_,_,_,_,_,_,_,_,_,
_,_,_,_,_,_,_,_,_,_,_,_,_,_,_,
_,_,_,T,T,_,_,T,_,_,_,_,_,_,_,
_,L,L,T,L,L,_,T,T,_,M,L,L,L,_,
_,_,L,L,L,_,L,L,T,L,L,_,_,_,_,
_,_,_,L,_,_,_,L,L,L,_,_,_,_,_,
_,_,_,_,_,_,_,_,L,_,_,_,_,_,_,

_,_,_,_,_,_,_,_,_,_,_,_,_,_,_,
_,_,_,_,_,_,_,_,_,_,_,_,_,_,_,
_,_,_,_,_,_,_,_,_,_,_,_,_,_,_,
_,_,_,_,_,_,_,_,_,_,_,_,_,_,_,
_,_,_,_,_,_,_,_,_,_,_,_,_,_,_,
_,_,_,_,_,_,_,_,_,_,_,_,_,_,_,
_,_,_,_,_,_,_,_,_,_,_,_,_,_,_,
_,_,_,_,_,_,_,_,_,_,_,_,_,_,_,
_,_,_,_,_,_,_,_,_,_,_,_,_,_,_,
_,_,_,_,_,_,_,_,_,_,_,_,_,_,_,
_,_,_,_,_,_,_,_,_,_,_,_,_,_,_,
_,_,_,_,_,_,_,_,_,_,_,_,_,_,_,
_,_,_,_,_,_,_,_,_,_,_,_,_,_,_,
_,_,_,_,_,_,_,_,_,_,_,_,_,_,_,
_,_,_,_,_,_,_,_,_,_,_,_,_,_,_,
_,_,_,_,_,_,_,_,_,_,_,_,_,_,_,
_,_,_,_,_,_,_,_,_,_,_,_,_,_,_,
_,_,_,_,_,_,_,_,_,_,_,_,_,_,_,
_,_,_,_,_,_,_,_,_,_,_,_,_,_,_,
_,_,_,_,_,_,_,_,_,_,_,_,_,_,_,
_,_,_,_,_,_,_,_,_,_,_,_,_,_,_,
_,_,_,_,_,_,_,_,_,_,_,_,_,_,_,
_,_,_,_,_,_,_,_,_,_,_,_,_,_,_,
_,_,_,_,_,_,_,_,_,_,_,_,_,_,_,
_,_,_,_,T,T,_,T,_,_,_,_,_,_,_,
_,L,L,L,L,L,_,_,M,L,M,L,L,L,L,
_,L,L,L,M,L,L,L,L,L,L,M,L,M,_,
_,_,_,_,_,_,_,M,L,M,_,_,_,_,_,
_,_,_,_,_,_,_,_,_,_,_,_,_,_,_,

_,_,_,_,_,_,_,_,_,_,_,_,_,_,_,
_,_,_,_,_,_,_,_,_,_,_,_,_,_,_,
_,_,_,_,_,_,_,_,_,_,_,_,_,_,_,
_,_,_,_,_,_,_,_,_,_,_,_,_,_,_,
_,_,_,_,_,_,_,_,_,_,_,_,_,_,_,
_,_,_,_,_,_,_,_,_,_,_,_,_,_,_,
_,_,_,_,_,_,_,_,_,_,_,_,_,_,_,
_,_,_,_,_,_,_,_,_,_,_,_,_,_,_,
_,_,_,_,_,_,_,_,_,_,_,_,_,_,_,
_,_,_,_,_,_,_,_,_,_,_,_,_,_,_,
_,_,_,_,_,_,_,_,_,_,_,_,_,_,_,
_,_,_,_,_,_,_,_,_,_,_,_,_,_,_,
_,_,_,_,_,_,_,_,_,_,_,_,_,_,_,
_,_,_,_,_,_,_,_,_,_,_,_,_,_,_,
_,_,_,_,_,_,_,_,_,_,_,_,_,_,_,
_,_,_,_,_,_,_,_,_,_,_,_,_,_,_,
_,_,_,_,_,_,_,_,_,_,_,_,_,_,_,
_,_,_,_,_,_,_,_,_,_,_,_,_,_,_,
_,_,_,_,_,_,_,_,_,_,_,_,_,_,_,
_,_,_,_,_,_,_,_,_,_,_,_,_,_,_,
_,_,_,_,_,_,_,_,_,_,_,_,_,_,_,
_,_,_,_,_,_,_,_,_,_,_,_,_,_,_,
_,_,_,_,_,_,_,_,_,_,_,_,_,_,_,
_,_,_,_,_,_,_,_,_,T,T,T,T,_,_,
_,_,_,_,_,T,_,T,_,T,_,_,T,_,_,
_,_,M,_,_,T,_,_,L,L,L,L,T,L,L,
L,L,L,L,L,L,L,L,L,L,_,L,L,L,_,
_,M,L,M,_,L,_,_,_,_,_,_,L,_,_,
_,_,_,_,_,_,_,_,_,_,_,_,_,_,_,

_,_,_,_,_,_,T,T,_,_,_,_,_,_,_,
_,_,_,_,_,_,T,T,_,_,_,_,_,_,_,
_,_,_,_,_,_,T,T,_,_,_,_,_,_,_,
_,_,_,_,_,_,T,T,_,_,_,_,_,_,_,
_,_,_,_,_,_,T,T,_,_,_,_,_,_,_,
_,_,_,_,_,_,T,T,_,_,_,_,_,_,_,
_,_,_,_,_,_,T,T,_,_,_,_,_,_,_,
_,_,_,_,_,_,T,T,_,_,_,_,_,_,_,
_,_,_,_,_,_,T,T,_,_,_,_,_,_,_,
_,_,_,_,_,_,T,T,_,_,_,_,_,_,_,
_,_,_,_,_,_,T,T,_,_,_,_,_,_,_,
_,_,_,_,_,_,T,T,_,_,_,_,_,_,_,
_,_,_,_,_,_,T,T,_,_,_,_,_,_,_,
_,_,_,_,_,_,T,T,_,_,_,_,_,_,_,
_,_,_,_,_,_,T,T,_,_,_,_,_,_,_,
_,_,_,_,_,_,T,T,_,_,_,_,_,_,_,
_,_,_,_,_,_,T,T,_,_,_,_,_,_,_,
_,_,_,_,_,_,T,T,_,_,_,_,_,_,_,
_,_,_,_,_,_,T,T,_,_,_,_,_,_,_,
_,_,_,_,_,_,T,T,_,_,_,_,_,_,_,
_,_,_,_,_,_,T,T,_,_,_,_,_,_,_,
_,_,_,_,_,_,T,T,_,_,_,_,_,_,_,
_,_,_,_,_,_,T,T,_,_,_,_,_,_,_,
_,_,_,_,_,_,T,T,T,T,_,_,_,_,_,
_,_,T,T,T,T,T,T,_,_,_,_,_,_,_,
_,_,T,_,_,_,_,T,M,L,L,L,L,L,L,
L,L,T,L,L,L,L,L,L,M,_,M,L,M,_,
_,L,L,L,M,L,M,L,_,_,_,_,_,_,_,
_,_,L,_,_,_,_,_,_,_,_,_,_,_,_,

_,_,_,_,_,T,T,T,T,_,_,_,_,_,_,
_,_,_,_,_,T,T,T,T,_,_,_,_,_,_,
_,_,_,_,_,T,T,T,T,_,_,_,_,_,_,
_,_,_,_,_,T,T,T,T,_,_,_,_,_,_,
_,_,_,_,_,T,T,T,T,_,_,_,_,_,_,
_,_,_,_,_,T,T,T,T,_,_,_,_,_,_,
_,_,_,_,_,T,T,T,T,_,_,_,_,_,_,
_,_,_,_,_,T,T,T,T,_,_,_,_,_,_,
_,_,_,_,_,T,T,T,T,_,_,_,_,_,_,
_,_,_,_,_,T,T,T,T,_,_,_,_,_,_,
_,_,_,_,_,T,T,T,T,_,_,_,_,_,_,
_,_,_,_,_,T,T,T,T,_,_,_,_,_,_,
_,_,_,_,_,T,T,T,T,_,_,_,_,_,_,
_,_,_,_,_,T,T,T,T,_,_,_,_,_,_,
_,_,_,_,_,T,T,T,T,_,_,_,_,_,_,
_,_,_,_,_,T,T,T,T,_,_,_,_,_,_,
_,_,_,_,_,T,T,T,T,_,_,_,_,_,_,
_,_,_,_,_,T,T,T,T,_,_,_,_,_,_,
_,_,_,_,_,T,T,T,T,_,_,_,_,_,_,
_,_,_,_,_,T,T,T,T,_,_,_,_,_,_,
_,_,_,_,_,T,T,T,T,_,_,_,_,_,_,
_,_,_,_,_,T,T,T,T,_,_,_,_,_,_,
_,_,_,_,_,T,T,T,T,_,_,_,_,_,_,
_,_,_,_,_,T,T,T,T,_,_,_,_,_,_,
_,_,_,_,_,T,T,T,T,_,_,_,_,_,_,
_,_,_,_,_,T,_,_,_,_,_,L,L,L,_,
L,L,L,L,L,T,L,L,L,L,_,_,_,_,_,
_,M,L,M,L,L,L,L,M,_,_,_,_,_,_,
_,_,_,_,_,L,_,_,_,_,_,_,_,_,_,

_,_,_,_,_,T,T,T,T,_,_,_,_,_,_,
_,_,_,_,_,T,T,T,T,_,_,_,_,_,_,
_,_,_,_,_,T,T,T,T,_,_,_,_,_,_,
_,_,_,_,_,T,T,T,T,_,_,_,_,_,_,
_,_,_,_,_,T,T,T,T,_,_,_,_,_,_,
_,_,_,_,_,T,T,T,T,_,_,_,_,_,_,
_,_,_,_,_,T,T,T,T,_,_,_,_,_,_,
_,_,_,_,_,T,T,T,T,_,_,_,_,_,_,
_,_,_,_,_,T,T,T,T,_,_,_,_,_,_,
_,_,_,_,_,T,T,T,T,_,_,_,_,_,_,
_,_,_,_,_,T,T,T,T,_,_,_,_,_,_,
_,_,_,_,_,T,T,T,T,_,_,_,_,_,_,
_,_,_,_,_,T,T,T,T,_,_,_,_,_,_,
_,_,_,_,_,T,T,T,T,_,_,_,_,_,_,
_,_,_,_,_,T,T,T,T,_,_,_,_,_,_,
_,_,_,_,_,T,T,T,T,_,_,_,_,_,_,
_,_,_,_,_,T,T,T,T,_,_,_,_,_,_,
_,_,_,_,_,T,T,T,T,_,_,_,_,_,_,
_,_,_,_,_,T,T,T,T,_,_,_,_,_,_,
_,_,_,_,_,T,T,T,T,_,_,_,_,_,_,
_,_,_,_,_,T,T,T,T,_,_,_,_,_,_,
_,_,_,_,_,T,T,T,T,_,_,_,_,_,_,
_,_,_,_,_,T,T,T,T,_,_,_,_,_,_,
_,_,_,T,T,T,T,T,T,_,_,_,_,_,_,
_,_,_,_,_,T,T,T,T,_,_,_,_,_,_,
_,_,M,L,M,_,_,T,_,_,_,_,_,_,_,
_,L,L,L,L,L,L,T,L,L,L,L,L,_,_,
_,_,_,_,M,L,L,L,L,_,_,_,_,_,_,
_,_,_,_,_,_,_,L,_,_,_,_,_,_,_,

_,_,_,_,_,_,T,T,_,_,_,_,_,_,_,
_,_,_,_,_,_,T,T,_,_,_,_,_,_,_,
_,_,_,_,_,_,T,T,_,_,_,_,_,_,_,
_,_,_,_,_,_,T,T,_,_,_,_,_,_,_,
_,_,_,_,_,_,T,T,_,_,_,_,_,_,_,
_,_,_,_,_,_,T,T,_,_,_,_,_,_,_,
_,_,_,_,_,_,T,T,_,_,_,_,_,_,_,
_,_,_,_,_,_,T,T,_,_,_,_,_,_,_,
_,_,_,_,_,_,T,T,_,_,_,_,_,_,_,
_,_,_,_,_,_,T,T,_,_,_,_,_,_,_,
_,_,_,_,_,_,T,T,_,_,_,_,_,_,_,
_,_,_,_,_,_,T,T,_,_,_,_,_,_,_,
_,_,_,_,_,_,T,T,_,_,_,_,_,_,_,
_,_,_,_,_,_,T,T,_,_,_,_,_,_,_,
_,_,_,_,_,_,T,T,_,_,_,_,_,_,_,
_,_,_,_,_,_,T,T,_,_,_,_,_,_,_,
_,_,_,_,_,_,T,T,_,_,_,_,_,_,_,
_,_,_,_,_,_,T,T,_,_,_,_,_,_,_,
_,_,_,_,_,_,T,T,_,_,_,_,_,_,_,
_,_,_,_,_,_,T,T,_,_,_,_,_,_,_,
_,_,_,_,_,_,T,T,_,_,_,_,_,_,_,
_,_,_,_,_,_,T,T,_,_,_,_,_,_,_,
_,_,_,_,_,_,T,T,_,_,_,_,_,_,_,
_,_,_,T,_,_,T,T,T,T,T,_,_,_,_,
_,_,_,T,_,_,T,T,_,T,_,_,_,_,_,
_,L,L,L,L,_,_,_,_,T,_,_,_,_,_,
_,_,M,L,M,L,L,L,L,L,L,L,L,L,_,
_,_,_,_,_,_,M,L,M,L,M,L,M,_,_,
_,_,_,_,_,_,_,_,_,_,_,_,_,_,_,

_,_,_,_,_,_,_,_,_,_,_,_,_,_,_,
_,_,_,_,_,_,_,_,_,_,_,_,_,_,_,
_,_,_,_,_,_,_,_,_,_,_,_,_,_,_,
_,_,_,_,_,_,_,_,_,_,_,_,_,_,_,
_,_,_,_,_,_,_,_,_,_,_,_,_,_,_,
_,_,_,_,_,_,_,_,_,_,_,_,_,_,_,
_,_,_,_,_,_,_,_,_,_,_,_,_,_,_,
_,_,_,_,_,_,_,_,_,_,_,_,_,_,_,
_,_,_,_,_,_,_,_,_,_,_,_,_,_,_,
_,_,_,_,_,_,_,_,_,_,_,_,_,_,_,
_,_,_,_,_,_,_,_,_,_,_,_,_,_,_,
_,_,_,_,_,_,_,_,_,_,_,_,_,_,_,
_,_,_,_,_,_,_,_,_,_,_,_,_,_,_,
_,_,_,_,_,_,_,_,_,_,_,_,_,_,_,
_,_,_,_,_,_,_,_,_,_,_,_,_,_,_,
_,_,_,_,_,_,_,_,_,_,_,_,_,_,_,
_,_,_,_,_,_,_,_,_,_,_,_,_,_,_,
_,_,_,_,_,_,_,_,_,_,_,_,_,_,_,
_,_,_,_,_,_,_,_,_,_,_,_,_,_,_,
_,_,_,_,_,_,_,_,_,_,_,_,_,_,_,
_,_,_,_,_,_,_,_,_,_,_,_,_,_,_,
_,_,_,_,_,_,_,_,_,_,_,_,_,_,_,
_,_,_,_,_,_,_,_,_,_,_,_,_,_,_,
_,_,T,T,_,_,_,_,_,_,T,T,_,_,_,
_,_,_,_,_,_,_,T,_,_,_,T,_,_,_,
L,L,L,L,L,_,_,_,_,_,_,T,_,_,_,
_,M,L,M,_,M,L,L,L,L,L,T,L,L,_,
_,_,_,_,_,_,_,_,_,_,L,L,L,_,_,
_,_,_,_,_,_,_,_,_,_,_,L,_,_,_,

_,_,_,_,_,_,_,_,_,_,_,_,_,_,_,
_,_,_,_,_,_,_,_,_,_,_,_,_,_,_,
_,_,_,_,_,_,_,_,_,_,_,_,_,_,_,
_,_,_,_,_,_,_,_,_,_,_,_,_,_,_,
_,_,_,_,_,_,_,_,_,_,_,_,_,_,_,
_,_,_,_,_,_,_,_,_,_,_,_,_,_,_,
_,_,_,_,_,_,_,_,_,_,_,_,_,_,_,
_,_,_,_,_,_,_,_,_,_,_,_,_,_,_,
_,_,_,_,_,_,_,_,_,_,_,_,_,_,_,
_,_,_,_,_,_,_,_,_,_,_,_,_,_,_,
_,_,_,_,_,_,_,_,_,_,_,_,_,_,_,
_,_,_,_,_,_,_,_,_,_,_,_,_,_,_,
_,_,_,_,_,_,_,_,_,_,_,_,_,_,_,
_,_,_,_,_,_,_,_,_,_,_,_,_,_,_,
_,_,_,_,_,_,_,_,_,_,_,_,_,_,_,
_,_,_,_,_,_,_,_,_,_,_,_,_,_,_,
_,_,_,_,_,_,_,_,_,_,_,_,_,_,_,
_,_,_,_,_,_,_,_,_,_,_,_,_,_,_,
_,_,_,_,_,_,_,_,_,_,_,_,_,_,_,
_,_,_,_,_,_,_,_,_,_,_,_,_,_,_,
_,_,_,_,_,_,_,_,_,_,_,_,_,_,_,
_,_,_,_,_,_,_,_,_,_,_,_,_,_,_,
_,_,_,_,_,_,_,_,_,_,_,_,_,_,_,
_,_,T,_,_,_,_,_,_,_,_,_,_,_,_,
_,_,T,_,_,_,_,T,_,_,_,_,_,_,_,
L,L,T,L,L,_,_,T,_,_,_,_,_,_,_,
_,L,L,L,L,L,L,L,L,L,L,L,L,L,_,
_,_,L,_,_,_,_,L,_,_,M,L,M,_,_,
_,_,_,_,_,_,_,_,_,_,_,_,_,_,_,

_,_,_,_,_,_,_,_,_,_,_,_,_,_,_,
_,_,_,_,_,_,_,_,_,_,_,_,_,_,_,
_,_,_,_,_,_,_,_,_,_,_,_,_,_,_,
_,_,_,_,_,_,_,_,_,_,_,_,_,_,_,
_,_,_,_,_,_,_,_,_,_,_,_,_,_,_,
_,_,_,_,_,_,_,_,_,_,_,_,_,_,_,
_,_,_,_,_,_,_,_,_,_,_,_,_,_,_,
_,_,_,_,_,_,_,_,_,_,_,_,_,_,_,
_,_,_,_,_,_,_,_,_,_,_,_,_,_,_,
_,_,_,_,_,_,_,_,_,_,_,_,_,_,_,
_,_,_,_,_,_,_,_,_,_,_,_,_,_,_,
_,_,_,_,_,_,_,_,_,_,_,_,_,_,_,
_,_,_,_,_,_,_,_,_,_,_,_,_,_,_,
_,_,_,_,_,_,_,_,_,_,_,_,_,_,_,
_,_,_,_,_,_,_,_,_,_,_,_,_,_,_,
_,_,_,_,_,_,_,_,_,_,_,_,_,_,_,
_,_,_,_,_,_,_,_,_,_,_,_,_,_,_,
_,_,_,_,_,_,_,_,_,_,_,_,_,_,_,
_,_,_,_,_,_,_,_,_,_,_,_,_,_,_,
_,_,_,_,_,_,_,_,_,_,_,_,_,_,_,
_,_,_,_,_,_,_,_,_,_,_,_,_,_,_,
_,_,_,_,_,_,_,_,_,_,_,_,_,_,_,
_,_,_,_,_,_,_,_,_,_,_,_,_,_,_,
_,_,_,_,_,_,_,_,_,_,_,_,_,_,_,
_,_,_,_,_,T,T,T,T,_,_,_,_,_,_,
L,L,L,L,M,_,_,_,_,_,_,_,_,_,_,
_,M,L,L,L,L,L,L,L,L,L,L,L,_,_,
_,_,_,_,M,L,M,_,M,L,M,_,_,_,_,
_,_,_,_,_,_,_,_,_,_,_,_,_,_,_,

_,_,_,_,_,_,_,_,_,_,_,_,_,_,_,
_,_,_,_,_,_,_,_,_,_,_,_,_,_,_,
_,_,_,_,_,_,_,_,_,_,_,_,_,_,_,
_,_,_,_,_,_,_,_,_,_,_,_,_,_,_,
_,_,_,_,_,_,_,_,_,_,_,_,_,_,_,
_,_,_,_,_,_,_,_,_,_,_,_,_,_,_,
_,_,_,_,_,_,_,_,_,_,_,_,_,_,_,
_,_,_,_,_,_,_,_,_,_,_,_,_,_,_,
_,_,_,_,_,_,_,_,_,_,_,_,_,_,_,
_,_,_,_,_,_,_,_,_,_,_,_,_,_,_,
_,_,_,_,_,_,_,_,_,_,_,_,_,_,_,
_,_,_,_,_,_,_,_,_,_,_,_,_,_,_,
_,_,_,_,_,_,_,_,_,_,_,_,_,_,_,
_,_,_,_,_,_,_,_,_,_,_,_,_,_,_,
_,_,_,_,_,_,_,_,_,_,_,_,_,_,_,
_,_,_,_,_,_,_,_,_,_,_,_,_,_,_,
_,_,_,_,_,_,_,_,_,_,_,_,_,_,_,
_,_,_,_,_,_,_,_,_,_,_,_,_,_,_,
_,_,_,_,_,_,_,_,_,_,_,_,_,_,_,
_,_,_,_,_,_,_,_,_,_,_,_,_,_,_,
_,_,_,_,_,_,_,_,_,_,_,_,_,_,_,
_,_,_,_,_,_,_,_,_,_,_,_,_,_,_,
_,_,_,_,_,_,_,_,_,_,_,_,_,_,_,
_,_,_,_,_,_,_,_,_,_,_,_,_,_,_,
_,_,_,_,_,T,_,_,T,_,_,_,_,_,_,
_,L,L,M,_,T,_,_,T,T,_,_,_,_,_,
_,_,_,L,L,T,L,L,L,T,L,L,_,_,_,
_,_,_,_,L,L,L,_,L,L,L,_,_,_,_,
_,_,_,_,_,L,_,_,_,L,_,_,_,_,_,

_,_,_,_,_,_,_,_,_,_,_,_,_,_,_,
_,_,_,_,_,_,_,_,_,_,_,_,_,_,_,
_,_,_,_,_,_,_,_,_,_,_,_,_,_,_,
_,_,_,_,_,_,_,_,_,_,_,_,_,_,_,
_,_,_,_,_,_,_,_,_,_,_,_,_,_,_,
_,_,_,_,_,_,_,_,_,_,_,_,_,_,_,
_,_,_,_,_,_,_,_,_,_,_,_,_,_,_,
_,_,_,_,_,_,_,_,_,_,_,_,_,_,_,
_,_,_,_,_,_,_,_,_,_,_,_,_,_,_,
_,_,_,_,_,_,_,_,_,_,_,_,_,_,_,
_,_,_,_,_,_,_,_,_,_,_,_,_,_,_,
_,_,_,_,_,_,_,_,_,_,_,_,_,_,_,
_,_,_,_,_,_,_,_,_,_,_,_,_,_,_,
_,_,_,_,_,_,_,_,_,_,_,_,_,_,_,
_,_,_,_,_,_,_,_,_,_,_,_,_,_,_,
_,_,_,_,_,_,_,_,_,_,_,_,_,_,_,
_,_,_,_,_,_,_,_,_,_,_,_,_,_,_,
_,_,_,_,_,_,_,_,_,_,_,_,_,_,_,
_,_,_,_,_,_,_,_,_,_,_,_,_,_,_,
_,_,_,_,_,_,_,_,_,_,_,_,_,_,_,
_,_,_,_,_,_,_,_,_,_,_,_,_,_,_,
_,_,_,_,_,_,_,_,_,_,_,_,_,_,_,
_,_,_,_,_,_,_,_,_,_,_,_,_,_,_,
_,_,_,_,_,_,_,_,_,_,_,_,_,_,_,
_,_,_,_,_,_,_,_,_,_,_,_,_,_,_,
_,_,_,_,_,_,_,_,_,_,_,_,_,_,_,
_,_,_,L,L,L,L,L,L,L,L,L,_,_,_,
_,_,_,_,M,L,M,_,M,L,M,_,_,_,_,
_,_,_,_,_,_,_,_,_,_,_,_,_,_,_,

_,_,_,_,_,_,_,_,_,_,_,_,_,_,_,
_,_,_,_,_,_,_,_,_,_,_,_,_,_,_,
_,_,_,_,_,_,_,_,_,_,_,_,_,_,_,
_,_,_,_,_,_,_,_,_,_,_,_,_,_,_,
_,_,_,_,_,_,_,_,_,_,_,_,_,_,_,
_,_,_,_,_,_,_,_,_,_,_,_,_,_,_,
_,_,_,_,_,_,_,_,_,_,_,_,_,_,_,
_,_,_,_,_,_,_,_,_,_,_,_,_,_,_,
_,_,_,_,_,_,_,_,_,_,_,_,_,_,_,
_,_,_,_,_,_,_,_,_,_,_,_,_,_,_,
_,_,_,_,_,_,_,_,_,_,_,_,_,_,_,
_,_,_,_,_,_,_,_,_,_,_,_,_,_,_,
_,_,_,_,_,_,_,_,_,_,_,_,_,_,_,
_,_,_,_,_,_,_,_,_,_,_,_,_,_,_,
_,_,_,_,_,_,_,_,_,_,_,_,_,_,_,
_,_,_,_,_,_,_,_,_,_,_,_,_,_,_,
_,_,_,_,_,_,_,_,_,_,_,_,_,_,_,
_,_,_,_,_,_,_,_,_,_,_,_,_,_,_,
_,_,_,_,_,_,_,_,_,_,_,_,_,_,_,
_,_,_,_,_,_,_,_,_,_,_,_,_,_,_,
_,_,_,_,_,_,_,_,_,_,_,_,_,_,_,
_,_,_,_,_,_,_,_,_,_,_,_,_,_,_,
_,_,_,_,_,_,_,_,_,_,_,_,_,_,_,
_,_,_,_,_,_,_,_,_,_,_,_,_,_,_,
_,_,_,_,_,_,_,_,_,_,_,_,_,_,_,
_,_,_,_,_,_,_,_,_,_,_,_,_,_,_,
_,_,_,_,L,L,L,_,L,L,L,_,_,_,_,
_,_,_,_,_,_,_,_,_,_,_,_,_,_,_,
_,_,_,_,_,_,_,_,_,_,_,_,_,_,_},
yslice_prob = {{ypos = 5, prob = 127}, {ypos = 9, prob = 127}}}

baobab_2 = {size = {x = 9, y = 12, z = 9}, data = {
_,_,_,_,_,_,_,_,_,
_,_,_,_,_,_,_,_,_,
_,_,_,_,_,_,_,_,_,
_,_,_,_,_,_,_,_,_,
_,_,_,_,_,_,_,_,_,
_,_,_,_,_,_,_,_,_,
_,_,_,_,_,_,_,_,_,
_,_,_,_,_,_,_,_,_,
_,_,_,_,_,_,_,_,_,
_,_,_,_,_,_,_,_,_,
_,_,M,L,L,L,M,_,_,
_,_,_,_,_,_,_,_,_,

_,_,_,_,_,_,_,_,_,
_,_,_,_,_,_,_,_,_,
_,_,_,_,_,_,_,_,_,
_,_,_,_,_,_,_,_,_,
_,_,_,_,_,_,_,_,_,
_,_,_,_,_,_,_,_,_,
_,_,_,_,_,_,_,_,_,
_,_,_,_,_,_,_,_,_,
_,_,_,_,_,_,_,_,_,
_,_,_,M,M,M,_,_,_,
_,L,L,L,L,L,L,L,_,
_,_,M,L,L,L,M,_,_,

_,_,_,_,_,_,_,_,_,
_,_,_,_,_,_,_,_,_,
_,_,_,_,_,_,_,_,_,
_,_,_,_,_,_,_,_,_,
_,_,_,_,_,_,_,_,_,
_,_,_,_,_,_,_,_,_,
_,_,_,_,_,_,_,_,_,
_,_,_,_,_,_,_,_,_,
_,_,_,_,_,_,_,_,_,
_,_,M,T,_,T,M,_,_,
M,L,L,L,L,L,L,L,M,
_,M,L,L,L,L,L,M,_,

_,_,_,T,T,T,_,_,_,
_,_,_,T,T,T,_,_,_,
_,_,_,T,T,T,_,_,_,
_,_,_,T,T,T,_,_,_,
_,_,_,T,T,T,_,_,_,
_,_,_,T,T,T,_,_,_,
_,_,_,T,T,T,_,_,_,
_,_,_,_,T,_,_,_,_,
_,_,_,_,T,_,_,_,_,
_,M,T,T,_,T,T,M,_,
L,L,L,L,L,L,L,L,L,
_,L,L,L,L,L,L,L,_,

_,_,_,T,T,T,_,_,_,
_,_,_,T,T,T,_,_,_,
_,_,_,T,T,T,_,_,_,
_,_,_,T,T,T,_,_,_,
_,_,_,T,T,T,_,_,_,
_,_,_,T,T,T,_,_,_,
_,_,_,T,T,T,_,_,_,
_,_,_,T,T,T,_,_,_,
_,_,_,T,T,T,_,_,_,
_,M,_,_,_,_,_,M,_,
L,L,L,L,L,L,L,L,L,
_,L,L,L,L,L,L,L,_,

_,_,_,T,T,T,_,_,_,
_,_,_,T,T,T,_,_,_,
_,_,_,T,T,T,_,_,_,
_,_,_,T,T,T,_,_,_,
_,_,_,T,T,T,_,_,_,
_,_,_,T,T,T,_,_,_,
_,_,_,T,T,T,_,_,_,
_,_,_,_,T,_,_,_,_,
_,_,_,_,T,_,_,_,_,
_,M,T,T,_,T,T,M,_,
L,L,L,L,L,L,L,L,L,
_,L,L,L,L,L,L,L,_,

_,_,_,_,_,_,_,_,_,
_,_,_,_,_,_,_,_,_,
_,_,_,_,_,_,_,_,_,
_,_,_,_,_,_,_,_,_,
_,_,_,_,_,_,_,_,_,
_,_,_,_,_,_,_,_,_,
_,_,_,_,_,_,_,_,_,
_,_,_,_,_,_,_,_,_,
_,_,_,_,_,_,_,_,_,
_,_,M,T,_,T,M,_,_,
M,L,L,L,L,L,L,L,M,
_,M,L,L,L,L,L,M,_,

_,_,_,_,_,_,_,_,_,
_,_,_,_,_,_,_,_,_,
_,_,_,_,_,_,_,_,_,
_,_,_,_,_,_,_,_,_,
_,_,_,_,_,_,_,_,_,
_,_,_,_,_,_,_,_,_,
_,_,_,_,_,_,_,_,_,
_,_,_,_,_,_,_,_,_,
_,_,_,_,_,_,_,_,_,
_,_,_,M,M,M,_,_,_,
_,L,L,L,L,L,L,L,_,
_,_,M,L,L,L,M,_,_,

_,_,_,_,_,_,_,_,_,
_,_,_,_,_,_,_,_,_,
_,_,_,_,_,_,_,_,_,
_,_,_,_,_,_,_,_,_,
_,_,_,_,_,_,_,_,_,
_,_,_,_,_,_,_,_,_,
_,_,_,_,_,_,_,_,_,
_,_,_,_,_,_,_,_,_,
_,_,_,_,_,_,_,_,_,
_,_,_,_,_,_,_,_,_,
_,_,M,L,L,L,M,_,_,
_,_,_,_,_,_,_,_,_},
yslice_prob = {{ypos = 3, prob = 127}}}

baobab_3 = {size = {x = 9, y = 14, z = 8}, data = {
_,_,_,_,_,_,_,_,_,
_,_,_,_,_,_,_,_,_,
_,_,_,_,_,_,_,_,_,
_,_,_,_,_,_,_,_,_,
_,_,_,_,_,_,_,_,_,
_,_,_,_,_,_,_,_,_,
_,_,_,_,_,_,_,_,_,
_,_,_,_,_,_,_,_,_,
_,_,_,_,_,_,_,_,_,
_,_,_,_,_,_,_,_,_,
_,_,_,_,_,_,_,_,_,
_,_,_,_,_,_,_,_,_,
_,_,M,L,L,L,M,_,_,
_,_,_,_,_,_,_,_,_,

_,_,_,_,_,_,_,_,_,
_,_,_,_,_,_,_,_,_,
_,_,_,_,_,_,_,_,_,
_,_,_,_,_,_,_,_,_,
_,_,_,_,_,_,_,_,_,
_,_,_,_,_,_,_,_,_,
_,_,_,_,_,_,_,_,_,
_,_,_,_,_,_,_,_,_,
_,_,_,_,_,_,_,_,_,
_,_,_,_,_,_,_,_,_,
_,_,_,_,_,_,_,_,_,
_,_,_,M,M,M,_,_,_,
_,L,L,L,L,L,L,L,_,
_,_,M,L,L,L,M,_,_,

_,_,_,_,_,_,_,_,_,
_,_,_,_,_,_,_,_,_,
_,_,_,_,_,_,_,_,_,
_,_,_,_,_,_,_,_,_,
_,_,_,_,_,_,_,_,_,
_,_,_,_,_,_,_,_,_,
_,_,_,_,_,_,_,_,_,
_,_,_,_,_,_,_,_,_,
_,_,_,_,_,_,_,_,_,
_,_,_,_,_,_,_,_,_,
_,_,_,_,T,T,_,_,_,
_,_,M,_,_,T,M,_,_,
M,L,L,L,L,L,L,L,M,
_,M,L,L,L,L,L,M,_,

_,_,_,T,T,_,_,_,_,
_,_,_,T,T,_,_,_,_,
_,_,_,T,T,_,_,_,_,
_,_,_,T,T,_,_,_,_,
_,_,_,T,T,_,_,_,_,
_,_,_,T,T,_,_,_,_,
_,_,_,T,T,_,_,_,_,
_,_,_,T,T,_,_,_,_,
_,_,_,T,T,_,_,_,_,
_,_,_,T,T,_,_,_,_,
_,_,T,T,T,_,_,_,_,
_,M,T,_,_,_,_,M,_,
L,L,L,L,L,L,L,L,L,
_,L,L,L,L,L,L,L,_,

_,_,_,T,T,_,_,_,_,
_,_,_,T,T,_,_,_,_,
_,_,_,T,T,_,_,_,_,
_,_,_,T,T,_,_,_,_,
_,_,_,T,T,_,_,_,_,
_,_,_,T,T,_,_,_,_,
_,_,_,T,T,_,_,_,_,
_,_,_,T,T,_,_,_,_,
_,_,_,T,T,_,_,_,_,
_,_,_,T,T,_,_,_,_,
_,_,_,T,T,T,_,_,_,
_,M,_,_,_,_,T,M,_,
L,L,L,L,L,L,L,L,L,
_,L,L,L,L,L,L,L,_,

_,_,_,_,_,_,_,_,_,
_,_,_,_,_,_,_,_,_,
_,_,_,_,_,_,_,_,_,
_,_,_,_,_,_,_,_,_,
_,_,_,_,_,_,_,_,_,
_,_,_,_,_,_,_,_,_,
_,_,_,_,_,_,_,_,_,
_,_,_,_,_,_,_,_,_,
_,_,_,_,_,_,_,_,_,
_,_,_,_,_,_,_,_,_,
_,_,_,T,_,_,_,_,_,
_,_,M,T,_,T,M,_,_,
M,L,L,L,L,L,L,L,M,
_,M,L,L,L,L,L,M,_,

_,_,_,_,_,_,_,_,_,
_,_,_,_,_,_,_,_,_,
_,_,_,_,_,_,_,_,_,
_,_,_,_,_,_,_,_,_,
_,_,_,_,_,_,_,_,_,
_,_,_,_,_,_,_,_,_,
_,_,_,_,_,_,_,_,_,
_,_,_,_,_,_,_,_,_,
_,_,_,_,_,_,_,_,_,
_,_,_,_,_,_,_,_,_,
_,_,_,_,_,_,_,_,_,
_,_,_,M,M,M,_,_,_,
_,L,L,L,L,L,L,L,_,
_,_,M,L,L,L,M,_,_,

_,_,_,_,_,_,_,_,_,
_,_,_,_,_,_,_,_,_,
_,_,_,_,_,_,_,_,_,
_,_,_,_,_,_,_,_,_,
_,_,_,_,_,_,_,_,_,
_,_,_,_,_,_,_,_,_,
_,_,_,_,_,_,_,_,_,
_,_,_,_,_,_,_,_,_,
_,_,_,_,_,_,_,_,_,
_,_,_,_,_,_,_,_,_,
_,_,_,_,_,_,_,_,_,
_,_,_,_,_,_,_,_,_,
_,_,M,L,L,L,M,_,_,
_,_,_,_,_,_,_,_,_},
yslice_prob = {{ypos = 3, prob = 127}}}

baobab_4 = {size = {x = 15, y = 16, z = 14}, data = {
_,_,_,_,_,_,_,_,_,_,_,_,_,_,_,
_,_,_,_,_,_,_,_,_,_,_,_,_,_,_,
_,_,_,_,_,_,_,_,_,_,_,_,_,_,_,
_,_,_,_,_,_,_,_,_,_,_,_,_,_,_,
_,_,_,_,_,_,_,_,_,_,_,_,_,_,_,
_,_,_,_,_,_,_,_,_,_,_,_,_,_,_,
_,_,_,_,_,_,_,_,_,_,_,_,_,_,_,
_,_,_,_,_,_,_,_,_,_,_,_,_,_,_,
_,_,_,_,_,_,_,_,_,_,_,_,_,_,_,
_,_,_,_,_,_,_,_,_,_,_,_,_,_,_,
_,_,_,_,_,_,_,_,_,_,_,_,_,_,_,
_,_,_,_,_,_,_,_,_,_,_,_,_,_,_,
_,_,_,_,_,_,_,_,_,_,_,_,_,_,_,
_,_,_,L,L,_,_,_,L,_,_,_,_,_,_,
_,_,_,_,_,_,_,L,L,L,_,_,_,_,_,
_,_,_,_,_,_,_,_,_,_,_,_,_,_,_,

_,_,_,_,_,_,_,_,_,_,_,_,_,_,_,
_,_,_,_,_,_,_,_,_,_,_,_,_,_,_,
_,_,_,_,_,_,_,_,_,_,_,_,_,_,_,
_,_,_,_,_,_,_,_,_,_,_,_,_,_,_,
_,_,_,_,_,_,_,_,_,_,_,_,_,_,_,
_,_,_,_,_,_,_,_,_,_,_,_,_,_,_,
_,_,_,_,_,_,_,_,_,_,_,_,_,_,_,
_,_,_,_,_,_,_,_,_,_,_,_,_,_,_,
_,_,_,_,_,_,_,_,_,_,_,_,_,_,_,
_,_,_,_,_,_,_,_,_,_,_,_,_,_,_,
_,_,_,_,_,_,_,_,_,_,_,_,_,_,_,
_,_,_,_,_,_,_,_,_,_,_,_,_,_,_,
_,_,L,L,L,_,_,_,_,_,_,_,_,_,_,
_,_,L,L,L,_,_,L,L,_,_,_,_,_,_,
_,_,_,L,_,_,L,L,L,L,_,_,_,_,_,
_,_,_,_,_,_,_,L,L,_,_,_,_,_,_,

_,_,_,_,_,_,_,_,_,_,_,_,_,_,_,
_,_,_,_,_,_,_,_,_,_,_,_,_,_,_,
_,_,_,_,_,_,_,_,_,_,_,_,_,_,_,
_,_,_,_,_,_,_,_,_,_,_,_,_,_,_,
_,_,_,_,_,_,_,_,_,_,_,_,_,_,_,
_,_,_,_,_,_,_,_,_,_,_,_,_,_,_,
_,_,_,_,_,_,_,_,_,_,_,_,_,_,_,
_,_,_,_,_,_,_,_,_,_,_,_,_,_,_,
_,_,_,_,_,_,_,_,_,_,_,_,_,_,_,
_,_,_,_,_,_,_,_,_,_,_,_,_,_,_,
_,_,_,_,_,_,_,_,_,_,_,_,_,_,_,
_,_,_,_,_,_,_,_,_,_,_,_,_,_,_,
_,_,_,L,T,_,_,_,_,_,_,_,_,_,_,
_,_,L,L,L,_,L,T,_,_,_,L,_,_,_,
_,_,_,L,_,L,L,L,L,L,L,L,_,_,_,
_,_,_,_,_,_,_,L,_,_,_,_,_,_,_,

_,_,_,_,_,_,_,_,_,_,_,_,_,_,_,
_,_,_,_,_,_,_,_,_,_,_,_,_,_,_,
_,_,_,_,_,_,_,_,_,_,_,_,_,_,_,
_,_,_,_,_,_,_,_,_,_,_,_,_,_,_,
_,_,_,_,_,_,_,_,_,_,_,_,_,_,_,
_,_,_,_,_,_,_,_,_,_,_,_,_,_,_,
_,_,_,_,_,_,_,_,_,_,_,_,_,_,_,
_,_,_,_,_,_,_,_,_,_,_,_,_,_,_,
_,_,_,_,_,_,_,_,_,_,_,_,_,_,_,
_,_,_,_,_,_,_,_,_,_,_,_,_,_,_,
_,_,_,_,_,_,_,_,_,_,_,_,_,_,_,
_,_,_,_,_,_,_,_,_,_,_,_,_,_,_,
_,_,_,_,T,_,_,_,_,_,_,_,_,_,_,
_,_,_,L,_,_,_,T,_,_,T,L,_,_,_,
_,_,_,_,_,_,_,L,_,L,L,L,L,_,_,
_,_,_,_,_,_,_,_,_,_,L,L,_,_,_,

_,_,_,_,_,_,_,_,_,_,_,_,_,_,_,
_,_,_,_,_,_,_,_,_,_,_,_,_,_,_,
_,_,_,_,_,_,_,T,_,_,_,_,_,_,_,
_,_,_,_,_,_,T,T,T,_,_,_,_,_,_,
_,_,_,_,_,T,T,T,T,T,_,_,_,_,_,
_,_,_,_,_,_,T,T,T,T,_,_,_,_,_,
_,_,_,_,_,_,T,T,T,T,_,_,_,_,_,
_,_,_,_,_,_,T,T,T,_,_,_,_,_,_,
_,_,_,_,_,_,_,T,T,_,_,_,_,_,_,
_,_,_,_,_,_,_,_,_,_,_,_,_,_,_,
_,_,_,_,_,_,_,_,_,_,_,_,_,_,_,
_,_,_,_,_,T,_,_,_,_,_,_,_,_,_,
_,_,L,_,_,_,_,T,_,_,_,L,L,L,_,
_,_,_,_,_,_,_,_,_,T,L,_,L,_,_,
_,_,_,_,_,_,_,_,_,L,L,L,_,_,_,
_,_,_,_,_,_,_,_,_,_,L,_,_,_,_,

_,_,_,_,_,_,_,_,_,_,_,_,_,_,_,
_,_,_,_,_,_,T,T,T,_,_,_,_,_,_,
_,_,_,_,_,T,T,T,T,T,_,_,_,_,_,
_,_,_,_,T,T,T,T,T,T,T,_,_,_,_,
_,_,_,_,T,T,_,_,_,T,T,_,_,_,_,
_,_,_,_,T,T,_,_,_,T,T,_,_,_,_,
_,_,_,_,T,T,_,_,_,T,T,_,_,_,_,
_,_,_,_,_,T,T,T,T,T,_,_,_,_,_,
_,_,_,_,_,T,T,T,T,_,_,_,_,_,_,
_,_,_,_,_,_,T,T,_,_,_,_,_,_,_,
_,_,_,_,_,T,T,T,_,_,_,_,_,_,_,
_,_,_,_,T,T,_,T,T,_,_,L,L,L,_,
_,L,L,T,_,_,_,_,T,_,_,L,L,L,_,
_,L,L,_,_,_,_,_,_,_,_,_,L,_,_,
_,L,_,_,_,_,_,_,_,_,L,_,_,_,_,
_,_,_,_,_,_,_,_,_,_,_,_,_,_,_,

_,_,_,_,_,_,T,_,T,_,_,_,_,_,_,
_,_,_,_,_,T,T,T,T,T,_,_,_,_,_,
_,_,_,_,_,T,_,_,_,T,T,_,_,_,_,
_,_,_,_,T,T,_,_,_,T,T,_,_,_,_,
_,_,_,_,T,_,_,_,_,_,T,_,_,_,_,
_,_,_,_,T,_,_,_,_,_,T,_,_,_,_,
_,_,_,_,T,_,_,_,_,_,T,_,_,_,_,
_,_,_,_,T,T,_,_,_,T,T,_,_,_,_,
_,_,_,_,_,T,_,_,_,T,T,_,_,_,_,
_,_,_,_,_,T,T,T,T,T,_,_,_,_,_,
_,_,_,_,_,T,T,T,T,_,_,_,_,_,_,
_,_,_,_,_,_,_,T,T,_,_,T,_,_,_,
_,L,T,_,_,_,_,_,_,_,_,L,L,L,_,
L,L,L,_,_,_,_,_,_,_,_,_,_,_,_,
_,L,_,_,_,_,_,_,_,_,_,_,_,_,_,
_,_,_,_,_,_,_,_,_,_,_,_,_,_,_,

_,_,_,_,_,_,_,_,_,_,_,_,_,_,_,
_,_,_,_,_,T,T,T,T,T,_,_,_,_,_,
_,_,_,_,_,T,_,_,_,T,T,_,_,_,_,
_,_,_,_,T,T,_,_,_,T,T,_,_,_,_,
_,_,_,_,T,_,_,_,_,_,T,_,_,_,_,
_,_,_,_,T,_,_,_,_,_,T,_,_,_,_,
_,_,_,_,T,_,_,_,_,_,T,_,_,_,_,
_,_,_,_,T,T,_,_,_,T,T,_,_,_,_,
_,_,_,_,T,T,_,_,_,T,T,_,_,_,_,
_,_,_,_,_,T,T,T,T,T,_,_,_,_,_,
_,_,_,_,_,_,_,T,T,_,T,_,_,_,_,
_,_,_,_,_,_,_,_,_,_,_,_,L,_,_,
L,L,_,_,_,_,_,_,_,_,_,_,_,_,_,
L,L,_,_,_,_,_,_,_,_,_,_,_,_,_,
_,_,_,_,_,_,_,_,_,_,_,_,_,_,_,
_,_,_,_,_,_,_,_,_,_,_,_,_,_,_,

_,_,_,_,_,_,T,_,T,_,_,_,_,_,_,
_,_,_,_,_,T,T,T,T,T,_,_,_,_,_,
_,_,_,_,_,T,_,_,_,T,T,_,_,_,_,
_,_,_,_,T,T,_,_,_,T,T,_,_,_,_,
_,_,_,_,T,_,_,_,_,_,T,_,_,_,_,
_,_,_,_,T,_,_,_,_,_,T,_,_,_,_,
_,_,_,_,T,_,_,_,_,_,T,_,_,_,_,
_,_,_,_,T,T,_,_,_,T,T,_,_,_,_,
_,_,_,_,_,T,_,_,_,T,_,_,_,_,_,
_,_,_,_,_,_,T,T,T,_,_,_,_,_,_,
_,_,_,_,_,T,_,T,_,_,_,_,_,_,_,
_,_,_,_,T,_,_,_,_,_,_,T,L,L,_,
_,_,L,L,L,_,_,_,_,_,_,_,_,_,_,
_,_,_,_,_,_,_,_,_,_,_,_,_,_,_,
_,_,_,_,_,_,_,_,_,_,_,_,_,_,_,
_,_,_,_,_,_,_,_,_,_,_,_,_,_,_,

_,_,_,_,_,_,_,_,_,_,_,_,_,_,_,
_,_,_,_,_,_,T,T,T,_,_,_,_,_,_,
_,_,_,_,_,T,T,T,T,T,_,_,_,_,_,
_,_,_,_,_,T,T,T,T,T,T,_,_,_,_,
_,_,_,_,T,T,_,_,_,T,T,_,_,_,_,
_,_,_,_,T,T,_,_,_,T,T,_,_,_,_,
_,_,_,_,T,T,_,_,_,T,_,_,_,_,_,
_,_,_,_,_,T,T,T,T,_,_,_,_,_,_,
_,_,_,_,_,_,T,T,T,_,_,_,_,_,_,
_,_,_,_,_,_,_,T,_,_,_,_,_,_,_,
_,_,_,_,_,_,T,_,_,_,_,_,L,L,_,
_,_,_,L,_,_,_,_,_,_,_,L,T,L,L,
_,L,L,T,L,_,_,_,_,_,L,L,L,L,_,
_,_,L,L,_,_,_,_,_,_,_,_,_,_,_,
_,_,_,_,_,_,_,_,_,_,_,_,_,_,_,
_,_,_,_,_,_,_,_,_,_,_,_,_,_,_,

_,_,_,_,_,_,_,_,_,_,_,_,_,_,_,
_,_,_,_,_,_,_,_,_,_,_,_,_,_,_,
_,_,_,_,_,_,_,T,T,_,_,_,_,_,_,
_,_,_,_,_,_,_,T,T,T,_,_,_,_,_,
_,_,_,_,_,_,T,T,T,T,_,_,_,_,_,
_,_,_,_,_,T,T,T,T,_,_,_,_,_,_,
_,_,_,_,_,T,T,T,T,_,_,_,_,_,_,
_,_,_,_,_,_,T,T,_,_,_,_,_,_,_,
_,_,_,_,_,_,T,T,_,_,_,_,_,_,_,
_,_,_,_,_,_,_,_,_,_,_,_,_,_,_,
_,_,_,_,_,_,_,_,_,_,_,_,_,_,_,
_,_,L,_,_,_,T,_,_,_,L,L,L,L,_,
_,L,L,L,L,_,L,_,_,_,L,L,L,L,L,
_,L,L,_,_,_,_,_,_,_,_,_,L,L,_,
_,_,_,_,_,_,_,_,_,_,_,_,_,_,_,
_,_,_,_,_,_,_,_,_,_,_,_,_,_,_,

_,_,_,_,_,_,_,_,_,_,_,_,_,_,_,
_,_,_,_,_,_,_,_,_,_,_,_,_,_,_,
_,_,_,_,_,_,_,_,_,_,_,_,_,_,_,
_,_,_,_,_,_,_,_,_,_,_,_,_,_,_,
_,_,_,_,_,_,_,_,_,_,_,_,_,_,_,
_,_,_,_,_,_,_,_,_,_,_,_,_,_,_,
_,_,_,_,_,_,_,_,_,_,_,_,_,_,_,
_,_,_,_,_,_,_,_,_,_,_,_,_,_,_,
_,_,_,_,_,_,_,_,_,_,_,_,_,_,_,
_,_,_,_,_,_,_,_,_,_,_,_,_,_,_,
_,_,_,_,_,_,_,_,_,_,_,_,_,_,_,
_,_,_,_,_,_,L,T,_,_,_,_,L,_,_,
_,_,L,L,_,L,L,L,L,_,_,L,L,L,_,
_,_,_,_,_,_,L,_,_,_,_,_,_,_,_,
_,_,_,_,_,_,_,_,_,_,_,_,_,_,_,
_,_,_,_,_,_,_,_,_,_,_,_,_,_,_,

_,_,_,_,_,_,_,_,_,_,_,_,_,_,_,
_,_,_,_,_,_,_,_,_,_,_,_,_,_,_,
_,_,_,_,_,_,_,_,_,_,_,_,_,_,_,
_,_,_,_,_,_,_,_,_,_,_,_,_,_,_,
_,_,_,_,_,_,_,_,_,_,_,_,_,_,_,
_,_,_,_,_,_,_,_,_,_,_,_,_,_,_,
_,_,_,_,_,_,_,_,_,_,_,_,_,_,_,
_,_,_,_,_,_,_,_,_,_,_,_,_,_,_,
_,_,_,_,_,_,_,_,_,_,_,_,_,_,_,
_,_,_,_,_,_,_,_,_,_,_,_,_,_,_,
_,_,_,_,_,_,_,_,_,_,_,_,_,_,_,
_,_,_,_,_,_,_,L,L,_,_,_,_,_,_,
_,_,_,_,_,L,L,L,L,_,_,_,_,_,_,
_,_,_,_,_,_,L,L,_,_,_,_,_,_,_,
_,_,_,_,_,_,_,_,_,_,_,_,_,_,_,
_,_,_,_,_,_,_,_,_,_,_,_,_,_,_,

_,_,_,_,_,_,_,_,_,_,_,_,_,_,_,
_,_,_,_,_,_,_,_,_,_,_,_,_,_,_,
_,_,_,_,_,_,_,_,_,_,_,_,_,_,_,
_,_,_,_,_,_,_,_,_,_,_,_,_,_,_,
_,_,_,_,_,_,_,_,_,_,_,_,_,_,_,
_,_,_,_,_,_,_,_,_,_,_,_,_,_,_,
_,_,_,_,_,_,_,_,_,_,_,_,_,_,_,
_,_,_,_,_,_,_,_,_,_,_,_,_,_,_,
_,_,_,_,_,_,_,_,_,_,_,_,_,_,_,
_,_,_,_,_,_,_,_,_,_,_,_,_,_,_,
_,_,_,_,_,_,_,_,_,_,_,_,_,_,_,
_,_,_,_,_,_,_,_,_,_,_,_,_,_,_,
_,_,_,_,_,_,L,L,L,_,_,_,_,_,_,
_,_,_,_,_,_,_,_,_,_,_,_,_,_,_,
_,_,_,_,_,_,_,_,_,_,_,_,_,_,_,
_,_,_,_,_,_,_,_,_,_,_,_,_,_,_}}

local function grow_baobab_tree(pos)
	if not default.can_grow(pos) then
		-- try a bit later again
		core.get_node_timer(pos):start(math.random(240, 600))
		return
	end
	if on_compost(pos) then
		if not enough_height(pos, 29) then
		core.get_node_timer(pos):start(300)
		return end
		add_tree(pos, 7, 1, 7, baobab_1)
		return
	end
	local model = math.random(1, 3)
	if model == 1 then
		add_tree(pos, 4, 1, 4, baobab_2)
	elseif model == 2 then
		add_tree(pos, 4, 1, 4, baobab_3)
	elseif model == 3 then
		add_tree(pos, 7, 1, 7, baobab_4)
	end
end

local mg_name = core.get_mapgen_setting("mg_name")

if mg_name ~= "v6" and mg_name ~= "singlenode" then
core.register_decoration({
	deco_type = "schematic",
	place_on = {"default:clay_dirt_with_savanna_grass"},
	sidelen = 16,
	noise_params = {
		offset = -0.05,
		scale = 0.001,
		spread = {x = 250, y = 250, z = 250},
		seed = 2,
		octaves = 3,
		persist = 0.66
	},
	biomes = {"savanna"},
	y_min = 1,
	y_max = 31000,
	schematic = baobab_2,
	flags = "place_center_x, place_center_z",
	rotation = "random",
})

core.register_decoration({
	deco_type = "schematic",
	place_on = {"default:clay_dirt_with_savanna_grass"},
	sidelen = 16,
	noise_params = {
		offset = -0.001,
		scale = 0.001,
		spread = {x = 250, y = 250, z = 250},
		seed = 2,
		octaves = 3,
		persist = 0.66
	},
	biomes = {"savanna"},
	y_min = 1,
	y_max = 31000,
	schematic = baobab_3,
	flags = "place_center_x, place_center_z",
	rotation = "random",
})

core.register_decoration({
	deco_type = "schematic",
	place_on = {"default:clay_dirt_with_savanna_grass"},
	sidelen = 16,
	noise_params = {
		offset = -0.001,
		scale = 0.003,
		spread = {x = 250, y = 250, z = 250},
		seed = 2,
		octaves = 3,
		persist = 0.66
	},
	biomes = {"savanna"},
	y_min = 1,
	y_max = 31000,
	schematic = baobab_4,
	flags = "place_center_x, place_center_z",
	rotation = "random",
})
end

core.register_node("baobab:sapling", {
	description = "Baobab Sapling",
	drawtype = "plantlike",
	tiles = {"baobab_sapling.png"},
	inventory_image = "baobab_sapling.png",
	wield_image = "baobab_sapling.png",
	paramtype = "light",
	sunlight_propagates = true,
	walkable = false,
	on_timer = grow_baobab_tree,
	selection_box = {
		type = "fixed",
		fixed = {-4/16, -.5, -4/16, 4/16, 7/16, 4/16}
	},
	groups = {snappy = 2, dig_immediate = 3, flammable = 2, attached_node = 1, sapling = 1},
	sounds = default.node_sound_leaves_defaults(),

	on_construct = function(pos)
		core.get_node_timer(pos):start(math.random(2400,4800))
	end,

	on_place = function(itemstack, placer, pointd)
		itemstack = default.sapling_on_place(itemstack, placer, pointd,
			"baobab:sapling",
			-- minp, maxp to be checked, relative to sapling pos
			-- minp_relative.y = 1 because sapling pos has been checked
			{x = -5, y = 1, z = -5},
			{x = 5, y = 27, z = 5},
			-- maximum interval of interior volume check
			4)

		return itemstack
	end,
	grown_height = 16,
})

core.register_node("baobab:trunk", {
	description = "Baobab Trunk",
	tiles = {"baobab_trunk_top.png", "baobab_trunk_top.png", "baobab_trunk.png"},
	paramtype2 = "facedir",
	is_ground_content = false,
	groups = {choppy = 2, flammable = 1, trunk = 1},
	sounds = default.node_sound_wood_defaults(),
	on_place = core.rotate_node
})

core.register_node("baobab:wood", {
	description = "Baobab Wood Planks",
	tiles = {"baobab_wood.png"},
	paramtype2 = "facedir",
	place_param2 = 0,
	is_ground_content = false,
	groups = {choppy = 2, oddly_breakable_by_hand = 1, flammable = 2, wood=1},
	sounds = default.node_sound_wood_defaults()
})

core.register_node("baobab:leaves", {
	description = "Baobab Leaves",
	drawtype = leaf_drawtype,
	mesh = "leaf_poof.obj",
	waving = waving_style,
	tiles = {"baobab_leaves.png"},
	special_tiles = {"baobab_leaves_simple.png"},
	inventory_image = leaf_image("baobab_leaves.png"),
	wield_image = leaf_image("baobab_leaves.png"),
	use_texture_alpha = "clip",
	paramtype = "light",
	is_ground_content = false,
	collision_box = leaf_cbox,
	groups = {snappy = 3, flammable = 1, leaves = 1, leafdecay = 1},
	drop = {
		max_items = 1,
		items = {
			{items = {"baobab:sapling"}, rarity = 20},
			{items = {"baobab:leaves"}}
		}
	},
	sounds = default.node_sound_leaves_defaults(),
	after_place_node = default.after_place_leaves,
})

core.register_craft({
	output = "baobab:wood 4",
	recipe = {{"baobab:trunk"}}
})

core.register_craft({
	type = "fuel",
	recipe = "baobab:trunk",
	burntime = 29,
})

core.register_craft({
	type = "fuel",
	recipe = "baobab:wood",
	burntime = 9,
})

default.register_leafdecay({
	trunks = {"baobab:trunk"},
	leaves = {"baobab:leaves"},
	radius = 2,
})

core.register_lbm({
	name = "baobab:convert_saplings_to_node_timer",
	nodenames = {"baobab:sapling"},
	action = function(pos)
		core.get_node_timer(pos):start(math.random(1200, 2400))
	end
})

doors.register_fencegate("baobab:wood_gate", {
	description = "Baobab Wood Fence Gate",
	texture = "baobab_wood.png",
	material = "baobab:wood",
	groups = {choppy = 2, oddly_breakable_by_hand = 2, flammable = 2}
})

default.register_fence("baobab:wood_fence", {
	description = "Baobab Wood Fence",
	texture = "baobab_fence.png",
	inventory_image = "default_fence_overlay.png^baobab_fence.png^default_fence_overlay.png^[makealpha:255,126,126",
	wield_image = "default_fence_overlay.png^baobab_fence.png^default_fence_overlay.png^[makealpha:255,126,126",
	material = "baobab:wood",
	groups = {choppy = 2, oddly_breakable_by_hand = 2, flammable = 2},
	sounds = default.node_sound_wood_defaults()
})

if core.get_modpath("stairs") then
stairs.register_stair_and_slab("baobab_wood", "baobab:wood",
	{choppy = 2, oddly_breakable_by_hand = 2, flammable = 2},
	{"baobab_wood.png"},
	"Baobab Wood Stair",
	"Baobab Wood Slab",
	default.node_sound_wood_defaults())
end

if core.get_modpath("bonemeal") then
	bonemeal:add_sapling({
		{"baobab:sapling", grow_baobab_tree, "soil"},
	})
end
