
-- Birch trees

local T = {name = "default:birch_trunk", force_place = true}
local L = {name = "default:birch_leaves"}
local M = {name = "default:birch_leaves", prob = 223}
local N = {name = "default:birch_leaves", prob = 150}

default.birch_tree = {size = {x = 5, y = 11, z = 5}, data = {
_,_,_,_,_,
_,_,_,_,_,
_,_,_,_,_,
_,_,_,_,_,
_,_,_,_,_,
_,N,L,N,_,
_,L,L,L,_,
_,N,L,N,_,
_,_,N,_,_,
_,_,_,_,_,
_,_,_,_,_,

_,_,_,_,_,
_,_,_,_,_,
_,_,_,_,_,
_,_,_,_,_,
_,_,L,_,_,
N,L,L,L,N,
L,L,L,L,L,
N,L,L,L,N,
_,L,L,L,_,
_,N,L,N,_,
_,_,N,_,_,

_,_,T,_,_,
_,_,T,_,_,
_,_,T,_,_,
_,_,T,_,_,
_,L,T,L,_,
L,L,T,L,L,
L,L,T,L,L,
L,L,T,L,L,
N,L,T,L,N,
_,L,L,L,_,
_,N,L,N,_,

_,_,_,_,_,
_,_,_,_,_,
_,_,_,_,_,
_,_,_,_,_,
_,_,L,_,_,
N,L,L,L,N,
L,L,L,L,L,
N,L,L,L,N,
_,L,L,L,_,
_,N,L,N,_,
_,_,L,_,_,

_,_,_,_,_,
_,_,_,_,_,
_,_,_,_,_,
_,_,_,_,_,
_,_,_,_,_,
_,N,L,N,_,
_,L,L,L,_,
_,N,L,N,_,
_,_,N,_,_,
_,_,_,_,_,
_,_,_,_,_},
yslice_prob = {{ypos = 1, prob = 127}, {ypos = 2, prob = 127}}}

default.birch_tree1 = {size = {x = 5, y = 14, z = 5}, data = {
_,_,_,_,_,
_,_,_,_,_,
_,_,_,_,_,
_,_,_,_,_,
_,N,L,N,_,
_,_,_,_,_,
_,_,_,_,_,
_,M,L,M,_,
_,_,_,_,_,
_,M,L,M,_,
_,_,_,_,_,
_,M,L,M,_,
_,_,_,_,_,
_,_,_,_,_,

_,_,_,_,_,
_,_,_,_,_,
_,_,_,_,_,
_,_,_,_,_,
N,L,L,L,N,
_,M,L,M,_,
_,M,L,M,_,
M,L,L,L,M,
_,M,L,M,_,
M,L,L,L,M,
_,M,L,M,_,
M,L,L,L,M,
_,M,L,M,_,
_,_,_,_,_,

_,_,T,_,_,
_,_,T,_,_,
_,_,T,_,_,
_,_,T,_,_,
L,L,T,L,L,
_,L,T,L,_,
_,L,T,L,_,
L,L,T,L,L,
_,L,T,L,_,
L,L,T,L,L,
_,L,T,L,_,
L,L,T,L,L,
_,L,L,L,_,
_,_,L,_,_,

_,_,_,_,_,
_,_,_,_,_,
_,_,_,_,_,
_,_,_,_,_,
N,L,L,L,N,
_,M,L,M,_,
_,M,L,M,_,
M,L,L,L,M,
_,M,L,M,_,
M,L,L,L,M,
_,M,L,M,_,
M,L,L,L,M,
_,M,L,M,_,
_,_,_,_,_,

_,_,_,_,_,
_,_,_,_,_,
_,_,_,_,_,
_,_,_,_,_,
_,N,L,N,_,
_,_,_,_,_,
_,_,_,_,_,
_,M,L,M,_,
_,_,_,_,_,
_,M,L,M,_,
_,_,_,_,_,
_,M,L,M,_,
_,_,_,_,_,
_,_,_,_,_},
yslice_prob = {{ypos = 3, prob = 127}, {ypos = 5, prob = 127}, {ypos = 6, prob = 127}, {ypos = 8, prob = 127}}}

default.birch_tree2 = {size = {x = 13, y = 17, z = 13}, data = {
_,_,_,_,_,_,_,_,_,_,_,_,_,
_,_,_,_,_,_,_,_,_,_,_,_,_,
_,_,_,_,_,_,_,_,_,_,_,_,_,
_,_,_,_,_,_,_,_,_,_,_,_,_,
_,_,_,_,_,_,_,_,_,_,_,_,_,
_,_,_,_,_,_,_,_,_,_,_,_,_,
_,_,_,_,_,_,_,_,_,_,_,_,_,
_,_,_,_,_,_,_,_,_,_,_,_,_,
_,_,_,_,_,_,L,_,_,_,_,_,_,
_,_,_,_,_,L,L,L,_,_,_,_,_,
_,_,_,_,_,L,L,L,_,_,_,_,_,
_,_,_,_,_,_,M,_,_,_,_,_,_,
_,_,_,_,_,_,_,_,_,_,_,_,_,
_,_,_,_,_,_,_,_,_,_,_,_,_,
_,_,_,_,_,_,_,_,_,_,_,_,_,
_,_,_,_,_,_,_,_,_,_,_,_,_,
_,_,_,_,_,_,_,_,_,_,_,_,_,

_,_,_,_,_,_,_,_,_,_,_,_,_,
_,_,_,_,_,_,_,_,_,_,_,_,_,
_,_,_,_,_,_,_,_,_,_,_,_,_,
_,_,_,_,_,_,_,_,_,_,_,_,_,
_,_,_,_,_,_,_,_,_,_,_,_,_,
_,_,_,M,_,_,_,_,_,_,_,_,_,
_,_,L,L,L,_,_,_,_,M,_,_,_,
_,_,L,L,L,_,M,_,L,L,L,_,_,
_,_,_,M,_,L,L,L,L,L,L,_,_,
_,_,_,_,L,L,L,L,L,M,_,_,_,
_,_,_,_,L,L,L,L,L,_,_,_,_,
_,_,_,_,_,L,L,L,_,_,_,_,_,
_,_,_,_,_,M,L,M,_,_,_,_,_,
_,_,_,_,_,_,_,_,_,_,_,_,_,
_,_,_,_,_,_,_,_,_,_,_,_,_,
_,_,_,_,_,_,_,_,_,_,_,_,_,
_,_,_,_,_,_,_,_,_,_,_,_,_,

_,_,_,_,_,_,_,_,_,_,_,_,_,
_,_,_,_,_,_,_,_,_,_,_,_,_,
_,_,_,_,_,_,_,_,_,_,_,_,_,
_,_,_,_,_,_,_,_,_,_,_,_,_,
_,_,_,L,_,_,_,_,_,_,_,_,_,
_,_,L,L,L,_,_,_,_,L,_,_,_,
_,L,L,L,L,M,_,M,L,L,L,_,_,
_,L,L,L,L,L,L,L,L,L,L,L,_,
_,_,L,L,L,L,L,L,L,L,L,L,_,
_,_,M,L,L,L,T,L,L,L,L,_,_,
_,_,_,_,L,L,T,L,L,L,M,_,_,
_,_,_,_,M,L,T,L,L,_,_,_,_,
_,_,_,_,_,L,L,L,_,_,_,_,_,
_,_,_,_,_,_,L,_,_,_,_,_,_,
_,_,_,_,_,_,_,_,_,_,_,_,_,
_,_,_,_,_,_,_,_,_,_,_,_,_,
_,_,_,_,_,_,_,_,_,_,_,_,_,

_,_,_,_,_,_,_,_,_,_,_,_,_,
_,_,_,_,_,_,_,_,_,_,_,_,_,
_,_,_,_,_,_,_,_,_,_,_,_,_,
_,_,_,_,_,_,_,_,_,_,_,_,_,
_,_,L,L,L,_,_,_,_,_,_,_,_,
_,M,L,L,L,M,_,_,L,L,L,_,_,
_,L,L,T,L,L,_,L,L,L,L,M,_,
_,L,L,T,L,L,_,L,L,T,L,L,_,
_,M,L,T,L,L,T,L,L,T,L,L,_,
_,_,L,L,L,L,L,L,L,T,L,M,_,
_,_,_,L,L,L,L,L,L,L,L,_,_,
_,_,_,_,L,L,L,L,L,L,_,_,_,
_,_,_,_,_,L,L,L,_,_,_,_,_,
_,_,_,_,_,_,_,_,_,_,_,_,_,
_,_,_,_,_,_,_,_,_,_,_,_,_,
_,_,_,_,_,_,_,_,_,_,_,_,_,
_,_,_,_,_,_,_,_,_,_,_,_,_,

_,_,_,_,_,_,_,_,_,_,_,_,_,
_,_,_,_,_,_,_,_,_,_,_,_,_,
_,_,_,_,_,_,_,_,_,_,_,_,_,
_,_,_,_,_,_,_,_,_,_,_,_,_,
_,_,_,L,_,_,_,_,_,_,_,_,_,
_,_,L,L,T,_,_,_,_,L,_,_,_,
_,L,L,L,L,_,_,_,T,L,L,_,_,
_,L,L,L,L,L,T,_,L,L,L,L,_,
_,_,L,L,L,L,_,L,L,L,L,L,_,
_,_,L,L,L,_,L,L,L,L,L,_,_,
_,L,L,L,L,L,L,L,L,L,L,L,_,
_,L,L,L,L,L,L,L,L,L,L,L,_,
_,_,L,_,L,L,L,L,L,_,L,_,_,
_,_,_,_,_,L,L,L,_,_,_,_,_,
_,_,_,_,_,_,M,_,_,_,_,_,_,
_,_,_,_,_,_,_,_,_,_,_,_,_,
_,_,_,_,_,_,_,_,_,_,_,_,_,

_,_,_,_,_,_,_,_,_,_,_,_,_,
_,_,_,_,_,_,_,_,_,_,_,_,_,
_,_,_,_,_,_,_,_,_,_,_,_,_,
_,_,_,_,_,_,_,_,_,_,_,_,_,
_,_,_,_,_,T,_,_,_,_,_,_,_,
_,_,_,M,_,_,_,T,_,_,_,_,_,
_,_,M,L,_,_,T,_,_,M,_,_,_,
_,_,L,L,L,_,_,_,_,L,M,_,_,
_,_,L,L,L,_,_,_,L,L,L,_,_,
_,L,L,L,_,_,_,_,L,L,L,L,_,
L,L,L,L,L,_,L,_,L,L,L,L,L,
L,L,L,L,L,L,L,L,L,L,L,L,L,
_,L,L,L,L,L,L,L,L,L,L,L,_,
_,M,L,_,L,L,L,L,L,_,L,M,_,
_,_,_,_,_,L,L,L,_,_,_,_,_,
_,_,_,_,_,M,L,M,_,_,_,_,_,
_,_,_,_,_,_,_,_,_,_,_,_,_,

_,_,_,_,_,_,T,_,_,_,_,_,_,
_,_,_,_,_,_,T,_,_,_,_,_,_,
_,_,_,_,_,_,T,_,_,_,_,_,_,
_,_,_,_,_,_,T,_,_,_,_,_,_,
_,_,_,_,_,_,T,_,_,_,_,_,_,
_,_,_,_,_,_,T,_,_,_,_,_,_,
_,_,_,_,_,_,T,_,_,_,_,_,_,
_,_,_,_,_,T,T,T,_,_,_,_,_,
_,M,L,_,T,_,T,_,T,_,L,M,_,
L,L,L,T,_,_,T,_,_,T,L,L,L,
L,L,T,L,L,L,T,L,L,L,T,L,L,
L,L,T,L,L,L,T,L,L,L,T,L,L,
M,L,T,L,L,L,T,L,L,L,T,L,M,
_,L,L,L,L,L,T,L,L,L,L,L,_,
_,_,L,_,M,L,T,L,M,_,L,_,_,
_,_,_,_,_,L,L,L,_,_,_,_,_,
_,_,_,_,_,_,L,_,_,_,_,_,_,

_,_,_,_,_,_,_,_,_,_,_,_,_,
_,_,_,_,_,_,_,_,_,_,_,_,_,
_,_,_,_,_,_,_,_,_,_,_,_,_,
_,_,_,_,_,_,_,_,_,_,_,_,_,
_,_,_,_,_,_,_,T,_,_,_,_,_,
_,_,_,_,_,T,_,_,_,M,_,_,_,
_,_,_,M,_,_,T,_,_,L,M,_,_,
_,_,M,L,_,_,_,_,L,L,L,_,_,
_,_,L,L,L,_,_,_,L,L,L,_,_,
_,L,L,L,L,_,_,_,_,L,L,L,_,
L,L,L,L,L,_,L,_,L,L,L,L,L,
L,L,L,L,L,L,L,L,L,L,L,L,L,
_,L,L,L,L,L,L,L,L,L,L,L,_,
_,M,L,_,L,L,L,L,L,_,L,M,_,
_,_,_,_,_,L,L,L,_,_,_,_,_,
_,_,_,_,_,M,L,M,_,_,_,_,_,
_,_,_,_,_,_,_,_,_,_,_,_,_,

_,_,_,_,_,_,_,_,_,_,_,_,_,
_,_,_,_,_,_,_,_,_,_,_,_,_,
_,_,_,_,_,_,_,_,_,_,_,_,_,
_,_,_,_,_,_,_,_,_,_,_,_,_,
_,_,_,_,_,_,_,_,_,L,_,_,_,
_,_,_,L,_,_,_,_,T,L,L,_,_,
_,_,L,L,T,_,_,_,L,L,L,L,_,
_,L,L,L,L,_,T,L,L,L,L,L,_,
_,L,L,L,L,L,_,L,L,L,L,_,_,
_,_,L,L,L,L,L,_,L,L,L,_,_,
_,L,L,L,L,L,L,L,L,L,L,L,_,
_,L,L,L,L,L,L,L,L,L,L,L,_,
_,_,L,_,L,L,L,L,L,_,L,_,_,
_,_,_,_,_,L,L,L,_,_,_,_,_,
_,_,_,_,_,_,M,_,_,_,_,_,_,
_,_,_,_,_,_,_,_,_,_,_,_,_,
_,_,_,_,_,_,_,_,_,_,_,_,_,

_,_,_,_,_,_,_,_,_,_,_,_,_,
_,_,_,_,_,_,_,_,_,_,_,_,_,
_,_,_,_,_,_,_,_,_,_,_,_,_,
_,_,_,_,_,_,_,_,_,_,_,_,_,
_,_,_,_,_,_,_,_,L,L,L,_,_,
_,_,L,L,L,_,_,M,L,L,L,M,_,
_,M,L,L,L,L,_,L,L,T,L,L,_,
_,L,L,T,L,L,_,L,L,T,L,L,_,
_,L,L,T,L,L,T,L,L,T,L,M,_,
_,M,L,T,L,L,L,L,L,L,L,_,_,
_,_,L,L,L,L,L,L,L,L,_,_,_,
_,_,_,L,L,L,L,L,L,_,_,_,_,
_,_,_,_,_,L,L,L,_,_,_,_,_,
_,_,_,_,_,_,_,_,_,_,_,_,_,
_,_,_,_,_,_,_,_,_,_,_,_,_,
_,_,_,_,_,_,_,_,_,_,_,_,_,
_,_,_,_,_,_,_,_,_,_,_,_,_,

_,_,_,_,_,_,_,_,_,_,_,_,_,
_,_,_,_,_,_,_,_,_,_,_,_,_,
_,_,_,_,_,_,_,_,_,_,_,_,_,
_,_,_,_,_,_,_,_,_,_,_,_,_,
_,_,_,_,_,_,_,_,_,L,_,_,_,
_,_,_,L,_,_,_,_,L,L,L,_,_,
_,_,L,L,L,M,_,M,L,L,L,L,_,
_,L,L,L,L,L,L,L,L,L,L,L,_,
_,L,L,L,L,L,L,L,L,L,L,_,_,
_,_,L,L,L,L,T,L,L,L,M,_,_,
_,_,M,L,L,L,T,L,L,_,_,_,_,
_,_,_,_,L,L,T,L,M,_,_,_,_,
_,_,_,_,_,L,L,L,_,_,_,_,_,
_,_,_,_,_,_,L,_,_,_,_,_,_,
_,_,_,_,_,_,_,_,_,_,_,_,_,
_,_,_,_,_,_,_,_,_,_,_,_,_,
_,_,_,_,_,_,_,_,_,_,_,_,_,

_,_,_,_,_,_,_,_,_,_,_,_,_,
_,_,_,_,_,_,_,_,_,_,_,_,_,
_,_,_,_,_,_,_,_,_,_,_,_,_,
_,_,_,_,_,_,_,_,_,_,_,_,_,
_,_,_,_,_,_,_,_,_,_,_,_,_,
_,_,_,_,_,_,_,_,_,M,_,_,_,
_,_,_,M,_,_,_,_,L,L,L,_,_,
_,_,L,L,L,_,M,_,L,L,L,_,_,
_,_,L,L,L,L,L,L,_,M,_,_,_,
_,_,_,M,L,L,L,L,L,_,_,_,_,
_,_,_,_,L,L,L,L,L,_,_,_,_,
_,_,_,_,_,L,L,L,_,_,_,_,_,
_,_,_,_,_,M,L,M,_,_,_,_,_,
_,_,_,_,_,_,_,_,_,_,_,_,_,
_,_,_,_,_,_,_,_,_,_,_,_,_,
_,_,_,_,_,_,_,_,_,_,_,_,_,
_,_,_,_,_,_,_,_,_,_,_,_,_,

_,_,_,_,_,_,_,_,_,_,_,_,_,
_,_,_,_,_,_,_,_,_,_,_,_,_,
_,_,_,_,_,_,_,_,_,_,_,_,_,
_,_,_,_,_,_,_,_,_,_,_,_,_,
_,_,_,_,_,_,_,_,_,_,_,_,_,
_,_,_,_,_,_,_,_,_,_,_,_,_,
_,_,_,_,_,_,_,_,_,_,_,_,_,
_,_,_,_,_,_,_,_,_,_,_,_,_,
_,_,_,_,_,_,L,_,_,_,_,_,_,
_,_,_,_,_,L,L,L,_,_,_,_,_,
_,_,_,_,_,L,L,L,_,_,_,_,_,
_,_,_,_,_,_,M,_,_,_,_,_,_,
_,_,_,_,_,_,_,_,_,_,_,_,_,
_,_,_,_,_,_,_,_,_,_,_,_,_,
_,_,_,_,_,_,_,_,_,_,_,_,_,
_,_,_,_,_,_,_,_,_,_,_,_,_,
_,_,_,_,_,_,_,_,_,_,_,_,_},
yslice_prob = {{ypos = 2, prob = 127}}}
