
-- Jungle trees

local L = {name = "default:jungle_leaves"}
local M = {name = "default:jungle_leaves", prob = 223}
local V = {name = "default:jungle_leaves", prob = 191}
local N = {name = "default:jungle_leaves", prob = 127}
local T = {name = "default:jungle_trunk", force_place = true}
local U = {name = "default:jungle_trunk", prob = 127, force_place = true}

default.jungle_tree = {size = {x = 5, y = 17, z = 5}, data = {
_,_,_,_,_,
_,_,_,_,_,
_,_,_,_,_,
_,_,_,_,_,
_,_,_,_,_,
_,_,_,_,_,
_,_,_,_,_,
_,_,_,_,_,
_,_,_,_,_,
_,_,_,_,_,
M,L,M,_,_,
_,_,M,L,M,
_,_,_,_,_,
_,_,_,_,_,
V,M,M,M,V,
V,M,M,M,V,
_,_,_,_,_,

_,_,T,_,_,
_,_,T,_,_,
_,_,U,_,_,
_,_,_,_,_,
_,_,_,_,_,
_,_,_,_,_,
_,_,_,_,_,
_,_,_,_,_,
_,_,_,_,_,
_,_,_,_,_,
L,T,L,_,_,
_,_,L,T,L,
_,_,_,_,_,
_,_,_,_,_,
M,T,L,T,M,
M,L,L,L,M,
_,M,M,M,_,

_,T,T,T,_,
_,T,T,T,_,
_,U,T,U,_,
_,_,T,_,_,
_,_,T,_,_,
_,_,T,_,_,
_,_,T,_,_,
_,_,T,_,_,
_,_,T,L,M,
M,L,T,_,_,
M,L,T,_,_,
_,_,T,L,M,
_,_,T,L,M,
_,_,T,_,_,
M,L,L,L,M,
M,L,L,L,M,
_,M,L,M,_,

_,_,T,_,_,
_,_,T,_,_,
_,_,U,_,_,
_,_,_,_,_,
_,_,_,_,_,
_,_,_,_,_,
_,_,_,_,_,
_,_,_,_,_,
_,_,L,T,L,
L,T,L,_,_,
_,_,_,_,_,
_,_,_,_,_,
_,_,L,T,L,
_,_,_,_,_,
M,T,L,T,M,
M,L,L,L,M,
_,M,M,M,_,

_,_,_,_,_,
_,_,_,_,_,
_,_,_,_,_,
_,_,_,_,_,
_,_,_,_,_,
_,_,_,_,_,
_,_,_,_,_,
_,_,_,_,_,
_,_,M,L,M,
M,L,M,_,_,
_,_,_,_,_,
_,_,_,_,_,
_,_,M,L,M,
_,_,_,_,_,
V,M,M,M,V,
V,M,M,M,V,
_,_,_,_,_},
yslice_prob = {{ypos = 6, prob = 191}, {ypos = 7, prob = 191}, {ypos = 8, prob = 191}, {ypos = 9, prob = 191}, {ypos = 10, prob = 191}}}

default.emergent_jungle_tree = {size = {x = 7, y = 37, z = 7}, data = {
_,_,_,_,_,_,_,
_,_,_,_,_,_,_,
_,_,_,_,_,_,_,
T,_,_,_,_,_,T,
T,_,_,_,_,_,T,
T,_,_,_,_,_,T,
U,_,_,_,_,_,U,
_,_,_,_,_,_,_,
_,_,_,_,_,_,_,
_,_,_,_,_,_,_,
_,_,_,_,_,_,_,
_,_,_,_,_,_,_,
_,_,_,_,_,_,_,
_,_,_,_,_,_,_,
_,_,_,_,_,_,_,
_,_,_,_,_,_,_,
_,_,_,_,_,_,_,
_,_,_,_,_,_,_,
_,_,_,_,_,_,_,
M,M,M,_,_,_,_,
_,_,_,_,_,_,_,
_,_,_,_,M,M,M,
_,_,_,_,_,_,_,
_,_,_,_,_,_,_,
_,_,M,M,M,_,_,
_,_,_,_,_,_,_,
_,_,_,_,_,_,_,
M,M,M,_,_,_,_,
_,_,_,_,_,_,_,
_,_,_,_,M,M,M,
_,_,_,_,_,_,_,
_,_,_,_,_,_,_,
_,N,N,N,N,N,_,
_,M,M,M,M,M,_,
_,M,M,M,M,M,_,
_,M,M,M,M,M,_,
_,_,_,_,_,_,_,

_,_,_,_,_,_,_,
_,_,T,_,T,_,_,
_,T,T,_,T,T,_,
_,T,T,_,T,T,_,
_,T,T,_,T,T,_,
_,T,T,_,T,T,_,
_,T,T,_,T,T,_,
_,U,T,_,T,U,_,
_,_,U,_,U,_,_,
_,_,_,_,_,_,_,
_,_,_,_,_,_,_,
_,_,_,_,_,_,_,
_,_,_,_,_,_,_,
_,_,_,_,_,_,_,
_,_,_,_,_,_,_,
_,_,_,_,_,_,_,
_,_,_,_,_,_,_,
_,_,_,_,_,_,_,
_,_,_,_,_,_,_,
M,T,M,_,_,_,_,
_,_,_,_,_,_,_,
_,_,_,_,M,T,M,
_,_,_,_,_,_,_,
_,_,_,_,_,_,_,
_,_,M,T,M,_,_,
_,_,_,_,_,_,_,
_,_,_,_,_,_,_,
M,T,M,_,_,_,_,
_,_,_,_,_,_,_,
_,_,_,_,M,T,M,
_,_,_,_,_,_,_,
_,_,_,_,_,_,_,
N,_,_,_,_,_,N,
M,L,_,_,_,L,M,
M,T,L,L,L,T,M,
M,L,L,L,L,L,M,
_,M,M,M,M,M,_,

_,_,T,_,T,_,_,
_,T,T,_,T,T,_,
_,T,T,_,T,T,_,
_,T,T,_,T,T,_,
_,T,T,T,T,T,_,
_,T,T,T,T,T,_,
_,T,T,T,T,T,_,
_,T,T,T,T,T,_,
_,U,T,T,T,U,_,
_,_,T,T,T,_,_,
_,_,T,T,T,_,_,
_,_,T,T,T,_,_,
_,_,T,T,T,_,_,
_,_,T,T,T,_,_,
_,_,T,T,T,_,_,
_,_,T,T,T,_,_,
_,_,T,T,T,_,_,
_,_,T,T,T,_,_,
_,_,T,T,T,_,_,
M,M,T,T,T,_,_,
_,_,T,T,T,_,_,
_,_,_,T,T,M,M,
M,M,M,T,_,_,_,
_,_,_,T,_,_,_,
_,_,M,T,M,_,_,
_,_,_,T,_,_,_,
_,_,_,T,M,M,M,
M,M,T,T,_,_,_,
_,_,_,T,_,_,_,
_,_,_,T,T,M,M,
M,M,M,T,_,_,_,
_,_,_,T,_,_,_,
N,_,T,T,T,_,N,
M,_,T,_,T,_,M,
M,L,L,_,L,L,M,
M,L,L,L,L,L,M,
_,M,L,L,L,M,_,

_,_,_,_,_,_,_,
_,_,_,_,_,_,_,
_,_,_,_,_,_,_,
_,_,_,_,_,_,_,
_,_,T,T,T,_,_,
_,_,T,T,T,_,_,
_,_,T,T,T,_,_,
_,_,T,T,T,_,_,
_,_,T,T,T,_,_,
_,_,T,T,T,_,_,
_,_,T,T,T,_,_,
_,_,T,T,T,_,_,
_,_,T,T,T,_,_,
_,_,T,T,T,_,_,
_,_,T,T,T,_,_,
_,_,T,T,T,_,_,
_,_,T,T,T,_,_,
_,_,T,T,T,_,_,
_,_,T,T,T,_,_,
_,_,T,T,T,_,_,
_,_,T,T,T,_,_,
_,_,T,T,T,_,_,
M,T,T,T,T,_,_,
_,_,T,T,T,_,_,
_,_,T,T,T,_,_,
_,_,T,T,T,_,_,
_,_,T,T,T,T,M,
_,_,T,T,T,_,_,
_,_,T,T,T,_,_,
_,_,T,T,T,_,_,
M,T,T,T,T,_,_,
_,_,T,T,T,_,_,
N,_,T,_,T,_,N,
M,_,_,_,_,_,M,
M,L,_,_,_,L,M,
M,L,L,L,L,L,M,
_,M,L,L,L,M,_,

_,_,T,_,T,_,_,
_,T,T,_,T,T,_,
_,T,T,_,T,T,_,
_,T,T,_,T,T,_,
_,T,T,T,T,T,_,
_,T,T,T,T,T,_,
_,T,T,T,T,T,_,
_,T,T,T,T,T,_,
_,U,T,T,T,U,_,
_,_,T,T,T,_,_,
_,_,T,T,T,_,_,
_,_,T,T,T,_,_,
_,_,T,T,T,_,_,
_,_,T,T,T,_,_,
_,_,T,T,T,_,_,
_,_,T,T,T,_,_,
_,_,T,T,T,_,_,
_,_,T,T,T,_,_,
_,_,T,T,T,_,_,
_,_,T,T,T,_,_,
_,_,T,T,T,_,_,
_,_,_,T,_,_,_,
M,M,M,T,_,_,_,
_,_,_,T,T,M,M,
_,_,_,T,_,_,_,
M,M,T,T,_,_,_,
_,_,_,T,M,M,M,
_,_,_,T,_,_,_,
_,_,M,T,M,_,_,
_,_,_,T,_,_,_,
M,M,M,T,_,_,_,
_,_,_,T,_,_,_,
N,_,T,T,T,_,N,
M,_,T,_,T,_,M,
M,L,L,_,L,L,M,
M,L,L,L,L,L,M,
_,M,L,L,L,M,_,

_,_,_,_,_,_,_,
_,_,T,_,T,_,_,
_,T,T,_,T,T,_,
_,T,T,_,T,T,_,
_,T,T,_,T,T,_,
_,T,T,_,T,T,_,
_,T,T,_,T,T,_,
_,U,T,_,T,U,_,
_,_,U,_,U,_,_,
_,_,_,_,_,_,_,
_,_,_,_,_,_,_,
_,_,_,_,_,_,_,
_,_,_,_,_,_,_,
_,_,_,_,_,_,_,
_,_,_,_,_,_,_,
_,_,_,_,_,_,_,
_,_,_,_,_,_,_,
_,_,_,_,_,_,_,
_,_,_,_,_,_,_,
_,_,_,_,_,_,_,
_,_,M,T,M,_,_,
_,_,_,_,_,_,_,
_,_,_,_,_,_,_,
_,_,_,_,M,T,M,
_,_,_,_,_,_,_,
M,T,M,_,_,_,_,
_,_,_,_,_,_,_,
_,_,_,_,_,_,_,
_,_,M,T,M,_,_,
_,_,_,_,_,_,_,
_,_,_,_,_,_,_,
_,_,_,_,_,_,_,
N,_,_,_,_,_,N,
M,L,_,_,_,L,M,
M,T,L,L,L,T,M,
M,L,L,L,L,L,M,
_,M,M,M,M,M,_,

_,_,_,_,_,_,_,
_,_,_,_,_,_,_,
_,_,_,_,_,_,_,
T,_,_,_,_,_,T,
T,_,_,_,_,_,T,
T,_,_,_,_,_,T,
U,_,_,_,_,_,U,
_,_,_,_,_,_,_,
_,_,_,_,_,_,_,
_,_,_,_,_,_,_,
_,_,_,_,_,_,_,
_,_,_,_,_,_,_,
_,_,_,_,_,_,_,
_,_,_,_,_,_,_,
_,_,_,_,_,_,_,
_,_,_,_,_,_,_,
_,_,_,_,_,_,_,
_,_,_,_,_,_,_,
_,_,_,_,_,_,_,
_,_,_,_,_,_,_,
_,_,M,M,M,_,_,
_,_,_,_,_,_,_,
_,_,_,_,_,_,_,
_,_,_,_,M,M,M,
_,_,_,_,_,_,_,
M,M,M,_,_,_,_,
_,_,_,_,_,_,_,
_,_,_,_,_,_,_,
_,_,M,M,M,_,_,
_,_,_,_,_,_,_,
_,_,_,_,_,_,_,
_,_,_,_,_,_,_,
_,N,N,N,N,N,_,
_,M,M,M,M,M,_,
_,M,M,M,M,M,_,
_,M,M,M,M,M,_,
_,_,_,_,_,_,_},
yslice_prob = {{ypos = 13, prob = 127}, {ypos = 14, prob = 127}, {ypos = 15, prob = 127}, {ypos = 16, prob = 127},
	{ypos = 17, prob = 127}, {ypos = 18, prob = 127}, {ypos = 19, prob = 127}, {ypos = 20, prob = 127},
	{ypos = 21, prob = 127}, {ypos = 22, prob = 127}, {ypos = 23, prob = 127}, {ypos = 24, prob = 127}}}

-- Jungle tree log

default.jungle_log = {size = {x = 5, y = 2, z = 1}, data = {
{name = "default:jungle_trunk", param2 = 12, prob = 127},
{name = "default:jungle_trunk", param2 = 12},
{name = "default:jungle_trunk", param2 = 12},
{name = "default:jungle_trunk", param2 = 12},
{name = "default:jungle_trunk", param2 = 12, prob = 127},
_,
_,
{name = "flowers:mushroom_brown", prob = 127},
_,
_}}
