
-- Pine trees

local T = {name = "default:pine_trunk", force_place = true}
local L = {name = "default:pine_needles"}
local C = {name = "default:pinecone_needles"}
local M = {name = "default:pinecone_needles", prob = 223}
local N = {name = "default:pinecone_needles", prob = 191}

default.pine_tree = {size = {x = 5, y = 16, z = 5}, data = {
_,_,_,_,_,
_,_,_,_,_,
_,_,_,_,_,
_,_,_,_,_,
_,_,_,_,_,
_,_,_,_,_,
_,_,_,_,_,
N,M,C,M,N,
_,_,_,_,_,
_,_,_,_,_,
N,M,C,M,N,
_,_,_,_,_,
_,_,_,_,_,
N,M,C,M,N,
_,_,_,_,_,
_,_,_,_,_,

_,_,_,_,_,
_,_,_,_,_,
_,_,_,_,_,
_,_,_,_,_,
_,_,_,_,_,
_,_,_,_,_,
_,_,_,_,_,
M,L,_,L,M,
_,L,L,L,_,
_,_,_,_,_,
M,L,_,L,M,
_,L,L,L,_,
_,_,_,_,_,
M,L,_,L,M,
_,C,C,C,_,
_,_,_,_,_,

_,_,T,_,_,
_,_,T,_,_,
_,_,T,_,_,
_,_,T,_,_,
_,_,T,_,_,
_,_,T,_,_,
_,_,T,_,_,
C,_,T,_,C,
_,L,T,L,_,
_,_,T,_,_,
C,_,T,_,C,
_,L,T,L,_,
_,_,T,_,_,
C,_,T,_,C,
_,C,L,C,_,
_,_,C,_,_,

_,_,_,_,_,
_,_,_,_,_,
_,_,_,_,_,
_,_,_,_,_,
_,_,_,_,_,
_,_,_,_,_,
_,_,_,_,_,
M,L,_,L,M,
_,L,L,L,_,
_,_,_,_,_,
M,L,_,L,M,
_,L,L,L,_,
_,_,_,_,_,
M,L,_,L,M,
_,C,C,C,_,
_,_,_,_,_,

_,_,_,_,_,
_,_,_,_,_,
_,_,_,_,_,
_,_,_,_,_,
_,_,_,_,_,
_,_,_,_,_,
_,_,_,_,_,
N,M,C,M,N,
_,_,_,_,_,
_,_,_,_,_,
N,M,C,M,N,
_,_,_,_,_,
_,_,_,_,_,
N,M,C,M,N,
_,_,_,_,_,
_,_,_,_,_},
yslice_prob = {{ypos = 2, prob = 127}, {ypos = 3, prob = 127}, {ypos = 4, prob = 127},
	{ypos = 5, prob = 127}, {ypos = 9, prob = 127}, {ypos = 12, prob = 127}}}

default.small_pine_tree = {size = {x = 5, y = 12, z = 5}, data = {
_,_,_,_,_,
_,_,_,_,_,
_,_,_,_,_,
_,_,_,_,_,
_,L,L,L,_,
_,_,L,_,_,
_,_,_,_,_,
_,_,_,_,_,
_,_,_,_,_,
_,_,_,_,_,
_,_,_,_,_,
_,_,_,_,_,

_,_,_,_,_,
_,_,_,_,_,
_,_,_,_,_,
_,_,_,_,_,
L,L,_,L,L,
_,L,L,L,_,
_,L,L,L,_,
_,L,L,L,_,
_,_,L,_,_,
_,_,L,_,_,
_,_,_,_,_,
_,_,_,_,_,

_,_,T,_,_,
_,_,T,_,_,
_,_,T,_,_,
_,_,T,_,_,
L,_,T,_,L,
L,L,T,L,L,
_,L,T,L,_,
_,L,T,L,_,
_,L,T,L,_,
_,L,T,L,_,
_,_,L,_,_,
_,_,L,_,_,

_,_,_,_,_,
_,_,_,_,_,
_,_,_,_,_,
_,_,_,_,_,
L,L,_,L,L,
_,L,L,L,_,
_,L,L,L,_,
_,L,L,L,_,
_,_,L,_,_,
_,_,L,_,_,
_,_,_,_,_,
_,_,_,_,_,

_,_,_,_,_,
_,_,_,_,_,
_,_,_,_,_,
_,_,_,_,_,
_,L,L,L,_,
_,_,L,_,_,
_,_,_,_,_,
_,_,_,_,_,
_,_,_,_,_,
_,_,_,_,_,
_,_,_,_,_,
_,_,_,_,_},
yslice_prob = {{ypos = 2, prob = 127}, {ypos = 3, prob = 127}, {ypos = 4, prob = 127}}}

default.pine_tree2 = {size = {x = 7, y = 25, z = 7}, data = {
_,_,_,_,_,_,_,
_,_,_,_,_,_,_,
_,_,_,_,_,_,_,
_,_,_,_,_,_,_,
_,_,_,_,_,_,_,
_,_,_,_,_,_,_,
_,_,_,_,_,_,_,
_,_,_,_,_,_,_,
_,M,C,C,C,M,_,
_,_,_,_,_,_,_,
_,_,_,_,_,_,_,
_,M,C,C,C,M,_,
_,_,_,_,_,_,_,
_,_,_,_,_,_,_,
_,_,C,C,C,_,_,
_,_,_,_,_,_,_,
_,_,_,_,_,_,_,
_,_,_,_,_,_,_,
_,_,_,_,_,_,_,
_,_,_,_,_,_,_,
_,_,_,_,_,_,_,
_,_,_,_,_,_,_,
_,_,_,_,_,_,_,
_,_,_,_,_,_,_,
_,_,_,_,_,_,_,

_,_,_,_,_,_,_,
_,_,_,_,_,_,_,
_,_,_,_,_,_,_,
_,_,_,_,_,_,_,
_,_,_,_,_,_,_,
_,_,_,_,_,_,_,
_,_,_,_,_,_,_,
_,_,_,_,_,_,_,
M,L,L,L,L,L,M,
_,_,L,L,L,_,_,
_,_,_,_,_,_,_,
M,L,L,L,L,L,M,
_,_,L,L,L,_,_,
_,_,_,_,_,_,_,
_,C,L,L,L,C,_,
_,_,L,L,L,_,_,
_,_,_,_,_,_,_,
_,_,C,C,C,_,_,
_,_,_,_,_,_,_,
_,_,_,_,_,_,_,
_,_,C,C,C,_,_,
_,_,_,_,_,_,_,
_,_,_,_,_,_,_,
_,_,_,_,_,_,_,
_,_,_,_,_,_,_,

_,_,_,_,_,_,_,
_,_,_,_,_,_,_,
_,_,_,_,_,_,_,
_,_,_,_,_,_,_,
_,_,_,_,_,_,_,
_,_,_,_,_,_,_,
_,_,_,_,_,_,_,
_,_,_,_,_,_,_,
C,L,L,T,L,L,C,
_,L,L,L,L,L,_,
_,_,_,_,_,_,_,
C,L,L,T,L,L,C,
_,L,L,L,L,L,_,
_,_,_,_,_,_,_,
C,L,L,T,L,L,C,
_,L,L,L,L,L,_,
_,_,_,_,_,_,_,
_,C,L,L,L,C,_,
_,_,_,L,_,_,_,
_,_,_,_,_,_,_,
_,C,L,L,L,C,_,
_,_,_,L,_,_,_,
_,_,C,L,C,_,_,
_,_,_,C,_,_,_,
_,_,_,_,_,_,_,

_,_,_,T,_,_,_,
_,_,_,T,_,_,_,
_,_,_,T,_,_,_,
_,_,_,T,_,_,_,
_,_,_,T,_,_,_,
_,_,_,T,_,_,_,
_,_,_,T,_,_,_,
_,_,_,T,_,_,_,
C,L,T,T,T,L,C,
_,L,L,T,L,L,_,
_,_,_,T,_,_,_,
C,L,T,T,T,L,C,
_,L,L,T,L,L,_,
_,_,_,T,_,_,_,
C,L,T,T,T,L,C,
_,L,L,T,L,L,_,
_,_,_,T,_,_,_,
_,C,L,T,L,C,_,
_,_,L,T,L,_,_,
_,_,_,T,_,_,_,
_,C,L,T,L,C,_,
_,_,L,T,L,_,_,
_,_,L,T,L,_,_,
_,_,C,L,C,_,_,
_,_,_,C,_,_,_,

_,_,_,_,_,_,_,
_,_,_,_,_,_,_,
_,_,_,_,_,_,_,
_,_,_,_,_,_,_,
_,_,_,_,_,_,_,
_,_,_,_,_,_,_,
_,_,_,_,_,_,_,
_,_,_,_,_,_,_,
C,L,L,T,L,L,C,
_,L,L,L,L,L,_,
_,_,_,_,_,_,_,
C,L,L,T,L,L,C,
_,L,L,L,L,L,_,
_,_,_,_,_,_,_,
C,L,L,T,L,L,C,
_,L,L,L,L,L,_,
_,_,_,_,_,_,_,
_,C,L,L,L,C,_,
_,_,_,L,_,_,_,
_,_,_,_,_,_,_,
_,C,L,L,L,C,_,
_,_,_,L,_,_,_,
_,_,C,L,C,_,_,
_,_,_,C,_,_,_,
_,_,_,_,_,_,_,

_,_,_,_,_,_,_,
_,_,_,_,_,_,_,
_,_,_,_,_,_,_,
_,_,_,_,_,_,_,
_,_,_,_,_,_,_,
_,_,_,_,_,_,_,
_,_,_,_,_,_,_,
_,_,_,_,_,_,_,
M,L,L,L,L,L,M,
_,_,L,L,L,_,_,
_,_,_,_,_,_,_,
M,L,L,L,L,L,M,
_,_,L,L,L,_,_,
_,_,_,_,_,_,_,
_,C,L,L,L,C,_,
_,_,L,L,L,_,_,
_,_,_,_,_,_,_,
_,_,C,C,C,_,_,
_,_,_,_,_,_,_,
_,_,_,_,_,_,_,
_,_,C,C,C,_,_,
_,_,_,_,_,_,_,
_,_,_,_,_,_,_,
_,_,_,_,_,_,_,
_,_,_,_,_,_,_,

_,_,_,_,_,_,_,
_,_,_,_,_,_,_,
_,_,_,_,_,_,_,
_,_,_,_,_,_,_,
_,_,_,_,_,_,_,
_,_,_,_,_,_,_,
_,_,_,_,_,_,_,
_,_,_,_,_,_,_,
_,M,C,C,C,M,_,
_,_,_,_,_,_,_,
_,_,_,_,_,_,_,
_,M,C,C,C,M,_,
_,_,_,_,_,_,_,
_,_,_,_,_,_,_,
_,_,C,C,C,_,_,
_,_,_,_,_,_,_,
_,_,_,_,_,_,_,
_,_,_,_,_,_,_,
_,_,_,_,_,_,_,
_,_,_,_,_,_,_,
_,_,_,_,_,_,_,
_,_,_,_,_,_,_,
_,_,_,_,_,_,_,
_,_,_,_,_,_,_,
_,_,_,_,_,_,_},
yslice_prob = {{ypos = 2, prob = 127}, {ypos = 4, prob = 127}, {ypos = 19, prob = 127}}}

default.pine_tree3 = {size = {x = 7, y = 25, z = 7}, data = {
_,_,_,_,_,_,_,
_,_,_,_,_,_,_,
_,_,_,_,_,_,_,
_,_,_,_,_,_,_,
_,_,_,_,_,_,_,
_,_,_,_,_,_,_,
_,_,_,_,_,_,_,
_,_,_,_,_,_,_,
_,M,C,C,C,M,_,
_,_,_,_,_,_,_,
_,_,_,_,_,_,_,
_,M,C,C,C,M,_,
_,_,_,_,_,_,_,
_,_,_,_,_,_,_,
_,M,C,C,C,M,_,
_,_,_,_,_,_,_,
_,_,_,_,_,_,_,
_,_,C,C,C,_,_,
_,_,_,_,_,_,_,
_,_,_,_,_,_,_,
_,_,_,_,_,_,_,
_,_,_,_,_,_,_,
_,_,_,_,_,_,_,
_,_,_,_,_,_,_,
_,_,_,_,_,_,_,

_,_,_,_,_,_,_,
_,_,_,_,_,_,_,
_,_,_,_,_,_,_,
_,_,_,_,_,_,_,
_,_,_,_,_,_,_,
_,_,_,_,_,_,_,
_,_,_,_,_,_,_,
_,_,_,_,_,_,_,
M,L,L,L,L,L,M,
_,_,L,L,L,_,_,
_,_,_,_,_,_,_,
M,L,L,L,L,L,M,
_,_,L,L,L,_,_,
_,_,_,_,_,_,_,
M,L,L,L,L,L,M,
_,_,L,L,L,_,_,
_,_,_,_,_,_,_,
_,C,L,L,L,C,_,
_,_,_,L,_,_,_,
_,_,_,_,_,_,_,
_,_,C,C,C,_,_,
_,_,_,_,_,_,_,
_,_,_,_,_,_,_,
_,_,_,_,_,_,_,
_,_,_,_,_,_,_,

_,_,_,_,_,_,_,
_,_,_,_,_,_,_,
_,_,_,_,_,_,_,
_,_,_,_,_,_,_,
_,_,_,_,_,_,_,
_,_,_,_,_,_,_,
_,_,_,_,_,_,_,
_,_,_,_,_,_,_,
C,L,L,T,L,L,C,
_,L,L,L,L,L,_,
_,_,_,_,_,_,_,
C,L,L,T,L,L,C,
_,L,L,L,L,L,_,
_,_,_,_,_,_,_,
C,L,L,T,L,L,C,
_,L,L,L,L,L,_,
_,_,_,_,_,_,_,
C,L,L,T,L,L,C,
_,_,L,L,L,_,_,
_,_,_,_,_,_,_,
_,C,L,L,L,C,_,
_,_,_,L,_,_,_,
_,_,C,L,C,_,_,
_,_,_,C,_,_,_,
_,_,_,_,_,_,_,

_,_,_,T,_,_,_,
_,_,_,T,_,_,_,
_,_,_,T,_,_,_,
_,_,_,T,_,_,_,
_,_,_,T,_,_,_,
_,_,_,T,_,_,_,
_,_,_,T,_,_,_,
_,_,_,T,_,_,_,
C,L,T,T,T,L,C,
_,L,L,T,L,L,_,
_,_,_,T,_,_,_,
C,L,T,T,T,L,C,
_,L,L,T,L,L,_,
_,_,_,T,_,_,_,
C,L,T,T,T,L,C,
_,L,L,T,L,L,_,
_,_,_,T,_,_,_,
C,L,T,T,T,L,C,
_,L,L,T,L,L,_,
_,_,_,T,_,_,_,
_,C,L,T,L,C,_,
_,_,L,T,L,_,_,
_,_,L,T,L,_,_,
_,_,C,L,C,_,_,
_,_,_,C,_,_,_,

_,_,_,_,_,_,_,
_,_,_,_,_,_,_,
_,_,_,_,_,_,_,
_,_,_,_,_,_,_,
_,_,_,_,_,_,_,
_,_,_,_,_,_,_,
_,_,_,_,_,_,_,
_,_,_,_,_,_,_,
C,L,L,T,L,L,C,
_,L,L,L,L,L,_,
_,_,_,_,_,_,_,
C,L,L,T,L,L,C,
_,L,L,L,L,L,_,
_,_,_,_,_,_,_,
C,L,L,T,L,L,C,
_,L,L,L,L,L,_,
_,_,_,_,_,_,_,
C,L,L,T,L,L,C,
_,_,L,L,L,_,_,
_,_,_,_,_,_,_,
_,C,L,L,L,C,_,
_,_,_,L,_,_,_,
_,_,C,L,C,_,_,
_,_,_,C,_,_,_,
_,_,_,_,_,_,_,

_,_,_,_,_,_,_,
_,_,_,_,_,_,_,
_,_,_,_,_,_,_,
_,_,_,_,_,_,_,
_,_,_,_,_,_,_,
_,_,_,_,_,_,_,
_,_,_,_,_,_,_,
_,_,_,_,_,_,_,
M,L,L,L,L,L,M,
_,_,L,L,L,_,_,
_,_,_,_,_,_,_,
M,L,L,L,L,L,M,
_,_,L,L,L,_,_,
_,_,_,_,_,_,_,
M,L,L,L,L,L,M,
_,_,L,L,L,_,_,
_,_,_,_,_,_,_,
_,C,L,L,L,C,_,
_,_,_,L,_,_,_,
_,_,_,_,_,_,_,
_,_,C,C,C,_,_,
_,_,_,_,_,_,_,
_,_,_,_,_,_,_,
_,_,_,_,_,_,_,
_,_,_,_,_,_,_,

_,_,_,_,_,_,_,
_,_,_,_,_,_,_,
_,_,_,_,_,_,_,
_,_,_,_,_,_,_,
_,_,_,_,_,_,_,
_,_,_,_,_,_,_,
_,_,_,_,_,_,_,
_,_,_,_,_,_,_,
_,M,C,C,C,M,_,
_,_,_,_,_,_,_,
_,_,_,_,_,_,_,
_,M,C,C,C,M,_,
_,_,_,_,_,_,_,
_,_,_,_,_,_,_,
_,M,C,C,C,M,_,
_,_,_,_,_,_,_,
_,_,_,_,_,_,_,
_,_,C,C,C,_,_,
_,_,_,_,_,_,_,
_,_,_,_,_,_,_,
_,_,_,_,_,_,_,
_,_,_,_,_,_,_,
_,_,_,_,_,_,_,
_,_,_,_,_,_,_,
_,_,_,_,_,_,_},
yslice_prob = {{ypos = 2, prob = 127}, {ypos = 4, prob = 127}}}

-- Pine tree log

default.pine_log = {size = {x = 5, y = 2, z = 1}, data = {
{name = "default:pine_trunk", param2 = 12, prob = 127},
{name = "default:pine_trunk", param2 = 12},
{name = "default:pine_trunk", param2 = 12},
{name = "default:pine_trunk", param2 = 12},
{name = "default:pine_trunk", param2 = 12, prob = 127},
_,
_,
{name = "flowers:mushroom_red", prob = 63},
_,
_}}

-- Pine bush

local L = {name = "default:pine_bush_needles"}
local M = {name = "default:pine_bush_needles", prob = 191}
local N = {name = "default:pine_bush_needles", prob = 127}
local S = {name = "default:pine_bush_stem", force_place = true}

default.pine_bush = {size = {x = 3, y = 2, z = 3}, data = {
M,L,M,
N,M,N,

L,S,L,
M,L,M,

M,L,M,
N,M,N}}
