-- Ecology schematics

bamboo_small = {size = {x = 1, y = 4, z = 1}, data = {
_,
{name = "ecology:bamboo_small"},
{name = "ecology:bamboo_small"},
{name = "ecology:bamboo_small_top"}},
yslice_prob = {{ypos = 2, prob = 127}}}

local L = {name = "ecology:bush_leaves", force_place = true}
local M = {name = "ecology:bush_leaves", prob = 223}
local V = {name = "ecology:bush_leaves", prob = 95}

shrub = {size = {x = 3, y = 1, z = 3}, data = {
V,M,V,

M,L,M,

V,M,V}}

local B = {name = "ecology:big_mushroom_brown"}
local T = {name = "ecology:big_mushroom_stem", force_place = true}
local G = {name = "ecology:giant_cortinarius_violaceus_cap"}
local R = {name = "ecology:red_mush_cap"}
local r = {name = "ecology:big_mushroom_red"}

mushroom_large = {size = {x = 10, y = 10, z = 10}, data = {
_,_,_,_,_,_,_,_,_,_,
_,_,_,_,_,_,_,_,_,_,
_,_,_,_,_,_,_,_,_,_,
_,_,_,_,_,_,_,_,_,_,
_,_,_,_,_,_,_,_,_,_,
_,_,_,_,_,_,_,_,_,_,
_,_,_,_,_,_,_,_,_,_,
_,_,_,_,_,_,_,_,_,_,
_,_,_,B,B,_,_,_,_,_,
_,_,_,_,_,B,B,_,_,_,

_,_,_,_,_,_,_,_,_,_,
_,_,_,_,_,_,_,_,_,_,
_,_,_,_,_,_,_,_,_,_,
_,_,_,_,_,_,_,_,_,_,
_,_,_,_,_,_,_,_,_,_,
_,_,_,_,_,_,_,_,_,_,
_,_,_,_,_,_,_,_,_,_,
_,_,_,_,_,_,_,_,_,_,
_,_,B,B,B,_,_,_,_,_,
_,_,_,_,_,B,B,B,_,_,

_,_,_,_,_,_,_,_,_,_,
_,_,_,_,_,_,_,_,_,_,
_,_,_,_,_,_,_,_,_,_,
_,_,_,_,_,_,_,_,_,_,
_,_,_,_,_,_,_,_,_,_,
_,_,_,_,_,_,_,_,_,_,
_,_,_,_,_,_,_,_,_,_,
_,_,_,_,_,_,_,_,_,_,
_,B,B,B,B,_,_,_,_,_,
_,_,_,_,_,B,B,B,B,_,

_,_,_,_,_,_,_,_,_,_,
_,_,_,_,_,_,_,_,_,_,
_,_,_,_,_,_,_,_,_,_,
_,_,_,_,_,_,_,_,_,_,
_,_,_,_,_,_,_,_,_,_,
_,_,_,_,_,_,_,_,_,_,
_,_,_,_,_,_,_,_,_,_,
_,_,_,_,_,_,_,_,_,_,
B,B,B,B,B,B,_,_,_,_,
_,_,_,_,_,B,B,B,B,B,

_,_,_,_,T,T,_,_,_,_,
_,_,_,_,T,T,_,_,_,_,
_,_,_,_,T,T,_,_,_,_,
_,_,_,_,T,T,_,_,_,_,
_,_,_,_,T,T,_,_,_,_,
_,_,_,_,T,T,_,_,_,_,
_,_,_,_,T,T,_,_,_,_,
_,_,_,_,T,T,_,_,_,_,
B,B,B,B,B,B,B,_,_,_,
_,_,_,_,_,_,B,B,B,B,

_,_,_,_,T,T,_,_,_,_,
_,_,_,_,T,T,_,_,_,_,
_,_,_,_,T,T,_,_,_,_,
_,_,_,_,T,T,_,_,_,_,
_,_,_,_,T,T,_,_,_,_,
_,_,_,_,T,T,_,_,_,_,
_,_,_,_,T,T,_,_,_,_,
B,B,B,B,B,T,_,_,_,_,
_,_,_,B,B,B,B,B,B,B,
_,_,_,_,_,_,_,_,_,_,

_,_,_,_,_,_,_,_,_,_,
_,_,_,_,_,_,_,_,_,_,
_,_,_,_,_,_,_,_,_,_,
_,_,_,_,_,_,_,_,_,_,
_,_,_,_,_,_,_,_,_,_,
_,_,_,_,_,_,_,_,_,_,
_,_,_,_,_,_,_,_,_,_,
B,B,B,B,B,_,_,_,_,_,
_,_,_,_,B,B,B,B,B,B,
_,_,_,_,_,_,_,_,_,_,

_,_,_,_,_,_,_,_,_,_,
_,_,_,_,_,_,_,_,_,_,
_,_,_,_,_,_,_,_,_,_,
_,_,_,_,_,_,_,_,_,_,
_,_,_,_,_,_,_,_,_,_,
_,_,_,_,_,_,_,_,_,_,
_,_,_,_,_,_,_,_,_,_,
_,B,B,B,B,_,_,_,_,_,
_,_,_,_,_,B,B,B,B,_,
_,_,_,_,_,_,_,_,_,_,

_,_,_,_,_,_,_,_,_,_,
_,_,_,_,_,_,_,_,_,_,
_,_,_,_,_,_,_,_,_,_,
_,_,_,_,_,_,_,_,_,_,
_,_,_,_,_,_,_,_,_,_,
_,_,_,_,_,_,_,_,_,_,
_,_,_,_,_,_,_,_,_,_,
_,_,B,B,B,_,_,_,_,_,
_,_,_,_,_,B,B,B,_,_,
_,_,_,_,_,_,_,_,_,_,

_,_,_,_,_,_,_,_,_,_,
_,_,_,_,_,_,_,_,_,_,
_,_,_,_,_,_,_,_,_,_,
_,_,_,_,_,_,_,_,_,_,
_,_,_,_,_,_,_,_,_,_,
_,_,_,_,_,_,_,_,_,_,
_,_,_,_,_,_,_,_,_,_,
_,_,_,B,B,_,_,_,_,_,
_,_,_,_,_,B,B,_,_,_,
_,_,_,_,_,_,_,_,_,_},
yslice_prob = {{ypos = 2, prob = 127}}}

giant_corti = {size = {x = 5, y = 7, z = 5}, data = {
_,_,_,_,_,
_,_,_,_,_,
_,_,_,_,_,
_,_,_,_,_,
_,G,G,G,_,
_,G,G,G,_,
_,_,_,_,_,

_,_,_,_,_,
_,_,_,_,_,
_,_,_,_,_,
_,_,_,_,_,
G,_,_,_,G,
G,G,_,G,G,
_,G,G,G,_,

_,_,T,_,_,
_,_,T,_,_,
_,_,T,_,_,
_,_,T,_,_,
G,_,T,_,G,
G,_,T,_,G,
_,G,G,G,_,

_,_,_,_,_,
_,_,_,_,_,
_,_,_,_,_,
_,_,_,_,_,
G,_,_,_,G,
G,G,_,G,G,
_,G,G,G,_,

_,_,_,_,_,
_,_,_,_,_,
_,_,_,_,_,
_,_,_,_,_,
_,G,G,G,_,
_,G,G,G,_,
_,_,_,_,_},
yslice_prob = {{ypos = 2, prob = 127}}}

giant_red_mush = {size = {x = 5, y = 6, z = 5}, data = {
_,_,_,_,_,
_,_,_,_,_,
_,_,_,_,_,
_,_,_,_,_,
_,R,R,R,_,
_,_,_,_,_,

_,_,_,_,_,
_,_,_,_,_,
_,_,_,_,_,
_,_,_,_,_,
R,R,_,R,R,
_,R,R,R,_,

_,_,T,_,_,
_,_,T,_,_,
_,_,T,_,_,
_,_,T,_,_,
R,_,T,_,R,
_,R,R,R,_,

_,_,_,_,_,
_,_,_,_,_,
_,_,_,_,_,
_,_,_,_,_,
R,R,_,R,R,
_,R,R,R,_,

_,_,_,_,_,
_,_,_,_,_,
_,_,_,_,_,
_,_,_,_,_,
_,R,R,R,_,
_,_,_,_,_},
yslice_prob = {{ypos = 2, prob = 127}}}

big_red_mush = {size = {x = 3, y = 4, z = 3}, data = {
_,_,_,
_,_,_,
r,r,r,
_,r,_,

_,T,_,
_,T,_,
r,T,r,
r,r,r,

_,_,_,
_,_,_,
r,r,r,
_,r,_}}

local C = {name = "ecology:brain_block", force_place = true}
local V = {name = "ecology:brain_block", prob = 138, force_place = true}

brain_coral = {size = {x = 5, y = 4, z = 5}, data = {
_,_,_,_,_,
_,C,C,C,_,
_,C,C,C,_,
_,_,_,_,_,

_,C,C,C,_,
C,_,_,_,C,
C,_,_,_,C,
_,V,C,C,_,

_,C,_,C,_,
C,_,_,_,C,
C,_,_,_,C,
_,C,C,C,_,

_,C,C,C,_,
C,_,_,_,C,
C,_,_,_,C,
_,C,C,_,_,

_,_,_,_,_,
_,C,C,C,_,
_,C,C,C,_,
_,_,_,_,_}}

brain_coral2 = {size = {x = 3, y = 7, z = 3}, data = {
_,_,_,
_,_,_,
_,_,_,
_,C,_,
_,C,_,
_,V,_,
_,_,_,

_,C,_,
_,C,_,
_,C,C,
C,_,C,
C,_,V,
C,_,_,
V,_,_,

_,_,_,
_,_,_,
_,C,_,
_,C,_,
_,C,_,
_,C,_,
_,V,_}}

C = {name = "ecology:bubble_block", force_place = true}
V = {name = "ecology:bubble_block", prob = 138, force_place = true}

bubble_coral = {size = {x = 5, y = 4, z = 5}, data = {
_,_,_,_,_,
_,C,C,C,_,
_,C,C,C,_,
_,_,_,_,_,

_,C,C,C,_,
C,_,_,_,C,
C,_,_,_,C,
_,V,C,C,_,

_,C,_,C,_,
C,_,_,_,C,
C,_,_,_,C,
_,C,C,C,_,

_,C,C,C,_,
C,_,_,_,C,
C,_,_,_,C,
_,C,C,_,_,

_,_,_,_,_,
_,C,C,C,_,
_,C,C,C,_,
_,_,_,_,_}}

C = {name = "ecology:tube_block", force_place = true}
V = {name = "ecology:tube_block", prob = 138, force_place = true}

tube_coral = {size = {x = 3, y = 7, z = 3}, data = {
C,C,C,
C,C,C,
_,C,_,
_,C,_,
_,C,_,
_,V,_,
_,_,_,

C,C,C,
C,_,C,
C,_,C,
C,_,C,
V,_,C,
_,_,C,
_,_,V,

C,C,C,
C,C,_,
_,C,_,
_,C,_,
_,V,_,
_,_,_,
_,_,_}}