
-- White willow tree	Salix alba

-- internationalization boilerplate
local S = core.get_translator(core.get_current_modname())

local L = {name = "white_willow:leaves"}
local M = {name = "white_willow:leaves", prob = 126}
local T = {name = "white_willow:trunk", force_place = true}

white_willow_tree = {size = {x=5, y=8, z=5}, data = {
_,_,_,_,_,
_,_,_,_,_,
_,_,_,_,_,
_,_,_,_,_,
_,M,L,M,_,
_,L,L,L,_,
_,L,M,L,_,
_,_,_,_,_,

_,_,_,_,_,
_,_,_,_,_,
_,_,_,_,_,
_,M,L,M,_,
M,L,L,L,M,
L,L,L,L,L,
L,L,L,L,L,
_,M,L,M,_,

_,_,T,_,_,
_,_,T,_,_,
_,_,T,_,_,
_,L,T,L,_,
L,L,T,L,L,
L,L,T,L,L,
M,L,L,L,M,
_,L,L,L,_,

_,_,_,_,_,
_,_,_,_,_,
_,_,_,_,_,
_,M,L,M,_,
M,L,L,L,M,
L,L,L,L,L,
L,L,L,L,L,
_,M,L,M,_,

_,_,_,_,_,
_,_,_,_,_,
_,_,_,_,_,
_,_,_,_,_,
_,M,L,M,_,
_,L,L,L,_,
_,L,M,L,_,
_,_,_,_,_},
yslice_prob = {{ypos=2, prob=123}, {ypos=4, prob=123}}}

white_willow_tree2 = {size = {x=23, y=20, z=23}, data = {
_,_,_,_,_,_,_,_,_,_,_,_,_,_,_,_,_,_,_,_,_,_,_,
_,_,_,_,_,_,_,_,_,_,_,_,_,_,_,_,_,_,_,_,_,_,_,
_,_,_,_,_,_,_,_,_,_,_,_,_,_,_,_,_,_,_,_,_,_,_,
_,_,_,_,_,_,_,_,_,_,_,_,_,_,_,_,_,_,_,_,_,_,_,
_,_,_,_,_,_,_,_,_,_,_,_,_,_,_,_,_,_,_,_,_,_,_,
_,_,_,_,_,_,_,_,_,_,_,_,_,_,_,_,_,_,_,_,_,_,_,
_,_,_,_,_,_,_,_,_,_,_,_,_,_,_,_,_,_,_,_,_,_,_,
_,_,_,_,_,_,_,_,_,_,_,_,_,_,_,_,_,_,_,_,_,_,_,
_,_,_,_,_,_,_,_,_,_,_,_,_,_,_,_,_,_,_,_,_,_,_,
_,_,_,_,_,_,_,_,_,_,_,_,_,_,_,_,_,_,_,_,_,_,_,
_,_,_,_,_,_,_,_,_,_,M,L,M,_,_,_,_,_,_,_,_,_,_,
_,_,_,_,_,_,_,_,_,_,L,L,L,_,_,_,_,_,_,_,_,_,_,
_,_,_,_,_,_,_,_,_,_,L,M,L,_,_,_,_,_,_,_,_,_,_,
_,_,_,_,_,_,_,_,_,_,_,_,_,_,_,_,_,_,_,_,_,_,_,
_,_,_,_,_,_,_,_,_,_,_,_,_,_,_,_,_,_,_,_,_,_,_,
_,_,_,_,_,_,_,_,_,_,_,_,_,_,_,_,_,_,_,_,_,_,_,
_,_,_,_,_,_,_,_,_,_,_,_,_,_,_,_,_,_,_,_,_,_,_,
_,_,_,_,_,_,_,_,_,_,_,_,_,_,_,_,_,_,_,_,_,_,_,
_,_,_,_,_,_,_,_,_,_,_,_,_,_,_,_,_,_,_,_,_,_,_,
_,_,_,_,_,_,_,_,_,_,_,_,_,_,_,_,_,_,_,_,_,_,_,

_,_,_,_,_,_,_,_,_,_,_,_,_,_,_,_,_,_,_,_,_,_,_,
_,_,_,_,_,_,_,_,_,_,_,_,_,_,_,_,_,_,_,_,_,_,_,
_,_,_,_,_,_,_,_,_,_,_,_,_,_,_,_,_,_,_,_,_,_,_,
_,_,_,_,_,_,_,_,_,_,_,_,_,_,_,_,_,_,_,_,_,_,_,
_,_,_,_,_,_,_,_,_,_,_,_,_,_,_,_,_,_,_,_,_,_,_,
_,_,_,_,_,_,_,_,_,_,_,_,_,_,_,_,_,_,_,_,_,_,_,
_,_,_,_,_,_,_,_,_,_,_,_,_,_,_,_,_,_,_,_,_,_,_,
_,_,_,_,_,_,_,_,_,_,_,_,_,_,_,_,_,_,_,_,_,_,_,
_,_,_,_,_,_,_,_,_,_,_,_,_,_,_,_,_,_,_,_,_,_,_,
_,_,_,_,_,_,_,_,_,_,_,_,_,_,_,_,_,_,_,_,_,_,_,
_,_,_,_,_,_,_,_,_,M,L,L,L,M,_,_,_,_,_,_,_,_,_,
_,_,_,_,_,_,_,_,_,L,L,L,L,L,_,_,_,_,_,_,_,_,_,
_,_,_,_,_,_,_,_,_,L,L,L,L,L,_,_,_,_,_,_,_,_,_,
_,_,_,_,_,_,_,_,_,_,M,L,M,_,_,_,_,_,_,_,_,_,_,
_,_,_,_,_,_,_,_,_,_,_,_,_,_,_,_,_,_,_,_,_,_,_,
_,_,_,_,_,_,_,_,_,_,_,_,_,_,_,_,_,_,_,_,_,_,_,
_,_,_,_,_,_,_,_,_,_,_,_,_,_,_,_,_,_,_,_,_,_,_,
_,_,_,_,_,_,_,_,_,_,_,_,_,_,_,_,_,_,_,_,_,_,_,
_,_,_,_,_,_,_,_,_,_,_,_,_,_,_,_,_,_,_,_,_,_,_,
_,_,_,_,_,_,_,_,_,_,_,_,_,_,_,_,_,_,_,_,_,_,_,

_,_,_,_,_,_,_,_,_,_,_,_,_,_,_,_,_,_,_,_,_,_,_,
_,_,_,_,_,_,_,_,_,_,_,_,_,_,_,_,_,_,_,_,_,_,_,
_,_,_,_,_,_,_,_,_,_,_,_,_,_,_,_,_,_,_,_,_,_,_,
_,_,_,_,_,_,_,_,_,_,_,_,_,_,_,_,_,_,_,_,_,_,_,
_,_,_,_,_,_,_,_,_,_,_,_,_,_,_,_,_,_,_,_,_,_,_,
_,_,_,_,_,_,_,_,_,_,_,_,_,_,_,_,_,_,_,_,_,_,_,
_,_,_,_,_,_,_,_,_,_,_,_,_,_,_,_,_,_,_,_,_,_,_,
_,_,_,_,_,_,_,_,_,_,_,_,_,_,_,_,_,_,_,_,_,_,_,
_,_,_,_,_,_,_,_,_,_,_,_,_,_,_,_,_,_,_,_,_,_,_,
_,_,_,_,_,_,_,_,_,_,_,_,_,_,_,_,_,_,_,_,_,_,_,
_,_,_,_,_,_,_,_,_,L,L,L,L,L,_,_,_,_,_,_,_,_,_,
_,_,_,_,_,_,_,_,_,L,L,T,L,L,_,_,_,_,_,_,_,_,_,
_,_,_,_,_,_,_,_,_,M,L,L,L,M,_,_,_,_,_,_,_,_,_,
_,_,_,_,_,_,_,_,_,_,L,L,L,_,_,_,_,_,_,_,_,_,_,
_,_,_,_,_,_,_,_,_,_,_,_,_,_,_,_,_,_,_,_,_,_,_,
_,_,_,_,_,_,_,_,_,_,_,_,_,_,_,_,_,_,_,_,_,_,_,
_,_,_,_,_,_,_,_,_,_,_,_,_,_,_,_,_,_,_,_,_,_,_,
_,_,_,_,_,_,_,_,_,_,_,_,_,_,_,_,_,_,_,_,_,_,_,
_,_,_,_,_,_,_,_,_,_,_,_,_,_,_,_,_,_,_,_,_,_,_,
_,_,_,_,_,_,_,_,_,_,_,_,_,_,_,_,_,_,_,_,_,_,_,

_,_,_,_,_,_,_,_,_,_,_,_,_,_,_,_,_,_,_,_,_,_,_,
_,_,_,_,_,_,_,_,_,_,_,_,_,_,_,_,_,_,_,_,_,_,_,
_,_,_,_,_,_,_,_,_,_,_,_,_,_,_,_,_,_,_,_,_,_,_,
_,_,_,_,_,_,_,_,_,_,_,_,_,_,_,_,_,_,_,_,_,_,_,
_,_,_,_,_,_,_,_,_,_,_,_,_,_,_,_,_,_,_,_,_,_,_,
_,_,_,_,_,_,_,_,_,_,_,_,_,_,_,_,_,_,_,_,_,_,_,
_,_,_,_,_,_,_,_,_,_,_,_,_,_,_,_,_,_,_,_,_,_,_,
_,_,_,_,_,_,_,_,_,_,_,_,_,_,_,_,_,_,_,_,_,_,_,
_,_,_,_,_,_,_,_,_,_,_,_,_,_,_,_,_,_,_,_,_,_,_,
_,_,_,_,_,_,_,_,_,_,_,_,_,_,_,_,_,_,_,_,_,_,_,
_,_,_,_,_,_,_,_,_,M,L,T,L,M,_,_,_,_,_,_,_,_,_,
_,_,_,_,M,L,M,_,_,L,L,L,L,L,_,_,M,L,M,_,_,_,_,
_,_,_,_,L,L,L,_,_,L,L,L,L,L,_,_,L,L,L,_,_,_,_,
_,_,_,_,L,M,L,_,_,_,L,L,L,_,_,_,L,M,L,_,_,_,_,
_,_,_,_,_,_,_,_,_,_,L,M,L,_,_,_,_,_,_,_,_,_,_,
_,_,_,_,_,_,_,_,_,_,_,_,_,_,_,_,_,_,_,_,_,_,_,
_,_,_,_,_,_,_,_,_,_,_,_,_,_,_,_,_,_,_,_,_,_,_,
_,_,_,_,_,_,_,_,_,_,_,_,_,_,_,_,_,_,_,_,_,_,_,
_,_,_,_,_,_,_,_,_,_,_,_,_,_,_,_,_,_,_,_,_,_,_,
_,_,_,_,_,_,_,_,_,_,_,_,_,_,_,_,_,_,_,_,_,_,_,

_,_,_,_,_,_,_,_,_,_,_,_,_,_,_,_,_,_,_,_,_,_,_,
_,_,_,_,_,_,_,_,_,_,_,_,_,_,_,_,_,_,_,_,_,_,_,
_,_,_,_,_,_,_,_,_,_,_,_,_,_,_,_,_,_,_,_,_,_,_,
_,_,_,_,_,_,_,_,_,_,_,_,_,_,_,_,_,_,_,_,_,_,_,
_,_,_,_,_,_,_,_,_,_,_,_,_,_,_,_,_,_,_,_,_,_,_,
_,_,_,_,_,_,_,_,_,_,_,_,_,_,_,_,_,_,_,_,_,_,_,
_,_,_,_,_,_,_,_,_,_,_,_,_,_,_,_,_,_,_,_,_,_,_,
_,_,_,_,_,_,_,_,_,_,_,_,_,_,_,_,_,_,_,_,_,_,_,
_,_,_,_,_,_,_,_,_,_,_,_,_,_,_,_,_,_,_,_,_,_,_,
_,_,_,_,_,_,_,_,_,_,_,T,_,_,_,_,_,_,_,_,_,_,_,
_,_,_,_,_,_,_,_,_,_,M,T,M,_,_,_,_,_,_,_,_,_,_,
_,_,_,M,L,L,L,M,_,_,L,L,L,_,_,M,L,L,L,M,_,_,_,
_,_,_,L,L,L,L,L,_,M,L,L,L,M,_,L,L,L,L,L,_,_,_,
_,_,_,L,L,L,L,L,_,L,L,L,L,L,_,L,L,L,L,L,_,_,_,
_,_,_,_,M,L,M,_,_,L,L,L,L,L,_,_,M,L,M,_,_,_,_,
_,_,_,_,_,_,_,_,_,_,M,L,M,_,_,_,_,_,_,_,_,_,_,
_,_,_,_,_,_,_,_,_,_,_,_,_,_,_,_,_,_,_,_,_,_,_,
_,_,_,_,_,_,_,_,_,_,_,_,_,_,_,_,_,_,_,_,_,_,_,
_,_,_,_,_,_,_,_,_,_,_,_,_,_,_,_,_,_,_,_,_,_,_,
_,_,_,_,_,_,_,_,_,_,_,_,_,_,_,_,_,_,_,_,_,_,_,

_,_,_,_,_,_,_,_,_,_,_,_,_,_,_,_,_,_,_,_,_,_,_,
_,_,_,_,_,_,_,_,_,_,_,_,_,_,_,_,_,_,_,_,_,_,_,
_,_,_,_,_,_,_,_,_,_,_,_,_,_,_,_,_,_,_,_,_,_,_,
_,_,_,_,_,_,_,_,_,_,_,_,_,_,_,_,_,_,_,_,_,_,_,
_,_,_,_,_,_,_,_,_,_,_,_,_,_,_,_,_,_,_,_,_,_,_,
_,_,_,_,_,_,_,_,_,_,_,_,_,_,_,_,_,_,_,_,_,_,_,
_,_,_,_,_,_,_,_,_,_,_,_,_,_,_,_,_,_,_,_,_,_,_,
_,_,_,_,_,_,_,_,_,_,_,_,_,_,_,_,_,_,_,_,_,_,_,
_,_,_,_,_,_,_,_,_,_,_,_,_,_,_,_,_,_,_,_,_,_,_,
_,_,_,_,_,_,_,_,_,_,_,T,_,_,_,_,_,_,_,_,_,_,_,
_,_,_,_,_,_,_,_,_,_,_,_,_,_,_,_,_,_,_,_,_,_,_,
_,_,_,L,L,L,L,L,_,_,_,_,_,_,_,L,L,L,L,L,_,_,_,
_,_,_,L,L,T,L,L,_,L,L,L,L,L,_,L,L,T,L,L,_,_,_,
_,_,_,M,L,L,L,M,_,L,L,T,L,L,_,M,L,L,L,M,_,_,_,
_,_,_,_,L,L,L,_,_,M,L,L,L,M,_,_,L,L,L,_,_,_,_,
_,_,_,_,_,_,_,_,_,_,L,L,L,_,_,_,_,_,_,_,_,_,_,
_,_,_,_,_,_,_,_,_,_,_,_,_,_,_,_,_,_,_,_,_,_,_,
_,_,_,_,_,_,_,_,_,_,_,_,_,_,_,_,_,_,_,_,_,_,_,
_,_,_,_,_,_,_,_,_,_,_,_,_,_,_,_,_,_,_,_,_,_,_,
_,_,_,_,_,_,_,_,_,_,_,_,_,_,_,_,_,_,_,_,_,_,_,

_,_,_,_,_,_,_,_,_,_,_,_,_,_,_,_,_,_,_,_,_,_,_,
_,_,_,_,_,_,_,_,_,_,_,_,_,_,_,_,_,_,_,_,_,_,_,
_,_,_,_,_,_,_,_,_,_,_,_,_,_,_,_,_,_,_,_,_,_,_,
_,_,_,_,_,_,_,_,_,_,_,_,_,_,_,_,_,_,_,_,_,_,_,
_,_,_,_,_,_,_,_,_,_,_,_,_,_,_,_,_,_,_,_,_,_,_,
_,_,_,_,_,_,_,_,_,_,_,_,_,_,_,_,_,_,_,_,_,_,_,
_,_,_,_,_,_,_,_,_,_,_,_,_,_,_,_,_,_,_,_,_,_,_,
_,_,_,_,_,_,_,_,_,_,_,_,_,_,_,_,_,_,_,_,_,_,_,
_,_,_,_,_,_,_,_,_,_,_,T,_,_,_,_,_,_,_,_,_,_,_,
_,_,_,_,_,_,_,_,_,_,_,T,_,_,_,_,_,_,_,_,_,_,_,
_,_,_,_,_,_,_,_,_,_,_,_,_,_,_,_,_,_,_,_,_,_,_,
_,_,_,M,L,L,T,M,_,_,_,_,_,_,_,M,T,L,L,M,_,_,_,
_,_,_,L,L,L,L,L,_,M,L,L,L,M,_,L,L,L,L,L,_,_,_,
_,_,_,L,L,L,L,L,_,L,L,T,L,L,_,L,L,L,L,L,_,_,_,
_,_,_,_,M,L,M,M,L,L,L,L,L,L,L,M,M,L,M,_,_,_,_,
_,_,_,_,_,_,_,L,L,L,M,L,M,L,L,L,_,_,_,_,_,_,_,
_,_,_,_,_,_,_,L,M,L,_,_,_,L,M,L,_,_,_,_,_,_,_,
_,_,_,_,_,_,_,_,_,_,_,_,_,_,_,_,_,_,_,_,_,_,_,
_,_,_,_,_,_,_,_,_,_,_,_,_,_,_,_,_,_,_,_,_,_,_,
_,_,_,_,_,_,_,_,_,_,_,_,_,_,_,_,_,_,_,_,_,_,_,

_,_,_,_,_,_,_,_,_,_,_,_,_,_,_,_,_,_,_,_,_,_,_,
_,_,_,_,_,_,_,_,_,_,_,_,_,_,_,_,_,_,_,_,_,_,_,
_,_,_,_,_,_,_,_,_,_,_,_,_,_,_,_,_,_,_,_,_,_,_,
_,_,_,_,_,_,_,_,_,_,_,_,_,_,_,_,_,_,_,_,_,_,_,
_,_,_,_,_,_,_,_,_,_,_,_,_,_,_,_,_,_,_,_,_,_,_,
_,_,_,_,_,_,_,_,_,_,_,_,_,_,_,_,_,_,_,_,_,_,_,
_,_,_,_,_,_,_,_,_,_,_,_,_,_,_,_,_,_,_,_,_,_,_,
_,_,_,_,_,_,_,_,_,_,_,_,_,_,_,_,_,_,_,_,_,_,_,
_,_,_,_,_,_,_,_,_,_,_,T,_,_,_,_,_,_,_,_,_,_,_,
_,_,_,_,_,_,_,_,_,_,_,_,_,_,_,_,_,_,_,_,_,_,_,
_,_,_,_,_,_,_,T,_,_,_,_,_,_,_,T,_,_,_,_,_,_,_,
_,_,_,_,M,L,M,T,_,_,_,_,_,_,_,T,M,L,M,_,_,_,_,
_,_,_,_,L,L,L,_,_,_,_,T,_,_,_,_,L,L,L,_,_,_,_,
_,_,_,_,L,M,L,_,_,_,L,L,L,_,_,_,L,M,L,_,_,_,_,
_,_,_,_,_,_,M,L,L,L,L,M,L,L,L,L,M,_,_,_,_,_,_,
_,_,_,_,_,_,L,L,L,L,L,L,L,L,L,L,L,_,_,_,_,_,_,
_,_,_,_,_,_,L,L,L,L,L,L,L,L,L,L,L,_,_,_,_,_,_,
_,_,_,_,_,_,_,M,L,M,L,M,L,M,L,M,_,_,_,_,_,_,_,
_,_,_,_,_,_,_,_,_,_,_,_,_,_,_,_,_,_,_,_,_,_,_,
_,_,_,_,_,_,_,_,_,_,_,_,_,_,_,_,_,_,_,_,_,_,_,

_,_,_,_,_,_,_,_,_,_,_,_,_,_,_,_,_,_,_,_,_,_,_,
_,_,_,_,_,_,_,_,_,_,_,_,_,_,_,_,_,_,_,_,_,_,_,
_,_,_,_,_,_,_,_,_,_,_,_,_,_,_,_,_,_,_,_,_,_,_,
_,_,_,_,_,_,_,_,_,_,_,_,_,_,_,_,_,_,_,_,_,_,_,
_,_,_,_,_,_,_,_,_,_,_,_,_,_,_,_,_,_,_,_,_,_,_,
_,_,_,_,_,_,_,_,_,_,_,_,_,_,_,_,_,_,_,_,_,_,_,
_,_,_,_,_,_,_,_,_,_,_,_,_,_,_,_,_,_,_,_,_,_,_,
_,_,_,_,_,_,_,_,_,_,_,T,_,_,_,_,_,_,_,_,_,_,_,
_,_,_,_,_,_,_,_,_,_,_,T,_,_,_,_,_,_,_,_,_,_,_,
_,_,_,_,_,_,_,_,_,_,_,_,_,_,_,_,_,_,_,_,_,_,_,
_,_,_,_,_,_,_,_,T,_,_,_,_,_,T,_,_,_,_,_,_,_,_,
_,_,_,_,_,_,_,_,_,_,_,_,_,_,_,_,_,_,_,_,_,_,_,
_,_,_,_,_,_,_,_,_,_,_,T,_,_,_,_,_,_,_,_,_,_,_,
_,_,_,_,_,_,_,_,_,_,_,_,_,_,_,_,_,_,_,_,_,_,_,
_,_,_,_,_,_,L,L,L,L,_,_,_,L,L,L,L,_,_,_,_,_,_,
_,_,_,_,_,_,L,L,T,L,L,L,L,L,T,L,L,_,_,_,_,_,_,
_,_,_,_,_,_,M,L,L,L,L,L,L,L,L,L,M,_,_,_,_,_,_,
_,_,_,_,_,_,_,L,L,L,L,L,L,L,L,L,_,_,_,_,_,_,_,
_,_,_,_,_,_,_,_,_,_,M,L,M,_,_,_,_,_,_,_,_,_,_,
_,_,_,_,_,_,_,_,_,_,_,_,_,_,_,_,_,_,_,_,_,_,_,

_,_,_,_,_,_,_,_,_,_,_,_,_,_,_,_,_,_,_,_,_,_,_,
_,_,_,_,_,_,_,_,_,_,_,_,_,_,_,_,_,_,_,_,_,_,_,
_,_,_,_,_,_,_,_,_,_,_,_,_,_,_,_,_,_,_,_,_,_,_,
_,_,_,_,_,_,_,_,_,_,_,_,_,_,_,_,_,_,_,_,_,_,_,
_,_,_,_,_,_,_,_,_,_,_,_,_,_,_,_,_,_,_,_,_,_,_,
_,_,_,_,_,_,_,_,_,_,_,_,_,_,_,_,_,_,_,_,_,_,_,
_,_,_,_,_,_,_,_,_,_,_,T,_,_,_,_,_,_,_,_,_,_,_,
_,_,_,_,_,_,_,_,_,_,_,T,_,_,_,_,_,_,_,_,_,_,_,
_,_,_,_,_,_,_,_,_,_,_,_,_,_,_,_,_,_,_,_,_,_,_,
_,M,L,M,_,_,_,_,_,T,_,_,_,T,_,_,_,_,_,M,L,M,_,
_,L,L,L,_,_,_,_,_,T,_,_,_,T,_,_,_,_,_,L,L,L,_,
_,L,M,L,_,_,_,_,_,_,_,T,_,_,_,_,_,_,_,L,M,L,_,
_,_,_,_,M,L,M,_,_,_,_,_,_,_,_,_,M,L,M,_,_,_,_,
_,_,_,_,L,L,L,_,_,_,_,_,_,_,_,_,L,L,L,_,_,_,_,
_,_,_,_,L,M,L,L,L,T,_,_,_,T,L,L,L,M,L,_,_,_,_,
_,_,_,_,_,_,L,L,L,L,L,L,L,L,L,L,L,_,_,_,_,_,_,
_,_,_,_,_,_,L,L,L,L,L,T,L,L,L,L,L,_,_,_,_,_,_,
_,_,_,_,_,_,_,M,L,M,L,L,L,M,L,M,_,_,_,_,_,_,_,
_,_,_,_,_,_,_,_,_,_,L,L,L,_,_,_,_,_,_,_,_,_,_,
_,_,_,_,_,_,_,_,_,_,_,_,_,_,_,_,_,_,_,_,_,_,_,

_,_,_,_,_,_,_,_,_,_,_,T,_,_,_,_,_,_,_,_,_,_,_,
_,_,_,_,_,_,_,_,_,_,T,T,T,_,_,_,_,_,_,_,_,_,_,
_,_,_,_,_,_,_,_,_,_,_,T,_,_,_,_,_,_,_,_,_,_,_,
_,_,_,_,_,_,_,_,_,_,_,T,_,_,_,_,_,_,_,_,_,_,_,
_,_,_,_,_,_,_,_,_,_,_,T,_,_,_,_,_,_,_,_,_,_,_,
_,_,_,_,_,_,_,_,_,_,_,T,_,_,_,_,_,_,_,_,_,_,_,
_,_,_,_,_,_,_,_,_,_,_,T,_,_,_,_,_,_,_,_,_,_,_,
_,_,_,_,_,_,_,_,_,_,_,_,_,_,_,_,_,_,_,_,_,_,_,
_,_,_,_,_,_,_,_,_,_,T,_,T,_,_,_,_,_,_,_,_,_,_,
M,L,L,L,M,_,_,_,_,_,T,_,T,_,_,_,_,_,M,L,L,L,M,
L,L,L,L,L,_,_,_,_,_,_,_,_,_,_,_,_,_,L,L,L,L,L,
L,L,L,L,L,_,_,_,_,_,_,T,_,_,_,_,_,_,L,L,L,L,L,
_,M,L,M,L,L,L,_,_,_,_,_,_,_,_,_,L,L,L,M,L,M,_,
_,_,_,L,L,L,L,L,_,_,T,_,T,_,_,L,L,L,L,L,_,_,_,
_,_,_,L,L,L,L,L,_,_,_,_,_,_,_,L,L,L,L,L,_,_,_,
_,_,_,_,M,L,M,L,L,L,L,T,L,L,L,L,M,L,M,_,_,_,_,
_,_,_,_,_,_,_,L,L,L,L,L,L,L,L,L,_,_,_,_,_,_,_,
_,_,_,_,_,_,_,L,L,L,L,L,L,L,L,L,_,_,_,_,_,_,_,
_,_,_,_,_,_,_,_,M,L,L,L,L,L,M,_,_,_,_,_,_,_,_,
_,_,_,_,_,_,_,_,_,_,M,L,M,_,_,_,_,_,_,_,_,_,_,

_,_,_,_,_,_,_,_,_,_,T,T,T,_,_,_,_,_,_,_,_,_,_,
_,_,_,_,_,_,_,_,_,_,T,T,T,_,_,_,_,_,_,_,_,_,_,
_,_,_,_,_,_,_,_,_,_,T,T,T,_,_,_,_,_,_,_,_,_,_,
_,_,_,_,_,_,_,_,_,_,T,T,T,_,_,_,_,_,_,_,_,_,_,
_,_,_,_,_,_,_,_,_,_,T,T,T,_,_,_,_,_,_,_,_,_,_,
_,_,_,_,_,_,_,_,_,T,T,T,T,T,_,_,_,_,_,_,_,_,_,
_,_,_,_,_,_,_,_,T,T,_,T,_,T,T,_,_,_,_,_,_,_,_,
_,_,_,_,_,_,T,T,T,_,_,T,_,_,T,T,T,_,_,_,_,_,_,
_,_,_,_,T,T,T,_,_,_,_,T,_,_,_,_,T,T,T,_,_,_,_,
L,L,L,T,T,_,_,_,_,_,_,T,_,_,_,_,_,_,T,T,L,L,L,
L,L,T,L,L,_,_,_,_,_,_,T,_,_,_,_,_,_,L,L,T,L,L,
M,L,L,L,M,_,_,_,_,T,T,T,T,T,_,_,_,_,M,L,L,L,M,
_,L,L,L,L,L,L,T,T,_,_,T,_,_,T,T,L,L,L,L,L,L,_,
_,_,_,L,L,T,T,L,_,_,_,T,_,_,_,L,T,T,L,L,_,_,_,
_,_,_,M,L,L,L,M,_,_,_,T,_,_,_,M,L,L,L,M,_,_,_,
_,_,_,_,L,L,L,L,L,L,T,T,T,L,L,L,L,L,L,_,_,_,_,
_,_,_,_,_,_,_,L,L,T,L,T,L,T,L,L,_,_,_,_,_,_,_,
_,_,_,_,_,_,_,M,L,L,L,T,L,L,L,M,_,_,_,_,_,_,_,
_,_,_,_,_,_,_,_,L,L,L,L,L,L,L,_,_,_,_,_,_,_,_,
_,_,_,_,_,_,_,_,_,_,L,L,L,_,_,_,_,_,_,_,_,_,_,

_,_,_,_,_,_,_,_,_,_,_,T,_,_,_,_,_,_,_,_,_,_,_,
_,_,_,_,_,_,_,_,_,_,T,T,T,_,_,_,_,_,_,_,_,_,_,
_,_,_,_,_,_,_,_,_,_,_,T,_,_,_,_,_,_,_,_,_,_,_,
_,_,_,_,_,_,_,_,_,_,_,T,_,_,_,_,_,_,_,_,_,_,_,
_,_,_,_,_,_,_,_,_,_,_,T,_,_,_,_,_,_,_,_,_,_,_,
_,_,_,_,_,_,_,_,_,_,_,T,_,_,_,_,_,_,_,_,_,_,_,
_,_,_,_,_,_,_,_,_,_,_,_,_,_,_,_,_,_,_,_,_,_,_,
_,_,_,_,_,_,_,_,_,_,_,_,_,_,_,_,_,_,_,_,_,_,_,
_,_,_,_,_,_,_,_,_,_,T,_,T,_,_,_,_,_,_,_,_,_,_,
M,L,L,L,M,_,_,_,_,_,T,_,T,_,_,_,_,_,M,L,L,L,M,
L,L,L,L,L,_,_,_,_,_,_,_,_,_,_,_,_,_,L,L,L,L,L,
L,L,L,L,L,_,_,_,_,_,_,T,_,_,_,_,_,_,L,L,L,L,L,
_,M,L,M,L,L,L,_,_,_,_,_,_,_,_,_,L,L,L,M,L,M,_,
_,_,_,L,L,L,L,L,_,_,T,_,T,_,_,L,L,L,L,L,_,_,_,
_,_,_,L,L,L,L,L,_,_,_,_,_,_,_,L,L,L,L,L,_,_,_,
_,_,_,_,M,L,M,L,L,L,L,T,L,L,L,L,M,L,M,_,_,_,_,
_,_,_,_,_,_,_,L,L,L,L,L,L,L,L,L,_,_,_,_,_,_,_,
_,_,_,_,_,_,_,L,L,L,L,L,L,L,L,L,_,_,_,_,_,_,_,
_,_,_,_,_,_,_,_,M,L,L,L,L,L,M,_,_,_,_,_,_,_,_,
_,_,_,_,_,_,_,_,_,_,M,L,M,_,_,_,_,_,_,_,_,_,_,

_,_,_,_,_,_,_,_,_,_,_,_,_,_,_,_,_,_,_,_,_,_,_,
_,_,_,_,_,_,_,_,_,_,_,_,_,_,_,_,_,_,_,_,_,_,_,
_,_,_,_,_,_,_,_,_,_,_,_,_,_,_,_,_,_,_,_,_,_,_,
_,_,_,_,_,_,_,_,_,_,_,_,_,_,_,_,_,_,_,_,_,_,_,
_,_,_,_,_,_,_,_,_,_,_,_,_,_,_,_,_,_,_,_,_,_,_,
_,_,_,_,_,_,_,_,_,_,_,T,_,_,_,_,_,_,_,_,_,_,_,
_,_,_,_,_,_,_,_,_,_,_,T,_,_,_,_,_,_,_,_,_,_,_,
_,_,_,_,_,_,_,_,_,_,_,_,_,_,_,_,_,_,_,_,_,_,_,
_,_,_,_,_,_,_,_,_,_,_,_,_,_,_,_,_,_,_,_,_,_,_,
_,M,L,M,_,_,_,_,_,T,_,_,_,T,_,_,_,_,_,M,L,M,_,
_,L,L,L,_,_,_,_,_,T,_,_,_,T,_,_,_,_,_,L,L,L,_,
_,L,M,L,_,_,_,_,_,_,_,T,_,_,_,_,_,_,_,L,M,L,_,
_,_,_,_,M,L,M,_,_,_,_,_,_,_,_,_,M,L,M,_,_,_,_,
_,_,_,_,L,L,L,_,_,_,_,_,_,_,_,_,L,L,L,_,_,_,_,
_,_,_,_,L,M,L,L,L,T,_,_,_,T,L,L,L,M,L,_,_,_,_,
_,_,_,_,_,_,L,L,L,L,L,L,L,L,L,L,L,_,_,_,_,_,_,
_,_,_,_,_,_,L,L,L,L,L,T,L,L,L,L,L,_,_,_,_,_,_,
_,_,_,_,_,_,_,M,L,M,L,L,L,M,L,M,_,_,_,_,_,_,_,
_,_,_,_,_,_,_,_,_,_,L,L,L,_,_,_,_,_,_,_,_,_,_,
_,_,_,_,_,_,_,_,_,_,_,_,_,_,_,_,_,_,_,_,_,_,_,

_,_,_,_,_,_,_,_,_,_,_,_,_,_,_,_,_,_,_,_,_,_,_,
_,_,_,_,_,_,_,_,_,_,_,_,_,_,_,_,_,_,_,_,_,_,_,
_,_,_,_,_,_,_,_,_,_,_,_,_,_,_,_,_,_,_,_,_,_,_,
_,_,_,_,_,_,_,_,_,_,_,_,_,_,_,_,_,_,_,_,_,_,_,
_,_,_,_,_,_,_,_,_,_,_,_,_,_,_,_,_,_,_,_,_,_,_,
_,_,_,_,_,_,_,_,_,_,_,_,_,_,_,_,_,_,_,_,_,_,_,
_,_,_,_,_,_,_,_,_,_,_,T,_,_,_,_,_,_,_,_,_,_,_,
_,_,_,_,_,_,_,_,_,_,_,T,_,_,_,_,_,_,_,_,_,_,_,
_,_,_,_,_,_,_,_,_,_,_,_,_,_,_,_,_,_,_,_,_,_,_,
_,_,_,_,_,_,_,_,_,_,_,_,_,_,_,_,_,_,_,_,_,_,_,
_,_,_,_,_,_,_,_,T,_,_,_,_,_,T,_,_,_,_,_,_,_,_,
_,_,_,_,_,_,_,_,_,_,_,_,_,_,_,_,_,_,_,_,_,_,_,
_,_,_,_,_,_,_,_,_,_,_,T,_,_,_,_,_,_,_,_,_,_,_,
_,_,_,_,_,_,_,_,_,_,_,_,_,_,_,_,_,_,_,_,_,_,_,
_,_,_,_,_,_,L,L,L,L,_,_,_,L,L,L,L,_,_,_,_,_,_,
_,_,_,_,_,_,L,L,T,L,L,L,L,L,T,L,L,_,_,_,_,_,_,
_,_,_,_,_,_,M,L,L,L,L,L,L,L,L,L,M,_,_,_,_,_,_,
_,_,_,_,_,_,_,L,L,L,L,L,L,L,L,L,_,_,_,_,_,_,_,
_,_,_,_,_,_,_,_,_,_,M,L,M,_,_,_,_,_,_,_,_,_,_,
_,_,_,_,_,_,_,_,_,_,_,_,_,_,_,_,_,_,_,_,_,_,_,

_,_,_,_,_,_,_,_,_,_,_,_,_,_,_,_,_,_,_,_,_,_,_,
_,_,_,_,_,_,_,_,_,_,_,_,_,_,_,_,_,_,_,_,_,_,_,
_,_,_,_,_,_,_,_,_,_,_,_,_,_,_,_,_,_,_,_,_,_,_,
_,_,_,_,_,_,_,_,_,_,_,_,_,_,_,_,_,_,_,_,_,_,_,
_,_,_,_,_,_,_,_,_,_,_,_,_,_,_,_,_,_,_,_,_,_,_,
_,_,_,_,_,_,_,_,_,_,_,_,_,_,_,_,_,_,_,_,_,_,_,
_,_,_,_,_,_,_,_,_,_,_,_,_,_,_,_,_,_,_,_,_,_,_,
_,_,_,_,_,_,_,_,_,_,_,T,_,_,_,_,_,_,_,_,_,_,_,
_,_,_,_,_,_,_,_,_,_,_,_,_,_,_,_,_,_,_,_,_,_,_,
_,_,_,_,_,_,_,_,_,_,_,_,_,_,_,_,_,_,_,_,_,_,_,
_,_,_,_,_,_,_,T,_,_,_,_,_,_,_,T,_,_,_,_,_,_,_,
_,_,_,_,M,L,M,T,_,_,_,_,_,_,_,T,M,L,M,_,_,_,_,
_,_,_,_,L,L,L,_,_,_,_,T,_,_,_,_,L,L,L,_,_,_,_,
_,_,_,_,L,M,L,_,_,_,L,L,L,_,_,_,L,M,L,_,_,_,_,
_,_,_,_,_,_,M,L,L,L,L,M,L,L,L,L,M,_,_,_,_,_,_,
_,_,_,_,_,_,L,L,L,L,L,L,L,L,L,L,L,_,_,_,_,_,_,
_,_,_,_,_,_,L,L,L,L,L,L,L,L,L,L,L,_,_,_,_,_,_,
_,_,_,_,_,_,_,M,L,M,L,M,L,M,L,M,_,_,_,_,_,_,_,
_,_,_,_,_,_,_,_,_,_,_,_,_,_,_,_,_,_,_,_,_,_,_,
_,_,_,_,_,_,_,_,_,_,_,_,_,_,_,_,_,_,_,_,_,_,_,

_,_,_,_,_,_,_,_,_,_,_,_,_,_,_,_,_,_,_,_,_,_,_,
_,_,_,_,_,_,_,_,_,_,_,_,_,_,_,_,_,_,_,_,_,_,_,
_,_,_,_,_,_,_,_,_,_,_,_,_,_,_,_,_,_,_,_,_,_,_,
_,_,_,_,_,_,_,_,_,_,_,_,_,_,_,_,_,_,_,_,_,_,_,
_,_,_,_,_,_,_,_,_,_,_,_,_,_,_,_,_,_,_,_,_,_,_,
_,_,_,_,_,_,_,_,_,_,_,_,_,_,_,_,_,_,_,_,_,_,_,
_,_,_,_,_,_,_,_,_,_,_,_,_,_,_,_,_,_,_,_,_,_,_,
_,_,_,_,_,_,_,_,_,_,_,T,_,_,_,_,_,_,_,_,_,_,_,
_,_,_,_,_,_,_,_,_,_,_,T,_,_,_,_,_,_,_,_,_,_,_,
_,_,_,_,_,_,_,_,_,_,_,_,_,_,_,_,_,_,_,_,_,_,_,
_,_,_,_,_,_,_,_,_,_,_,_,_,_,_,_,_,_,_,_,_,_,_,
_,_,_,M,L,L,T,M,_,_,_,_,_,_,_,M,T,L,L,M,_,_,_,
_,_,_,L,L,L,L,L,_,M,L,L,L,M,_,L,L,L,L,L,_,_,_,
_,_,_,L,L,L,L,L,_,L,L,T,L,L,_,L,L,L,L,L,_,_,_,
_,_,_,_,M,L,M,M,L,L,L,L,L,L,L,M,M,L,M,_,_,_,_,
_,_,_,_,_,_,_,L,L,L,M,L,M,L,L,L,_,_,_,_,_,_,_,
_,_,_,_,_,_,_,L,M,L,_,_,_,L,M,L,_,_,_,_,_,_,_,
_,_,_,_,_,_,_,_,_,_,_,_,_,_,_,_,_,_,_,_,_,_,_,
_,_,_,_,_,_,_,_,_,_,_,_,_,_,_,_,_,_,_,_,_,_,_,
_,_,_,_,_,_,_,_,_,_,_,_,_,_,_,_,_,_,_,_,_,_,_,

_,_,_,_,_,_,_,_,_,_,_,_,_,_,_,_,_,_,_,_,_,_,_,
_,_,_,_,_,_,_,_,_,_,_,_,_,_,_,_,_,_,_,_,_,_,_,
_,_,_,_,_,_,_,_,_,_,_,_,_,_,_,_,_,_,_,_,_,_,_,
_,_,_,_,_,_,_,_,_,_,_,_,_,_,_,_,_,_,_,_,_,_,_,
_,_,_,_,_,_,_,_,_,_,_,_,_,_,_,_,_,_,_,_,_,_,_,
_,_,_,_,_,_,_,_,_,_,_,_,_,_,_,_,_,_,_,_,_,_,_,
_,_,_,_,_,_,_,_,_,_,_,_,_,_,_,_,_,_,_,_,_,_,_,
_,_,_,_,_,_,_,_,_,_,_,_,_,_,_,_,_,_,_,_,_,_,_,
_,_,_,_,_,_,_,_,_,_,_,T,_,_,_,_,_,_,_,_,_,_,_,
_,_,_,_,_,_,_,_,_,_,_,_,_,_,_,_,_,_,_,_,_,_,_,
_,_,_,_,_,_,_,_,_,_,_,_,_,_,_,_,_,_,_,_,_,_,_,
_,_,_,L,L,L,L,L,_,_,_,_,_,_,_,L,L,L,L,L,_,_,_,
_,_,_,L,L,T,L,L,_,L,L,L,L,L,_,L,L,T,L,L,_,_,_,
_,_,_,M,L,L,L,M,_,L,L,T,L,L,_,M,L,L,L,M,_,_,_,
_,_,_,_,L,L,L,_,_,M,L,L,L,M,_,_,L,L,L,_,_,_,_,
_,_,_,_,_,_,_,_,_,_,L,L,L,_,_,_,_,_,_,_,_,_,_,
_,_,_,_,_,_,_,_,_,_,_,_,_,_,_,_,_,_,_,_,_,_,_,
_,_,_,_,_,_,_,_,_,_,_,_,_,_,_,_,_,_,_,_,_,_,_,
_,_,_,_,_,_,_,_,_,_,_,_,_,_,_,_,_,_,_,_,_,_,_,
_,_,_,_,_,_,_,_,_,_,_,_,_,_,_,_,_,_,_,_,_,_,_,

_,_,_,_,_,_,_,_,_,_,_,_,_,_,_,_,_,_,_,_,_,_,_,
_,_,_,_,_,_,_,_,_,_,_,_,_,_,_,_,_,_,_,_,_,_,_,
_,_,_,_,_,_,_,_,_,_,_,_,_,_,_,_,_,_,_,_,_,_,_,
_,_,_,_,_,_,_,_,_,_,_,_,_,_,_,_,_,_,_,_,_,_,_,
_,_,_,_,_,_,_,_,_,_,_,_,_,_,_,_,_,_,_,_,_,_,_,
_,_,_,_,_,_,_,_,_,_,_,_,_,_,_,_,_,_,_,_,_,_,_,
_,_,_,_,_,_,_,_,_,_,_,_,_,_,_,_,_,_,_,_,_,_,_,
_,_,_,_,_,_,_,_,_,_,_,_,_,_,_,_,_,_,_,_,_,_,_,
_,_,_,_,_,_,_,_,_,_,_,T,_,_,_,_,_,_,_,_,_,_,_,
_,_,_,_,_,_,_,_,_,_,M,T,M,_,_,_,_,_,_,_,_,_,_,
_,_,_,_,_,_,_,_,_,_,L,L,L,_,_,_,_,_,_,_,_,_,_,
_,_,_,M,L,L,L,M,_,_,L,M,L,_,_,M,L,L,L,M,_,_,_,
_,_,_,L,L,L,L,L,_,M,L,L,L,M,_,L,L,L,L,L,_,_,_,
_,_,_,L,L,L,L,L,_,L,L,L,L,L,_,L,L,L,L,L,_,_,_,
_,_,_,_,M,L,M,_,_,L,L,L,L,L,_,_,M,L,M,_,_,_,_,
_,_,_,_,_,_,_,_,_,_,M,L,M,_,_,_,_,_,_,_,_,_,_,
_,_,_,_,_,_,_,_,_,_,_,_,_,_,_,_,_,_,_,_,_,_,_,
_,_,_,_,_,_,_,_,_,_,_,_,_,_,_,_,_,_,_,_,_,_,_,
_,_,_,_,_,_,_,_,_,_,_,_,_,_,_,_,_,_,_,_,_,_,_,
_,_,_,_,_,_,_,_,_,_,_,_,_,_,_,_,_,_,_,_,_,_,_,

_,_,_,_,_,_,_,_,_,_,_,_,_,_,_,_,_,_,_,_,_,_,_,
_,_,_,_,_,_,_,_,_,_,_,_,_,_,_,_,_,_,_,_,_,_,_,
_,_,_,_,_,_,_,_,_,_,_,_,_,_,_,_,_,_,_,_,_,_,_,
_,_,_,_,_,_,_,_,_,_,_,_,_,_,_,_,_,_,_,_,_,_,_,
_,_,_,_,_,_,_,_,_,_,_,_,_,_,_,_,_,_,_,_,_,_,_,
_,_,_,_,_,_,_,_,_,_,_,_,_,_,_,_,_,_,_,_,_,_,_,
_,_,_,_,_,_,_,_,_,_,_,_,_,_,_,_,_,_,_,_,_,_,_,
_,_,_,_,_,_,_,_,_,_,_,_,_,_,_,_,_,_,_,_,_,_,_,
_,_,_,_,_,_,_,_,_,_,_,_,_,_,_,_,_,_,_,_,_,_,_,
_,_,_,_,_,_,_,_,_,M,L,T,L,M,_,_,_,_,_,_,_,_,_,
_,_,_,_,_,_,_,_,_,L,L,L,L,L,_,_,_,_,_,_,_,_,_,
_,_,_,_,M,L,M,_,_,L,L,L,L,L,_,_,M,L,M,_,_,_,_,
_,_,_,_,L,L,L,_,_,_,M,L,M,_,_,_,L,L,L,_,_,_,_,
_,_,_,_,L,M,L,_,_,_,L,L,L,_,_,_,L,M,L,_,_,_,_,
_,_,_,_,_,_,_,_,_,_,L,M,L,_,_,_,_,_,_,_,_,_,_,
_,_,_,_,_,_,_,_,_,_,_,_,_,_,_,_,_,_,_,_,_,_,_,
_,_,_,_,_,_,_,_,_,_,_,_,_,_,_,_,_,_,_,_,_,_,_,
_,_,_,_,_,_,_,_,_,_,_,_,_,_,_,_,_,_,_,_,_,_,_,
_,_,_,_,_,_,_,_,_,_,_,_,_,_,_,_,_,_,_,_,_,_,_,
_,_,_,_,_,_,_,_,_,_,_,_,_,_,_,_,_,_,_,_,_,_,_,

_,_,_,_,_,_,_,_,_,_,_,_,_,_,_,_,_,_,_,_,_,_,_,
_,_,_,_,_,_,_,_,_,_,_,_,_,_,_,_,_,_,_,_,_,_,_,
_,_,_,_,_,_,_,_,_,_,_,_,_,_,_,_,_,_,_,_,_,_,_,
_,_,_,_,_,_,_,_,_,_,_,_,_,_,_,_,_,_,_,_,_,_,_,
_,_,_,_,_,_,_,_,_,_,_,_,_,_,_,_,_,_,_,_,_,_,_,
_,_,_,_,_,_,_,_,_,_,_,_,_,_,_,_,_,_,_,_,_,_,_,
_,_,_,_,_,_,_,_,_,_,_,_,_,_,_,_,_,_,_,_,_,_,_,
_,_,_,_,_,_,_,_,_,_,_,_,_,_,_,_,_,_,_,_,_,_,_,
_,_,_,_,_,_,_,_,_,_,_,_,_,_,_,_,_,_,_,_,_,_,_,
_,_,_,_,_,_,_,_,_,L,L,L,L,L,_,_,_,_,_,_,_,_,_,
_,_,_,_,_,_,_,_,_,L,L,T,L,L,_,_,_,_,_,_,_,_,_,
_,_,_,_,_,_,_,_,_,M,L,L,L,M,_,_,_,_,_,_,_,_,_,
_,_,_,_,_,_,_,_,_,_,L,L,L,_,_,_,_,_,_,_,_,_,_,
_,_,_,_,_,_,_,_,_,_,_,_,_,_,_,_,_,_,_,_,_,_,_,
_,_,_,_,_,_,_,_,_,_,_,_,_,_,_,_,_,_,_,_,_,_,_,
_,_,_,_,_,_,_,_,_,_,_,_,_,_,_,_,_,_,_,_,_,_,_,
_,_,_,_,_,_,_,_,_,_,_,_,_,_,_,_,_,_,_,_,_,_,_,
_,_,_,_,_,_,_,_,_,_,_,_,_,_,_,_,_,_,_,_,_,_,_,
_,_,_,_,_,_,_,_,_,_,_,_,_,_,_,_,_,_,_,_,_,_,_,
_,_,_,_,_,_,_,_,_,_,_,_,_,_,_,_,_,_,_,_,_,_,_,

_,_,_,_,_,_,_,_,_,_,_,_,_,_,_,_,_,_,_,_,_,_,_,
_,_,_,_,_,_,_,_,_,_,_,_,_,_,_,_,_,_,_,_,_,_,_,
_,_,_,_,_,_,_,_,_,_,_,_,_,_,_,_,_,_,_,_,_,_,_,
_,_,_,_,_,_,_,_,_,_,_,_,_,_,_,_,_,_,_,_,_,_,_,
_,_,_,_,_,_,_,_,_,_,_,_,_,_,_,_,_,_,_,_,_,_,_,
_,_,_,_,_,_,_,_,_,_,_,_,_,_,_,_,_,_,_,_,_,_,_,
_,_,_,_,_,_,_,_,_,_,_,_,_,_,_,_,_,_,_,_,_,_,_,
_,_,_,_,_,_,_,_,_,_,_,_,_,_,_,_,_,_,_,_,_,_,_,
_,_,_,_,_,_,_,_,_,_,_,_,_,_,_,_,_,_,_,_,_,_,_,
_,_,_,_,_,_,_,_,_,M,L,L,L,M,_,_,_,_,_,_,_,_,_,
_,_,_,_,_,_,_,_,_,L,L,L,L,L,_,_,_,_,_,_,_,_,_,
_,_,_,_,_,_,_,_,_,L,L,L,L,L,_,_,_,_,_,_,_,_,_,
_,_,_,_,_,_,_,_,_,_,M,L,M,_,_,_,_,_,_,_,_,_,_,
_,_,_,_,_,_,_,_,_,_,_,_,_,_,_,_,_,_,_,_,_,_,_,
_,_,_,_,_,_,_,_,_,_,_,_,_,_,_,_,_,_,_,_,_,_,_,
_,_,_,_,_,_,_,_,_,_,_,_,_,_,_,_,_,_,_,_,_,_,_,
_,_,_,_,_,_,_,_,_,_,_,_,_,_,_,_,_,_,_,_,_,_,_,
_,_,_,_,_,_,_,_,_,_,_,_,_,_,_,_,_,_,_,_,_,_,_,
_,_,_,_,_,_,_,_,_,_,_,_,_,_,_,_,_,_,_,_,_,_,_,
_,_,_,_,_,_,_,_,_,_,_,_,_,_,_,_,_,_,_,_,_,_,_,

_,_,_,_,_,_,_,_,_,_,_,_,_,_,_,_,_,_,_,_,_,_,_,
_,_,_,_,_,_,_,_,_,_,_,_,_,_,_,_,_,_,_,_,_,_,_,
_,_,_,_,_,_,_,_,_,_,_,_,_,_,_,_,_,_,_,_,_,_,_,
_,_,_,_,_,_,_,_,_,_,_,_,_,_,_,_,_,_,_,_,_,_,_,
_,_,_,_,_,_,_,_,_,_,_,_,_,_,_,_,_,_,_,_,_,_,_,
_,_,_,_,_,_,_,_,_,_,_,_,_,_,_,_,_,_,_,_,_,_,_,
_,_,_,_,_,_,_,_,_,_,_,_,_,_,_,_,_,_,_,_,_,_,_,
_,_,_,_,_,_,_,_,_,_,_,_,_,_,_,_,_,_,_,_,_,_,_,
_,_,_,_,_,_,_,_,_,_,_,_,_,_,_,_,_,_,_,_,_,_,_,
_,_,_,_,_,_,_,_,_,_,M,L,M,_,_,_,_,_,_,_,_,_,_,
_,_,_,_,_,_,_,_,_,_,L,L,L,_,_,_,_,_,_,_,_,_,_,
_,_,_,_,_,_,_,_,_,_,L,M,L,_,_,_,_,_,_,_,_,_,_,
_,_,_,_,_,_,_,_,_,_,_,_,_,_,_,_,_,_,_,_,_,_,_,
_,_,_,_,_,_,_,_,_,_,_,_,_,_,_,_,_,_,_,_,_,_,_,
_,_,_,_,_,_,_,_,_,_,_,_,_,_,_,_,_,_,_,_,_,_,_,
_,_,_,_,_,_,_,_,_,_,_,_,_,_,_,_,_,_,_,_,_,_,_,
_,_,_,_,_,_,_,_,_,_,_,_,_,_,_,_,_,_,_,_,_,_,_,
_,_,_,_,_,_,_,_,_,_,_,_,_,_,_,_,_,_,_,_,_,_,_,
_,_,_,_,_,_,_,_,_,_,_,_,_,_,_,_,_,_,_,_,_,_,_,
_,_,_,_,_,_,_,_,_,_,_,_,_,_,_,_,_,_,_,_,_,_,_},
yslice_prob = {{ypos=3, prob=123}}}

local function grow_white_willow_tree(pos)
	if on_compost(pos) then
		if not enough_height(pos, 16) then
		core.get_node_timer(pos):start(300)
		return end
		add_tree(pos, 11, 1, 11, white_willow_tree2)
		return
	end
	add_tree(pos, 2, 1, 2, white_willow_tree, "0")
end

-- Decoration

local mg_name = core.get_mapgen_setting("mg_name")

if mg_name ~= "v6" and mg_name ~= "singlenode" then
	core.register_decoration({
		deco_type = "schematic",
		place_on = {"default:dirt_with_grass"},
		sidelen = 16,
		noise_params = {
			offset = 0.0005,
			scale = 0.0002,
			spread = {x = 250, y = 250, z = 250},
			seed = 2,
			octaves = 3,
			persist = 0.66
		},
		biomes = {"deciduous_forest"},
		y_min = 1,
		y_max = 62,
		schematic = white_willow_tree,
		flags = "place_center_x, place_center_z",
		spawn_by = {"default:water_source", "default:fresh_water_source"},
		num_spawn_by = 2,
	})
end

-- Nodes

core.register_node("white_willow:sapling", {
	description = S("White Willow Tree Sapling"),
	drawtype = "plantlike",
	tiles = {"white_willow_sapling.png"},
	inventory_image = "white_willow_sapling.png",
	paramtype = "light",
	sunlight_propagates = true,
	walkable = false,
	selection_box = {
		type = "fixed",
		fixed = {-4/16, -0.5, -4/16, 4/16, 7/16, 4/16}
	},
	groups = {snappy = 2, dig_immediate = 3, flammable = 2, attached_node = 1, sapling = 1},
	sounds = default.node_sound_leaves_defaults(),

	on_construct = function(pos)
		core.get_node_timer(pos):start(math.random(600, 3000))
	end,

	on_place = function(itemstack, placer, pointd)
		itemstack = default.sapling_on_place(itemstack, placer, pointd,
			"white_willow:sapling",
			-- minp, maxp to be checked, relative to sapling pos
			-- minp_relative.y = 1 because sapling pos has been checked
			{x = -2, y = 1, z = -2},
			{x = 2, y = 5, z = 2},
			-- maximum interval of interior volume check
			4)

		return itemstack
	end,

	on_timer = function(pos)
		if #core.find_nodes_in_area({x = pos.x + 1, y = pos.y, z = pos.z + 1},
			{x = pos.x - 1, y = pos.y, z = pos.z - 1}, {"default:water_source", "default:fresh_water_source"}) > 0 then

			if not default.can_grow(pos) then
				core.get_node_timer(pos):start(math.random(250, 1450))
			else
				core.log("action", "A white willow sapling grows into a tree at ".. core.pos_to_string(pos))
				grow_white_willow_tree(pos)
			end
		else
			core.set_node(pos, {name = "default:dry_shrub"})
		end
	end,
	grown_height = 5,
})

core.register_node("white_willow:trunk", {
	description = S("White Willow Trunk"),
	tiles = {"white_willow_trunk_top.png", "white_willow_trunk_top.png", "white_willow_trunk.png"},
	paramtype2 = "facedir",
	is_ground_content = false,
	groups = {choppy = 3, flammable = 1, trunk = 1},
	sounds = default.node_sound_wood_defaults(),
	on_place = core.rotate_node,
})

core.register_node("white_willow:wood", {
	description = S("White Willow Wood"),
	tiles = {"white_willow_wood.png"},
	paramtype2 = "facedir",
	place_param2 = 0,
	is_ground_content = false,
	groups = {choppy = 3, oddly_breakable_by_hand = 2, flammable = 2, wood = 1},
	sounds = default.node_sound_wood_defaults(),
})

core.register_node("white_willow:leaves", {
	description = S("White Willow Leaves"),
	drawtype = leaf_drawtype,
	mesh = "leaf_poof.obj",
	waving = waving_style,
	tiles = {"white_willow_leaves.png"},
	inventory_image = leaf_image("white_willow_leaves.png"),
	wield_image = leaf_image("white_willow_leaves.png"),
	use_texture_alpha = "clip",
	paramtype = "light",
	is_ground_content = false,
	collision_box = leaf_cbox,
	groups = {snappy = 3, leafdecay = 3, flammable = 2, leaves = 1},
	drop = {
		max_items = 1,
		items = {
			{items = {"white_willow:sapling"}, rarity = 20},
			{items = {"white_willow:leaves"}}
		}
	},
	sounds = default.node_sound_leaves_defaults(),
	after_place_node = default.after_place_leaves,
})

-- Recipes

core.register_craft({
	output = "white_willow:wood 4",
	recipe = {{"white_willow:trunk"}}
})

core.register_craft({
	type = "fuel",
	recipe = "white_willow:trunk",
	burntime = 30,
})

core.register_craft({
	type = "fuel",
	recipe = "white_willow:wood",
	burntime = 9,
})


core.register_lbm({
	name = "white_willow:convert_white_willow_saplings_to_node_timer",
	nodenames = {"white_willow:sapling"},
	action = function(pos)
		core.get_node_timer(pos):start(math.random(300, 1500))
	end
})

default.register_leafdecay({
	trunks = {"white_willow:trunk"},
	leaves = {"white_willow:leaves"},
	radius = 2,
})

doors.register_fencegate("white_willow:wood_gate", {
	description = S("White Willow Wood Fence Gate"),
	texture = "white_willow_wood.png",
	material = "white_willow:wood",
	groups = {choppy = 2, oddly_breakable_by_hand = 2, flammable = 2}
})

default.register_fence("white_willow:wood_fence", {
	description = S("White Willow Wood Fence"),
	texture = "white_willow_fence.png",
	material = "white_willow:wood",
	groups = {choppy = 2, oddly_breakable_by_hand = 2, flammable = 2},
	sounds = default.node_sound_wood_defaults()
})

if core.get_modpath("stairs") then
stairs.register_stair_and_slab("white_willow_wood", "white_willow:wood",
	{choppy = 3, oddly_breakable_by_hand = 2, flammable = 2},
	{"white_willow_wood.png"},
	S("White Willow Wood Stair"),
	S("White Willow Wood Slab"),
	default.node_sound_wood_defaults())
end

if core.get_modpath("bonemeal") then
	bonemeal:add_sapling({
		{"white_willow:sapling", nil, "soil"},
	})
end
