
-- Acacia tree

local L = {name = "default:acacia_leaves"}
local M = {name = "default:acacia_leaves", prob = 223}
local T = {name = "default:acacia_trunk", force_place = true}

default.acacia_tree = {size = {x = 11, y = 10, z = 11}, data = {
_,_,_,_,_,_,_,_,_,_,_,
_,_,_,_,_,_,_,_,_,_,_,
_,_,_,_,_,_,_,_,_,_,_,
_,_,_,_,_,_,_,_,_,_,_,
_,_,_,_,_,_,_,_,_,_,_,
_,_,_,_,_,_,_,_,_,_,_,
_,_,_,_,_,_,_,_,_,_,_,
_,_,_,M,M,M,_,_,_,_,_,
_,_,_,_,_,_,M,M,_,_,_,
_,_,_,_,_,_,_,_,_,_,_,

_,_,_,_,_,_,_,_,_,_,_,
_,_,_,_,_,_,_,_,_,_,_,
_,_,_,_,_,_,_,_,_,_,_,
_,_,_,_,_,_,_,_,_,_,_,
_,_,_,_,_,_,_,_,_,_,_,
_,_,_,_,_,_,_,_,_,_,_,
_,_,_,_,_,_,_,_,_,_,_,
_,M,L,L,L,L,_,_,_,_,_,
_,_,_,M,_,L,L,L,L,M,_,
_,_,_,_,_,_,_,M,_,_,_,

_,_,_,_,_,_,_,_,_,_,_,
_,_,_,_,_,_,_,_,_,_,_,
_,_,_,_,_,_,_,_,_,_,_,
_,_,_,_,_,_,_,_,_,_,_,
_,_,_,_,_,_,_,_,_,_,_,
_,_,_,_,_,_,_,_,_,_,_,
_,_,_,_,_,_,_,_,_,_,_,
_,L,L,L,L,L,_,_,_,_,_,
_,_,M,M,M,L,L,L,L,L,_,
_,_,_,_,_,_,M,M,M,_,_,

_,_,_,_,_,_,_,_,_,_,_,
_,_,_,_,_,_,_,_,_,_,_,
_,_,_,_,_,_,_,_,_,_,_,
_,_,_,_,_,_,_,_,_,_,_,
_,_,_,_,_,_,_,_,_,_,_,
_,_,_,_,_,_,_,_,_,_,_,
_,_,_,T,_,_,_,_,_,_,_,
M,L,L,L,L,L,_,T,_,_,_,
_,M,M,M,M,L,L,L,L,L,M,
_,_,_,_,_,M,M,M,M,M,_,

_,_,_,_,_,_,_,_,_,_,_,
_,_,_,_,_,_,_,_,_,_,_,
_,_,_,_,_,_,_,_,_,_,_,
_,_,_,_,_,_,_,_,_,_,_,
_,_,_,_,_,_,_,_,_,_,_,
_,_,_,_,T,_,_,_,_,_,_,
_,_,_,_,_,_,T,_,_,_,_,
M,L,L,L,L,_,_,_,_,_,_,
_,_,M,M,M,L,L,L,L,L,M,
_,_,_,_,_,_,M,M,M,_,_,

_,_,_,_,_,T,_,_,_,_,_,
_,_,_,_,_,T,_,_,_,_,_,
_,_,_,_,_,T,_,_,_,_,_,
_,_,_,_,_,T,_,_,_,_,_,
_,_,_,_,_,T,_,_,_,_,_,
_,_,_,_,_,T,_,_,_,_,_,
_,_,_,_,_,_,_,_,_,_,_,
M,L,L,L,_,_,_,L,L,L,M,
_,L,L,L,L,L,L,L,L,L,_,
_,_,_,M,_,_,_,M,_,_,_,

_,_,_,_,_,_,_,_,_,_,_,
_,_,_,_,_,_,_,_,_,_,_,
_,_,_,_,_,_,_,_,_,_,_,
_,_,_,_,_,_,_,_,_,_,_,
_,_,_,_,_,_,_,_,_,_,_,
_,_,_,_,_,_,T,_,_,_,_,
_,_,_,_,T,_,_,_,_,_,_,
_,_,_,_,_,_,L,L,L,L,M,
M,L,L,L,L,L,M,M,M,_,_,
_,_,M,M,M,_,_,_,_,_,_,

_,_,_,_,_,_,_,_,_,_,_,
_,_,_,_,_,_,_,_,_,_,_,
_,_,_,_,_,_,_,_,_,_,_,
_,_,_,_,_,_,_,_,_,_,_,
_,_,_,_,_,_,_,_,_,_,_,
_,_,_,_,_,_,_,_,_,_,_,
_,_,_,_,_,_,_,T,_,_,_,
_,_,_,T,_,L,L,L,L,L,M,
M,L,L,L,L,L,M,M,M,M,_,
_,M,M,M,M,M,_,_,_,_,_,

_,_,_,_,_,_,_,_,_,_,_,
_,_,_,_,_,_,_,_,_,_,_,
_,_,_,_,_,_,_,_,_,_,_,
_,_,_,_,_,_,_,_,_,_,_,
_,_,_,_,_,_,_,_,_,_,_,
_,_,_,_,_,_,_,_,_,_,_,
_,_,_,_,_,_,_,_,_,_,_,
_,_,_,_,_,L,L,L,L,L,_,
_,L,L,L,L,L,M,M,M,_,_,
_,_,M,M,M,_,_,_,_,_,_,

_,_,_,_,_,_,_,_,_,_,_,
_,_,_,_,_,_,_,_,_,_,_,
_,_,_,_,_,_,_,_,_,_,_,
_,_,_,_,_,_,_,_,_,_,_,
_,_,_,_,_,_,_,_,_,_,_,
_,_,_,_,_,_,_,_,_,_,_,
_,_,_,_,_,_,_,_,_,_,_,
_,_,_,_,_,L,L,L,L,M,_,
_,M,L,L,L,L,_,M,_,_,_,
_,_,_,M,_,_,_,_,_,_,_,

_,_,_,_,_,_,_,_,_,_,_,
_,_,_,_,_,_,_,_,_,_,_,
_,_,_,_,_,_,_,_,_,_,_,
_,_,_,_,_,_,_,_,_,_,_,
_,_,_,_,_,_,_,_,_,_,_,
_,_,_,_,_,_,_,_,_,_,_,
_,_,_,_,_,_,_,_,_,_,_,
_,_,_,_,_,M,M,M,_,_,_,
_,_,_,M,M,_,_,_,_,_,_,
_,_,_,_,_,_,_,_,_,_,_},
yslice_prob = {{ypos = 2, prob = 127}, {ypos = 3, prob = 127}, {ypos = 4, prob = 127}}}

-- Acacia tree log

default.acacia_log = {size = {x = 5, y = 1, z = 1}, data = {
{name = "default:acacia_trunk", param2 = 12, prob = 127},
{name = "default:acacia_trunk", param2 = 12},
{name = "default:acacia_trunk", param2 = 12},
{name = "default:acacia_trunk", param2 = 12},
{name = "default:acacia_trunk", param2 = 12, prob = 127}}}

-- Acacia bush

local L = {name = "default:acacia_bush_leaves"}
local M = {name = "default:acacia_bush_leaves", prob = 191}
local N = {name = "default:acacia_bush_leaves", prob = 127}
local S = {name = "default:acacia_bush_stem", force_place = true}

default.acacia_bush = {size = {x = 3, y = 2, z = 3}, data = {
N,M,N,
M,L,M,

M,S,M,
L,L,L,

N,M,N,
M,L,M}}
