
-- Apple trees

local L = {name = "default:apple_leaves_fruiting"}
local M = {name = "default:apple_leaves_fruiting", prob = 223}
local T = {name = "default:apple_trunk", force_place = true}

default.apple_tree = {size = {x = 7, y = 8, z = 7}, data = {
_,_,_,_,_,_,_,
_,_,_,_,_,_,_,
_,_,_,_,_,_,_,
_,_,_,_,_,_,_,
_,_,M,L,M,_,_,
_,_,_,M,_,_,_,
_,_,_,_,_,_,_,
_,_,_,_,_,_,_,

_,_,_,_,_,_,_,
_,_,_,_,_,_,_,
_,_,_,_,_,_,_,
_,_,_,_,_,_,_,
_,L,L,_,L,L,_,
_,M,L,L,L,M,_,
_,_,M,L,M,_,_,
_,_,_,_,_,_,_,

_,_,_,_,_,_,_,
_,_,_,_,_,_,_,
_,_,_,_,_,_,_,
_,_,_,_,_,_,_,
M,L,T,_,_,L,M,
_,L,L,_,T,L,_,
_,M,L,L,L,M,_,
_,_,_,M,_,_,_,

_,_,_,T,_,_,_,
_,_,_,T,_,_,_,
_,_,_,T,_,_,_,
_,_,_,T,_,_,_,
L,_,_,T,_,_,L,
M,L,_,_,_,L,M,
_,L,L,L,L,L,_,
_,_,M,L,M,_,_,

_,_,_,_,_,_,_,
_,_,_,_,_,_,_,
_,_,_,_,_,_,_,
_,_,_,_,_,_,_,
M,L,_,_,T,L,M,
_,L,T,_,L,L,_,
_,M,L,L,L,M,_,
_,_,_,M,_,_,_,

_,_,_,_,_,_,_,
_,_,_,_,_,_,_,
_,_,_,_,_,_,_,
_,_,_,_,_,_,_,
_,L,L,_,L,L,_,
_,M,L,L,L,M,_,
_,_,M,L,M,_,_,
_,_,_,_,_,_,_,

_,_,_,_,_,_,_,
_,_,_,_,_,_,_,
_,_,_,_,_,_,_,
_,_,_,_,_,_,_,
_,_,M,L,M,_,_,
_,_,_,M,_,_,_,
_,_,_,_,_,_,_,
_,_,_,_,_,_,_},
yslice_prob = {{ypos = 2, prob = 127}}}

default.apple_tree2 = {size = {x = 13, y = 13, z = 13}, data = {
_,_,_,_,_,_,_,_,_,_,_,_,_,
_,_,_,_,_,_,_,_,_,_,_,_,_,
_,_,_,_,_,_,_,_,_,_,_,_,_,
_,_,_,_,_,_,_,_,_,_,_,_,_,
_,_,_,_,_,_,_,_,_,_,_,_,_,
_,_,_,_,_,_,_,_,_,_,_,_,_,
_,_,_,_,_,L,L,L,_,_,_,_,_,
_,_,_,_,_,M,L,M,_,_,_,_,_,
_,_,_,_,_,_,_,_,_,_,_,_,_,
_,_,_,_,_,_,_,_,_,_,_,_,_,
_,_,_,_,_,_,_,_,_,_,_,_,_,
_,_,_,_,_,_,_,_,_,_,_,_,_,
_,_,_,_,_,_,_,_,_,_,_,_,_,

_,_,_,_,_,_,_,_,_,_,_,_,_,
_,_,_,_,_,_,_,_,_,_,_,_,_,
_,_,_,_,_,_,_,_,_,_,_,_,_,
_,_,_,_,_,_,_,_,_,_,_,_,_,
_,_,_,_,_,_,_,_,_,_,_,_,_,
_,_,_,_,_,_,M,_,_,_,_,_,_,
_,_,_,_,L,L,L,L,L,_,_,_,_,
_,_,_,_,M,L,L,L,M,_,_,_,_,
_,_,_,_,_,L,L,M,_,_,_,_,_,
_,_,_,_,_,_,_,_,_,_,_,_,_,
_,_,_,_,_,_,_,_,_,_,_,_,_,
_,_,_,_,_,_,_,_,_,_,_,_,_,
_,_,_,_,_,_,_,_,_,_,_,_,_,

_,_,_,_,_,_,_,_,_,_,_,_,_,
_,_,_,_,_,_,_,_,_,_,_,_,_,
_,_,_,_,_,_,_,_,_,_,_,_,_,
_,_,_,_,_,_,_,_,_,_,_,_,_,
_,_,_,_,_,_,_,_,_,_,_,_,_,
_,_,_,_,_,M,_,M,_,_,_,_,_,
_,_,_,_,L,L,T,L,L,_,_,_,_,
_,_,_,_,L,L,L,L,L,_,_,_,_,
_,_,_,_,_,L,L,L,_,_,_,_,_,
_,_,_,L,L,L,_,_,_,_,_,_,_,
_,_,_,M,L,M,_,L,L,L,_,_,_,
_,_,_,_,_,_,_,M,L,M,_,_,_,
_,_,_,_,_,_,_,_,_,_,_,_,_,

_,_,_,_,_,_,_,_,_,_,_,_,_,
_,_,_,_,_,_,_,_,_,_,_,_,_,
_,_,_,_,_,_,_,_,_,_,_,_,_,
_,_,_,_,_,_,_,_,_,_,_,_,_,
_,_,_,_,_,_,_,_,_,_,_,_,_,
_,_,_,_,_,_,_,_,_,_,_,_,_,
_,_,_,_,L,L,T,L,L,_,_,_,_,
_,_,_,M,L,L,L,L,L,M,_,_,_,
_,_,_,_,M,L,L,L,_,_,_,_,_,
_,_,L,L,L,L,L,_,M,_,_,_,_,
_,_,M,L,L,L,L,L,L,L,L,_,_,
_,_,_,M,L,L,L,L,L,L,M,_,_,
_,_,_,_,_,_,_,M,L,M,_,_,_,

_,_,_,_,_,_,_,_,_,_,_,_,_,
_,_,_,_,_,_,_,_,_,_,_,_,_,
_,_,_,_,_,_,_,_,_,_,_,_,_,
_,_,_,_,_,_,_,_,_,_,_,_,_,
_,_,_,_,_,_,_,_,_,_,_,_,_,
_,_,_,_,_,_,T,_,_,_,_,_,_,
_,L,L,L,_,L,L,L,_,L,L,L,_,
_,M,L,L,M,L,L,L,M,L,L,M,_,
_,_,_,M,T,L,_,_,_,_,_,_,_,
_,_,L,L,T,L,L,_,T,M,_,_,_,
_,_,L,L,L,L,L,L,T,L,L,_,_,
_,_,_,L,L,L,L,L,L,L,L,_,_,
_,_,_,_,_,_,_,L,L,L,_,_,_,

_,_,_,_,_,_,_,_,_,_,_,_,_,
_,_,_,_,_,_,_,_,_,_,_,_,_,
_,_,_,_,_,_,_,_,_,_,_,_,_,
_,_,_,_,_,_,_,_,_,_,_,_,_,
_,_,_,_,_,_,T,_,_,_,_,_,_,
_,_,M,_,_,_,_,_,_,_,M,_,_,
L,L,L,L,L,T,_,_,L,L,L,L,L,
M,L,L,L,L,T,_,T,L,L,L,L,M,
_,L,L,L,L,_,_,T,_,L,L,M,_,
_,_,L,L,L,L,L,_,_,_,_,_,_,
_,_,M,L,L,L,L,L,L,L,L,_,_,
_,_,_,L,L,L,L,L,L,L,M,_,_,
_,_,_,_,_,_,_,M,L,M,_,_,_,

_,_,_,_,_,_,T,_,_,_,_,_,_,
_,_,_,_,_,_,T,_,_,_,_,_,_,
_,_,_,_,_,_,T,_,_,_,_,_,_,
_,_,_,_,_,_,T,_,_,_,_,_,_,
_,_,_,_,_,T,T,T,_,_,_,_,_,
_,M,_,_,T,_,T,_,T,_,_,M,_,
L,L,T,T,L,_,T,_,L,T,T,L,L,
L,L,L,L,L,_,_,_,L,L,L,L,L,
_,L,L,L,_,_,_,_,_,L,L,L,_,
_,_,_,L,L,L,_,L,L,L,_,_,_,
_,_,_,L,L,L,M,L,L,L,_,_,_,
_,_,_,L,L,L,M,L,L,L,_,_,_,
_,_,_,_,_,_,_,_,_,_,_,_,_,

_,_,_,_,_,_,_,_,_,_,_,_,_,
_,_,_,_,_,_,_,_,_,_,_,_,_,
_,_,_,_,_,_,_,_,_,_,_,_,_,
_,_,_,_,_,_,_,_,_,_,_,_,_,
_,_,_,_,_,_,T,_,_,_,_,_,_,
_,_,M,_,_,_,_,_,_,_,M,_,_,
L,L,L,L,L,_,_,T,L,L,L,L,L,
M,L,L,L,L,T,_,T,L,L,L,L,M,
_,M,L,L,_,T,_,_,L,L,L,L,_,
_,_,_,_,_,_,L,L,L,L,L,_,_,
_,_,L,L,L,L,L,L,L,L,M,_,_,
_,_,M,L,L,L,L,L,L,L,_,_,_,
_,_,_,M,L,M,_,_,_,_,_,_,_,

_,_,_,_,_,_,_,_,_,_,_,_,_,
_,_,_,_,_,_,_,_,_,_,_,_,_,
_,_,_,_,_,_,_,_,_,_,_,_,_,
_,_,_,_,_,_,_,_,_,_,_,_,_,
_,_,_,_,_,_,_,_,_,_,_,_,_,
_,_,_,_,_,_,T,_,_,_,_,_,_,
_,L,L,L,_,L,L,L,_,L,L,L,_,
_,M,L,L,M,L,L,L,M,L,L,M,_,
_,_,_,_,_,_,_,L,T,M,_,_,_,
_,_,_,M,T,_,L,L,T,L,L,_,_,
_,_,L,L,T,L,L,L,L,L,L,_,_,
_,_,L,L,L,L,L,L,L,L,_,_,_,
_,_,_,L,L,L,_,_,_,_,_,_,_,

_,_,_,_,_,_,_,_,_,_,_,_,_,
_,_,_,_,_,_,_,_,_,_,_,_,_,
_,_,_,_,_,_,_,_,_,_,_,_,_,
_,_,_,_,_,_,_,_,_,_,_,_,_,
_,_,_,_,_,_,_,_,_,_,_,_,_,
_,_,_,_,_,_,_,_,_,_,_,_,_,
_,_,_,_,L,L,T,L,L,_,_,_,_,
_,_,_,M,L,L,L,L,L,M,_,_,_,
_,_,_,_,_,L,L,L,M,_,_,_,_,
_,_,_,_,M,_,L,L,L,L,L,_,_,
_,_,L,L,L,L,L,L,L,L,M,_,_,
_,_,M,L,L,L,L,L,L,M,_,_,_,
_,_,_,M,L,M,_,_,_,_,_,_,_,

_,_,_,_,_,_,_,_,_,_,_,_,_,
_,_,_,_,_,_,_,_,_,_,_,_,_,
_,_,_,_,_,_,_,_,_,_,_,_,_,
_,_,_,_,_,_,_,_,_,_,_,_,_,
_,_,_,_,_,_,_,_,_,_,_,_,_,
_,_,_,_,_,M,_,M,_,_,_,_,_,
_,_,_,_,L,L,T,L,L,_,_,_,_,
_,_,_,_,L,L,L,L,L,_,_,_,_,
_,_,_,_,_,L,L,L,_,_,_,_,_,
_,_,_,_,_,_,_,L,L,L,_,_,_,
_,_,_,L,L,L,_,M,L,M,_,_,_,
_,_,_,M,L,M,_,_,_,_,_,_,_,
_,_,_,_,_,_,_,_,_,_,_,_,_,

_,_,_,_,_,_,_,_,_,_,_,_,_,
_,_,_,_,_,_,_,_,_,_,_,_,_,
_,_,_,_,_,_,_,_,_,_,_,_,_,
_,_,_,_,_,_,_,_,_,_,_,_,_,
_,_,_,_,_,_,_,_,_,_,_,_,_,
_,_,_,_,_,_,M,_,_,_,_,_,_,
_,_,_,_,L,L,L,L,L,_,_,_,_,
_,_,_,_,M,L,L,L,M,_,_,_,_,
_,_,_,_,_,M,L,L,_,_,_,_,_,
_,_,_,_,_,_,_,_,_,_,_,_,_,
_,_,_,_,_,_,_,_,_,_,_,_,_,
_,_,_,_,_,_,_,_,_,_,_,_,_,
_,_,_,_,_,_,_,_,_,_,_,_,_,

_,_,_,_,_,_,_,_,_,_,_,_,_,
_,_,_,_,_,_,_,_,_,_,_,_,_,
_,_,_,_,_,_,_,_,_,_,_,_,_,
_,_,_,_,_,_,_,_,_,_,_,_,_,
_,_,_,_,_,_,_,_,_,_,_,_,_,
_,_,_,_,_,_,_,_,_,_,_,_,_,
_,_,_,_,_,L,L,L,_,_,_,_,_,
_,_,_,_,_,M,L,M,_,_,_,_,_,
_,_,_,_,_,_,_,_,_,_,_,_,_,
_,_,_,_,_,_,_,_,_,_,_,_,_,
_,_,_,_,_,_,_,_,_,_,_,_,_,
_,_,_,_,_,_,_,_,_,_,_,_,_,
_,_,_,_,_,_,_,_,_,_,_,_,_},
yslice_prob = {{ypos = 2, prob = 127}}}
