
-- Aspen tree

local T = {name = "default:aspen_trunk", force_place = true}
local L = {name = "default:aspen_leaves"}
local M = {name = "default:aspen_leaves", prob = 223}
local N = {name = "default:aspen_leaves", prob = 127}

default.aspen_tree = {size = {x = 5, y = 14, z = 5}, data = {
_,_,_,_,_,
_,_,_,_,_,
_,_,_,_,_,
_,_,_,_,_,
_,_,_,_,_,
_,_,_,_,_,
_,_,_,_,_,
N,M,L,M,N,
_,_,_,_,_,
N,M,L,M,N,
_,_,_,_,_,
N,M,L,M,N,
_,_,_,_,_,
_,_,_,_,_,

_,_,_,_,_,
_,_,_,_,_,
_,_,_,_,_,
_,_,_,_,_,
_,_,_,_,_,
_,_,_,_,_,
_,M,L,M,_,
M,L,L,L,M,
_,M,L,M,_,
M,L,L,L,M,
_,M,L,M,_,
M,L,L,L,M,
_,M,L,M,_,
_,_,_,_,_,

_,_,T,_,_,
_,_,T,_,_,
_,_,T,_,_,
_,_,T,_,_,
_,_,T,_,_,
_,_,T,_,_,
_,L,T,L,_,
L,L,T,L,L,
_,L,T,L,_,
L,L,T,L,L,
_,L,T,L,_,
L,L,T,L,L,
_,L,L,L,_,
_,_,L,_,_,

_,_,_,_,_,
_,_,_,_,_,
_,_,_,_,_,
_,_,_,_,_,
_,_,_,_,_,
_,_,_,_,_,
_,M,L,M,_,
M,L,L,L,M,
_,M,L,M,_,
M,L,L,L,M,
_,M,L,M,_,
M,L,L,L,M,
_,M,L,M,_,
_,_,_,_,_,

_,_,_,_,_,
_,_,_,_,_,
_,_,_,_,_,
_,_,_,_,_,
_,_,_,_,_,
_,_,_,_,_,
_,_,_,_,_,
N,M,L,M,N,
_,_,_,_,_,
N,M,L,M,N,
_,_,_,_,_,
N,M,L,M,N,
_,_,_,_,_,
_,_,_,_,_},
yslice_prob = {{ypos = 2, prob = 127}, {ypos = 3, prob = 127}, {ypos = 4, prob = 127}, {ypos = 8, prob = 127}, {ypos = 10, prob = 127}}}

default.aspen_tree2 = {size = {x = 15, y = 25, z = 15}, data = {
_,_,_,_,_,_,_,_,_,_,_,_,_,_,_,
_,_,_,_,_,_,_,_,_,_,_,_,_,_,_,
_,_,_,_,_,_,_,_,_,_,_,_,_,_,_,
_,_,_,_,_,_,_,_,_,_,_,_,_,_,_,
_,_,_,_,_,_,_,_,_,_,_,_,_,_,_,
_,_,_,_,_,_,_,_,_,_,_,_,_,_,_,
_,_,_,_,_,_,_,_,_,_,_,_,_,_,_,
_,_,_,_,_,_,_,_,_,_,_,_,_,_,_,
_,_,_,_,_,_,_,_,_,_,_,_,_,_,_,
_,_,_,_,_,_,_,_,_,_,_,_,_,_,_,
_,_,_,_,_,_,_,_,_,_,_,_,_,_,_,
_,_,_,_,_,_,_,_,_,_,_,_,_,_,_,
_,_,_,_,_,_,_,_,_,_,_,_,_,_,_,
_,_,_,_,_,N,M,L,M,N,_,_,_,_,_,
_,_,_,_,_,_,_,_,_,_,_,_,_,_,_,
_,_,_,_,_,_,_,_,_,_,_,_,_,_,_,
_,_,_,_,_,_,_,_,_,_,_,_,_,_,_,
_,_,_,_,_,_,_,_,_,_,_,_,_,_,_,
_,_,_,_,_,_,_,_,_,_,_,_,_,_,_,
_,_,_,_,_,_,_,_,_,_,_,_,_,_,_,
_,_,_,_,_,_,_,_,_,_,_,_,_,_,_,
_,_,_,_,_,_,_,_,_,_,_,_,_,_,_,
_,_,_,_,_,_,_,_,_,_,_,_,_,_,_,
_,_,_,_,_,_,_,_,_,_,_,_,_,_,_,
_,_,_,_,_,_,_,_,_,_,_,_,_,_,_,

_,_,_,_,_,_,_,_,_,_,_,_,_,_,_,
_,_,_,_,_,_,_,_,_,_,_,_,_,_,_,
_,_,_,_,_,_,_,_,_,_,_,_,_,_,_,
_,_,_,_,_,_,_,_,_,_,_,_,_,_,_,
_,_,_,_,_,_,_,_,_,_,_,_,_,_,_,
_,_,_,_,_,_,_,_,_,_,_,_,_,_,_,
_,_,_,_,_,_,_,_,_,_,_,_,_,_,_,
_,_,_,_,_,_,_,_,_,_,_,_,_,_,_,
_,_,_,_,_,_,_,_,_,_,_,_,_,_,_,
_,_,_,_,_,_,_,_,_,_,_,_,_,_,_,
_,N,M,L,M,N,_,_,_,_,_,_,_,_,_,
_,_,_,_,_,_,_,_,_,_,_,_,_,_,_,
_,_,_,_,_,_,M,L,M,_,_,_,_,_,_,
_,_,_,_,_,M,L,L,L,M,_,_,_,_,_,
_,_,_,_,_,_,M,L,M,_,_,_,_,_,_,
_,_,_,_,_,_,_,_,_,_,_,_,_,_,_,
_,_,_,_,_,_,_,_,_,_,_,_,_,_,_,
_,_,_,_,_,_,_,_,_,_,_,_,_,_,_,
_,_,_,_,_,_,_,_,_,_,_,_,_,_,_,
_,_,_,_,_,_,_,_,_,_,_,_,_,_,_,
_,_,_,_,_,_,_,_,_,_,_,_,_,_,_,
_,_,_,_,_,_,_,_,_,_,_,_,_,_,_,
_,_,_,_,_,_,_,_,_,_,_,_,_,_,_,
_,_,_,_,_,_,_,_,_,_,_,_,_,_,_,
_,_,_,_,_,_,_,_,_,_,_,_,_,_,_,

_,_,_,_,_,_,_,_,_,_,_,_,_,_,_,
_,_,_,_,_,_,_,_,_,_,_,_,_,_,_,
_,_,_,_,_,_,_,_,_,_,_,_,_,_,_,
_,_,_,_,_,_,_,_,_,_,_,_,_,_,_,
_,_,_,_,_,_,_,_,_,_,_,_,_,_,_,
_,_,_,_,_,_,_,_,_,_,_,_,_,_,_,
_,_,_,_,_,_,_,_,_,_,_,_,_,_,_,
_,_,_,_,_,_,_,_,_,_,_,_,_,_,_,
_,_,_,_,_,_,_,_,_,_,_,_,_,_,_,
_,_,M,L,M,_,_,_,_,_,_,_,_,_,_,
_,M,L,L,L,M,_,_,_,_,_,_,_,_,_,
_,_,M,L,M,_,_,L,_,_,_,_,_,_,_,
_,_,_,_,_,_,L,L,L,_,_,_,_,_,_,
_,_,_,_,_,L,L,T,L,L,_,_,_,_,_,
_,_,_,_,_,_,L,L,L,M,L,M,N,_,_,
_,_,_,_,_,_,_,L,_,_,_,_,_,_,_,
_,_,_,_,_,_,_,_,_,_,_,_,_,_,_,
_,_,N,M,L,M,N,_,_,_,_,_,_,_,_,
_,_,_,_,_,_,_,_,N,M,L,M,N,_,_,
_,_,_,_,_,_,_,_,_,_,_,_,_,_,_,
_,_,_,_,_,_,_,_,_,_,_,_,_,_,_,
_,_,_,_,_,_,_,_,_,_,_,_,_,_,_,
_,_,_,_,_,_,_,_,_,_,_,_,_,_,_,
_,_,_,_,_,_,_,_,_,_,_,_,_,_,_,
_,_,_,_,_,_,_,_,_,_,_,_,_,_,_,

_,_,_,_,_,_,_,_,_,_,_,_,_,_,_,
_,_,_,_,_,_,_,_,_,_,_,_,_,_,_,
_,_,_,_,_,_,_,_,_,_,_,_,_,_,_,
_,_,_,_,_,_,_,_,_,_,_,_,_,_,_,
_,_,_,_,_,_,_,_,_,_,_,_,_,_,_,
_,_,_,_,_,_,_,_,_,_,_,_,_,_,_,
_,_,_,_,_,_,_,_,_,_,_,_,_,_,_,
_,_,_,_,_,_,_,_,_,_,_,_,_,_,_,
_,_,_,_,L,_,_,_,_,_,_,_,_,_,_,
_,_,L,L,L,M,_,_,_,_,_,_,_,_,_,
_,L,L,T,L,L,_,_,_,_,_,_,_,_,_,
_,_,L,L,L,_,L,L,L,_,_,_,_,_,_,
_,_,_,L,_,M,L,T,L,M,_,_,_,_,_,
_,_,_,_,_,M,L,L,L,L,L,M,_,_,_,
_,_,_,_,_,_,M,L,M,L,L,L,M,_,_,
_,_,_,_,_,_,_,_,_,M,L,M,_,_,_,
_,_,_,M,L,M,_,_,_,_,_,_,_,_,_,
_,_,M,L,L,L,M,_,_,M,L,M,_,_,_,
_,_,_,M,L,M,_,_,M,L,L,L,M,_,_,
_,_,_,_,_,_,_,_,_,M,L,M,_,_,_,
_,_,_,_,_,_,_,_,_,_,_,_,_,_,_,
_,_,_,_,_,_,_,_,_,_,_,_,_,_,_,
_,_,_,_,_,_,_,_,_,_,_,_,_,_,_,
_,_,_,_,_,_,_,_,_,_,_,_,_,_,_,
_,_,_,_,_,_,_,_,_,_,_,_,_,_,_,

_,_,_,_,_,_,_,_,_,_,_,_,_,_,_,
_,_,_,_,_,_,_,_,_,_,_,_,_,_,_,
_,_,_,_,_,_,_,_,_,_,_,_,_,_,_,
_,_,_,_,_,_,_,_,_,_,_,_,_,_,_,
_,_,_,_,_,_,_,_,_,_,_,_,_,_,_,
_,_,_,_,_,_,_,_,_,_,_,_,_,_,_,
_,_,_,_,_,_,_,_,_,_,_,_,_,_,_,
_,_,_,_,_,_,_,_,_,_,_,_,_,_,_,
_,_,_,L,L,L,_,_,_,_,_,_,_,_,_,
_,_,M,L,T,L,_,_,_,_,_,_,_,_,_,
_,M,L,L,L,M,_,_,_,_,_,_,_,_,_,
_,_,M,L,M,_,_,T,_,_,_,_,_,_,_,
_,_,_,_,_,_,L,L,L,L,_,_,_,_,_,
_,_,_,_,_,N,M,L,M,L,L,L,_,_,_,
_,_,_,_,_,_,_,_,L,L,T,L,L,_,_,
_,_,_,_,_,L,_,_,_,L,L,L,_,_,_,
_,_,_,L,L,L,M,_,_,L,L,_,_,_,_,
_,_,L,L,T,L,L,_,M,L,L,L,_,_,_,
_,_,_,L,L,L,_,_,L,L,T,L,L,_,_,
_,_,_,_,L,_,_,_,_,L,L,L,_,_,_,
_,_,_,_,_,_,_,_,_,_,L,_,_,_,_,
_,_,_,_,_,_,_,_,_,_,_,_,_,_,_,
_,_,_,_,_,_,_,_,_,_,_,_,_,_,_,
_,_,_,_,_,_,_,_,_,_,_,_,_,_,_,
_,_,_,_,_,_,_,_,_,_,_,_,_,_,_,

_,_,_,_,_,_,_,_,_,_,_,_,_,_,_,
_,_,_,_,_,_,_,_,_,_,_,_,_,_,_,
_,_,_,_,_,_,_,_,_,_,_,_,_,_,_,
_,_,_,_,_,_,_,_,_,_,_,_,_,_,_,
_,_,_,_,_,_,_,_,_,_,_,_,_,_,_,
_,_,_,_,_,_,_,_,_,_,_,_,_,_,_,
_,_,_,_,_,_,_,_,_,_,_,_,_,_,_,
_,_,_,_,_,_,_,_,_,_,_,_,_,_,_,
_,_,_,_,L,T,_,_,_,_,_,_,_,_,_,
_,_,_,M,L,_,_,_,_,_,_,_,_,_,_,
_,N,M,L,M,N,_,T,_,_,_,M,_,_,_,
_,_,_,_,_,_,_,_,_,_,N,M,L,M,N,
_,_,_,_,_,_,_,_,L,L,L,_,_,_,_,
_,_,_,_,_,_,_,_,L,T,L,M,_,_,_,
_,_,_,_,_,_,_,_,M,L,L,L,M,_,_,
_,_,_,_,L,L,L,_,_,M,L,M,_,_,_,
_,N,M,L,L,T,L,_,L,L,L,_,_,_,_,
_,_,M,L,L,L,M,_,L,T,L,M,_,_,_,
_,_,_,M,L,M,_,_,M,L,L,L,M,_,_,
_,_,_,_,_,_,_,_,_,M,L,M,_,_,_,
_,_,_,_,_,_,M,L,M,_,_,_,_,_,_,
_,_,_,_,_,_,_,_,_,_,_,_,_,_,_,
_,_,_,_,_,N,M,L,M,N,_,_,_,_,_,
_,_,_,_,_,_,_,_,_,_,_,_,_,_,_,
_,_,_,_,_,_,_,_,_,_,_,_,_,_,_,

_,_,_,_,_,_,_,_,_,_,_,_,_,_,_,
_,_,_,_,_,_,_,_,_,_,_,_,_,_,_,
_,_,_,_,_,_,_,_,_,_,_,_,_,_,_,
_,_,_,_,_,_,_,_,_,_,_,_,_,_,_,
_,_,_,_,_,_,_,_,_,_,_,_,_,_,_,
_,_,_,_,_,_,_,_,_,_,_,_,_,_,_,
_,_,_,_,_,_,_,_,_,_,_,_,_,_,_,
_,_,_,_,_,_,T,_,_,_,_,_,_,_,_,
_,_,_,_,_,_,_,_,_,_,_,_,_,_,_,
_,_,_,M,_,_,_,T,_,_,_,L,_,_,_,
N,M,L,M,N,_,_,_,_,_,L,L,L,M,_,
_,_,_,_,_,_,_,_,_,_,M,L,L,L,M,
_,_,_,_,_,_,_,_,T,L,_,M,L,M,_,
_,_,_,_,_,_,_,_,_,L,M,_,_,_,_,
_,_,_,_,L,_,_,_,N,M,L,M,N,_,_,
_,_,M,L,L,L,T,_,_,_,_,_,_,_,_,
_,M,L,L,L,L,_,_,T,L,_,_,_,_,_,
_,_,M,L,L,M,N,_,_,L,M,_,_,_,_,
_,_,_,_,_,_,_,_,N,M,L,M,N,_,_,
_,_,_,_,_,_,M,L,M,_,_,_,_,_,_,
_,_,_,_,_,M,L,L,L,M,_,_,_,_,_,
_,_,_,_,_,_,L,L,L,_,_,_,_,_,_,
_,_,_,_,_,M,L,L,L,M,_,_,_,_,_,
_,_,_,_,_,_,M,L,M,_,_,_,_,_,_,
_,_,_,_,_,_,_,_,_,_,_,_,_,_,_,

_,_,_,_,_,_,_,T,_,_,_,_,_,_,_,
_,_,_,_,_,_,_,T,_,_,_,_,_,_,_,
_,_,_,_,_,_,_,T,_,_,_,_,_,_,_,
_,_,_,_,_,_,_,T,_,_,_,_,_,_,_,
_,_,_,_,_,_,_,T,_,_,_,_,_,_,_,
_,_,_,_,_,_,_,T,_,_,_,_,_,_,_,
_,_,_,_,_,_,_,T,_,_,_,_,_,_,_,
_,_,_,_,_,_,_,T,T,_,_,_,_,_,_,
_,_,_,L,_,_,_,T,_,T,_,_,_,_,_,
_,M,L,L,L,_,_,T,_,_,T,L,L,_,_,
M,L,L,L,M,_,_,T,_,_,L,T,L,L,_,
_,M,L,M,_,_,_,T,_,_,L,L,T,L,L,
_,_,_,_,_,_,_,T,_,_,_,L,L,L,_,
_,_,_,_,_,_,T,T,_,_,_,_,L,_,_,
_,_,_,L,L,T,_,T,_,_,_,_,_,_,_,
_,_,L,L,T,L,_,T,_,_,_,_,_,_,_,
_,L,L,T,L,L,_,T,_,_,_,_,_,_,_,
_,_,L,L,L,_,_,T,_,_,_,_,_,_,_,
_,_,_,L,_,_,_,T,_,_,_,_,_,_,_,
_,_,_,_,_,_,L,T,L,_,_,_,_,_,_,
_,_,_,_,_,L,L,T,L,L,_,_,_,_,_,
_,_,_,_,_,_,L,T,L,_,_,_,_,_,_,
_,_,_,_,_,L,L,T,L,L,_,_,_,_,_,
_,_,_,_,_,_,L,L,L,_,_,_,_,_,_,
_,_,_,_,_,_,_,L,_,_,_,_,_,_,_,

_,_,_,_,_,_,_,_,_,_,_,_,_,_,_,
_,_,_,_,_,_,_,_,_,_,_,_,_,_,_,
_,_,_,_,_,_,_,_,_,_,_,_,_,_,_,
_,_,_,_,_,_,_,_,_,_,_,_,_,_,_,
_,_,_,_,_,_,_,_,_,_,_,_,_,_,_,
_,_,_,_,_,_,_,_,_,_,_,_,_,_,_,
_,_,_,_,_,_,T,_,_,_,_,_,_,_,_,
_,_,_,_,_,T,_,_,_,_,_,_,_,_,_,
_,_,L,L,T,_,_,T,_,_,_,_,_,_,_,
_,L,L,T,L,_,_,_,_,_,_,L,_,_,_,
L,L,T,L,L,_,_,_,T,_,L,L,L,M,_,
_,L,L,L,_,_,T,_,_,_,M,L,L,L,M,
_,_,L,_,_,_,_,_,_,_,_,M,L,M,_,
_,_,_,_,_,_,_,_,T,_,_,_,_,_,_,
_,_,_,_,L,_,_,_,_,L,_,_,_,_,_,
_,_,M,L,L,L,_,_,_,L,M,_,_,_,_,
_,M,L,L,L,M,_,T,N,M,L,M,N,_,_,
_,_,M,L,M,_,L,L,L,_,_,_,_,_,_,
_,_,_,_,_,N,M,L,M,N,_,_,_,_,_,
_,_,_,_,_,_,M,L,M,_,_,_,_,_,_,
_,_,_,_,_,M,L,L,L,M,_,_,_,_,_,
_,_,_,_,_,_,L,L,L,_,_,_,_,_,_,
_,_,_,_,_,M,L,L,L,M,_,_,_,_,_,
_,_,_,_,_,_,M,L,M,_,_,_,_,_,_,
_,_,_,_,_,_,_,_,_,_,_,_,_,_,_,

_,_,_,_,_,_,_,_,_,_,_,_,_,_,_,
_,_,_,_,_,_,_,_,_,_,_,_,_,_,_,
_,_,_,_,_,_,_,_,_,_,_,_,_,_,_,
_,_,_,_,_,_,_,_,_,_,_,_,_,_,_,
_,_,_,_,_,_,_,_,_,_,_,_,_,_,_,
_,_,_,_,_,_,_,_,_,_,_,_,_,_,_,
_,_,_,_,_,_,_,_,_,_,_,_,_,_,_,
_,_,_,_,_,_,_,_,_,_,_,_,_,_,_,
_,_,_,L,_,_,_,_,_,_,_,_,_,_,_,
_,M,L,L,L,_,_,T,_,_,_,_,_,_,_,
M,L,L,L,M,_,_,_,_,_,_,M,_,_,_,
_,M,L,M,_,_,_,_,_,T,L,M,L,M,N,
_,_,_,_,L,T,_,_,_,_,L,L,_,_,_,
_,_,_,M,L,_,_,_,_,N,M,L,M,N,_,
_,N,M,L,M,N,_,_,L,T,L,_,_,_,_,
_,_,_,_,M,_,_,_,L,_,L,M,_,_,_,
_,N,M,L,M,N,L,L,L,L,L,L,M,_,_,
_,_,_,_,_,M,L,T,L,M,L,M,_,_,_,
_,_,_,_,_,M,L,L,L,M,_,_,_,_,_,
_,_,_,_,_,_,M,L,M,_,_,_,_,_,_,
_,_,_,_,_,_,M,L,M,_,_,_,_,_,_,
_,_,_,_,_,_,_,_,_,_,_,_,_,_,_,
_,_,_,_,_,N,M,L,M,N,_,_,_,_,_,
_,_,_,_,_,_,_,_,_,_,_,_,_,_,_,
_,_,_,_,_,_,_,_,_,_,_,_,_,_,_,

_,_,_,_,_,_,_,_,_,_,_,_,_,_,_,
_,_,_,_,_,_,_,_,_,_,_,_,_,_,_,
_,_,_,_,_,_,_,_,_,_,_,_,_,_,_,
_,_,_,_,_,_,_,_,_,_,_,_,_,_,_,
_,_,_,_,_,_,_,_,_,_,_,_,_,_,_,
_,_,_,_,_,_,_,_,_,_,_,_,_,_,_,
_,_,_,_,_,_,_,_,_,_,_,_,_,_,_,
_,_,_,_,_,_,_,_,_,_,_,_,_,_,_,
_,_,_,_,_,_,_,_,_,_,_,_,_,_,_,
_,_,_,M,_,_,_,_,_,_,_,_,_,_,_,
N,M,L,M,N,_,_,T,_,_,_,_,_,_,_,
_,_,_,_,_,_,L,L,L,L,L,L,_,_,_,
_,_,_,L,L,L,M,L,M,L,T,L,M,_,_,
_,_,M,L,T,L,_,_,_,M,L,L,L,M,_,
_,M,L,L,L,M,_,_,_,L,M,L,M,_,_,
_,_,M,L,M,_,_,_,M,L,T,L,_,_,_,
_,_,_,_,_,_,_,L,L,L,T,L,L,_,_,
_,_,_,_,_,_,L,L,L,L,L,L,_,_,_,
_,_,_,_,_,L,L,T,L,L,L,_,_,_,_,
_,_,_,_,_,_,L,L,L,_,_,_,_,_,_,
_,_,_,_,_,_,_,L,_,_,_,_,_,_,_,
_,_,_,_,_,_,_,_,_,_,_,_,_,_,_,
_,_,_,_,_,_,_,_,_,_,_,_,_,_,_,
_,_,_,_,_,_,_,_,_,_,_,_,_,_,_,
_,_,_,_,_,_,_,_,_,_,_,_,_,_,_,

_,_,_,_,_,_,_,_,_,_,_,_,_,_,_,
_,_,_,_,_,_,_,_,_,_,_,_,_,_,_,
_,_,_,_,_,_,_,_,_,_,_,_,_,_,_,
_,_,_,_,_,_,_,_,_,_,_,_,_,_,_,
_,_,_,_,_,_,_,_,_,_,_,_,_,_,_,
_,_,_,_,_,_,_,_,_,_,_,_,_,_,_,
_,_,_,_,_,_,_,_,_,_,_,_,_,_,_,
_,_,_,_,_,_,_,_,_,_,_,_,_,_,_,
_,_,_,_,_,_,_,_,_,_,_,_,_,_,_,
_,_,_,_,_,_,_,_,_,_,_,_,_,_,_,
_,_,_,_,_,_,L,L,L,_,_,_,_,_,_,
_,_,_,_,_,M,L,T,L,M,L,_,_,_,_,
_,_,_,_,L,M,L,L,L,L,L,L,L,_,_,
_,_,L,L,L,L,M,L,M,L,L,T,L,L,_,
_,L,L,T,L,L,_,_,_,_,L,L,L,_,_,
_,_,L,L,L,_,_,_,_,M,L,L,_,_,_,
_,_,_,L,_,_,_,_,M,L,L,L,M,_,_,
_,_,_,_,_,_,M,L,M,M,L,M,_,_,_,
_,_,_,_,_,M,L,L,L,M,_,_,_,_,_,
_,_,_,_,_,_,M,L,M,_,_,_,_,_,_,
_,_,_,_,_,_,_,_,_,_,_,_,_,_,_,
_,_,_,_,_,_,_,_,_,_,_,_,_,_,_,
_,_,_,_,_,_,_,_,_,_,_,_,_,_,_,
_,_,_,_,_,_,_,_,_,_,_,_,_,_,_,
_,_,_,_,_,_,_,_,_,_,_,_,_,_,_,

_,_,_,_,_,_,_,_,_,_,_,_,_,_,_,
_,_,_,_,_,_,_,_,_,_,_,_,_,_,_,
_,_,_,_,_,_,_,_,_,_,_,_,_,_,_,
_,_,_,_,_,_,_,_,_,_,_,_,_,_,_,
_,_,_,_,_,_,_,_,_,_,_,_,_,_,_,
_,_,_,_,_,_,_,_,_,_,_,_,_,_,_,
_,_,_,_,_,_,_,_,_,_,_,_,_,_,_,
_,_,_,_,_,_,_,_,_,_,_,_,_,_,_,
_,_,_,_,_,_,_,_,_,_,_,_,_,_,_,
_,_,_,_,_,_,_,_,_,_,_,_,_,_,_,
_,_,_,_,_,_,_,L,_,_,_,_,_,_,_,
_,_,_,_,_,_,L,L,L,_,_,_,_,_,_,
_,_,_,_,_,L,L,T,L,L,M,L,M,_,_,
_,_,M,L,M,_,L,L,L,M,L,L,L,M,_,
_,M,L,L,L,M,_,L,_,_,M,L,M,_,_,
_,_,M,L,M,_,_,_,_,_,_,_,_,_,_,
_,_,_,_,_,_,_,_,N,M,L,M,N,_,_,
_,_,_,_,_,_,_,_,_,_,_,_,_,_,_,
_,_,_,_,_,N,M,L,M,N,_,_,_,_,_,
_,_,_,_,_,_,_,_,_,_,_,_,_,_,_,
_,_,_,_,_,_,_,_,_,_,_,_,_,_,_,
_,_,_,_,_,_,_,_,_,_,_,_,_,_,_,
_,_,_,_,_,_,_,_,_,_,_,_,_,_,_,
_,_,_,_,_,_,_,_,_,_,_,_,_,_,_,
_,_,_,_,_,_,_,_,_,_,_,_,_,_,_,

_,_,_,_,_,_,_,_,_,_,_,_,_,_,_,
_,_,_,_,_,_,_,_,_,_,_,_,_,_,_,
_,_,_,_,_,_,_,_,_,_,_,_,_,_,_,
_,_,_,_,_,_,_,_,_,_,_,_,_,_,_,
_,_,_,_,_,_,_,_,_,_,_,_,_,_,_,
_,_,_,_,_,_,_,_,_,_,_,_,_,_,_,
_,_,_,_,_,_,_,_,_,_,_,_,_,_,_,
_,_,_,_,_,_,_,_,_,_,_,_,_,_,_,
_,_,_,_,_,_,_,_,_,_,_,_,_,_,_,
_,_,_,_,_,_,_,_,_,_,_,_,_,_,_,
_,_,_,_,_,_,_,_,_,_,_,_,_,_,_,
_,_,_,_,_,_,M,L,M,_,_,_,_,_,_,
_,_,_,_,_,M,L,L,L,M,_,_,_,_,_,
_,_,_,_,_,_,M,L,M,N,M,L,M,N,_,
_,N,M,L,M,N,_,_,_,_,_,_,_,_,_,
_,_,_,_,_,_,_,_,_,_,_,_,_,_,_,
_,_,_,_,_,_,_,_,_,_,_,_,_,_,_,
_,_,_,_,_,_,_,_,_,_,_,_,_,_,_,
_,_,_,_,_,_,_,_,_,_,_,_,_,_,_,
_,_,_,_,_,_,_,_,_,_,_,_,_,_,_,
_,_,_,_,_,_,_,_,_,_,_,_,_,_,_,
_,_,_,_,_,_,_,_,_,_,_,_,_,_,_,
_,_,_,_,_,_,_,_,_,_,_,_,_,_,_,
_,_,_,_,_,_,_,_,_,_,_,_,_,_,_,
_,_,_,_,_,_,_,_,_,_,_,_,_,_,_,

_,_,_,_,_,_,_,_,_,_,_,_,_,_,_,
_,_,_,_,_,_,_,_,_,_,_,_,_,_,_,
_,_,_,_,_,_,_,_,_,_,_,_,_,_,_,
_,_,_,_,_,_,_,_,_,_,_,_,_,_,_,
_,_,_,_,_,_,_,_,_,_,_,_,_,_,_,
_,_,_,_,_,_,_,_,_,_,_,_,_,_,_,
_,_,_,_,_,_,_,_,_,_,_,_,_,_,_,
_,_,_,_,_,_,_,_,_,_,_,_,_,_,_,
_,_,_,_,_,_,_,_,_,_,_,_,_,_,_,
_,_,_,_,_,_,_,_,_,_,_,_,_,_,_,
_,_,_,_,_,_,_,_,_,_,_,_,_,_,_,
_,_,_,_,_,_,_,_,_,_,_,_,_,_,_,
_,_,_,_,_,N,M,L,M,N,_,_,_,_,_,
_,_,_,_,_,_,_,_,_,_,_,_,_,_,_,
_,_,_,_,_,_,_,_,_,_,_,_,_,_,_,
_,_,_,_,_,_,_,_,_,_,_,_,_,_,_,
_,_,_,_,_,_,_,_,_,_,_,_,_,_,_,
_,_,_,_,_,_,_,_,_,_,_,_,_,_,_,
_,_,_,_,_,_,_,_,_,_,_,_,_,_,_,
_,_,_,_,_,_,_,_,_,_,_,_,_,_,_,
_,_,_,_,_,_,_,_,_,_,_,_,_,_,_,
_,_,_,_,_,_,_,_,_,_,_,_,_,_,_,
_,_,_,_,_,_,_,_,_,_,_,_,_,_,_,
_,_,_,_,_,_,_,_,_,_,_,_,_,_,_,
_,_,_,_,_,_,_,_,_,_,_,_,_,_,_},
yslice_prob = {{ypos = 2, prob = 127}}}

-- Aspen tree log

default.aspen_log = {size = {x = 5, y = 2, z = 1}, data = {
{name = "default:aspen_trunk", param2 = 12, prob = 127},
{name = "default:aspen_trunk", param2 = 12},
{name = "default:aspen_trunk", param2 = 12},
{name = "default:aspen_trunk", param2 = 12},
{name = "default:aspen_trunk", param2 = 12, prob = 127},
_,
{name = "flowers:mushroom_red", prob = 63},
{name = "flowers:mushroom_brown", prob = 63},
_,
_}}
