
-- Mangrove trees

local L = {name = "default:mangrove_leaves"}
local M = {name = "default:mangrove_leaves", prob = 223}
local T = {name = "default:mangrove_trunk", force_place = true}

default.mangrove_tree1 = {size = {x = 5, y = 12, z = 5}, data = {
_,_,_,_,_,
_,_,_,_,_,
_,_,_,_,_,
_,_,_,_,_,
_,_,_,_,_,
_,_,_,_,_,
_,_,_,_,_,
L,L,L,_,_,
_,_,_,_,_,
_,_,_,_,_,
_,_,_,_,_,
_,_,_,_,_,

_,_,T,_,_,
_,_,T,_,_,
_,_,_,_,_,
_,_,_,_,_,
_,_,_,_,_,
_,_,_,_,_,
_,_,_,_,_,
L,T,L,_,_,
_,L,_,_,_,
_,_,_,_,_,
_,L,L,L,_,
_,_,_,_,_,

_,T,T,T,_,
_,T,T,T,_,
_,_,T,_,_,
_,_,T,_,_,
_,_,T,_,_,
_,_,T,L,L,
_,_,T,_,_,
L,L,T,_,_,
_,L,T,L,_,
_,_,T,_,_,
_,L,L,L,_,
_,_,L,_,_,

_,_,T,_,_,
_,_,T,_,_,
_,_,_,_,_,
_,_,_,_,_,
_,_,_,_,_,
_,_,L,T,L,
_,_,_,L,_,
_,_,_,_,_,
_,L,T,L,_,
_,_,L,_,_,
_,L,L,L,_,
_,_,_,_,_,

_,_,_,_,_,
_,_,_,_,_,
_,_,_,_,_,
_,_,_,_,_,
_,_,_,_,_,
_,_,L,L,L,
_,_,_,_,_,
_,_,_,_,_,
_,L,L,L,_,
_,_,_,_,_,
_,_,_,_,_,
_,_,_,_,_},
yslice_prob = {{ypos = 5, prob = 127}, {ypos = 9, prob = 127}}}

default.mangrove_tree2 = {size = {x = 5, y = 16, z = 5}, data = {
_,_,_,_,_,
_,_,_,_,_,
_,_,_,_,_,
_,_,_,_,_,
_,_,_,_,_,
_,_,_,_,_,
_,_,_,_,_,
_,_,_,_,_,
_,_,L,L,L,
_,_,_,_,_,
_,_,_,_,_,
_,_,_,_,_,
L,L,L,_,_,
_,_,_,_,_,
_,M,L,M,_,
_,_,_,_,_,

_,_,T,_,_,
_,_,T,_,_,
_,_,_,_,_,
_,_,_,_,_,
_,_,_,_,_,
_,_,_,_,_,
L,L,L,_,_,
_,_,_,_,_,
_,_,L,T,L,
_,_,_,L,_,
_,_,_,_,_,
_,_,L,L,L,
L,T,L,_,_,
_,L,_,_,_,
M,L,L,L,M,
_,M,M,M,_,

_,T,T,T,_,
_,T,T,T,_,
_,_,T,_,_,
_,_,T,_,_,
_,_,T,_,_,
_,_,T,_,_,
L,T,T,_,_,
_,L,T,_,_,
_,_,T,L,L,
_,_,T,_,_,
L,L,T,_,_,
_,_,T,T,L,
L,L,T,L,_,
_,_,T,_,_,
L,L,L,L,L,
_,M,L,M,_,

_,_,T,_,_,
_,_,T,_,_,
_,_,_,_,_,
_,_,_,_,_,
_,_,_,_,_,
_,_,_,_,_,
L,L,L,_,_,
_,_,_,_,_,
_,_,_,_,_,
_,_,_,_,_,
L,T,L,_,_,
_,L,L,L,L,
_,_,_,_,_,
_,_,_,_,_,
M,L,L,L,M,
_,M,M,M,_,

_,_,_,_,_,
_,_,_,_,_,
_,_,_,_,_,
_,_,_,_,_,
_,_,_,_,_,
_,_,_,_,_,
_,_,_,_,_,
_,_,_,_,_,
_,_,_,_,_,
_,_,_,_,_,
L,L,L,_,_,
_,_,_,_,_,
_,_,_,_,_,
_,_,_,_,_,
_,M,L,M,_,
_,_,_,_,_},
yslice_prob = {{ypos = 6, prob = 127}, {ypos = 8, prob = 127}, {ypos = 11, prob = 127}}}

default.tree_mangrove_1 = {size = {x = 5, y = 11, z = 5}, data = {
_,_,_,_,_,
_,_,_,_,_,
_,_,_,_,_,
_,_,_,_,_,
_,_,_,_,_,
_,_,_,_,_,
_,_,_,_,_,
_,L,L,L,_,
_,_,_,_,_,
_,_,_,_,_,
_,_,_,_,_,

_,_,T,_,_,
_,_,_,_,_,
_,_,_,_,_,
_,_,_,_,_,
_,_,_,_,_,
_,_,_,_,_,
L,L,L,_,_,
_,L,T,L,_,
_,_,L,_,_,
L,L,L,_,_,
_,_,_,_,_,

_,T,T,T,_,
_,_,T,_,_,
_,_,T,_,_,
_,_,T,_,_,
_,_,T,_,_,
_,_,T,_,_,
L,L,T,_,_,
_,L,T,L,_,
_,_,T,_,_,
L,T,L,L,L,
_,L,_,_,_,

_,_,T,_,_,
_,_,_,_,_,
_,_,_,_,_,
_,_,_,_,_,
_,_,_,_,_,
_,_,_,_,_,
L,L,L,_,_,
_,_,_,_,_,
_,_,_,_,_,
L,L,L,T,L,
_,_,_,L,_,

_,_,_,_,_,
_,_,_,_,_,
_,_,_,_,_,
_,_,_,_,_,
_,_,_,_,_,
_,_,_,_,_,
_,_,_,_,_,
_,_,_,_,_,
_,_,_,_,_,
_,_,L,L,L,
_,_,_,_,_}}
default.tree_mangrove_2 = {size = {x = 5, y = 13, z = 5}, data = {
_,_,_,_,_,
_,_,_,_,_,
_,_,_,_,_,
_,_,_,_,_,
_,_,_,_,_,
_,_,_,_,_,
_,_,L,L,L,
_,_,_,_,_,
_,_,_,_,_,
_,_,_,_,_,
_,_,_,_,_,
_,_,_,_,_,
_,_,_,_,_,

_,_,T,_,_,
_,_,_,_,_,
_,_,_,_,_,
_,_,_,_,_,
_,_,_,_,_,
_,_,_,_,_,
_,_,L,T,L,
_,_,_,L,_,
_,L,L,L,_,
_,_,_,_,_,
_,_,_,_,_,
L,L,L,L,L,
_,_,_,_,_,

_,T,T,T,_,
_,_,T,_,_,
_,_,T,_,_,
_,_,T,_,_,
_,_,T,_,_,
_,_,T,_,_,
_,_,T,L,L,
_,_,T,_,_,
_,L,T,L,_,
_,_,T,_,_,
_,L,T,L,_,
L,T,L,T,L,
_,L,_,L,_,

_,_,T,_,_,
_,_,_,_,_,
_,_,_,_,_,
_,_,_,_,_,
_,_,_,_,_,
_,_,_,_,_,
_,_,_,_,_,
_,_,_,_,_,
_,L,L,L,_,
_,_,_,_,_,
_,L,L,L,_,
L,L,L,L,L,
_,_,_,_,_,

_,_,_,_,_,
_,_,_,_,_,
_,_,_,_,_,
_,_,_,_,_,
_,_,_,_,_,
_,_,_,_,_,
_,_,_,_,_,
_,_,_,_,_,
_,_,_,_,_,
_,_,_,_,_,
_,L,L,L,_,
_,_,_,_,_,
_,_,_,_,_}}
default.tree_mangrove_3 = {size = {x = 5, y = 13, z = 5}, data = {
_,_,_,_,_,
_,_,_,_,_,
_,_,_,_,_,
_,_,_,_,_,
_,_,_,_,_,
_,_,_,_,_,
_,_,_,_,_,
_,_,_,_,_,
_,_,_,_,_,
_,_,_,_,_,
_,L,L,L,_,
_,_,_,_,_,
_,_,_,_,_,

_,_,T,_,_,
_,_,_,_,_,
_,_,_,_,_,
_,_,_,_,_,
_,_,_,_,_,
_,_,_,_,_,
_,_,_,_,_,
_,L,L,L,_,
_,_,_,_,_,
_,_,_,_,_,
_,L,L,L,_,
_,_,L,L,L,
_,_,_,_,_,

_,T,T,T,_,
_,_,T,_,_,
_,_,T,_,_,
_,_,T,_,_,
_,_,T,_,_,
_,_,T,_,_,
_,_,T,_,_,
_,L,T,L,_,
_,_,T,L,L,
_,L,T,L,_,
_,L,T,L,_,
_,_,L,T,L,
_,_,_,L,_,

_,_,T,_,_,
_,_,_,_,_,
_,_,_,_,_,
_,_,_,_,_,
_,_,_,_,_,
_,_,_,_,_,
_,_,_,_,_,
_,L,L,L,_,
_,_,L,L,L,
_,L,T,L,_,
_,_,L,_,_,
_,_,L,T,L,
_,_,_,L,_,

_,_,_,_,_,
_,_,_,_,_,
_,_,_,_,_,
_,_,_,_,_,
_,_,_,_,_,
_,_,_,_,_,
_,_,_,_,_,
_,_,_,_,_,
_,_,L,L,L,
_,L,L,L,_,
_,_,_,_,_,
_,_,L,L,L,
_,_,_,_,_}}

local D = {name = "default:dirt", force_place = true}
local G = {name = "default:dirt_with_swamp_grass", force_place = true}
local M = {name = "default:mud", force_place = true}
local F = {name = "default:fresh_water_source", force_place = true}
local B = {name = "flowers:giant_waterlily", prob = 127, force_place = true}

small_pool = {size = {x = 6, y = 3, z = 7}, data = {
_,_,D,D,_,_,
_,_,G,G,_,_,
_,_,_,_,_,_,

_,D,M,M,D,_,
_,G,F,F,G,_,
_,_,_,_,_,_,

D,M,M,M,M,D,
G,F,F,F,F,G,
_,_,I,I,_,_,

D,M,M,M,M,D,
G,F,F,F,F,G,
_,_,I,B,_,_,

D,M,M,M,M,D,
G,F,F,F,F,G,
_,_,I,I,_,_,

_,D,M,M,M,D,
_,G,F,F,F,G,
_,_,_,_,_,_,

_,_,D,D,D,_,
_,_,G,G,G,_,
_,_,_,_,_,_}}

big_pool = {size = {x = 9, y = 3, z = 9}, data = {
_,_,_,D,D,D,_,_,_,
_,_,_,G,G,G,_,_,_,
_,_,_,_,_,_,_,_,_,

_,_,D,M,M,M,D,D,_,
_,_,G,F,F,F,G,G,_,
_,_,_,_,_,_,_,_,_,

_,D,M,M,M,M,M,M,D,
_,G,F,F,F,F,F,F,G,
_,_,_,I,I,I,_,_,_,

D,M,M,M,M,M,M,M,D,
G,F,F,F,F,F,F,F,G,
_,_,I,I,I,I,I,_,_,

D,M,M,M,M,M,M,M,D,
G,F,F,F,F,F,F,F,G,
_,_,I,I,I,I,I,_,_,

_,D,M,M,M,M,M,M,D,
_,G,F,F,F,F,F,F,G,
_,_,_,I,I,I,I,_,_,

_,_,D,M,M,M,M,M,D,
_,_,G,F,F,F,F,F,G,
_,_,_,_,I,I,I,_,_,

_,_,_,D,M,M,M,D,_,
_,_,_,G,F,F,F,G,_,
_,_,_,_,_,_,_,_,_,

_,_,_,_,D,D,D,_,_,
_,_,_,_,G,G,G,_,_,
_,_,_,_,_,_,_,_,_}}
