
-- Orange trees

local L = {name = "default:orange_leaves_fruiting"}
local M = {name = "default:orange_leaves_fruiting", prob = 223}
local T = {name = "default:orange_trunk", force_place = true}

default.orange_tree = {size = {x = 7, y = 8, z = 7}, data = {
_,_,_,_,_,_,_,
_,_,_,_,_,_,_,
_,_,_,_,_,_,_,
_,_,_,_,_,_,_,
_,_,M,L,M,_,_,
_,_,_,M,_,_,_,
_,_,_,_,_,_,_,
_,_,_,_,_,_,_,

_,_,_,_,_,_,_,
_,_,_,_,_,_,_,
_,_,_,_,_,_,_,
_,_,_,_,_,_,_,
_,L,L,_,L,L,_,
_,M,L,L,L,M,_,
_,_,M,L,M,_,_,
_,_,_,_,_,_,_,

_,_,_,_,_,_,_,
_,_,_,_,_,_,_,
_,_,_,_,_,_,_,
_,_,_,_,_,_,_,
M,L,T,_,_,L,M,
_,L,L,_,T,L,_,
_,M,L,L,L,M,_,
_,_,_,M,_,_,_,

_,_,_,T,_,_,_,
_,_,_,T,_,_,_,
_,_,_,T,_,_,_,
_,_,_,T,_,_,_,
L,_,_,T,_,_,L,
M,L,_,_,_,L,M,
_,L,L,L,L,L,_,
_,_,M,L,M,_,_,

_,_,_,_,_,_,_,
_,_,_,_,_,_,_,
_,_,_,_,_,_,_,
_,_,_,_,_,_,_,
M,L,_,_,T,L,M,
_,L,T,_,L,L,_,
_,M,L,L,L,M,_,
_,_,_,M,_,_,_,

_,_,_,_,_,_,_,
_,_,_,_,_,_,_,
_,_,_,_,_,_,_,
_,_,_,_,_,_,_,
_,L,L,_,L,L,_,
_,M,L,L,L,M,_,
_,_,M,L,M,_,_,
_,_,_,_,_,_,_,

_,_,_,_,_,_,_,
_,_,_,_,_,_,_,
_,_,_,_,_,_,_,
_,_,_,_,_,_,_,
_,_,M,L,M,_,_,
_,_,_,M,_,_,_,
_,_,_,_,_,_,_,
_,_,_,_,_,_,_},
yslice_prob = {{ypos = 2, prob = 127}}}

default.small_orange_tree = {size = {x = 5, y = 6, z = 5}, data = {
_,_,_,_,_,
_,_,_,_,_,
_,_,_,_,_,
_,_,L,_,_,
_,_,L,_,_,
_,_,_,_,_,

_,_,_,_,_,
_,_,_,_,_,
_,_,_,_,_,
_,M,L,M,_,
_,L,L,L,_,
_,_,L,_,_,

_,_,T,_,_,
_,_,T,_,_,
_,_,T,_,_,
L,L,T,L,L,
L,L,L,L,L,
_,L,L,L,_,

_,_,_,_,_,
_,_,_,_,_,
_,_,_,_,_,
_,M,L,M,_,
_,L,L,L,_,
_,_,L,_,_,

_,_,_,_,_,
_,_,_,_,_,
_,_,_,_,_,
_,_,L,_,_,
_,_,L,_,_,
_,_,_,_,_},
yslice_prob = {{ypos = 1, prob = 127}}}
