
-- Palm tree

-- internationalization boilerplate
local S = core.get_translator(core.get_current_modname())

local L = {name = "palm:leaves"}
local T = {name = "palm:trunk", force_place = true}

palm_tree = {size = {x = 11, y = 26, z = 11}, data = {
_,_,_,_,_,_,_,_,_,_,_,
_,_,_,_,_,_,_,_,_,_,_,
_,_,_,_,_,_,_,_,_,_,_,
_,_,_,_,_,_,_,_,_,_,_,
_,_,_,_,_,_,_,_,_,_,_,
_,_,_,_,_,_,_,_,_,_,_,
_,_,_,_,_,_,_,_,_,_,_,
_,_,_,_,_,_,_,_,_,_,_,
_,_,_,_,_,_,_,_,_,_,_,
_,_,_,_,_,_,_,_,_,_,_,
_,_,_,_,_,_,_,_,_,_,_,
_,_,_,_,_,_,_,_,_,_,_,
_,_,_,_,_,_,_,_,_,_,_,
_,_,_,_,_,_,_,_,_,_,_,
_,_,_,_,_,_,_,_,_,_,_,
_,_,_,_,_,_,_,_,_,_,_,
_,_,_,_,_,_,_,_,_,_,_,
_,_,_,_,_,_,_,_,_,_,_,
_,_,_,_,_,_,_,_,_,_,_,
_,_,_,_,_,_,_,_,_,_,_,
_,_,_,_,_,_,_,_,_,_,_,
_,_,_,_,_,L,_,_,_,_,_,
_,_,_,_,_,_,_,_,_,_,_,
_,_,_,_,_,_,_,_,_,_,_,
_,_,_,_,_,_,_,_,_,_,_,
_,_,_,_,_,_,_,_,_,_,_,

_,_,_,_,_,_,_,_,_,_,_,
_,_,_,_,_,_,_,_,_,_,_,
_,_,_,_,_,_,_,_,_,_,_,
_,_,_,_,_,_,_,_,_,_,_,
_,_,_,_,_,_,_,_,_,_,_,
_,_,_,_,_,_,_,_,_,_,_,
_,_,_,_,_,_,_,_,_,_,_,
_,_,_,_,_,_,_,_,_,_,_,
_,_,_,_,_,_,_,_,_,_,_,
_,_,_,_,_,_,_,_,_,_,_,
_,_,_,_,_,_,_,_,_,_,_,
_,_,_,_,_,_,_,_,_,_,_,
_,_,_,_,_,_,_,_,_,_,_,
_,_,_,_,_,_,_,_,_,_,_,
_,_,_,_,_,_,_,_,_,_,_,
_,_,_,_,_,_,_,_,_,_,_,
_,_,_,_,_,_,_,_,_,_,_,
_,_,_,_,_,_,_,_,_,_,_,
_,_,_,_,_,_,_,_,_,_,_,
_,_,_,_,_,_,_,_,_,_,_,
_,_,_,_,_,_,_,_,_,_,_,
_,_,_,_,_,L,_,_,_,_,_,
_,_,_,_,_,_,_,_,_,_,_,
_,_,_,L,_,_,_,L,_,_,_,
_,_,_,_,_,_,_,_,_,_,_,
_,_,_,_,_,_,_,_,_,_,_,

_,_,_,_,_,_,_,_,_,_,_,
_,_,_,_,_,_,_,_,_,_,_,
_,_,_,_,_,_,_,_,_,_,_,
_,_,_,_,_,_,_,_,_,_,_,
_,_,_,_,_,_,_,_,_,_,_,
_,_,_,_,_,_,_,_,_,_,_,
_,_,_,_,_,_,_,_,_,_,_,
_,_,_,_,_,_,_,_,_,_,_,
_,_,_,_,_,_,_,_,_,_,_,
_,_,_,_,_,_,_,_,_,_,_,
_,_,_,_,_,_,_,_,_,_,_,
_,_,_,_,_,_,_,_,_,_,_,
_,_,_,_,_,_,_,_,_,_,_,
_,_,_,_,_,_,_,_,_,_,_,
_,_,_,_,_,_,_,_,_,_,_,
_,_,_,_,_,_,_,_,_,_,_,
_,_,_,_,_,_,_,_,_,_,_,
_,_,_,_,_,_,_,_,_,_,_,
_,_,_,_,_,_,_,_,_,_,_,
_,_,_,_,_,_,_,_,_,_,_,
_,_,L,_,_,L,_,_,L,_,_,
_,_,_,_,_,_,_,_,_,_,_,
_,_,_,_,_,_,_,_,_,_,_,
_,_,_,L,L,_,L,L,_,_,_,
_,_,_,_,_,_,_,_,_,_,_,
_,_,_,_,_,_,_,_,_,_,_,

_,_,_,_,_,_,_,_,_,_,_,
_,_,_,_,_,_,_,_,_,_,_,
_,_,_,_,_,_,_,_,_,_,_,
_,_,_,_,_,_,_,_,_,_,_,
_,_,_,_,_,_,_,_,_,_,_,
_,_,_,_,_,_,_,_,_,_,_,
_,_,_,_,_,_,_,_,_,_,_,
_,_,_,_,_,_,_,_,_,_,_,
_,_,_,_,_,_,_,_,_,_,_,
_,_,_,_,_,_,_,_,_,_,_,
_,_,_,_,_,_,_,_,_,_,_,
_,_,_,_,_,_,_,_,_,_,_,
_,_,_,_,_,_,_,_,_,_,_,
_,_,_,_,_,_,_,_,_,_,_,
_,_,_,_,_,_,_,_,_,_,_,
_,_,_,_,_,_,_,_,_,_,_,
_,_,_,_,_,_,_,_,_,_,_,
_,_,_,_,_,_,_,_,_,_,_,
_,_,_,_,_,_,_,_,_,_,_,
_,_,_,_,_,_,_,_,_,_,_,
_,_,_,L,_,L,_,L,_,_,_,
_,_,_,_,_,_,_,_,_,_,_,
_,_,_,_,L,_,L,_,_,_,_,
_,L,L,_,_,_,_,_,L,L,_,
_,_,_,_,_,_,_,_,_,_,_,
_,_,_,_,_,L,_,_,_,_,_,

_,_,_,_,_,_,_,_,_,_,_,
_,_,_,_,_,_,_,_,_,_,_,
_,_,_,_,_,_,_,_,_,_,_,
_,_,_,_,_,_,_,_,_,_,_,
_,_,_,_,_,_,_,_,_,_,_,
_,_,_,_,_,_,_,_,_,_,_,
_,_,_,_,_,_,_,_,_,_,_,
_,_,_,_,_,_,_,_,_,_,_,
_,_,_,_,_,_,_,_,_,_,_,
_,_,_,_,_,_,_,_,_,_,_,
_,_,_,_,_,_,_,_,_,_,_,
_,_,_,_,_,_,_,_,_,_,_,
_,_,_,_,_,_,_,_,_,_,_,
_,_,_,_,_,_,_,_,_,_,_,
_,_,_,_,_,_,_,_,_,_,_,
_,_,_,_,_,_,_,_,_,_,_,
_,_,_,_,_,_,_,_,_,_,_,
_,_,_,_,_,_,_,_,_,_,_,
_,_,_,_,_,_,_,_,_,_,_,
_,_,_,_,_,L,_,_,_,_,_,
_,_,_,_,L,_,L,_,_,_,_,
_,_,_,_,_,L,_,_,_,_,_,
_,_,_,L,_,_,_,L,_,_,_,
_,_,L,_,_,L,_,_,L,_,_,
_,_,_,_,_,L,_,_,_,_,_,
_,_,_,_,_,_,_,_,_,_,_,

_,_,_,_,_,T,_,_,_,_,_,
_,_,_,_,_,T,_,_,_,_,_,
_,_,_,_,_,T,_,_,_,_,_,
_,_,_,_,_,T,_,_,_,_,_,
_,_,_,_,_,T,_,_,_,_,_,
_,_,_,_,_,T,_,_,_,_,_,
_,_,_,_,_,T,_,_,_,_,_,
_,_,_,_,_,T,_,_,_,_,_,
_,_,_,_,_,T,_,_,_,_,_,
_,_,_,_,_,T,_,_,_,_,_,
_,_,_,_,_,T,_,_,_,_,_,
_,_,_,_,_,T,_,_,_,_,_,
_,_,_,_,_,T,_,_,_,_,_,
_,_,_,_,_,T,_,_,_,_,_,
_,_,_,_,_,T,_,_,_,_,_,
_,_,_,_,_,T,_,_,_,_,_,
_,_,_,_,_,T,_,_,_,_,_,
_,_,_,_,_,T,_,_,_,_,_,
_,_,_,_,_,T,_,_,_,_,_,
_,_,_,_,L,L,L,_,_,_,_,
_,_,L,L,_,T,_,L,L,_,_,
L,L,_,_,L,L,L,_,_,L,L,
_,_,_,_,_,L,_,_,_,_,_,
_,_,_,_,L,_,L,_,_,_,_,
_,_,_,_,L,_,L,_,_,_,_,
_,_,_,L,_,_,_,L,_,_,_,

_,_,_,_,_,_,_,_,_,_,_,
_,_,_,_,_,_,_,_,_,_,_,
_,_,_,_,_,_,_,_,_,_,_,
_,_,_,_,_,_,_,_,_,_,_,
_,_,_,_,_,_,_,_,_,_,_,
_,_,_,_,_,_,_,_,_,_,_,
_,_,_,_,_,_,_,_,_,_,_,
_,_,_,_,_,_,_,_,_,_,_,
_,_,_,_,_,_,_,_,_,_,_,
_,_,_,_,_,_,_,_,_,_,_,
_,_,_,_,_,_,_,_,_,_,_,
_,_,_,_,_,_,_,_,_,_,_,
_,_,_,_,_,_,_,_,_,_,_,
_,_,_,_,_,_,_,_,_,_,_,
_,_,_,_,_,_,_,_,_,_,_,
_,_,_,_,_,_,_,_,_,_,_,
_,_,_,_,_,_,_,_,_,_,_,
_,_,_,_,_,_,_,_,_,_,_,
_,_,_,_,_,_,_,_,_,_,_,
_,_,_,_,_,L,_,_,_,_,_,
_,_,_,_,L,_,L,_,_,_,_,
_,_,_,_,_,L,_,_,_,_,_,
_,_,_,L,_,_,_,L,_,_,_,
_,_,L,_,_,L,_,_,L,_,_,
_,_,_,_,_,L,_,_,_,_,_,
_,_,_,_,_,_,_,_,_,_,_,

_,_,_,_,_,_,_,_,_,_,_,
_,_,_,_,_,_,_,_,_,_,_,
_,_,_,_,_,_,_,_,_,_,_,
_,_,_,_,_,_,_,_,_,_,_,
_,_,_,_,_,_,_,_,_,_,_,
_,_,_,_,_,_,_,_,_,_,_,
_,_,_,_,_,_,_,_,_,_,_,
_,_,_,_,_,_,_,_,_,_,_,
_,_,_,_,_,_,_,_,_,_,_,
_,_,_,_,_,_,_,_,_,_,_,
_,_,_,_,_,_,_,_,_,_,_,
_,_,_,_,_,_,_,_,_,_,_,
_,_,_,_,_,_,_,_,_,_,_,
_,_,_,_,_,_,_,_,_,_,_,
_,_,_,_,_,_,_,_,_,_,_,
_,_,_,_,_,_,_,_,_,_,_,
_,_,_,_,_,_,_,_,_,_,_,
_,_,_,_,_,_,_,_,_,_,_,
_,_,_,_,_,_,_,_,_,_,_,
_,_,_,_,_,_,_,_,_,_,_,
_,_,_,L,_,L,_,L,_,_,_,
_,_,_,_,_,_,_,_,_,_,_,
_,_,_,_,L,_,L,_,_,_,_,
_,L,L,_,_,_,_,_,L,L,_,
_,_,_,_,_,_,_,_,_,_,_,
_,_,_,_,_,L,_,_,_,_,_,

_,_,_,_,_,_,_,_,_,_,_,
_,_,_,_,_,_,_,_,_,_,_,
_,_,_,_,_,_,_,_,_,_,_,
_,_,_,_,_,_,_,_,_,_,_,
_,_,_,_,_,_,_,_,_,_,_,
_,_,_,_,_,_,_,_,_,_,_,
_,_,_,_,_,_,_,_,_,_,_,
_,_,_,_,_,_,_,_,_,_,_,
_,_,_,_,_,_,_,_,_,_,_,
_,_,_,_,_,_,_,_,_,_,_,
_,_,_,_,_,_,_,_,_,_,_,
_,_,_,_,_,_,_,_,_,_,_,
_,_,_,_,_,_,_,_,_,_,_,
_,_,_,_,_,_,_,_,_,_,_,
_,_,_,_,_,_,_,_,_,_,_,
_,_,_,_,_,_,_,_,_,_,_,
_,_,_,_,_,_,_,_,_,_,_,
_,_,_,_,_,_,_,_,_,_,_,
_,_,_,_,_,_,_,_,_,_,_,
_,_,_,_,_,_,_,_,_,_,_,
_,_,L,_,_,L,_,_,L,_,_,
_,_,_,_,_,_,_,_,_,_,_,
_,_,_,_,_,_,_,_,_,_,_,
_,_,_,L,L,_,L,L,_,_,_,
_,_,_,_,_,_,_,_,_,_,_,
_,_,_,_,_,_,_,_,_,_,_,

_,_,_,_,_,_,_,_,_,_,_,
_,_,_,_,_,_,_,_,_,_,_,
_,_,_,_,_,_,_,_,_,_,_,
_,_,_,_,_,_,_,_,_,_,_,
_,_,_,_,_,_,_,_,_,_,_,
_,_,_,_,_,_,_,_,_,_,_,
_,_,_,_,_,_,_,_,_,_,_,
_,_,_,_,_,_,_,_,_,_,_,
_,_,_,_,_,_,_,_,_,_,_,
_,_,_,_,_,_,_,_,_,_,_,
_,_,_,_,_,_,_,_,_,_,_,
_,_,_,_,_,_,_,_,_,_,_,
_,_,_,_,_,_,_,_,_,_,_,
_,_,_,_,_,_,_,_,_,_,_,
_,_,_,_,_,_,_,_,_,_,_,
_,_,_,_,_,_,_,_,_,_,_,
_,_,_,_,_,_,_,_,_,_,_,
_,_,_,_,_,_,_,_,_,_,_,
_,_,_,_,_,_,_,_,_,_,_,
_,_,_,_,_,_,_,_,_,_,_,
_,_,_,_,_,_,_,_,_,_,_,
_,_,_,_,_,L,_,_,_,_,_,
_,_,_,_,_,_,_,_,_,_,_,
_,_,_,L,_,_,_,L,_,_,_,
_,_,_,_,_,_,_,_,_,_,_,
_,_,_,_,_,_,_,_,_,_,_,

_,_,_,_,_,_,_,_,_,_,_,
_,_,_,_,_,_,_,_,_,_,_,
_,_,_,_,_,_,_,_,_,_,_,
_,_,_,_,_,_,_,_,_,_,_,
_,_,_,_,_,_,_,_,_,_,_,
_,_,_,_,_,_,_,_,_,_,_,
_,_,_,_,_,_,_,_,_,_,_,
_,_,_,_,_,_,_,_,_,_,_,
_,_,_,_,_,_,_,_,_,_,_,
_,_,_,_,_,_,_,_,_,_,_,
_,_,_,_,_,_,_,_,_,_,_,
_,_,_,_,_,_,_,_,_,_,_,
_,_,_,_,_,_,_,_,_,_,_,
_,_,_,_,_,_,_,_,_,_,_,
_,_,_,_,_,_,_,_,_,_,_,
_,_,_,_,_,_,_,_,_,_,_,
_,_,_,_,_,_,_,_,_,_,_,
_,_,_,_,_,_,_,_,_,_,_,
_,_,_,_,_,_,_,_,_,_,_,
_,_,_,_,_,_,_,_,_,_,_,
_,_,_,_,_,_,_,_,_,_,_,
_,_,_,_,_,L,_,_,_,_,_,
_,_,_,_,_,_,_,_,_,_,_,
_,_,_,_,_,_,_,_,_,_,_,
_,_,_,_,_,_,_,_,_,_,_,
_,_,_,_,_,_,_,_,_,_,_},
yslice_prob = {{ypos = 2, prob = 127}, {ypos = 4, prob = 117}, {ypos = 6, prob = 107}}}

local function grow_palm_tree(pos)
	if not default.can_grow(pos) then
		-- try a bit later again
		core.get_node_timer(pos):start(math.random(240, 600))
		return
	end
	add_tree(pos, 5, 1, 5, palm_tree, "0")
end

-- Decoration

local mg_name = core.get_mapgen_setting("mg_name")

if mg_name ~= "v6" and mg_name ~= "singlenode" then
	core.register_decoration({
		deco_type = "schematic",
		place_on = {"default:dirt_with_rainforest_litter"},
		sidelen = 16,
		noise_params = {
			offset = 0.0005,
			scale = 0.00005,
			spread = {x = 250, y = 250, z = 250},
			seed = 2,
			octaves = 3,
			persist = 0.66
		},
		biomes = {"rainforest"},
		y_min = 1,
		y_max = 32,
		schematic = palm_tree,
		flags = "place_center_x, place_center_z",
	})
end

-- Nodes

core.register_node("palm:sapling", {
	description = S("Palm Tree Sapling"),
	drawtype = "plantlike",
	tiles = {"palm_sapling.png"},
	inventory_image = "palm_sapling.png",
	paramtype = "light",
	sunlight_propagates = true,
	walkable = false,
	on_timer = grow_palm_tree,
	selection_box = {
		type = "fixed",
		fixed = {-.3, -.5, -.3, .3, .35, .3}
	},
	groups = {snappy = 2, dig_immediate = 3, flammable = 2, attached_node = 1, sapling = 1},
	sounds = default.node_sound_leaves_defaults(),

	on_construct = function(pos)
		core.get_node_timer(pos):start(math.random(300, 1500))
	end,

	on_place = function(itemstack, placer, pointd)
		itemstack = default.sapling_on_place(itemstack, placer, pointd,
			"palm:sapling",
			-- minp, maxp to be checked, relative to sapling pos
			-- minp_relative.y = 1 because sapling pos has been checked
			{x = -5, y = 1, z = -5},
			{x = 6, y = 22, z = 6},
			-- maximum interval of interior volume check
			4)

		return itemstack
	end,
	grown_height = 19,
})

core.register_node("palm:trunk", {
	description = S("Palm Trunk"),
	tiles = {"palm_trunk_top.png", "palm_trunk_top.png", "palm_trunk.png"},
	paramtype2 = "facedir",
	is_ground_content = false,
	groups = {choppy = 2, flammable = 2, trunk = 1},
	sounds = default.node_sound_wood_defaults(),
	on_place = core.rotate_node,
})

core.register_node("palm:wood", {
	description = S("Palm Wood"),
	tiles = {"palm_wood.png"},
	paramtype2 = "facedir",
	place_param2 = 0,
	is_ground_content = false,
	groups = {choppy = 2, oddly_breakable_by_hand = 2, flammable = 3, wood = 1},
	sounds = default.node_sound_wood_defaults(),
})

core.register_node("palm:leaves", {
	description = S("Palm Leaves"),
	drawtype = leaf_drawtype,
	mesh = "leaf_droop.obj",
	waving = waving_style,
	tiles = {"palm_leaves.png"..leaf_image("^[transformFY")},
	inventory_image = leaf_image("palm_leaves.png"),
	wield_image = leaf_image("palm_leaves.png"),
	use_texture_alpha = "clip",
	paramtype = "light",
	is_ground_content = false,
	collision_box = leaf_cbox,
	groups = {snappy = 3, leafdecay = 3, flammable = 2, leaves = 1},
	drop = {
		max_items = 1,
		items = {
			{items = {"palm:sapling"}, rarity = 20},
			{items = {"palm:leaves"}}
		}
	},
	sounds = default.node_sound_leaves_defaults(),
	after_place_node = default.after_place_leaves,
})

-- Recipes

core.register_craft({
	output = "palm:wood 4",
	recipe = {{"palm:trunk"}}
})

core.register_lbm({
	name = "palm:convert_palm_saplings_to_node_timer",
	nodenames = {"palm:sapling"},
	action = function(pos)
		core.get_node_timer(pos):start(math.random(300, 1500))
	end
})

default.register_leafdecay({
	trunks = {"palm:trunk"},
	leaves = {"palm:leaves"},
	radius = 5,
})

doors.register_fencegate("palm:wood_gate", {
	description = S("Palm Wood Fence Gate"),
	texture = "palm_wood.png^[transformR90",
	material = "palm:wood",
	groups = {choppy = 2, oddly_breakable_by_hand = 2, flammable = 3}
})

default.register_fence("palm:wood_fence", {
	description = S("Palm Wood Fence"),
	texture = "palm_fence.png",
	material = "palm:wood",
	groups = {choppy = 2, oddly_breakable_by_hand = 2, flammable = 3},
	sounds = default.node_sound_wood_defaults()
})

if core.get_modpath("stairs") then
stairs.register_stair_and_slab("palm_wood", "palm:wood",
	{choppy = 2, oddly_breakable_by_hand = 2, flammable = 3},
	{"palm_wood.png"},
	S("Palm Wood Stair"),
	S("Palm Wood Slab"),
	default.node_sound_wood_defaults())
end

if core.get_modpath("bonemeal") then
	bonemeal:add_sapling({
		{"palm:sapling", grow_palm_tree, "soil"},
	})
end
