
-- Solarie tree

-- internationalization boilerplate
local S = core.get_translator(core.get_current_modname())

local L = {name = "solarie:leaves"}
local M = {name = "solarie:leaves", prob = 223}
local T = {name = "solarie:trunk", force_place = true}

solarie_tree = {size = {x = 13, y = 22, z = 13}, data = {
_,_,_,_,_,_,_,_,_,_,_,_,_,
_,_,_,_,_,_,_,_,_,_,_,_,_,
_,_,_,_,_,_,_,_,_,_,_,_,_,
_,_,_,_,_,_,_,_,_,_,_,_,_,
_,_,_,_,_,_,_,_,_,_,_,_,_,
_,_,_,_,_,_,_,_,_,_,_,_,_,
_,_,_,_,_,_,_,_,_,_,_,_,_,
_,_,_,_,_,_,_,_,_,_,_,_,_,
_,_,_,_,_,_,_,_,_,_,_,_,_,
_,_,_,_,_,_,_,_,_,_,_,_,_,
_,_,_,_,_,_,_,_,_,_,_,_,_,
_,_,_,_,_,_,_,_,_,_,_,_,_,
_,_,_,_,_,_,_,_,_,_,_,_,_,
_,_,_,_,_,_,_,_,_,_,_,_,_,
_,_,_,_,_,_,_,_,_,_,_,_,_,
_,_,_,_,_,_,M,_,_,_,_,_,_,
_,_,_,_,_,_,L,_,_,_,_,_,_,
_,_,_,_,_,_,L,_,_,_,_,_,_,
_,_,_,_,_,_,_,_,_,_,_,_,_,
_,_,_,_,_,_,_,_,_,_,_,_,_,
_,_,_,_,_,_,_,_,_,_,_,_,_,
_,_,_,_,_,_,_,_,_,_,_,_,_,

_,_,_,_,_,_,_,_,_,_,_,_,_,
_,_,_,_,_,_,_,_,_,_,_,_,_,
_,_,_,_,_,_,_,_,_,_,_,_,_,
_,_,_,_,_,_,_,_,_,_,_,_,_,
_,_,_,_,_,_,_,_,_,_,_,_,_,
_,_,_,_,_,_,_,_,_,_,_,_,_,
_,_,_,_,_,_,_,_,_,_,_,_,_,
_,_,_,_,_,_,_,_,_,_,_,_,_,
_,_,_,_,_,_,_,_,_,_,_,_,_,
_,_,_,_,_,_,_,_,_,_,_,_,_,
_,_,_,_,_,_,_,_,_,_,_,_,_,
_,_,_,_,_,_,M,_,_,_,_,_,_,
_,_,_,_,_,_,L,_,_,_,_,_,_,
_,_,_,_,_,_,L,_,_,_,_,_,_,
_,_,_,_,_,_,_,_,_,_,_,_,_,
_,_,_,_,_,_,_,_,_,_,_,_,_,
_,_,_,_,_,_,_,_,_,_,_,_,_,
_,_,_,_,_,_,L,_,_,_,_,_,_,
_,_,_,_,_,L,L,L,_,_,_,_,_,
_,_,_,_,_,_,_,_,_,_,_,_,_,
_,_,_,_,_,_,_,_,_,_,_,_,_,
_,_,_,_,_,_,_,_,_,_,_,_,_,

_,_,_,_,_,_,_,_,_,_,_,_,_,
_,_,_,_,_,_,_,_,_,_,_,_,_,
_,_,_,_,_,_,_,_,_,_,_,_,_,
_,_,_,_,_,_,_,_,_,_,_,_,_,
_,_,_,_,_,_,_,_,_,_,_,_,_,
_,_,_,_,_,_,_,_,_,_,_,_,_,
_,_,_,_,_,_,_,_,_,_,_,_,_,
_,_,_,_,_,_,_,_,_,_,_,_,_,
_,_,_,_,_,_,_,_,_,_,_,_,_,
_,_,_,_,_,_,_,_,_,_,_,_,_,
_,_,_,_,_,_,_,_,_,_,_,_,_,
_,_,M,_,_,_,_,_,_,_,M,_,_,
_,_,L,_,_,_,_,_,_,_,L,_,_,
_,_,L,L,_,_,L,_,_,L,L,_,_,
_,_,_,L,_,L,L,L,_,L,_,_,_,
_,_,_,_,_,_,L,_,_,_,_,_,_,
_,_,_,_,_,_,_,_,_,_,_,_,_,
_,_,L,L,_,L,L,L,_,L,L,_,_,
_,_,_,_,L,L,L,L,L,_,_,_,_,
_,_,_,_,_,_,L,_,_,_,_,_,_,
_,_,_,_,_,_,_,_,_,_,_,_,_,
_,_,_,_,_,_,_,_,_,_,_,_,_,

_,_,_,_,_,_,_,_,_,_,_,_,_,
_,_,_,_,_,_,_,_,_,_,_,_,_,
_,_,_,_,_,_,_,_,_,_,_,_,_,
_,_,_,_,_,_,_,_,_,_,_,_,_,
_,_,_,_,_,_,_,_,_,_,_,_,_,
_,_,_,_,_,_,_,_,_,_,_,_,_,
_,_,_,_,_,_,_,_,_,_,_,_,_,
_,_,_,_,_,_,_,_,_,_,_,_,_,
_,_,_,_,_,_,_,_,_,_,_,_,_,
_,_,_,_,_,_,_,_,_,_,_,_,_,
_,_,_,_,_,_,_,_,_,_,_,_,_,
_,_,_,_,_,_,_,_,_,_,_,_,_,
_,_,_,_,_,_,_,_,_,_,_,_,_,
_,_,L,_,_,_,_,_,_,_,L,_,_,
_,_,L,L,_,_,L,_,_,L,L,_,_,
_,_,_,L,L,L,L,L,L,L,_,_,_,
_,_,_,_,_,_,L,_,_,_,_,_,_,
_,_,L,L,_,L,L,L,_,L,L,_,_,
_,_,_,L,L,L,L,L,L,L,_,_,_,
_,_,_,_,_,L,L,L,_,_,_,_,_,
_,_,_,_,_,_,_,_,_,_,_,_,_,
_,_,_,_,_,_,_,_,_,_,_,_,_,

_,_,_,_,_,_,_,_,_,_,_,_,_,
_,_,_,_,_,_,_,_,_,_,_,_,_,
_,_,_,_,_,_,_,_,_,_,_,_,_,
_,_,_,_,_,_,_,_,_,_,_,_,_,
_,_,_,_,_,_,_,_,_,_,_,_,_,
_,_,_,_,_,_,_,_,_,_,_,_,_,
_,_,_,_,_,_,_,_,_,_,_,_,_,
_,_,_,_,_,_,L,_,_,_,_,_,_,
_,_,_,_,_,_,_,_,_,_,_,_,_,
_,_,_,_,_,_,_,_,_,_,_,_,_,
_,_,_,_,_,_,_,_,_,_,_,_,_,
_,_,_,_,_,_,_,_,_,_,_,_,_,
_,_,_,_,_,_,_,_,_,_,_,_,_,
_,_,_,_,_,_,_,_,_,_,_,_,_,
_,_,_,_,_,L,L,L,_,_,_,_,_,
_,_,_,L,L,L,L,L,L,L,_,_,_,
_,_,_,_,L,L,L,L,L,_,_,_,_,
_,_,_,_,L,L,L,L,L,_,_,_,_,
_,_,L,L,L,L,T,L,L,L,L,_,_,
_,_,_,_,L,L,L,L,L,_,_,_,_,
_,_,_,_,_,L,L,L,_,_,_,_,_,
_,_,_,_,_,_,_,_,_,_,_,_,_,

_,_,_,_,_,_,_,_,_,_,_,_,_,
_,_,_,_,_,_,_,_,_,_,_,_,_,
_,_,_,_,_,_,_,_,_,_,_,_,_,
_,_,_,_,_,_,_,_,_,_,_,_,_,
_,_,_,_,_,_,_,_,_,_,_,_,_,
_,_,_,_,_,_,_,_,_,_,_,_,_,
_,_,_,_,_,_,_,_,_,_,_,_,_,
_,_,_,_,_,_,_,_,_,_,_,_,_,
_,_,_,_,_,_,L,_,_,_,_,_,_,
_,_,_,_,_,_,_,_,_,_,_,_,_,
_,_,_,_,_,_,_,_,_,_,_,_,_,
_,_,_,_,_,_,_,_,_,_,_,_,_,
_,_,_,_,_,_,_,_,_,_,_,_,_,
_,_,_,_,_,_,L,_,_,_,_,_,_,
_,_,L,_,L,L,L,L,L,_,L,_,_,
_,_,_,L,L,L,T,L,L,L,_,_,_,
_,_,_,_,L,L,L,L,L,_,_,_,_,
_,_,L,L,L,L,T,L,L,L,L,_,_,
_,L,L,L,L,L,L,L,L,L,L,L,_,
_,_,_,L,L,L,L,L,L,L,_,_,_,
_,_,_,_,L,L,L,L,L,_,_,_,_,
_,_,_,_,_,_,L,_,_,_,_,_,_,

_,_,_,_,_,_,T,_,_,_,_,_,_,
_,_,_,_,_,_,T,_,_,_,_,_,_,
_,_,_,_,_,_,T,_,_,_,_,_,_,
_,_,_,_,_,_,T,_,_,_,_,_,_,
_,_,_,_,_,_,T,_,_,_,_,_,_,
_,_,_,_,_,_,T,_,_,_,_,_,_,
_,_,_,_,_,_,T,_,_,_,_,_,_,
_,_,_,_,_,_,T,_,_,_,_,_,_,
_,_,_,_,_,_,T,_,_,_,_,_,_,
_,_,_,_,L,_,T,_,L,_,_,_,_,
_,_,_,_,_,L,T,L,_,_,_,_,_,
_,M,_,_,_,_,T,_,_,_,_,M,_,
_,L,_,_,_,_,T,_,_,_,_,L,_,
_,L,L,_,_,L,T,L,_,_,L,L,_,
_,_,L,L,L,L,T,L,L,L,L,_,_,
M,_,L,L,L,T,T,T,L,L,L,_,M,
L,_,_,L,L,L,T,L,L,L,_,_,L,
L,L,L,L,L,T,T,T,L,L,L,L,L,
_,L,L,L,T,L,T,L,T,L,L,L,_,
_,_,L,L,L,L,L,L,L,L,L,_,_,
_,_,_,_,L,L,L,L,L,_,_,_,_,
_,_,_,_,_,L,L,L,_,_,_,_,_,

_,_,_,_,_,_,_,_,_,_,_,_,_,
_,_,_,_,_,_,_,_,_,_,_,_,_,
_,_,_,_,_,_,_,_,_,_,_,_,_,
_,_,_,_,_,_,_,_,_,_,_,_,_,
_,_,_,_,_,_,_,_,_,_,_,_,_,
_,_,_,_,_,_,_,_,_,_,_,_,_,
_,_,_,_,_,_,_,_,_,_,_,_,_,
_,_,_,_,_,_,_,_,_,_,_,_,_,
_,_,_,_,_,_,L,_,_,_,_,_,_,
_,_,_,_,_,_,_,_,_,_,_,_,_,
_,_,_,_,_,_,_,_,_,_,_,_,_,
_,_,_,_,_,_,_,_,_,_,_,_,_,
_,_,_,_,_,_,_,_,_,_,_,_,_,
_,_,_,_,_,_,L,_,_,_,_,_,_,
_,_,L,_,L,L,L,L,L,_,L,_,_,
_,_,_,L,L,L,T,L,L,L,_,_,_,
_,_,_,_,L,L,L,L,L,_,_,_,_,
_,_,L,L,L,L,T,L,L,L,L,_,_,
_,L,L,L,L,L,L,L,L,L,L,L,_,
_,_,_,L,L,L,L,L,L,L,_,_,_,
_,_,_,_,L,L,L,L,L,_,_,_,_,
_,_,_,_,_,_,L,_,_,_,_,_,_,

_,_,_,_,_,_,_,_,_,_,_,_,_,
_,_,_,_,_,_,_,_,_,_,_,_,_,
_,_,_,_,_,_,_,_,_,_,_,_,_,
_,_,_,_,_,_,_,_,_,_,_,_,_,
_,_,_,_,_,_,_,_,_,_,_,_,_,
_,_,_,_,_,_,_,_,_,_,_,_,_,
_,_,_,_,_,_,_,_,_,_,_,_,_,
_,_,_,_,_,_,L,_,_,_,_,_,_,
_,_,_,_,_,_,_,_,_,_,_,_,_,
_,_,_,_,_,_,_,_,_,_,_,_,_,
_,_,_,_,_,_,_,_,_,_,_,_,_,
_,_,_,_,_,_,_,_,_,_,_,_,_,
_,_,_,_,_,_,_,_,_,_,_,_,_,
_,_,_,_,_,_,_,_,_,_,_,_,_,
_,_,_,_,_,L,L,L,_,_,_,_,_,
_,_,_,L,L,L,L,L,L,L,_,_,_,
_,_,_,_,L,L,L,L,L,_,_,_,_,
_,_,_,_,L,L,L,L,L,_,_,_,_,
_,_,L,L,L,L,T,L,L,L,L,_,_,
_,_,_,_,L,L,L,L,L,_,_,_,_,
_,_,_,_,_,L,L,L,_,_,_,_,_,
_,_,_,_,_,_,_,_,_,_,_,_,_,

_,_,_,_,_,_,_,_,_,_,_,_,_,
_,_,_,_,_,_,_,_,_,_,_,_,_,
_,_,_,_,_,_,_,_,_,_,_,_,_,
_,_,_,_,_,_,_,_,_,_,_,_,_,
_,_,_,_,_,_,_,_,_,_,_,_,_,
_,_,_,_,_,_,_,_,_,_,_,_,_,
_,_,_,_,_,_,_,_,_,_,_,_,_,
_,_,_,_,_,_,_,_,_,_,_,_,_,
_,_,_,_,_,_,_,_,_,_,_,_,_,
_,_,_,_,_,_,_,_,_,_,_,_,_,
_,_,_,_,_,_,_,_,_,_,_,_,_,
_,_,_,_,_,_,_,_,_,_,_,_,_,
_,_,_,_,_,_,_,_,_,_,_,_,_,
_,_,L,_,_,_,_,_,_,_,L,_,_,
_,_,L,L,_,_,L,_,_,L,L,_,_,
_,_,_,L,L,L,L,L,L,L,_,_,_,
_,_,_,_,_,_,L,_,_,_,_,_,_,
_,_,L,L,_,L,L,L,_,L,L,_,_,
_,_,_,L,L,L,L,L,L,L,_,_,_,
_,_,_,_,_,L,L,L,_,_,_,_,_,
_,_,_,_,_,_,_,_,_,_,_,_,_,
_,_,_,_,_,_,_,_,_,_,_,_,_,

_,_,_,_,_,_,_,_,_,_,_,_,_,
_,_,_,_,_,_,_,_,_,_,_,_,_,
_,_,_,_,_,_,_,_,_,_,_,_,_,
_,_,_,_,_,_,_,_,_,_,_,_,_,
_,_,_,_,_,_,_,_,_,_,_,_,_,
_,_,_,_,_,_,_,_,_,_,_,_,_,
_,_,_,_,_,_,_,_,_,_,_,_,_,
_,_,_,_,_,_,_,_,_,_,_,_,_,
_,_,_,_,_,_,_,_,_,_,_,_,_,
_,_,_,_,_,_,_,_,_,_,_,_,_,
_,_,_,_,_,_,_,_,_,_,_,_,_,
_,_,M,_,_,_,_,_,_,_,M,_,_,
_,_,L,_,_,_,_,_,_,_,L,_,_,
_,_,L,L,_,_,L,_,_,L,L,_,_,
_,_,_,L,_,L,L,L,_,L,_,_,_,
_,_,_,_,_,_,L,_,_,_,_,_,_,
_,_,_,_,_,_,_,_,_,_,_,_,_,
_,_,L,L,_,L,L,L,_,L,L,_,_,
_,_,_,_,L,L,L,L,L,_,_,_,_,
_,_,_,_,_,_,L,_,_,_,_,_,_,
_,_,_,_,_,_,_,_,_,_,_,_,_,
_,_,_,_,_,_,_,_,_,_,_,_,_,

_,_,_,_,_,_,_,_,_,_,_,_,_,
_,_,_,_,_,_,_,_,_,_,_,_,_,
_,_,_,_,_,_,_,_,_,_,_,_,_,
_,_,_,_,_,_,_,_,_,_,_,_,_,
_,_,_,_,_,_,_,_,_,_,_,_,_,
_,_,_,_,_,_,_,_,_,_,_,_,_,
_,_,_,_,_,_,_,_,_,_,_,_,_,
_,_,_,_,_,_,_,_,_,_,_,_,_,
_,_,_,_,_,_,_,_,_,_,_,_,_,
_,_,_,_,_,_,_,_,_,_,_,_,_,
_,_,_,_,_,_,_,_,_,_,_,_,_,
_,_,_,_,_,_,M,_,_,_,_,_,_,
_,_,_,_,_,_,L,_,_,_,_,_,_,
_,_,_,_,_,_,L,_,_,_,_,_,_,
_,_,_,_,_,_,_,_,_,_,_,_,_,
_,_,_,_,_,_,_,_,_,_,_,_,_,
_,_,_,_,_,_,_,_,_,_,_,_,_,
_,_,_,_,_,_,L,_,_,_,_,_,_,
_,_,_,_,_,L,L,L,_,_,_,_,_,
_,_,_,_,_,_,_,_,_,_,_,_,_,
_,_,_,_,_,_,_,_,_,_,_,_,_,
_,_,_,_,_,_,_,_,_,_,_,_,_,

_,_,_,_,_,_,_,_,_,_,_,_,_,
_,_,_,_,_,_,_,_,_,_,_,_,_,
_,_,_,_,_,_,_,_,_,_,_,_,_,
_,_,_,_,_,_,_,_,_,_,_,_,_,
_,_,_,_,_,_,_,_,_,_,_,_,_,
_,_,_,_,_,_,_,_,_,_,_,_,_,
_,_,_,_,_,_,_,_,_,_,_,_,_,
_,_,_,_,_,_,_,_,_,_,_,_,_,
_,_,_,_,_,_,_,_,_,_,_,_,_,
_,_,_,_,_,_,_,_,_,_,_,_,_,
_,_,_,_,_,_,_,_,_,_,_,_,_,
_,_,_,_,_,_,_,_,_,_,_,_,_,
_,_,_,_,_,_,_,_,_,_,_,_,_,
_,_,_,_,_,_,_,_,_,_,_,_,_,
_,_,_,_,_,_,_,_,_,_,_,_,_,
_,_,_,_,_,_,M,_,_,_,_,_,_,
_,_,_,_,_,_,L,_,_,_,_,_,_,
_,_,_,_,_,_,L,_,_,_,_,_,_,
_,_,_,_,_,_,_,_,_,_,_,_,_,
_,_,_,_,_,_,_,_,_,_,_,_,_,
_,_,_,_,_,_,_,_,_,_,_,_,_,
_,_,_,_,_,_,_,_,_,_,_,_,_},
yslice_prob = {{ypos = 1, prob = 127}}}

local function grow_solarie_tree(pos)
	if not default.can_grow(pos) then
		-- try a bit later again
		core.get_node_timer(pos):start(math.random(240, 600))
		return
	end
	add_tree(pos, 6, 1, 6, solarie_tree, "0")
end

-- Decoration

local mg_name = core.get_mapgen_setting("mg_name")

if mg_name ~= "v6" and mg_name ~= "singlenode" then
	core.register_decoration({
		deco_type = "schematic",
		place_on = {"default:dirt_with_rainforest_litter"},
		sidelen = 16,
		noise_params = {
			offset = 0.0005,-- 0,
			scale = 0.00005,-- -0.0002,
			spread = {x = 250, y = 250, z = 250},
			seed = 2,
			octaves = 3,
			persist = 0.66
		},
		biomes = {"rainforest"},
		y_min = 2,
		y_max = 32,-- 31000,
		schematic = solarie_tree,
		flags = "place_center_x, place_center_z",
	})
end

-- Nodes

core.register_node("solarie:sapling", {
	description = S("Solarie Tree Sapling"),
	drawtype = "plantlike",
	tiles = {"solarie_sapling.png"},
	inventory_image = "solarie_sapling.png",
	paramtype = "light",
	sunlight_propagates = true,
	walkable = false,
	on_timer = grow_solarie_tree,
	selection_box = {
		type = "fixed",
		fixed = {-4/16, -.5, -4/16, 4/16, 7/16, 4/16}
	},
	groups = {snappy = 2, dig_immediate = 3, flammable = 2, attached_node = 1, sapling = 1},
	sounds = default.node_sound_leaves_defaults(),

	on_construct = function(pos)
		core.get_node_timer(pos):start(math.random(600, 3000))
	end,

	on_place = function(itemstack, placer, pointd)
		itemstack = default.sapling_on_place(itemstack, placer, pointd,
			"solarie:sapling",
			-- minp, maxp to be checked, relative to sapling pos
			-- minp_relative.y = 1 because sapling pos has been checked
			{x = -6, y = 1, z = -6},
			{x = 6, y = 18, z = 6},
			-- maximum interval of interior volume check
			4)

		return itemstack
	end,
	grown_height = 17,
})

core.register_node("solarie:trunk", {
	description = S("Solarie Trunk"),
	tiles = {"solarie_trunk_top.png", "solarie_trunk_top.png", "solarie_trunk.png"},
	paramtype2 = "facedir",
	is_ground_content = false,
	groups = {choppy = 2, flammable = 1, trunk = 1},
	sounds = default.node_sound_wood_defaults(),
	on_place = core.rotate_node,
})

core.register_node("solarie:wood", {
	description = S("Solarie Wood"),
	tiles = {"solarie_wood.png"},
	is_ground_content = false,
	groups = {choppy = 2, oddly_breakable_by_hand = 1, flammable = 1, wood = 1},
	sounds = default.node_sound_wood_defaults(),
})

core.register_node("solarie:leaves", {
	description = S("Solarie Leaves"),
	drawtype = leaf_drawtype,
	mesh = "leaf_droop.obj",
	waving = waving_style,
	tiles = {"solarie_leaves.png"..leaf_image("^[transformFY")},
	inventory_image = leaf_image("solarie_leaves.png"),
	wield_image = leaf_image("solarie_leaves.png"),
	use_texture_alpha = "clip",
	paramtype = "light",
	is_ground_content = false,
	collision_box = leaf_cbox,
	groups = {snappy = 3, leafdecay = 3, flammable = 2, leaves = 1},
	drop = {
		max_items = 1,
		items = {
			{items = {"solarie:sapling"}, rarity = 20},
			{items = {"solarie:leaves"}}
		}
	},
	sounds = default.node_sound_leaves_defaults(),
	after_place_node = default.after_place_leaves,
})

-- Recipes

core.register_craft({
	output = "solarie:wood 4",
	recipe = {{"solarie:trunk"}}
})

core.register_craft({
	output = "default:gold_lump",
	recipe = {
		{"solarie:wood", "solarie:wood", "solarie:wood"},
		{"solarie:wood", "solarie:wood", "solarie:wood"},
		{"solarie:wood", "solarie:wood", "solarie:wood"}
	},
	replacements = {{"solarie:wood", "default:wood"}, {"solarie:wood", "default:wood"},
		{"solarie:wood", "default:wood"}, {"solarie:wood", "default:wood"},
		{"solarie:wood", "default:wood"}, {"solarie:wood", "default:wood"},
		{"solarie:wood", "default:wood"}, {"solarie:wood", "default:wood"},
		{"solarie:wood", "default:wood"}
	}
})

core.register_craft({
	type = "fuel",
	recipe = "solarie:trunk",
	burntime = 30,
})

core.register_craft({
	type = "fuel",
	recipe = "solarie:wood",
	burntime = 7,
})


core.register_lbm({
	name = "solarie:convert_solarie_saplings_to_node_timer",
	nodenames = {"solarie:sapling"},
	action = function(pos)
		core.get_node_timer(pos):start(math.random(300, 1500))
	end
})

default.register_leafdecay({
	trunks = {"solarie:trunk"},
	leaves = {"solarie:leaves"},
	radius = 4,
})

if core.get_modpath("bonemeal") then
	bonemeal:add_sapling({
		{"solarie:sapling", grow_solarie_tree, "soil"},
	})
end
