
local T = {name = "ethereal:bamboo", force_place = true}
local L = {name = "ethereal:bamboo_leaves"}
local V = {name = "ethereal:bamboo_leaves", prob = 100}

ethereal.bambootree = {size = {x = 5, y = 21, z = 5}, data = {-- was 18 total
_,_,_,_,_,
_,_,_,_,_,
_,_,_,_,_,
_,_,_,_,_,
_,_,_,_,_,
_,_,_,_,_,
_,_,_,_,_,
_,_,_,_,_,
_,_,_,_,_,
_,_,_,_,_,
_,_,_,_,_,
_,_,_,_,_,
_,_,_,_,_,
_,_,_,_,_,
_,_,_,_,_,
_,_,_,_,_,
_,_,V,_,_,
_,_,V,_,_,
_,_,V,_,_,
_,_,_,_,_,
_,_,_,_,_,

_,_,_,_,_,
_,_,_,_,_,
_,_,_,_,_,
_,_,_,_,_,
_,_,_,_,_,
_,_,_,_,_,
_,_,_,_,_,
_,_,_,_,_,
_,_,_,_,_,
_,_,_,_,_,
_,_,_,_,_,
_,_,_,_,_,
_,_,_,_,_,
_,_,_,_,_,
_,_,_,_,_,
_,_,L,_,_,
_,V,L,V,_,
_,V,L,L,_,
_,L,L,L,_,
_,V,L,V,_,
_,_,_,_,_,

_,_,_,_,_,
_,_,T,_,_,
_,_,T,_,_,
_,_,T,_,_,
_,_,T,_,_,
_,_,T,_,_,
_,_,T,_,_,
_,_,T,_,_,
_,_,T,_,_,
_,_,T,_,_,
_,_,T,_,_,
_,_,T,_,_,
_,_,T,_,_,
_,_,T,_,_,
_,_,T,_,_,
_,L,T,L,_,
V,L,T,L,V,
V,L,T,L,V,
V,L,T,L,V,
_,L,L,L,_,
_,_,L,_,_,

_,_,_,_,_,
_,_,_,_,_,
_,_,_,_,_,
_,_,_,_,_,
_,_,_,_,_,
_,_,_,_,_,
_,_,_,_,_,
_,_,_,_,_,
_,_,_,_,_,
_,_,_,_,_,
_,_,_,_,_,
_,_,_,_,_,
_,_,_,_,_,
_,_,_,_,_,
_,_,_,_,_,
_,_,L,_,_,
_,V,L,V,_,
_,L,L,V,_,
_,L,L,L,_,
_,V,L,V,_,
_,_,_,_,_,

_,_,_,_,_,
_,_,_,_,_,
_,_,_,_,_,
_,_,_,_,_,
_,_,_,_,_,
_,_,_,_,_,
_,_,_,_,_,
_,_,_,_,_,
_,_,_,_,_,
_,_,_,_,_,
_,_,_,_,_,
_,_,_,_,_,
_,_,_,_,_,
_,_,_,_,_,
_,_,_,_,_,
_,_,_,_,_,
_,_,V,_,_,
_,_,V,_,_,
_,_,V,_,_,
_,_,_,_,_,
_,_,_,_,_},
yslice_prob = {{ypos = 1, prob = 127}, {ypos = 2, prob = 127}, {ypos = 3, prob = 127}}}

local S = {name = "ethereal:bamboo_sprout_4", force_place = true}

ethereal.bambootreesprout = {size = {x = 3, y = 12, z = 3}, data = {
_,_,_,
_,_,_,
_,_,_,
_,_,_,
_,_,_,
_,_,_,
_,_,_,
_,_,_,
_,V,_,
_,V,_,
_,V,_,
_,_,_,

_,T,_,
_,T,_,
_,T,_,
_,T,_,
_,T,_,
_,T,_,
_,T,_,
_,T,_,
V,T,V,
V,S,V,
V,S,V,
_,S,_,

_,_,_,
_,_,_,
_,_,_,
_,_,_,
_,_,_,
_,_,_,
_,_,_,
_,_,_,
_,V,_,
_,V,_,
_,V,_,
_,_,_}}
