
local T = {name = "ethereal:banana_corm", force_place = true}
local L = {name = "ethereal:bananaleaves"}
local V = {name = "ethereal:bananaleaves", prob = 180}
local B = {name = "ethereal:banana_cluster_3"}
local O = {name = "ethereal:banana_cluster_3", prob = 70}

ethereal.bananatree = {size = {x = 7, y = 12, z = 7}, data = {
_,_,_,_,_,_,_,
_,_,_,_,_,_,_,
_,_,_,_,_,_,_,
_,_,_,_,_,_,_,
_,_,_,_,_,_,_,
_,_,_,_,_,_,_,
_,_,_,_,_,_,_,
_,_,_,_,_,_,_,
_,_,_,_,_,_,_,
_,_,_,_,_,_,_,
_,_,_,L,_,_,_,
_,_,_,V,_,_,_,

_,_,_,_,_,_,_,
_,_,_,_,_,_,_,
_,_,_,_,_,_,_,
_,_,_,_,_,_,_,
_,_,_,_,_,_,_,
_,_,_,_,_,_,_,
_,_,_,_,_,_,_,
_,_,_,_,_,_,_,
_,_,_,O,_,_,_,
_,_,_,B,_,_,_,
_,_,_,L,_,_,_,
_,_,_,_,_,_,_,

_,_,_,_,_,_,_,
_,_,_,_,_,_,_,
_,_,_,_,_,_,_,
_,_,_,_,_,_,_,
_,_,_,_,_,_,_,
_,_,_,_,_,_,_,
_,_,_,_,_,_,_,
_,_,_,T,_,_,_,
_,_,O,T,O,_,_,
_,_,B,L,B,_,_,
_,L,L,L,L,L,_,
L,V,_,L,_,V,L,

_,_,_,T,_,_,_,
_,_,_,T,_,_,_,
_,_,_,T,_,_,_,
_,_,_,T,_,_,_,
_,_,_,T,_,_,_,
_,_,_,T,_,_,_,
_,_,_,T,_,_,_,
_,_,_,_,_,_,_,
_,_,_,O,_,_,_,
_,_,_,B,_,_,_,
_,_,_,L,_,_,_,
_,_,_,_,_,_,_,

_,_,_,_,_,_,_,
_,_,_,_,_,_,_,
_,_,_,_,_,_,_,
_,_,_,_,_,_,_,
_,_,_,_,_,_,_,
_,_,_,_,_,_,_,
_,_,_,_,_,_,_,
_,_,_,_,_,_,_,
_,_,_,_,_,_,_,
_,_,_,_,_,_,_,
_,_,_,L,_,_,_,
_,_,_,V,_,_,_,

_,_,_,_,_,_,_,
_,_,_,_,_,_,_,
_,_,_,_,_,_,_,
_,_,_,_,_,_,_,
_,_,_,_,_,_,_,
_,_,_,_,_,_,_,
_,_,_,_,_,_,_,
_,_,_,_,_,_,_,
_,_,_,_,_,_,_,
_,_,_,_,_,_,_,
_,_,_,_,_,_,_,
_,_,_,L,_,_,_,

_,_,_,_,_,_,_,
_,_,_,_,_,_,_,
_,_,_,_,_,_,_,
_,_,_,_,_,_,_,
_,_,_,_,_,_,_,
_,_,_,_,_,_,_,
_,_,_,_,_,_,_,
_,_,_,_,_,_,_,
_,_,_,_,_,_,_,
_,_,_,_,_,_,_,
_,_,_,_,_,_,_,
_,_,_,_,_,_,_},
yslice_prob = {{ypos = 1, prob = 127}, {ypos = 2, prob = 117}, {ypos = 4, prob = 107}, {ypos = 7, prob = 97}}}
