
local L = {name = "ethereal:redwood_leaves"}
local M = {name = "ethereal:redwood_leaves", prob = 223}
local T = {name = "ethereal:redwood_trunk", force_place = true}

ethereal.redwood_tree = {size = {x = 17, y = 23, z = 17}, data = {
_,_,_,_,_,_,_,_,_,_,_,_,_,_,_,_,_,
_,_,_,_,_,_,_,_,_,_,_,_,_,_,_,_,_,
_,_,_,_,_,_,_,_,_,_,_,_,_,_,_,_,_,
_,_,_,_,_,_,_,_,_,_,_,_,_,_,_,_,_,
_,_,_,_,_,_,_,_,_,_,_,_,_,_,_,_,_,
_,_,_,_,_,_,_,_,_,_,_,_,_,_,_,_,_,
_,_,_,_,_,_,_,_,_,_,_,_,_,_,_,_,_,
_,_,_,_,_,_,_,_,_,_,_,_,_,_,_,_,_,
_,_,_,_,_,_,_,_,_,_,_,_,_,_,_,_,_,
_,_,_,_,_,_,_,_,_,_,_,_,_,_,_,_,_,
_,_,_,_,_,_,_,_,_,_,_,_,_,_,_,_,_,
_,_,_,_,_,_,_,_,_,_,_,_,_,_,_,_,_,
_,_,_,_,_,_,_,_,_,_,_,_,_,_,_,_,_,
_,_,_,_,_,_,_,_,_,_,_,_,_,_,_,_,_,
_,_,_,_,_,_,_,_,_,_,_,_,_,_,_,_,_,
_,_,_,_,_,_,_,_,_,_,_,_,_,_,_,_,_,
_,_,_,_,_,_,_,_,_,_,_,_,_,_,_,_,_,
_,_,_,_,_,_,_,_,_,_,_,_,_,_,_,_,_,
_,_,_,_,_,_,_,_,_,_,_,_,_,_,_,_,_,
_,_,_,_,_,_,_,_,_,_,_,_,_,_,_,_,_,
_,_,_,_,_,_,_,_,_,_,_,_,_,_,_,_,_,
_,_,_,_,_,_,_,_,_,_,_,_,_,_,_,_,_,
_,_,_,_,_,_,_,_,_,_,_,_,_,_,_,_,_,

_,_,_,_,_,_,_,_,_,_,_,_,_,_,_,_,_,
_,_,_,_,_,_,_,_,_,_,_,_,_,_,_,_,_,
_,_,_,_,_,_,_,_,_,_,_,_,_,_,_,_,_,
_,_,_,_,_,_,_,_,_,_,_,_,_,_,_,_,_,
_,_,_,_,_,_,_,_,_,_,_,_,_,_,_,_,_,
_,_,_,_,_,_,_,_,_,_,_,_,_,_,_,_,_,
_,_,_,_,_,_,_,_,_,_,_,_,_,_,_,_,_,
_,_,_,_,_,_,_,_,_,_,_,_,_,_,_,_,_,
_,_,_,_,_,_,_,_,_,_,_,_,_,_,_,_,_,
_,_,_,_,_,_,_,_,_,_,_,_,_,_,_,_,_,
_,_,_,_,_,_,_,_,_,_,_,_,_,_,_,_,_,
_,_,_,_,_,_,_,_,_,_,_,_,_,_,_,_,_,
_,_,_,_,_,_,_,_,_,_,_,_,_,_,_,_,_,
_,_,_,_,_,_,_,_,L,L,L,_,_,_,_,_,_,
_,_,_,_,_,_,_,_,M,L,M,_,_,_,_,_,_,
_,_,_,_,_,_,_,_,_,_,_,_,_,_,_,_,_,
_,_,_,_,_,_,_,_,_,_,_,_,_,_,_,_,_,
_,_,_,_,_,_,_,_,_,_,_,_,_,_,_,_,_,
_,_,_,_,_,_,_,_,_,_,_,_,_,_,_,_,_,
_,_,_,_,_,_,_,_,_,_,_,_,_,_,_,_,_,
_,_,_,_,_,_,_,_,_,_,_,_,_,_,_,_,_,
_,_,_,_,_,_,_,_,_,_,_,_,_,_,_,_,_,
_,_,_,_,_,_,_,_,_,_,_,_,_,_,_,_,_,

_,_,_,_,_,_,_,_,_,_,_,_,_,_,_,_,_,
_,_,_,_,_,_,_,_,_,_,_,_,_,_,_,_,_,
_,_,_,_,_,_,_,_,_,_,_,_,_,_,_,_,_,
_,_,_,_,_,_,_,_,_,_,_,_,_,_,_,_,_,
_,_,_,_,_,_,_,_,_,_,_,_,_,_,_,_,_,
_,_,_,_,_,_,_,_,_,_,_,_,_,_,_,_,_,
_,_,_,_,_,_,_,_,_,_,_,_,_,_,_,_,_,
_,_,_,_,_,_,_,_,_,_,_,_,_,_,_,_,_,
_,_,_,_,_,_,_,_,_,_,_,_,_,_,_,_,_,
_,_,_,_,_,_,_,_,_,_,_,_,_,_,_,_,_,
_,_,_,_,_,_,_,_,_,_,_,_,_,_,_,_,_,
_,_,_,_,_,_,_,_,_,_,_,_,_,_,_,_,_,
_,_,_,_,_,_,_,_,_,_,_,_,_,_,_,_,_,
_,_,_,_,_,_,_,L,L,L,L,L,_,_,_,_,_,
_,_,_,_,_,_,_,M,L,L,L,M,_,_,_,_,_,
_,_,_,_,_,_,_,_,_,L,_,_,_,_,_,_,_,
_,_,_,_,_,_,_,_,_,_,_,_,_,_,_,_,_,
_,_,_,_,_,_,_,_,_,_,_,_,_,_,_,_,_,
_,_,_,_,_,_,_,_,_,_,_,_,_,_,_,_,_,
_,_,_,_,_,_,_,_,_,_,_,_,_,_,_,_,_,
_,_,_,_,_,_,_,_,_,_,_,_,_,_,_,_,_,
_,_,_,_,_,_,_,_,_,_,_,_,_,_,_,_,_,
_,_,_,_,_,_,_,_,_,_,_,_,_,_,_,_,_,

_,_,_,_,_,_,_,_,_,_,_,_,_,_,_,_,_,
_,_,_,_,_,_,_,_,_,_,_,_,_,_,_,_,_,
_,_,_,_,_,_,_,_,_,_,_,_,_,_,_,_,_,
_,_,_,_,_,_,_,_,_,_,_,_,_,_,_,_,_,
_,_,_,_,_,_,_,_,_,_,_,_,_,_,_,_,_,
_,_,_,_,_,_,_,_,_,_,_,_,_,_,_,_,_,
_,_,_,_,_,_,_,_,_,_,_,_,_,_,_,_,_,
_,_,_,_,_,_,_,_,_,_,_,_,_,_,_,_,_,
_,_,_,_,_,_,_,_,_,_,_,_,_,_,_,_,_,
_,_,_,_,_,_,_,_,_,_,_,_,_,_,_,_,_,
_,_,_,_,_,_,_,_,_,_,_,_,_,_,_,_,_,
_,_,_,_,_,_,_,_,_,_,_,_,_,_,_,_,_,
_,_,_,_,_,_,_,_,_,_,_,_,_,_,_,_,_,
_,_,_,_,_,_,L,L,L,L,L,L,L,_,_,_,_,
_,_,_,_,_,_,_,L,L,L,L,L,_,_,_,_,_,
_,_,_,_,_,_,_,_,L,L,L,_,_,_,_,_,_,
_,_,_,_,L,L,L,L,_,_,_,_,_,_,_,_,_,
_,_,_,_,M,L,L,_,_,_,_,_,_,_,_,_,_,
_,_,_,_,_,_,_,_,_,_,_,_,_,_,_,_,_,
_,_,_,_,_,_,_,_,_,_,_,_,_,_,_,_,_,
_,_,_,_,_,_,_,_,_,_,_,_,_,_,_,_,_,
_,_,_,_,_,_,_,_,_,_,_,_,_,_,_,_,_,
_,_,_,_,_,_,_,_,_,_,_,_,_,_,_,_,_,

_,_,_,_,_,_,_,_,_,_,_,_,_,_,_,_,_,
_,_,_,_,_,_,_,_,_,_,_,_,_,_,_,_,_,
_,_,_,_,_,_,_,_,_,_,_,_,_,_,_,_,_,
_,_,_,_,_,_,_,_,_,_,_,_,_,_,_,_,_,
_,_,_,_,_,_,_,_,_,_,_,_,_,_,_,_,_,
_,_,_,_,_,_,_,_,_,_,_,_,_,_,_,_,_,
_,_,_,_,_,_,_,_,_,_,_,_,_,_,_,_,_,
_,_,_,_,_,_,_,_,_,_,_,_,_,_,_,_,_,
_,_,_,_,_,_,_,_,_,_,_,_,_,_,_,_,_,
_,_,_,_,_,_,_,_,_,_,_,_,_,_,_,_,_,
_,_,_,_,_,_,_,_,_,_,_,_,_,_,_,_,_,
_,_,_,_,_,_,_,_,_,_,_,_,_,_,_,_,_,
_,_,_,_,_,_,_,_,_,_,_,_,_,_,_,_,_,
_,_,_,_,_,_,L,L,L,T,L,L,L,_,_,_,_,
_,_,_,_,_,_,_,L,L,L,L,L,_,_,_,_,_,
_,_,_,_,_,_,_,M,L,L,L,M,_,_,_,_,_,
_,_,_,L,L,L,L,L,L,_,_,_,_,_,_,_,_,
_,_,_,M,L,L,L,L,_,_,_,_,_,_,_,_,_,
_,_,_,_,M,L,L,_,_,_,_,_,_,_,_,_,_,
_,_,_,_,_,_,L,L,L,L,L,_,_,_,_,_,_,
_,_,_,_,_,_,_,_,M,_,_,_,_,_,_,_,_,
_,_,_,_,_,_,_,_,_,_,_,_,_,_,_,_,_,
_,_,_,_,_,_,_,_,_,_,_,_,_,_,_,_,_,

_,_,_,_,_,_,_,_,_,_,_,_,_,_,_,_,_,
_,_,_,_,_,_,_,_,_,_,_,_,_,_,_,_,_,
_,_,_,_,_,_,_,_,_,_,_,_,_,_,_,_,_,
_,_,_,_,_,_,_,_,_,_,_,_,_,_,_,_,_,
_,_,_,_,_,_,_,_,_,_,_,_,_,_,_,_,_,
_,_,_,_,_,_,_,_,_,_,_,_,_,_,_,_,_,
_,_,_,_,_,_,_,_,_,_,_,_,_,_,_,_,_,
_,_,_,_,_,_,_,_,_,_,_,_,_,_,_,_,_,
_,_,_,_,_,_,_,_,_,_,_,_,_,_,_,_,_,
_,_,_,_,_,_,_,_,_,_,_,_,_,_,_,_,_,
_,_,_,_,_,_,_,_,_,_,_,_,_,_,_,_,_,
_,_,_,_,_,_,_,_,_,_,_,_,_,_,_,_,_,
_,_,_,_,_,_,_,_,_,T,_,_,_,_,_,_,_,
_,_,_,_,_,_,_,L,L,T,L,L,_,L,L,_,_,
_,_,_,_,_,_,_,L,L,L,L,L,_,_,_,_,_,
_,_,_,_,_,_,_,_,L,L,L,_,_,_,_,_,_,
_,_,_,L,L,L,L,L,L,_,_,_,_,_,_,_,_,
_,_,_,L,L,L,L,L,M,_,_,_,_,_,_,_,_,
_,_,_,_,L,L,L,M,M,_,_,_,_,_,_,_,_,
_,_,_,_,_,L,L,L,L,L,L,L,_,_,_,_,_,
_,_,_,_,_,_,M,L,L,L,M,_,_,_,_,_,_,
_,_,_,_,_,_,_,_,M,_,_,_,_,_,_,_,_,
_,_,_,_,_,_,_,_,_,_,_,_,_,_,_,_,_,

_,_,_,_,_,_,_,_,_,_,_,_,_,_,_,_,_,
_,_,_,_,_,_,_,_,_,_,_,_,_,_,_,_,_,
_,_,_,_,_,_,_,_,T,_,_,_,_,_,_,_,_,
_,_,_,_,_,_,_,_,_,_,_,_,_,_,_,_,_,
_,_,_,_,_,_,_,_,_,_,_,_,_,_,_,_,_,
_,_,_,_,_,_,_,_,_,_,_,_,_,_,_,_,_,
_,_,_,_,_,_,_,_,_,_,_,_,_,_,_,_,_,
_,_,_,_,_,_,_,_,_,_,_,_,_,_,_,_,_,
_,_,_,_,_,_,_,_,_,_,_,_,_,_,_,_,_,
_,_,_,_,_,_,_,_,_,_,_,_,_,_,_,_,_,
_,_,_,_,_,_,_,_,_,_,_,_,_,_,_,_,_,
_,_,_,_,_,_,_,_,_,_,_,_,_,_,_,_,_,
_,_,_,_,_,_,_,_,_,T,_,_,_,_,_,_,_,
_,_,_,_,_,_,_,L,L,L,L,L,L,L,L,L,_,
_,_,_,_,_,_,_,_,L,L,L,_,L,L,L,M,_,
_,_,_,_,_,_,_,_,_,L,_,_,_,M,_,_,_,
_,_,_,L,L,L,T,L,L,L,_,_,_,_,_,_,_,
_,_,_,L,L,L,L,L,L,_,_,_,_,_,_,_,_,
_,_,_,_,L,L,L,L,L,L,M,_,_,_,_,_,_,
_,_,_,_,L,L,L,L,L,L,L,L,L,_,_,_,_,
_,_,_,_,_,M,L,L,L,L,L,M,_,_,_,_,_,
_,_,_,_,_,_,M,L,L,L,M,_,_,_,_,_,_,
_,_,_,_,_,_,_,_,_,_,_,_,_,_,_,_,_,

_,_,_,_,_,_,_,_,_,_,_,_,_,_,_,_,_,
_,_,_,_,_,_,_,_,T,T,_,_,_,_,_,_,_,
_,_,_,_,_,_,_,T,T,T,_,_,_,_,_,_,_,
_,_,_,_,_,_,_,T,T,T,_,_,_,_,_,_,_,
_,_,_,_,_,_,_,T,T,T,_,_,_,_,_,_,_,
_,_,_,_,_,_,_,T,T,T,_,_,_,_,_,_,_,
_,_,_,_,_,_,_,T,T,T,_,_,_,_,_,_,_,
_,_,_,_,_,_,_,T,T,T,_,_,_,_,_,_,_,
_,_,_,_,_,_,_,T,T,T,_,_,_,_,_,_,_,
_,_,_,_,_,_,_,T,T,T,_,_,_,_,_,_,_,
_,_,_,_,_,_,_,T,T,T,_,_,_,_,_,_,_,
_,_,_,_,_,_,_,T,T,T,_,_,_,_,_,_,_,
_,_,_,_,_,_,_,T,T,T,_,_,_,_,_,_,_,
_,_,_,_,_,_,_,_,T,L,L,L,L,L,L,L,L,
_,_,_,_,_,_,_,_,T,L,_,L,L,L,L,L,M,
_,_,_,L,L,_,_,T,T,_,_,_,L,L,L,_,_,
_,_,_,L,L,L,L,L,T,L,_,_,_,_,_,_,_,
_,_,_,_,L,L,L,L,T,_,_,_,_,_,_,_,_,
_,_,_,_,_,M,L,L,T,L,L,_,_,_,_,_,_,
_,_,_,_,L,L,L,L,L,L,L,L,L,_,_,_,_,
_,_,_,_,_,L,L,L,L,L,L,L,_,_,_,_,_,
_,_,_,_,_,_,L,L,L,L,L,_,_,_,_,_,_,
_,_,_,_,_,_,_,M,L,M,_,_,_,_,_,_,_,

_,_,_,_,_,_,_,_,T,_,_,_,_,_,_,_,_,
_,_,_,_,_,_,_,T,T,_,_,_,_,_,_,_,_,
_,_,_,_,_,_,T,T,T,T,_,_,_,_,_,_,_,
_,_,_,_,_,_,_,T,T,T,_,_,_,_,_,_,_,
_,_,_,_,_,_,_,T,T,T,_,_,_,_,_,_,_,
_,_,_,_,_,_,_,T,T,T,_,_,_,_,_,_,_,
_,_,_,_,_,_,_,T,T,T,_,_,_,_,_,_,_,
_,_,_,_,_,_,_,T,T,T,_,_,_,_,_,_,_,
_,_,_,_,_,_,_,T,T,T,_,_,_,_,_,_,_,
_,_,_,_,_,_,_,T,T,T,_,_,_,_,_,_,_,
_,_,_,_,_,_,_,T,T,T,_,_,_,_,_,_,_,
_,_,_,_,_,_,_,T,T,T,_,_,_,_,_,_,_,
_,_,_,_,_,_,_,T,T,T,T,T,T,_,_,_,_,
_,_,_,_,_,_,_,T,T,T,L,L,T,T,L,L,L,
_,_,_,_,_,_,_,T,T,T,L,L,L,L,L,L,L,
_,_,L,L,L,L,L,T,T,T,_,L,L,L,L,L,_,
_,_,M,L,L,L,L,T,T,T,L,_,_,_,_,_,_,
_,_,_,_,M,L,L,T,T,T,_,_,_,_,_,_,_,
_,_,_,_,_,M,L,T,T,T,L,M,_,_,_,_,_,
_,_,_,_,L,L,L,L,T,L,L,L,L,_,_,_,_,
_,_,_,_,M,L,L,L,L,L,L,L,M,_,_,_,_,
_,_,_,_,_,M,L,L,L,L,L,M,_,_,_,_,_,
_,_,_,_,_,_,_,L,L,L,_,_,_,_,_,_,_,

_,_,_,_,_,_,_,_,_,_,_,_,_,_,_,_,_,
_,_,_,_,_,_,_,T,_,T,_,_,_,_,_,_,_,
_,_,_,_,_,_,_,T,T,T,T,_,_,_,_,_,_,
_,_,_,_,_,_,_,T,T,T,_,_,_,_,_,_,_,
_,_,_,_,_,_,_,T,T,T,_,_,_,_,_,_,_,
_,_,_,_,_,_,_,T,T,T,_,_,_,_,_,_,_,
_,_,_,_,_,_,_,T,T,T,_,_,_,_,_,_,_,
_,_,_,_,_,_,_,T,T,T,_,_,_,_,_,_,_,
_,_,_,_,_,_,_,T,T,T,_,_,_,_,_,_,_,
_,_,_,_,_,_,_,T,T,T,_,_,_,_,_,_,_,
_,_,_,_,_,_,_,T,T,T,_,_,_,_,_,_,_,
_,_,_,_,_,_,_,T,T,T,_,_,_,_,_,_,_,
_,_,_,_,_,_,L,T,T,T,_,_,_,_,_,_,_,
_,_,_,_,_,_,_,T,T,_,L,L,L,L,L,L,L,
_,_,_,_,_,T,T,T,T,_,_,L,L,L,L,L,M,
_,L,L,L,L,L,L,L,T,T,_,_,L,L,L,_,_,
_,M,L,L,L,L,L,L,T,L,L,L,L,_,_,_,_,
_,_,_,L,L,L,_,_,T,L,L,M,_,_,_,_,_,
_,_,_,_,_,_,L,L,T,L,L,_,_,_,_,_,_,
_,_,_,_,L,L,L,L,L,L,L,L,L,_,_,_,_,
_,_,_,_,_,L,L,L,L,L,L,L,_,_,_,_,_,
_,_,_,_,_,_,L,L,L,L,L,_,_,_,_,_,_,
_,_,_,_,_,_,_,M,L,M,_,_,_,_,_,_,_,

_,_,_,_,_,_,_,_,_,_,_,_,_,_,_,_,_,
_,_,_,_,_,_,_,_,_,_,_,_,_,_,_,_,_,
_,_,_,_,_,_,_,T,_,T,_,_,_,_,_,_,_,
_,_,_,_,_,_,_,_,_,_,_,_,_,_,_,_,_,
_,_,_,_,_,_,_,_,_,_,_,_,_,_,_,_,_,
_,_,_,_,_,_,_,_,_,_,_,_,_,_,_,_,_,
_,_,_,_,_,_,_,_,_,_,_,_,_,_,_,_,_,
_,_,_,_,_,_,_,_,_,_,_,_,_,_,_,_,_,
_,_,_,_,_,_,_,_,_,_,_,_,_,_,_,_,_,
_,_,_,_,_,_,_,_,_,_,_,_,_,_,_,_,_,
_,_,_,_,_,_,_,_,_,_,_,_,_,_,_,_,_,
_,_,_,_,_,_,_,T,_,_,_,_,_,_,_,_,_,
_,_,_,_,_,L,L,L,L,L,_,_,_,_,_,_,_,
_,_,_,_,_,_,L,L,L,_,_,L,L,L,L,L,_,
_,_,_,_,_,T,_,L,_,_,_,_,L,L,L,M,_,
_,L,L,L,T,T,L,L,_,T,_,_,_,M,_,_,_,
_,L,L,L,L,L,L,L,L,L,L,L,L,L,_,_,_,
_,_,L,L,L,L,L,_,L,L,L,L,L,_,_,_,_,
_,_,_,_,_,_,M,L,L,L,L,M,_,_,_,_,_,
_,_,_,_,L,L,L,L,L,L,L,L,L,_,_,_,_,
_,_,_,_,_,M,L,L,L,L,L,M,_,_,_,_,_,
_,_,_,_,_,_,M,L,L,L,M,_,_,_,_,_,_,
_,_,_,_,_,_,_,_,_,_,_,_,_,_,_,_,_,

_,_,_,_,_,_,_,_,_,_,_,_,_,_,_,_,_,
_,_,_,_,_,_,_,_,_,_,_,_,_,_,_,_,_,
_,_,_,_,_,_,_,_,_,_,_,_,_,_,_,_,_,
_,_,_,_,_,_,_,_,_,_,_,_,_,_,_,_,_,
_,_,_,_,_,_,_,_,_,_,_,_,_,_,_,_,_,
_,_,_,_,_,_,_,_,_,_,_,_,_,_,_,_,_,
_,_,_,_,_,_,_,_,_,_,_,_,_,_,_,_,_,
_,_,_,_,_,_,_,_,_,_,_,_,_,_,_,_,_,
_,_,_,_,_,_,_,_,_,_,_,_,_,_,_,_,_,
_,_,_,_,_,_,_,_,_,_,_,_,_,_,_,_,_,
_,_,_,_,_,_,_,_,_,_,_,_,_,_,_,_,_,
_,_,_,_,_,_,_,T,_,_,_,_,_,_,_,_,_,
_,_,_,_,_,L,L,T,L,L,_,_,_,_,_,_,_,
_,_,_,_,_,L,L,L,L,L,_,_,_,L,L,_,_,
_,_,_,_,_,_,L,L,L,_,_,_,_,_,_,_,_,
_,L,L,L,L,L,L,L,_,_,_,_,_,_,_,_,_,
_,M,L,L,L,L,L,L,L,L,T,L,L,L,_,_,_,
_,_,_,L,L,L,_,_,L,L,L,L,L,L,_,_,_,
_,_,_,_,_,_,_,_,M,L,L,L,L,_,_,_,_,
_,_,_,_,_,L,L,L,L,L,L,L,_,_,_,_,_,
_,_,_,_,_,_,M,L,L,L,M,_,_,_,_,_,_,
_,_,_,_,_,_,_,_,M,_,_,_,_,_,_,_,_,
_,_,_,_,_,_,_,_,_,_,_,_,_,_,_,_,_,

_,_,_,_,_,_,_,_,_,_,_,_,_,_,_,_,_,
_,_,_,_,_,_,_,_,_,_,_,_,_,_,_,_,_,
_,_,_,_,_,_,_,_,_,_,_,_,_,_,_,_,_,
_,_,_,_,_,_,_,_,_,_,_,_,_,_,_,_,_,
_,_,_,_,_,_,_,_,_,_,_,_,_,_,_,_,_,
_,_,_,_,_,_,_,_,_,_,_,_,_,_,_,_,_,
_,_,_,_,_,_,_,_,_,_,_,_,_,_,_,_,_,
_,_,_,_,_,_,_,_,_,_,_,_,_,_,_,_,_,
_,_,_,_,_,_,_,_,_,_,_,_,_,_,_,_,_,
_,_,_,_,_,_,_,_,_,_,_,_,_,_,_,_,_,
_,_,_,_,_,_,_,_,_,_,_,_,_,_,_,_,_,
_,_,_,_,_,_,_,_,_,_,_,_,_,_,_,_,_,
_,_,_,_,L,L,L,T,L,L,L,_,_,_,_,_,_,
_,_,_,_,_,L,L,L,L,L,_,_,_,_,_,_,_,
_,_,_,_,_,M,L,L,L,M,_,_,_,_,_,_,_,
_,_,L,L,L,L,L,_,_,_,_,_,_,_,_,_,_,
_,_,M,L,L,L,_,_,L,L,L,L,L,L,_,_,_,
_,_,_,_,M,_,_,_,M,L,L,L,L,L,_,_,_,
_,_,_,_,_,_,_,_,_,M,L,L,L,_,_,_,_,
_,_,_,_,_,_,L,L,L,L,L,_,_,_,_,_,_,
_,_,_,_,_,_,_,_,M,_,_,_,_,_,_,_,_,
_,_,_,_,_,_,_,_,_,_,_,_,_,_,_,_,_,
_,_,_,_,_,_,_,_,_,_,_,_,_,_,_,_,_,

_,_,_,_,_,_,_,_,_,_,_,_,_,_,_,_,_,
_,_,_,_,_,_,_,_,_,_,_,_,_,_,_,_,_,
_,_,_,_,_,_,_,_,_,_,_,_,_,_,_,_,_,
_,_,_,_,_,_,_,_,_,_,_,_,_,_,_,_,_,
_,_,_,_,_,_,_,_,_,_,_,_,_,_,_,_,_,
_,_,_,_,_,_,_,_,_,_,_,_,_,_,_,_,_,
_,_,_,_,_,_,_,_,_,_,_,_,_,_,_,_,_,
_,_,_,_,_,_,_,_,_,_,_,_,_,_,_,_,_,
_,_,_,_,_,_,_,_,_,_,_,_,_,_,_,_,_,
_,_,_,_,_,_,_,_,_,_,_,_,_,_,_,_,_,
_,_,_,_,_,_,_,_,_,_,_,_,_,_,_,_,_,
_,_,_,_,_,_,_,_,_,_,_,_,_,_,_,_,_,
_,_,_,_,L,L,L,L,L,L,L,_,_,_,_,_,_,
_,_,_,_,_,L,L,L,L,L,_,_,_,_,_,_,_,
_,_,_,_,_,_,L,L,L,_,_,_,_,_,_,_,_,
_,_,_,L,L,_,_,_,_,_,_,_,_,_,_,_,_,
_,_,_,_,_,_,_,_,L,L,L,L,L,L,_,_,_,
_,_,_,_,_,_,_,_,_,L,L,L,L,M,_,_,_,
_,_,_,_,_,_,_,_,_,_,L,L,M,_,_,_,_,
_,_,_,_,_,_,_,_,_,_,_,_,_,_,_,_,_,
_,_,_,_,_,_,_,_,_,_,_,_,_,_,_,_,_,
_,_,_,_,_,_,_,_,_,_,_,_,_,_,_,_,_,
_,_,_,_,_,_,_,_,_,_,_,_,_,_,_,_,_,

_,_,_,_,_,_,_,_,_,_,_,_,_,_,_,_,_,
_,_,_,_,_,_,_,_,_,_,_,_,_,_,_,_,_,
_,_,_,_,_,_,_,_,_,_,_,_,_,_,_,_,_,
_,_,_,_,_,_,_,_,_,_,_,_,_,_,_,_,_,
_,_,_,_,_,_,_,_,_,_,_,_,_,_,_,_,_,
_,_,_,_,_,_,_,_,_,_,_,_,_,_,_,_,_,
_,_,_,_,_,_,_,_,_,_,_,_,_,_,_,_,_,
_,_,_,_,_,_,_,_,_,_,_,_,_,_,_,_,_,
_,_,_,_,_,_,_,_,_,_,_,_,_,_,_,_,_,
_,_,_,_,_,_,_,_,_,_,_,_,_,_,_,_,_,
_,_,_,_,_,_,_,_,_,_,_,_,_,_,_,_,_,
_,_,_,_,_,_,_,_,_,_,_,_,_,_,_,_,_,
_,_,_,_,_,L,L,L,L,L,_,_,_,_,_,_,_,
_,_,_,_,_,M,L,L,L,M,_,_,_,_,_,_,_,
_,_,_,_,_,_,_,L,_,_,_,_,_,_,_,_,_,
_,_,_,_,_,_,_,_,_,_,_,_,_,_,_,_,_,
_,_,_,_,_,_,_,_,_,L,L,L,L,_,_,_,_,
_,_,_,_,_,_,_,_,_,_,L,L,M,_,_,_,_,
_,_,_,_,_,_,_,_,_,_,_,_,_,_,_,_,_,
_,_,_,_,_,_,_,_,_,_,_,_,_,_,_,_,_,
_,_,_,_,_,_,_,_,_,_,_,_,_,_,_,_,_,
_,_,_,_,_,_,_,_,_,_,_,_,_,_,_,_,_,
_,_,_,_,_,_,_,_,_,_,_,_,_,_,_,_,_,

_,_,_,_,_,_,_,_,_,_,_,_,_,_,_,_,_,
_,_,_,_,_,_,_,_,_,_,_,_,_,_,_,_,_,
_,_,_,_,_,_,_,_,_,_,_,_,_,_,_,_,_,
_,_,_,_,_,_,_,_,_,_,_,_,_,_,_,_,_,
_,_,_,_,_,_,_,_,_,_,_,_,_,_,_,_,_,
_,_,_,_,_,_,_,_,_,_,_,_,_,_,_,_,_,
_,_,_,_,_,_,_,_,_,_,_,_,_,_,_,_,_,
_,_,_,_,_,_,_,_,_,_,_,_,_,_,_,_,_,
_,_,_,_,_,_,_,_,_,_,_,_,_,_,_,_,_,
_,_,_,_,_,_,_,_,_,_,_,_,_,_,_,_,_,
_,_,_,_,_,_,_,_,_,_,_,_,_,_,_,_,_,
_,_,_,_,_,_,_,_,_,_,_,_,_,_,_,_,_,
_,_,_,_,_,_,_,L,L,L,_,_,_,_,_,_,_,
_,_,_,_,_,_,_,M,L,M,_,_,_,_,_,_,_,
_,_,_,_,_,_,_,_,_,_,_,_,_,_,_,_,_,
_,_,_,_,_,_,_,_,_,_,_,_,_,_,_,_,_,
_,_,_,_,_,_,_,_,_,_,_,_,_,_,_,_,_,
_,_,_,_,_,_,_,_,_,_,_,_,_,_,_,_,_,
_,_,_,_,_,_,_,_,_,_,_,_,_,_,_,_,_,
_,_,_,_,_,_,_,_,_,_,_,_,_,_,_,_,_,
_,_,_,_,_,_,_,_,_,_,_,_,_,_,_,_,_,
_,_,_,_,_,_,_,_,_,_,_,_,_,_,_,_,_,
_,_,_,_,_,_,_,_,_,_,_,_,_,_,_,_,_,

_,_,_,_,_,_,_,_,_,_,_,_,_,_,_,_,_,
_,_,_,_,_,_,_,_,_,_,_,_,_,_,_,_,_,
_,_,_,_,_,_,_,_,_,_,_,_,_,_,_,_,_,
_,_,_,_,_,_,_,_,_,_,_,_,_,_,_,_,_,
_,_,_,_,_,_,_,_,_,_,_,_,_,_,_,_,_,
_,_,_,_,_,_,_,_,_,_,_,_,_,_,_,_,_,
_,_,_,_,_,_,_,_,_,_,_,_,_,_,_,_,_,
_,_,_,_,_,_,_,_,_,_,_,_,_,_,_,_,_,
_,_,_,_,_,_,_,_,_,_,_,_,_,_,_,_,_,
_,_,_,_,_,_,_,_,_,_,_,_,_,_,_,_,_,
_,_,_,_,_,_,_,_,_,_,_,_,_,_,_,_,_,
_,_,_,_,_,_,_,_,_,_,_,_,_,_,_,_,_,
_,_,_,_,_,_,_,_,_,_,_,_,_,_,_,_,_,
_,_,_,_,_,_,_,_,_,_,_,_,_,_,_,_,_,
_,_,_,_,_,_,_,_,_,_,_,_,_,_,_,_,_,
_,_,_,_,_,_,_,_,_,_,_,_,_,_,_,_,_,
_,_,_,_,_,_,_,_,_,_,_,_,_,_,_,_,_,
_,_,_,_,_,_,_,_,_,_,_,_,_,_,_,_,_,
_,_,_,_,_,_,_,_,_,_,_,_,_,_,_,_,_,
_,_,_,_,_,_,_,_,_,_,_,_,_,_,_,_,_,
_,_,_,_,_,_,_,_,_,_,_,_,_,_,_,_,_,
_,_,_,_,_,_,_,_,_,_,_,_,_,_,_,_,_,
_,_,_,_,_,_,_,_,_,_,_,_,_,_,_,_,_},
yslice_prob = {{ypos = 3, prob = 127}, {ypos = 4, prob = 127}, {ypos = 5, prob = 127}}}

ethereal.redwood_tree2 = {size = {x = 19, y = 37, z = 19}, data = {
_,_,_,_,_,_,_,_,_,_,_,_,_,_,_,_,_,_,_,
_,_,_,_,_,_,_,_,_,_,_,_,_,_,_,_,_,_,_,
_,_,_,_,_,_,_,_,_,_,_,_,_,_,_,_,_,_,_,
_,_,_,_,_,_,_,_,_,_,_,_,_,_,_,_,_,_,_,
_,_,_,_,_,_,_,_,_,_,_,_,_,_,_,_,_,_,_,
_,_,_,_,_,_,_,_,_,_,_,_,_,_,_,_,_,_,_,
_,_,_,_,_,_,_,_,_,_,_,_,_,_,_,_,_,_,_,
_,_,_,_,_,_,_,_,_,_,_,_,_,_,_,_,_,_,_,
_,_,_,_,_,_,_,_,_,_,_,_,_,_,_,_,_,_,_,
_,_,_,_,_,_,_,_,_,_,_,_,_,_,_,_,_,_,_,
_,_,_,_,_,_,_,_,_,_,_,_,_,_,_,_,_,_,_,
_,_,_,_,_,_,_,_,_,_,_,_,_,_,_,_,_,_,_,
_,_,_,_,_,_,_,_,_,_,_,_,_,_,_,_,_,_,_,
_,_,_,_,_,_,_,_,_,_,_,_,_,_,_,_,_,_,_,
_,_,_,_,_,_,_,_,_,_,_,_,_,_,_,_,_,_,_,
_,_,_,_,_,_,_,_,_,_,_,_,_,_,_,_,_,_,_,
_,_,_,_,_,_,_,_,_,_,_,_,_,_,_,_,_,_,_,
_,_,_,_,_,_,_,_,_,_,_,_,_,_,_,_,_,_,_,
_,_,_,_,_,_,_,_,_,_,_,_,_,_,_,_,_,_,_,
_,_,_,_,_,_,_,_,_,_,_,_,_,_,_,_,_,_,_,
_,_,_,_,_,_,_,_,_,_,_,_,_,_,_,_,_,_,_,
_,_,_,_,_,_,_,_,_,_,_,_,_,_,_,_,_,_,_,
_,_,_,_,_,_,_,_,L,L,L,_,_,_,_,_,_,_,_,
_,_,_,_,_,_,_,_,M,L,M,_,_,_,_,_,_,_,_,
_,_,_,_,_,_,_,_,_,_,_,_,_,_,_,_,_,_,_,
_,_,_,_,_,_,_,_,_,_,_,_,_,_,_,_,_,_,_,
_,_,_,_,_,_,_,_,_,_,_,_,_,_,_,_,_,_,_,
_,_,_,_,_,_,_,_,_,_,_,_,_,_,_,_,_,_,_,
_,_,_,_,_,_,_,_,_,_,_,_,_,_,_,_,_,_,_,
_,_,_,_,_,_,_,_,_,_,_,_,_,_,_,_,_,_,_,
_,_,_,_,_,_,_,_,_,_,_,_,_,_,_,_,_,_,_,
_,_,_,_,_,_,_,_,_,_,_,_,_,_,_,_,_,_,_,
_,_,_,_,_,_,_,_,_,_,_,_,_,_,_,_,_,_,_,
_,_,_,_,_,_,_,_,_,_,_,_,_,_,_,_,_,_,_,
_,_,_,_,_,_,_,_,_,_,_,_,_,_,_,_,_,_,_,
_,_,_,_,_,_,_,_,_,_,_,_,_,_,_,_,_,_,_,
_,_,_,_,_,_,_,_,_,_,_,_,_,_,_,_,_,_,_,

_,_,_,_,_,_,_,_,_,_,_,_,_,_,_,_,_,_,_,
_,_,_,_,_,_,_,_,_,_,_,_,_,_,_,_,_,_,_,
_,_,_,_,_,_,_,_,_,_,_,_,_,_,_,_,_,_,_,
_,_,_,_,_,_,_,_,_,_,_,_,_,_,_,_,_,_,_,
_,_,_,_,_,_,_,_,_,_,_,_,_,_,_,_,_,_,_,
_,_,_,_,_,_,_,_,_,_,_,_,_,_,_,_,_,_,_,
_,_,_,_,_,_,_,_,_,_,_,_,_,_,_,_,_,_,_,
_,_,_,_,_,_,_,_,_,_,_,_,_,_,_,_,_,_,_,
_,_,_,_,_,_,_,_,_,_,_,_,_,_,_,_,_,_,_,
_,_,_,_,_,_,_,_,_,_,_,_,_,_,_,_,_,_,_,
_,_,_,_,_,_,_,_,_,_,_,_,_,_,_,_,_,_,_,
_,_,_,_,_,_,_,_,_,_,_,_,_,_,_,_,_,_,_,
_,_,_,_,_,_,_,_,_,_,_,_,_,_,_,_,_,_,_,
_,_,_,_,_,_,_,_,_,_,_,_,_,_,_,_,_,_,_,
_,_,_,_,_,_,_,_,_,_,_,_,_,_,_,_,_,_,_,
_,_,_,_,_,_,_,_,_,_,_,_,_,_,_,_,_,_,_,
_,_,_,_,_,_,_,_,_,_,_,_,_,_,_,_,_,_,_,
_,_,_,_,_,_,_,_,_,_,_,_,_,_,_,_,_,_,_,
_,_,_,_,_,_,_,_,_,_,_,_,_,_,_,_,_,_,_,
_,_,_,_,_,_,_,_,_,_,_,_,_,_,_,_,_,_,_,
_,_,_,_,_,_,_,_,_,_,_,_,_,_,_,_,_,_,_,
_,_,_,_,_,_,_,_,_,_,_,_,_,_,_,_,_,_,_,
_,_,_,_,_,_,_,L,L,L,L,L,_,_,_,_,_,_,_,
_,_,_,_,_,_,_,M,L,L,L,M,_,_,_,_,_,_,_,
_,_,_,_,_,_,_,_,_,L,_,_,_,_,_,_,_,_,_,
_,_,_,_,_,_,_,_,_,_,_,_,_,_,_,_,_,_,_,
_,_,_,_,_,_,_,_,_,_,_,_,_,_,_,_,_,_,_,
_,_,_,_,_,_,_,_,_,_,_,_,_,_,_,_,_,_,_,
_,_,_,_,_,_,_,_,_,_,_,_,_,_,_,_,_,_,_,
_,_,_,_,_,_,_,_,_,_,_,_,_,_,_,_,_,_,_,
_,_,_,_,_,_,_,_,_,_,_,_,_,_,_,_,_,_,_,
_,_,_,_,_,_,_,_,_,_,_,_,_,_,_,_,_,_,_,
_,_,_,_,_,_,_,_,_,_,_,_,_,_,_,_,_,_,_,
_,_,_,_,_,_,_,_,_,_,_,_,_,_,_,_,_,_,_,
_,_,_,_,_,_,_,_,_,_,_,_,_,_,_,_,_,_,_,
_,_,_,_,_,_,_,_,_,_,_,_,_,_,_,_,_,_,_,
_,_,_,_,_,_,_,_,_,_,_,_,_,_,_,_,_,_,_,

_,_,_,_,_,_,_,_,_,_,_,_,_,_,_,_,_,_,_,
_,_,_,_,_,_,_,_,_,_,_,_,_,_,_,_,_,_,_,
_,_,_,_,_,_,_,_,_,_,_,_,_,_,_,_,_,_,_,
_,_,_,_,_,_,_,_,_,_,_,_,_,_,_,_,_,_,_,
_,_,_,_,_,_,_,_,_,_,_,_,_,_,_,_,_,_,_,
_,_,_,_,_,_,_,_,_,_,_,_,_,_,_,_,_,_,_,
_,_,_,_,_,_,_,_,_,_,_,_,_,_,_,_,_,_,_,
_,_,_,_,_,_,_,_,_,_,_,_,_,_,_,_,_,_,_,
_,_,_,_,_,_,_,_,_,_,_,_,_,_,_,_,_,_,_,
_,_,_,_,_,_,_,_,_,_,_,_,_,_,_,_,_,_,_,
_,_,_,_,_,_,_,_,_,_,_,_,_,_,_,_,_,_,_,
_,_,_,_,_,_,_,_,_,_,_,_,_,_,_,_,_,_,_,
_,_,_,_,_,_,_,_,_,_,_,_,_,_,_,_,_,_,_,
_,_,_,_,_,_,_,_,_,_,_,_,_,_,_,_,_,_,_,
_,_,_,_,_,_,_,_,_,_,_,_,_,_,_,_,_,_,_,
_,_,_,_,_,_,_,_,_,_,_,_,_,_,_,_,_,_,_,
_,_,_,_,_,_,_,_,_,_,_,_,_,_,_,_,_,_,_,
_,_,_,_,_,_,_,_,_,_,_,_,_,_,_,_,_,_,_,
_,_,_,_,_,_,_,_,_,_,_,_,_,_,_,_,_,_,_,
_,_,_,_,_,_,_,_,_,_,_,_,_,_,_,_,_,_,_,
_,_,_,_,_,_,_,_,_,_,_,_,_,_,_,_,_,_,_,
_,_,_,_,_,_,_,_,_,_,_,_,_,_,_,_,_,_,_,
_,_,_,_,_,_,L,L,L,L,L,L,L,_,_,_,_,_,_,
_,_,_,_,_,_,_,L,L,L,L,L,_,_,_,_,_,_,_,
_,_,_,_,_,_,_,_,L,L,L,_,_,_,_,_,_,_,_,
_,_,_,_,_,_,_,_,_,_,_,_,_,_,_,_,_,_,_,
_,_,_,_,_,_,_,_,_,_,_,_,_,_,_,_,_,_,_,
_,_,_,_,_,_,_,_,_,_,_,L,L,L,L,_,_,_,_,
_,_,_,_,_,_,_,_,_,_,_,_,L,L,M,_,_,_,_,
_,_,_,_,_,_,_,_,_,_,_,_,_,_,_,_,_,_,_,
_,_,_,_,_,_,_,_,_,_,_,_,_,_,_,_,_,_,_,
_,_,_,_,_,_,_,_,_,_,_,_,_,_,_,_,_,_,_,
_,_,_,_,_,_,_,_,_,_,_,_,_,_,_,_,_,_,_,
_,_,_,_,_,_,_,_,_,_,_,_,_,_,_,_,_,_,_,
_,_,_,_,_,_,_,_,_,_,_,_,_,_,_,_,_,_,_,
_,_,_,_,_,_,_,_,_,_,_,_,_,_,_,_,_,_,_,
_,_,_,_,_,_,_,_,_,_,_,_,_,_,_,_,_,_,_,

_,_,_,_,_,_,_,_,_,_,_,_,_,_,_,_,_,_,_,
_,_,_,_,_,_,_,_,_,_,_,_,_,_,_,_,_,_,_,
_,_,_,_,_,_,_,_,_,_,_,_,_,_,_,_,_,_,_,
_,_,_,_,_,_,_,_,_,_,_,_,_,_,_,_,_,_,_,
_,_,_,_,_,_,_,_,_,_,_,_,_,_,_,_,_,_,_,
_,_,_,_,_,_,_,_,_,_,_,_,_,_,_,_,_,_,_,
_,_,_,_,_,_,_,_,_,_,_,_,_,_,_,_,_,_,_,
_,_,_,_,_,_,_,_,_,_,_,_,_,_,_,_,_,_,_,
_,_,_,_,_,_,_,_,_,_,_,_,_,_,_,_,_,_,_,
_,_,_,_,_,_,_,_,_,_,_,_,_,_,_,_,_,_,_,
_,_,_,_,_,_,_,_,_,_,_,_,_,_,_,_,_,_,_,
_,_,_,_,_,_,_,_,_,_,_,_,_,_,_,_,_,_,_,
_,_,_,_,_,_,_,_,_,_,_,_,_,_,_,_,_,_,_,
_,_,_,_,_,_,_,_,_,_,_,_,_,_,_,_,_,_,_,
_,_,_,_,_,_,_,_,_,_,_,_,_,_,_,_,_,_,_,
_,_,_,_,_,_,_,_,_,_,_,_,_,_,_,_,_,_,_,
_,_,_,_,_,_,_,_,_,_,_,_,_,_,_,_,_,_,_,
_,_,_,_,_,_,_,_,_,_,_,_,_,_,_,_,_,_,_,
_,_,_,_,_,_,_,_,_,_,_,_,_,_,_,_,_,_,_,
_,_,_,_,_,_,_,_,_,_,_,_,_,_,_,_,_,_,_,
_,_,_,_,_,_,_,_,_,_,_,_,_,_,_,_,_,_,_,
_,_,_,_,_,_,_,_,_,_,_,_,_,_,_,_,_,_,_,
_,_,_,_,_,_,L,L,L,T,L,L,L,_,_,_,_,_,_,
_,_,_,_,_,_,_,L,L,L,L,L,_,_,_,_,_,_,_,
_,_,_,_,_,_,_,M,L,L,L,M,_,_,_,_,_,_,_,
_,_,_,_,_,_,_,_,_,_,_,_,_,_,_,_,_,_,_,
_,_,_,_,_,_,_,_,_,_,_,_,_,_,_,_,_,_,_,
_,_,_,_,_,_,_,_,_,_,L,L,L,L,L,L,_,_,_,
_,_,_,_,_,_,_,_,_,_,_,L,L,L,L,M,_,_,_,
_,_,_,_,_,_,_,_,_,_,_,_,L,L,M,_,_,_,_,
_,_,_,_,_,_,_,_,_,_,_,_,_,_,_,_,_,_,_,
_,_,_,_,_,_,_,_,_,_,_,_,_,_,_,_,_,_,_,
_,_,_,_,_,_,_,_,_,_,_,_,_,_,_,_,_,_,_,
_,_,_,_,_,_,_,_,_,_,_,_,_,_,_,_,_,_,_,
_,_,_,_,_,_,_,_,_,_,_,_,_,_,_,_,_,_,_,
_,_,_,_,_,_,_,_,_,_,_,_,_,_,_,_,_,_,_,
_,_,_,_,_,_,_,_,_,_,_,_,_,_,_,_,_,_,_,

_,_,_,_,_,_,_,_,_,_,_,_,_,_,_,_,_,_,_,
_,_,_,_,_,_,_,_,_,_,_,_,_,_,_,_,_,_,_,
_,_,_,_,_,_,_,_,_,_,_,_,_,_,_,_,_,_,_,
_,_,_,_,_,_,_,_,_,_,_,_,_,_,_,_,_,_,_,
_,_,_,_,_,_,_,_,_,_,_,_,_,_,_,_,_,_,_,
_,_,_,_,_,_,_,_,_,_,_,_,_,_,_,_,_,_,_,
_,_,_,_,_,_,_,_,_,_,_,_,_,_,_,_,_,_,_,
_,_,_,_,_,_,_,_,_,_,_,_,_,_,_,_,_,_,_,
_,_,_,_,_,_,_,_,_,_,_,_,_,_,_,_,_,_,_,
_,_,_,_,_,_,_,_,_,_,_,_,_,_,_,_,_,_,_,
_,_,_,_,_,_,_,_,_,_,_,_,_,_,_,_,_,_,_,
_,_,_,_,_,_,_,_,_,_,_,_,_,_,_,_,_,_,_,
_,_,_,_,_,_,_,_,_,_,_,_,_,_,_,_,_,_,_,
_,_,_,_,_,_,_,_,_,_,_,_,_,_,_,_,_,_,_,
_,_,_,_,_,_,_,_,_,_,_,_,_,_,_,_,_,_,_,
_,_,_,_,_,_,_,_,_,_,_,_,_,_,_,_,_,_,_,
_,_,_,_,_,_,_,_,_,_,_,_,_,_,_,_,_,_,_,
_,_,_,_,_,_,_,_,_,_,_,_,_,_,_,_,_,_,_,
_,_,_,_,_,_,_,_,_,_,_,_,_,_,_,_,_,_,_,
_,_,_,_,_,_,_,_,_,_,_,_,_,_,_,_,_,_,_,
_,_,_,_,_,_,_,_,_,_,_,_,_,_,_,_,_,_,_,
_,_,_,_,_,_,_,_,_,_,_,_,_,_,_,_,_,_,_,
_,_,_,_,_,_,_,L,L,T,L,L,_,_,_,_,_,_,_,
_,_,_,_,_,_,_,L,L,L,L,L,_,_,_,_,_,_,_,
_,_,_,_,_,_,_,_,L,L,L,_,_,_,_,_,_,_,_,
_,_,_,_,_,_,_,_,_,_,_,_,_,_,_,_,_,_,_,
_,_,_,_,_,_,_,_,_,_,_,_,_,_,_,_,_,_,_,
_,_,_,_,_,_,_,_,_,_,L,L,L,L,L,L,_,_,_,
_,_,_,_,_,_,_,_,_,_,M,L,L,L,L,L,_,_,_,
_,_,_,_,_,_,_,_,_,_,_,M,L,L,L,_,_,_,_,
_,_,_,_,_,L,L,L,L,_,_,_,_,_,_,_,_,_,_,
_,_,_,_,_,M,L,L,_,_,_,_,_,_,_,_,_,_,_,
_,_,_,_,_,_,_,_,_,_,_,_,_,_,_,_,_,_,_,
_,_,_,_,_,_,_,_,_,_,_,_,_,_,_,_,_,_,_,
_,_,_,_,_,_,_,_,_,_,_,_,_,_,_,_,_,_,_,
_,_,_,_,_,_,_,_,_,_,_,_,_,_,_,_,_,_,_,
_,_,_,_,_,_,_,_,_,_,_,_,_,_,_,_,_,_,_,

_,_,_,_,_,_,_,_,_,_,_,_,_,_,_,_,_,_,_,
_,_,_,_,_,_,_,_,_,_,_,_,_,_,_,_,_,_,_,
_,_,_,_,_,_,_,_,_,_,_,_,_,_,_,_,_,_,_,
_,_,_,_,_,_,_,_,_,_,_,_,_,_,_,_,_,_,_,
_,_,_,_,_,_,_,_,_,_,_,_,_,_,_,_,_,_,_,
_,_,_,_,_,_,_,_,_,_,_,_,_,_,_,_,_,_,_,
_,_,_,_,_,_,_,_,_,_,_,_,_,_,_,_,_,_,_,
_,_,_,_,_,_,_,_,_,_,_,_,_,_,_,_,_,_,_,
_,_,_,_,_,_,_,_,_,_,_,_,_,_,_,_,_,_,_,
_,_,_,_,_,_,_,_,_,_,_,_,_,_,_,_,_,_,_,
_,_,_,_,_,_,_,_,_,_,_,_,_,_,_,_,_,_,_,
_,_,_,_,_,_,_,_,_,_,_,_,_,_,_,_,_,_,_,
_,_,_,_,_,_,_,_,_,_,_,_,_,_,_,_,_,_,_,
_,_,_,_,_,_,_,_,_,_,_,_,_,_,_,_,_,_,_,
_,_,_,_,_,_,_,_,_,_,_,_,_,_,_,_,_,_,_,
_,_,_,_,_,_,_,_,_,_,_,_,_,_,_,_,_,_,_,
_,_,_,_,_,_,_,_,_,_,_,_,_,_,_,_,_,_,_,
_,_,_,_,_,_,_,_,_,_,_,_,_,_,_,_,_,_,_,
_,_,_,_,_,_,_,_,_,_,_,_,_,_,_,L,L,_,_,
_,_,_,_,_,_,_,_,_,_,_,_,_,_,_,_,_,_,_,
_,_,_,_,_,_,_,_,_,_,_,_,_,_,_,_,_,_,_,
_,_,_,_,_,_,_,_,_,T,_,_,_,_,_,_,_,_,_,
_,_,_,_,_,_,_,L,L,T,L,L,_,_,_,_,_,_,_,
_,_,_,_,_,_,_,_,L,L,L,_,_,_,_,_,_,_,_,
_,_,L,L,_,_,_,_,_,L,_,_,_,_,_,_,_,_,_,
_,_,_,_,_,_,_,_,_,_,_,_,_,_,_,_,_,_,_,
_,_,_,_,_,_,_,_,_,_,_,_,_,_,_,_,_,_,_,
_,_,_,_,_,_,_,_,_,L,L,L,T,L,L,L,_,_,_,
_,_,_,_,_,_,_,_,_,_,L,L,L,L,L,L,_,_,_,
_,_,_,_,_,_,_,_,_,_,_,L,L,L,L,_,_,_,_,
_,_,_,_,L,L,L,L,L,L,_,_,_,_,_,_,_,_,_,
_,_,_,_,M,L,L,L,L,_,_,_,_,_,_,_,_,_,_,
_,_,_,_,_,M,L,L,_,_,_,_,_,_,_,_,_,_,_,
_,_,_,_,_,_,_,L,L,L,L,L,_,_,_,_,_,_,_,
_,_,_,_,_,_,_,_,_,M,_,_,_,_,_,_,_,_,_,
_,_,_,_,_,_,_,_,_,_,_,_,_,_,_,_,_,_,_,
_,_,_,_,_,_,_,_,_,_,_,_,_,_,_,_,_,_,_,

_,_,_,_,_,_,_,_,_,_,_,_,_,_,_,_,_,_,_,
_,_,_,_,_,_,_,_,_,_,_,_,_,_,_,_,_,_,_,
_,_,_,_,_,_,_,_,_,T,_,_,_,_,_,_,_,_,_,
_,_,_,_,_,_,_,_,_,T,T,_,_,_,_,_,_,_,_,
_,_,_,_,_,_,_,T,T,T,T,T,_,_,_,_,_,_,_,
_,_,_,_,_,_,_,_,T,T,_,_,_,_,_,_,_,_,_,
_,_,_,_,_,_,_,_,_,_,_,_,_,_,_,_,_,_,_,
_,_,_,_,_,_,_,_,_,_,_,_,_,_,_,_,_,_,_,
_,_,_,_,_,_,_,_,_,_,_,_,_,_,_,_,_,_,_,
_,_,_,_,_,_,_,_,_,_,_,_,_,_,_,_,_,_,_,
_,_,_,_,_,_,_,_,_,_,_,_,_,_,_,_,_,_,_,
_,_,_,_,_,_,_,_,_,_,_,_,_,_,_,_,_,_,_,
_,_,_,_,_,_,_,_,_,_,_,_,_,_,_,_,_,_,_,
_,_,_,_,_,_,_,_,_,_,_,_,_,_,_,_,_,_,_,
_,_,_,_,_,_,_,_,_,_,_,_,_,_,_,_,_,_,_,
_,_,_,_,_,_,_,_,_,_,_,_,_,_,_,_,_,_,_,
_,_,_,_,_,_,_,_,_,_,_,_,_,_,_,_,_,_,_,
_,_,_,_,_,_,_,_,_,_,_,_,_,_,_,_,_,_,_,
_,_,_,_,_,_,_,_,_,_,_,_,_,L,L,L,L,L,_,
_,_,_,_,_,_,_,_,_,_,_,_,_,_,L,L,L,M,_,
_,_,_,_,_,_,_,_,_,_,_,_,_,_,_,M,_,_,_,
_,_,_,_,_,_,_,_,_,T,_,_,_,_,_,_,_,_,_,
_,_,_,_,_,_,_,_,L,L,L,_,_,_,_,_,_,_,_,
_,_,_,_,_,_,_,_,_,L,_,_,_,_,_,_,_,_,_,
_,L,L,L,L,L,_,_,_,_,_,_,_,_,_,_,_,_,_,
_,M,L,L,L,_,_,_,_,_,_,_,_,_,_,_,_,_,_,
_,_,_,M,_,_,_,_,_,_,_,T,_,_,_,_,_,_,_,
_,_,_,_,_,_,_,_,_,L,L,T,L,L,L,L,_,_,_,
_,_,_,_,_,_,_,_,_,_,L,L,L,L,L,_,_,_,_,
_,_,_,_,_,_,_,_,_,_,_,L,L,M,_,_,_,_,_,
_,_,_,_,L,L,L,L,L,L,_,_,_,_,_,_,_,_,_,
_,_,_,_,L,L,L,L,L,M,_,_,_,_,_,_,_,_,_,
_,_,_,_,_,L,L,L,M,M,_,_,_,_,_,_,_,_,_,
_,_,_,_,_,_,L,L,L,L,L,L,L,_,_,_,_,_,_,
_,_,_,_,_,_,_,M,L,L,L,M,_,_,_,_,_,_,_,
_,_,_,_,_,_,_,_,_,M,_,_,_,_,_,_,_,_,_,
_,_,_,_,_,_,_,_,_,_,_,_,_,_,_,_,_,_,_,

_,_,_,_,_,_,_,_,_,_,_,_,_,_,_,_,_,_,_,
_,_,_,_,_,_,_,_,_,T,_,_,_,_,_,_,_,_,_,
_,_,_,_,_,_,_,T,_,_,_,_,_,_,_,_,_,_,_,
_,_,_,_,_,_,_,T,_,_,_,_,_,_,_,_,_,_,_,
_,_,_,_,_,_,_,T,T,T,T,T,_,_,_,_,_,_,_,
_,_,_,_,_,_,_,T,T,T,T,T,_,_,_,_,_,_,_,
_,_,_,_,_,_,_,_,T,T,T,_,_,_,_,_,_,_,_,
_,_,_,_,_,_,_,_,T,T,T,_,_,_,_,_,_,_,_,
_,_,_,_,_,_,_,_,T,T,T,_,_,_,_,_,_,_,_,
_,_,_,_,_,_,_,_,T,T,T,_,_,_,_,_,_,_,_,
_,_,_,_,_,_,_,_,T,T,T,_,_,_,_,_,_,_,_,
_,_,_,_,_,_,_,_,T,T,T,_,_,_,_,_,_,_,_,
_,_,_,_,_,_,_,_,T,T,_,_,_,_,_,_,_,_,_,
_,_,_,_,_,_,_,_,T,T,_,_,_,_,_,_,_,_,_,
_,_,_,_,_,_,_,_,_,T,_,_,_,_,_,_,_,_,_,
_,_,_,_,_,_,_,_,_,T,_,_,_,_,_,_,_,_,_,
_,_,_,_,_,_,_,_,_,T,_,_,_,_,_,_,_,_,_,
_,_,_,_,_,_,_,_,_,T,_,_,_,_,_,_,_,_,_,
_,_,_,_,_,_,_,_,_,_,_,_,L,L,L,L,L,L,L,
_,_,_,_,_,_,_,_,_,_,_,_,_,L,L,L,L,L,M,
_,_,_,_,_,_,_,_,_,_,_,_,_,_,L,L,L,_,_,
_,_,_,_,_,_,_,_,_,T,_,_,_,_,_,_,_,_,_,
_,_,_,_,_,_,_,_,_,_,_,_,_,_,_,_,_,_,_,
_,_,_,_,_,_,_,_,_,_,_,_,_,_,_,_,_,_,_,
L,L,L,L,L,L,L,_,_,_,_,_,_,_,_,_,_,_,_,
M,L,L,L,L,L,_,_,_,_,_,_,_,_,_,_,_,_,_,
_,_,L,L,L,_,_,_,_,_,T,T,_,_,_,_,_,_,_,
_,_,_,_,_,_,_,_,_,L,L,L,L,L,L,L,L,_,_,
_,_,_,_,_,_,_,_,_,_,L,L,L,M,_,_,_,_,_,
_,_,_,_,_,_,_,_,_,_,_,_,_,_,_,_,_,_,_,
_,_,_,_,L,L,L,T,L,L,L,_,_,_,_,_,_,_,_,
_,_,_,_,L,L,L,L,L,L,_,_,_,_,_,_,_,_,_,
_,_,_,_,_,L,L,L,L,L,L,M,_,_,_,_,_,_,_,
_,_,_,_,_,L,L,L,L,L,L,L,L,L,_,_,_,_,_,
_,_,_,_,_,_,M,L,L,L,L,L,M,_,_,_,_,_,_,
_,_,_,_,_,_,_,M,L,L,L,M,_,_,_,_,_,_,_,
_,_,_,_,_,_,_,_,_,_,_,_,_,_,_,_,_,_,_,

_,_,_,_,_,_,_,_,_,_,_,T,_,_,_,_,_,_,_,
_,_,_,_,_,_,_,_,_,_,_,T,_,_,_,_,_,_,_,
_,_,_,_,_,_,_,_,_,_,_,_,_,_,_,_,_,_,_,
_,_,_,_,_,_,_,_,_,_,_,_,_,_,_,_,_,_,_,
_,_,_,_,_,_,T,T,T,T,T,T,T,_,_,_,_,_,_,
_,_,_,_,_,_,T,T,T,T,T,T,_,_,_,_,_,_,_,
_,_,_,_,_,_,_,T,T,T,T,T,_,_,_,_,_,_,_,
_,_,_,_,_,_,_,T,T,T,T,T,_,_,_,_,_,_,_,
_,_,_,_,_,_,_,T,T,T,T,T,_,_,_,_,_,_,_,
_,_,_,_,_,_,_,T,T,T,T,T,_,_,_,_,_,_,_,
_,_,_,_,_,_,_,T,T,T,T,T,_,_,_,_,_,_,_,
_,_,_,_,_,_,_,T,T,T,T,_,_,_,_,_,_,_,_,
_,_,_,_,_,_,_,T,T,T,T,_,_,_,_,_,_,_,_,
_,_,_,_,_,_,_,_,T,T,T,_,_,_,_,_,_,_,_,
_,_,_,_,_,_,_,_,T,T,T,_,_,_,_,_,_,_,_,
_,_,_,_,_,_,_,_,T,T,T,_,_,_,_,_,_,_,_,
_,_,_,_,_,_,_,_,T,T,T,_,_,_,_,_,_,_,_,
_,_,_,_,_,_,_,_,T,T,T,_,_,T,T,_,_,_,_,
_,_,_,_,_,_,_,_,T,T,T,_,L,L,T,T,L,L,L,
_,_,_,_,_,_,_,_,T,T,T,_,L,L,L,L,L,L,L,
_,_,_,_,_,_,_,_,T,T,T,_,_,L,L,L,L,L,_,
_,_,_,_,_,_,_,_,T,T,T,_,_,_,_,_,_,_,_,
_,_,_,_,_,_,_,_,T,T,T,_,_,_,_,_,_,_,_,
_,_,_,_,_,T,_,_,T,T,T,_,_,_,_,_,_,_,_,
L,L,L,T,T,T,L,_,T,T,T,_,_,_,_,_,_,_,_,
L,L,L,L,L,L,L,_,T,T,T,_,_,_,_,_,_,_,_,
_,L,L,L,L,L,_,_,T,T,T,_,_,_,_,_,_,_,_,
_,_,_,_,_,_,_,_,_,T,L,L,L,L,L,L,L,L,_,
_,_,_,_,_,_,_,_,_,T,_,_,_,_,L,L,L,M,_,
_,_,_,_,_,_,_,_,T,T,_,_,_,_,_,M,_,_,_,
_,_,_,_,L,L,L,L,L,T,L,_,_,_,_,_,_,_,_,
_,_,_,_,_,L,L,L,L,T,_,_,_,_,_,_,_,_,_,
_,_,_,_,_,_,M,L,L,T,L,L,_,_,_,_,_,_,_,
_,_,_,_,_,L,L,L,L,L,L,L,L,L,_,_,_,_,_,
_,_,_,_,_,_,L,L,L,L,L,L,L,_,_,_,_,_,_,
_,_,_,_,_,_,_,L,L,L,L,L,_,_,_,_,_,_,_,
_,_,_,_,_,_,_,_,M,L,M,_,_,_,_,_,_,_,_,

_,_,_,_,_,_,_,T,_,_,_,_,_,_,_,_,_,_,_,
_,_,_,_,_,_,_,T,_,_,_,_,T,_,_,_,_,_,_,
_,_,_,_,_,_,T,T,_,_,_,_,T,_,_,_,_,_,_,
_,_,_,_,_,_,T,_,_,_,_,_,T,_,_,_,_,_,_,
_,_,_,_,_,_,T,T,T,T,T,T,T,_,_,_,_,_,_,
_,_,_,_,_,_,T,T,T,T,T,T,T,_,_,_,_,_,_,
_,_,_,_,_,_,T,T,T,T,T,T,T,_,_,_,_,_,_,
_,_,_,_,_,_,T,T,T,T,T,T,_,_,_,_,_,_,_,
_,_,_,_,_,_,_,T,T,T,T,T,_,_,_,_,_,_,_,
_,_,_,_,_,_,_,T,T,T,T,T,_,_,_,_,_,_,_,
_,_,_,_,_,_,_,T,T,T,T,T,_,_,_,_,_,_,_,
_,_,_,_,_,_,_,T,T,T,T,T,_,_,_,_,_,_,_,
_,_,_,_,_,_,_,T,T,T,T,T,_,_,_,_,_,_,_,
_,_,_,_,_,_,_,T,T,T,T,T,_,_,_,_,_,_,_,
_,_,_,_,_,_,_,T,T,T,T,T,_,_,_,_,_,_,_,
_,_,_,_,_,_,_,T,T,T,T,T,_,_,_,_,_,_,_,
_,_,_,_,_,_,_,T,T,T,T,T,_,_,_,_,_,_,_,
_,_,_,_,_,_,_,T,T,T,T,T,T,T,_,_,_,_,_,
_,_,_,_,_,_,_,T,T,T,T,_,L,L,L,L,L,L,L,
_,_,_,_,_,_,_,T,T,T,T,_,_,L,L,L,L,L,M,
_,_,_,_,_,_,_,_,T,T,T,_,_,_,L,L,L,_,_,
_,_,_,_,_,_,_,_,T,T,T,_,_,_,_,_,_,_,_,
_,_,_,_,_,_,_,_,T,T,T,_,_,_,_,_,_,_,_,
_,_,_,_,_,T,T,T,T,T,T,_,_,_,_,_,_,_,_,
L,L,L,L,L,L,L,_,T,T,T,_,_,_,_,_,_,_,_,
M,L,L,L,L,L,_,_,T,T,T,_,_,_,_,_,_,_,_,
_,_,L,L,L,_,_,_,T,T,T,T,T,T,_,_,_,_,_,
_,_,_,_,_,_,_,_,T,T,T,_,L,L,L,L,L,L,L,
_,_,_,_,_,_,_,_,T,T,T,_,_,L,L,L,L,L,M,
_,_,_,_,_,L,L,L,T,T,T,_,_,_,L,L,L,_,_,
_,_,_,_,_,L,L,L,T,T,T,L,_,_,_,_,_,_,_,
_,_,_,_,_,_,M,L,T,T,T,_,_,_,_,_,_,_,_,
_,_,_,_,_,_,M,L,T,T,T,L,M,_,_,_,_,_,_,
_,_,_,_,_,L,L,L,L,T,L,L,L,L,_,_,_,_,_,
_,_,_,_,_,M,L,L,L,L,L,L,L,M,_,_,_,_,_,
_,_,_,_,_,_,M,L,L,L,L,L,M,_,_,_,_,_,_,
_,_,_,_,_,_,_,_,L,L,L,_,_,_,_,_,_,_,_,

_,_,_,_,_,_,_,_,_,_,_,_,_,_,_,_,_,_,_,
_,_,_,_,_,_,_,_,_,_,T,_,_,_,_,_,_,_,_,
_,_,_,_,_,_,_,_,_,_,T,_,_,_,_,_,_,_,_,
_,_,_,_,_,_,T,_,_,_,_,_,_,_,_,_,_,_,_,
_,_,_,_,_,_,T,T,T,T,T,T,T,_,_,_,_,_,_,
_,_,_,_,_,_,T,T,T,T,T,T,T,_,_,_,_,_,_,
_,_,_,_,_,_,_,T,T,T,T,T,T,_,_,_,_,_,_,
_,_,_,_,_,_,_,T,T,T,T,T,_,_,_,_,_,_,_,
_,_,_,_,_,_,_,T,T,T,T,T,_,_,_,_,_,_,_,
_,_,_,_,_,_,_,T,T,T,T,T,_,_,_,_,_,_,_,
_,_,_,_,_,_,_,T,T,T,T,T,_,_,_,_,_,_,_,
_,_,_,_,_,_,_,T,T,T,T,T,_,_,_,_,_,_,_,
_,_,_,_,_,_,_,T,T,T,T,T,_,_,_,_,_,_,_,
_,_,_,_,_,_,_,_,T,T,T,_,_,_,_,_,_,_,_,
_,_,_,_,_,_,_,_,T,T,T,_,_,_,_,_,_,_,_,
_,_,_,_,_,_,_,_,T,T,T,_,_,_,_,_,_,_,_,
_,_,_,_,_,_,_,_,T,T,T,_,_,_,_,_,_,_,_,
_,_,_,_,_,_,_,_,T,T,T,_,_,_,_,_,_,_,_,
_,_,_,_,_,_,_,_,T,T,T,_,_,L,L,L,L,L,_,
_,_,_,_,_,_,_,_,T,T,T,_,_,_,L,L,L,M,_,
_,_,_,_,_,_,_,_,T,T,T,_,_,_,_,M,_,_,_,
_,_,_,_,_,_,_,_,T,T,T,_,_,_,_,_,_,_,_,
_,_,_,_,_,_,_,_,T,T,T,_,_,_,_,_,_,_,_,
_,_,_,_,_,_,_,_,T,T,T,_,_,_,_,_,_,_,_,
_,L,L,L,L,L,_,_,T,T,T,_,_,_,_,_,_,_,_,
_,M,L,L,L,_,_,_,T,T,T,_,_,_,_,_,_,_,_,
_,_,_,M,_,_,_,_,T,T,T,_,_,T,_,_,_,_,_,
_,_,_,_,_,_,_,_,T,T,_,_,L,T,T,T,L,L,L,
_,_,_,_,_,_,T,T,T,T,_,_,L,L,L,L,L,L,L,
_,_,_,L,L,L,L,L,L,T,T,_,_,L,L,L,L,L,_,
_,_,_,_,M,L,L,L,L,T,L,L,L,L,_,_,_,_,_,
_,_,_,_,_,_,_,_,_,T,L,L,M,_,_,_,_,_,_,
_,_,_,_,_,_,_,L,L,T,L,L,_,_,_,_,_,_,_,
_,_,_,_,_,L,L,L,L,L,L,L,L,L,_,_,_,_,_,
_,_,_,_,_,_,L,L,L,L,L,L,L,_,_,_,_,_,_,
_,_,_,_,_,_,_,L,L,L,L,L,_,_,_,_,_,_,_,
_,_,_,_,_,_,_,_,M,L,M,_,_,_,_,_,_,_,_,

_,_,_,_,_,_,_,_,T,_,_,_,_,_,_,_,_,_,_,
_,_,_,_,_,_,_,_,T,_,_,_,_,_,_,_,_,_,_,
_,_,_,_,_,_,_,_,T,_,_,T,_,_,_,_,_,_,_,
_,_,_,_,_,_,_,_,_,_,_,T,_,_,_,_,_,_,_,
_,_,_,_,_,_,_,T,T,T,T,T,_,_,_,_,_,_,_,
_,_,_,_,_,_,_,T,T,T,T,T,_,_,_,_,_,_,_,
_,_,_,_,_,_,_,T,T,T,T,T,_,_,_,_,_,_,_,
_,_,_,_,_,_,_,T,T,T,T,_,_,_,_,_,_,_,_,
_,_,_,_,_,_,_,_,T,T,T,_,_,_,_,_,_,_,_,
_,_,_,_,_,_,_,_,T,T,T,_,_,_,_,_,_,_,_,
_,_,_,_,_,_,_,_,T,T,_,_,_,_,_,_,_,_,_,
_,_,_,_,_,_,_,_,T,T,_,_,_,_,_,_,_,_,_,
_,_,_,_,_,_,_,_,T,T,_,_,_,_,_,_,_,_,_,
_,_,_,_,_,_,_,_,_,T,_,_,_,_,_,_,_,_,_,
_,_,_,_,_,_,_,_,_,T,_,_,_,_,_,_,_,_,_,
_,_,_,_,_,_,_,_,_,T,_,_,_,_,_,_,_,_,_,
_,_,_,_,_,_,_,_,_,_,_,_,_,_,_,_,_,_,_,
_,_,_,_,_,_,_,_,_,_,_,_,_,_,_,_,_,_,_,
_,_,_,_,_,_,_,_,_,_,_,_,_,_,_,L,L,_,_,
_,_,_,_,_,_,_,_,_,_,_,_,_,_,_,_,_,_,_,
_,_,_,_,_,_,_,_,_,_,_,_,_,_,_,_,_,_,_,
_,_,_,_,_,_,_,_,_,_,_,T,_,_,_,_,_,_,_,
_,_,_,_,_,_,_,_,_,_,_,L,L,L,_,_,_,_,_,
_,_,_,_,_,_,_,_,_,_,_,_,_,_,_,_,_,_,_,
_,_,L,L,_,_,_,_,_,_,_,_,_,_,_,_,_,_,_,
_,_,_,_,_,_,_,_,T,_,_,_,_,_,_,_,_,_,_,
_,_,_,_,_,_,_,_,_,_,_,_,_,_,_,_,_,_,_,
_,_,_,_,_,_,_,_,_,_,_,_,L,L,L,L,L,L,L,
_,_,_,_,_,_,T,_,_,_,_,_,_,L,L,L,L,L,M,
_,_,L,L,L,L,T,L,L,_,T,_,_,_,L,L,L,_,_,
_,_,_,L,L,L,L,L,L,L,L,L,L,L,L,_,_,_,_,
_,_,_,_,M,L,L,_,_,L,L,L,L,L,_,_,_,_,_,
_,_,_,_,_,_,_,M,L,L,L,L,M,_,_,_,_,_,_,
_,_,_,_,_,L,L,L,L,L,L,L,L,L,_,_,_,_,_,
_,_,_,_,_,_,M,L,L,L,L,L,M,_,_,_,_,_,_,
_,_,_,_,_,_,_,M,L,L,L,M,_,_,_,_,_,_,_,
_,_,_,_,_,_,_,_,_,_,_,_,_,_,_,_,_,_,_,

_,_,_,_,_,_,_,_,_,_,_,_,_,_,_,_,_,_,_,
_,_,_,_,_,_,_,_,_,_,_,_,_,_,_,_,_,_,_,
_,_,_,_,_,_,_,T,T,_,T,_,_,_,_,_,_,_,_,
_,_,_,_,_,_,_,T,_,_,T,_,_,_,_,_,_,_,_,
_,_,_,_,_,_,_,T,T,T,T,T,_,_,_,_,_,_,_,
_,_,_,_,_,_,_,_,T,T,T,_,_,_,_,_,_,_,_,
_,_,_,_,_,_,_,_,_,T,_,_,_,_,_,_,_,_,_,
_,_,_,_,_,_,_,_,_,_,_,_,_,_,_,_,_,_,_,
_,_,_,_,_,_,_,_,_,_,_,_,_,_,_,_,_,_,_,
_,_,_,_,_,_,_,_,_,_,_,_,_,_,_,_,_,_,_,
_,_,_,_,_,_,_,_,_,_,_,_,_,_,_,_,_,_,_,
_,_,_,_,_,_,_,_,_,_,_,_,_,_,_,_,_,_,_,
_,_,_,_,_,_,_,_,_,_,_,_,_,_,_,_,_,_,_,
_,_,_,_,_,_,_,_,_,_,_,_,_,_,_,_,_,_,_,
_,_,_,_,_,_,_,_,_,_,_,_,_,_,_,_,_,_,_,
_,_,_,_,_,_,_,_,_,_,_,_,_,_,_,_,_,_,_,
_,_,_,_,_,_,_,_,_,_,_,_,_,_,_,_,_,_,_,
_,_,_,_,_,_,_,_,_,_,_,_,_,_,_,_,_,_,_,
_,_,_,_,_,_,_,_,_,_,_,_,_,_,_,_,_,_,_,
_,_,_,_,_,_,_,_,_,_,_,_,_,_,_,_,_,_,_,
_,_,_,_,_,_,_,_,_,_,_,_,_,_,_,_,_,_,_,
_,_,_,_,_,_,_,_,_,_,_,_,T,_,_,_,_,_,_,
_,_,_,_,_,_,_,_,_,_,L,L,L,L,L,L,_,_,_,
_,_,_,_,_,_,_,_,_,_,_,L,L,L,M,_,_,_,_,
_,_,_,_,_,_,_,_,_,_,_,_,_,_,_,_,_,_,_,
_,_,_,_,_,_,_,_,T,_,_,_,_,_,_,_,_,_,_,
_,_,_,_,_,_,_,L,L,L,_,_,_,_,_,_,_,_,_,
_,_,_,_,_,_,_,_,L,_,_,_,_,L,L,L,L,L,_,
_,_,_,_,_,_,_,_,_,_,_,_,_,_,L,L,L,M,_,
_,_,L,L,L,T,L,L,L,_,_,_,_,_,_,M,_,_,_,
_,_,L,L,L,L,L,L,L,L,L,T,L,L,L,_,_,_,_,
_,_,_,L,L,L,L,_,_,L,L,L,L,L,L,_,_,_,_,
_,_,_,_,_,_,_,_,_,M,L,L,L,L,_,_,_,_,_,
_,_,_,_,_,_,L,L,L,L,L,L,L,_,_,_,_,_,_,
_,_,_,_,_,_,_,M,L,L,L,M,_,_,_,_,_,_,_,
_,_,_,_,_,_,_,_,_,M,_,_,_,_,_,_,_,_,_,
_,_,_,_,_,_,_,_,_,_,_,_,_,_,_,_,_,_,_,

_,_,_,_,_,_,_,_,_,_,_,_,_,_,_,_,_,_,_,
_,_,_,_,_,_,_,_,_,_,_,_,_,_,_,_,_,_,_,
_,_,_,_,_,_,_,_,_,_,_,_,_,_,_,_,_,_,_,
_,_,_,_,_,_,_,_,_,_,_,_,_,_,_,_,_,_,_,
_,_,_,_,_,_,_,_,_,_,_,_,_,_,_,_,_,_,_,
_,_,_,_,_,_,_,_,_,_,_,_,_,_,_,_,_,_,_,
_,_,_,_,_,_,_,_,_,_,_,_,_,_,_,_,_,_,_,
_,_,_,_,_,_,_,_,_,_,_,_,_,_,_,_,_,_,_,
_,_,_,_,_,_,_,_,_,_,_,_,_,_,_,_,_,_,_,
_,_,_,_,_,_,_,_,_,_,_,_,_,_,_,_,_,_,_,
_,_,_,_,_,_,_,_,_,_,_,_,_,_,_,_,_,_,_,
_,_,_,_,_,_,_,_,_,_,_,_,_,_,_,_,_,_,_,
_,_,_,_,_,_,_,_,_,_,_,_,_,_,_,_,_,_,_,
_,_,_,_,_,_,_,_,_,_,_,_,_,_,_,_,_,_,_,
_,_,_,_,_,_,_,_,_,_,_,_,_,_,_,_,_,_,_,
_,_,_,_,_,_,_,_,_,_,_,_,_,_,_,_,_,_,_,
_,_,_,_,_,_,_,_,_,_,_,_,_,_,_,_,_,_,_,
_,_,_,_,_,_,_,_,_,_,_,_,_,_,_,_,_,_,_,
_,_,_,_,_,_,_,_,_,_,_,_,_,_,_,_,_,_,_,
_,_,_,_,_,_,_,_,_,_,_,_,_,_,_,_,_,_,_,
_,_,_,_,_,_,_,_,_,_,_,_,_,_,_,_,_,_,_,
_,_,_,_,_,_,_,_,_,_,_,_,_,_,_,_,_,_,_,
_,_,_,_,_,_,_,_,_,_,L,L,T,L,L,L,L,_,_,
_,_,_,_,_,_,_,_,_,_,_,L,L,L,L,L,_,_,_,
_,_,_,_,_,_,_,_,_,_,_,_,L,L,M,_,_,_,_,
_,_,_,_,_,_,_,_,T,_,_,_,_,_,_,_,_,_,_,
_,_,_,_,_,_,L,L,L,L,L,_,_,_,_,_,_,_,_,
_,_,_,_,_,_,_,L,L,L,_,_,_,_,_,L,L,_,_,
_,_,_,_,_,_,_,_,L,_,_,_,_,_,_,_,_,_,_,
_,_,L,L,L,L,L,L,_,_,_,_,_,_,_,_,_,_,_,
_,_,L,L,L,L,L,M,_,L,L,L,L,L,L,_,_,_,_,
_,_,_,L,L,L,M,_,_,M,L,L,L,L,L,_,_,_,_,
_,_,_,_,_,_,_,_,_,_,M,L,L,L,_,_,_,_,_,
_,_,_,_,_,_,_,L,L,L,L,L,_,_,_,_,_,_,_,
_,_,_,_,_,_,_,_,_,M,_,_,_,_,_,_,_,_,_,
_,_,_,_,_,_,_,_,_,_,_,_,_,_,_,_,_,_,_,
_,_,_,_,_,_,_,_,_,_,_,_,_,_,_,_,_,_,_,

_,_,_,_,_,_,_,_,_,_,_,_,_,_,_,_,_,_,_,
_,_,_,_,_,_,_,_,_,_,_,_,_,_,_,_,_,_,_,
_,_,_,_,_,_,_,_,_,_,_,_,_,_,_,_,_,_,_,
_,_,_,_,_,_,_,_,_,_,_,_,_,_,_,_,_,_,_,
_,_,_,_,_,_,_,_,_,_,_,_,_,_,_,_,_,_,_,
_,_,_,_,_,_,_,_,_,_,_,_,_,_,_,_,_,_,_,
_,_,_,_,_,_,_,_,_,_,_,_,_,_,_,_,_,_,_,
_,_,_,_,_,_,_,_,_,_,_,_,_,_,_,_,_,_,_,
_,_,_,_,_,_,_,_,_,_,_,_,_,_,_,_,_,_,_,
_,_,_,_,_,_,_,_,_,_,_,_,_,_,_,_,_,_,_,
_,_,_,_,_,_,_,_,_,_,_,_,_,_,_,_,_,_,_,
_,_,_,_,_,_,_,_,_,_,_,_,_,_,_,_,_,_,_,
_,_,_,_,_,_,_,_,_,_,_,_,_,_,_,_,_,_,_,
_,_,_,_,_,_,_,_,_,_,_,_,_,_,_,_,_,_,_,
_,_,_,_,_,_,_,_,_,_,_,_,_,_,_,_,_,_,_,
_,_,_,_,_,_,_,_,_,_,_,_,_,_,_,_,_,_,_,
_,_,_,_,_,_,_,_,_,_,_,_,_,_,_,_,_,_,_,
_,_,_,_,_,_,_,_,_,_,_,_,_,_,_,_,_,_,_,
_,_,_,_,_,_,_,_,_,_,_,_,_,_,_,_,_,_,_,
_,_,_,_,_,_,_,_,_,_,_,_,_,_,_,_,_,_,_,
_,_,_,_,_,_,_,_,_,_,_,_,_,_,_,_,_,_,_,
_,_,_,_,_,_,_,_,_,_,_,_,_,_,_,_,_,_,_,
_,_,_,_,_,_,_,_,_,_,L,L,L,T,L,L,L,_,_,
_,_,_,_,_,_,_,_,_,_,_,L,L,L,L,L,L,_,_,
_,_,_,_,_,_,_,_,_,_,_,_,L,L,L,L,_,_,_,
_,_,_,_,_,_,_,_,T,_,_,_,_,_,_,_,_,_,_,
_,_,_,_,_,_,L,L,T,L,L,_,_,_,_,_,_,_,_,
_,_,_,_,_,_,L,L,L,L,L,_,_,_,_,_,_,_,_,
_,_,_,_,_,_,_,L,L,L,_,_,_,_,_,_,_,_,_,
_,_,L,L,L,L,L,L,_,_,_,_,_,_,_,_,_,_,_,
_,_,M,L,L,L,L,_,_,L,L,L,L,L,L,_,_,_,_,
_,_,_,M,L,L,_,_,_,_,L,L,L,L,M,_,_,_,_,
_,_,_,_,_,_,_,_,_,_,_,L,L,M,_,_,_,_,_,
_,_,_,_,_,_,_,_,_,_,_,_,_,_,_,_,_,_,_,
_,_,_,_,_,_,_,_,_,_,_,_,_,_,_,_,_,_,_,
_,_,_,_,_,_,_,_,_,_,_,_,_,_,_,_,_,_,_,
_,_,_,_,_,_,_,_,_,_,_,_,_,_,_,_,_,_,_,

_,_,_,_,_,_,_,_,_,_,_,_,_,_,_,_,_,_,_,
_,_,_,_,_,_,_,_,_,_,_,_,_,_,_,_,_,_,_,
_,_,_,_,_,_,_,_,_,_,_,_,_,_,_,_,_,_,_,
_,_,_,_,_,_,_,_,_,_,_,_,_,_,_,_,_,_,_,
_,_,_,_,_,_,_,_,_,_,_,_,_,_,_,_,_,_,_,
_,_,_,_,_,_,_,_,_,_,_,_,_,_,_,_,_,_,_,
_,_,_,_,_,_,_,_,_,_,_,_,_,_,_,_,_,_,_,
_,_,_,_,_,_,_,_,_,_,_,_,_,_,_,_,_,_,_,
_,_,_,_,_,_,_,_,_,_,_,_,_,_,_,_,_,_,_,
_,_,_,_,_,_,_,_,_,_,_,_,_,_,_,_,_,_,_,
_,_,_,_,_,_,_,_,_,_,_,_,_,_,_,_,_,_,_,
_,_,_,_,_,_,_,_,_,_,_,_,_,_,_,_,_,_,_,
_,_,_,_,_,_,_,_,_,_,_,_,_,_,_,_,_,_,_,
_,_,_,_,_,_,_,_,_,_,_,_,_,_,_,_,_,_,_,
_,_,_,_,_,_,_,_,_,_,_,_,_,_,_,_,_,_,_,
_,_,_,_,_,_,_,_,_,_,_,_,_,_,_,_,_,_,_,
_,_,_,_,_,_,_,_,_,_,_,_,_,_,_,_,_,_,_,
_,_,_,_,_,_,_,_,_,_,_,_,_,_,_,_,_,_,_,
_,_,_,_,_,_,_,_,_,_,_,_,_,_,_,_,_,_,_,
_,_,_,_,_,_,_,_,_,_,_,_,_,_,_,_,_,_,_,
_,_,_,_,_,_,_,_,_,_,_,_,_,_,_,_,_,_,_,
_,_,_,_,_,_,_,_,_,_,_,_,_,_,_,_,_,_,_,
_,_,_,_,_,_,_,_,_,_,_,L,L,L,L,L,L,_,_,
_,_,_,_,_,_,_,_,_,_,_,M,L,L,L,L,L,_,_,
_,_,_,_,_,_,_,_,_,_,_,_,M,L,L,L,_,_,_,
_,_,_,_,_,_,_,_,_,_,_,_,_,_,_,_,_,_,_,
_,_,_,_,_,L,L,L,T,L,L,L,_,_,_,_,_,_,_,
_,_,_,_,_,_,L,L,L,L,L,_,_,_,_,_,_,_,_,
_,_,_,_,_,_,M,L,L,L,M,_,_,_,_,_,_,_,_,
_,_,_,L,L,L,L,_,_,_,_,_,_,_,_,_,_,_,_,
_,_,_,M,L,L,_,_,_,_,L,L,L,L,_,_,_,_,_,
_,_,_,_,_,_,_,_,_,_,_,L,L,M,_,_,_,_,_,
_,_,_,_,_,_,_,_,_,_,_,_,_,_,_,_,_,_,_,
_,_,_,_,_,_,_,_,_,_,_,_,_,_,_,_,_,_,_,
_,_,_,_,_,_,_,_,_,_,_,_,_,_,_,_,_,_,_,
_,_,_,_,_,_,_,_,_,_,_,_,_,_,_,_,_,_,_,
_,_,_,_,_,_,_,_,_,_,_,_,_,_,_,_,_,_,_,

_,_,_,_,_,_,_,_,_,_,_,_,_,_,_,_,_,_,_,
_,_,_,_,_,_,_,_,_,_,_,_,_,_,_,_,_,_,_,
_,_,_,_,_,_,_,_,_,_,_,_,_,_,_,_,_,_,_,
_,_,_,_,_,_,_,_,_,_,_,_,_,_,_,_,_,_,_,
_,_,_,_,_,_,_,_,_,_,_,_,_,_,_,_,_,_,_,
_,_,_,_,_,_,_,_,_,_,_,_,_,_,_,_,_,_,_,
_,_,_,_,_,_,_,_,_,_,_,_,_,_,_,_,_,_,_,
_,_,_,_,_,_,_,_,_,_,_,_,_,_,_,_,_,_,_,
_,_,_,_,_,_,_,_,_,_,_,_,_,_,_,_,_,_,_,
_,_,_,_,_,_,_,_,_,_,_,_,_,_,_,_,_,_,_,
_,_,_,_,_,_,_,_,_,_,_,_,_,_,_,_,_,_,_,
_,_,_,_,_,_,_,_,_,_,_,_,_,_,_,_,_,_,_,
_,_,_,_,_,_,_,_,_,_,_,_,_,_,_,_,_,_,_,
_,_,_,_,_,_,_,_,_,_,_,_,_,_,_,_,_,_,_,
_,_,_,_,_,_,_,_,_,_,_,_,_,_,_,_,_,_,_,
_,_,_,_,_,_,_,_,_,_,_,_,_,_,_,_,_,_,_,
_,_,_,_,_,_,_,_,_,_,_,_,_,_,_,_,_,_,_,
_,_,_,_,_,_,_,_,_,_,_,_,_,_,_,_,_,_,_,
_,_,_,_,_,_,_,_,_,_,_,_,_,_,_,_,_,_,_,
_,_,_,_,_,_,_,_,_,_,_,_,_,_,_,_,_,_,_,
_,_,_,_,_,_,_,_,_,_,_,_,_,_,_,_,_,_,_,
_,_,_,_,_,_,_,_,_,_,_,_,_,_,_,_,_,_,_,
_,_,_,_,_,_,_,_,_,_,_,L,L,L,L,L,L,_,_,
_,_,_,_,_,_,_,_,_,_,_,_,L,L,L,L,M,_,_,
_,_,_,_,_,_,_,_,_,_,_,_,_,L,L,M,_,_,_,
_,_,_,_,_,_,_,_,_,_,_,_,_,_,_,_,_,_,_,
_,_,_,_,_,L,L,L,L,L,L,L,_,_,_,_,_,_,_,
_,_,_,_,_,_,L,L,L,L,L,_,_,_,_,_,_,_,_,
_,_,_,_,_,_,_,L,L,L,_,_,_,_,_,_,_,_,_,
_,_,_,_,_,_,_,_,_,_,_,_,_,_,_,_,_,_,_,
_,_,_,_,_,_,_,_,_,_,_,_,_,_,_,_,_,_,_,
_,_,_,_,_,_,_,_,_,_,_,_,_,_,_,_,_,_,_,
_,_,_,_,_,_,_,_,_,_,_,_,_,_,_,_,_,_,_,
_,_,_,_,_,_,_,_,_,_,_,_,_,_,_,_,_,_,_,
_,_,_,_,_,_,_,_,_,_,_,_,_,_,_,_,_,_,_,
_,_,_,_,_,_,_,_,_,_,_,_,_,_,_,_,_,_,_,
_,_,_,_,_,_,_,_,_,_,_,_,_,_,_,_,_,_,_,

_,_,_,_,_,_,_,_,_,_,_,_,_,_,_,_,_,_,_,
_,_,_,_,_,_,_,_,_,_,_,_,_,_,_,_,_,_,_,
_,_,_,_,_,_,_,_,_,_,_,_,_,_,_,_,_,_,_,
_,_,_,_,_,_,_,_,_,_,_,_,_,_,_,_,_,_,_,
_,_,_,_,_,_,_,_,_,_,_,_,_,_,_,_,_,_,_,
_,_,_,_,_,_,_,_,_,_,_,_,_,_,_,_,_,_,_,
_,_,_,_,_,_,_,_,_,_,_,_,_,_,_,_,_,_,_,
_,_,_,_,_,_,_,_,_,_,_,_,_,_,_,_,_,_,_,
_,_,_,_,_,_,_,_,_,_,_,_,_,_,_,_,_,_,_,
_,_,_,_,_,_,_,_,_,_,_,_,_,_,_,_,_,_,_,
_,_,_,_,_,_,_,_,_,_,_,_,_,_,_,_,_,_,_,
_,_,_,_,_,_,_,_,_,_,_,_,_,_,_,_,_,_,_,
_,_,_,_,_,_,_,_,_,_,_,_,_,_,_,_,_,_,_,
_,_,_,_,_,_,_,_,_,_,_,_,_,_,_,_,_,_,_,
_,_,_,_,_,_,_,_,_,_,_,_,_,_,_,_,_,_,_,
_,_,_,_,_,_,_,_,_,_,_,_,_,_,_,_,_,_,_,
_,_,_,_,_,_,_,_,_,_,_,_,_,_,_,_,_,_,_,
_,_,_,_,_,_,_,_,_,_,_,_,_,_,_,_,_,_,_,
_,_,_,_,_,_,_,_,_,_,_,_,_,_,_,_,_,_,_,
_,_,_,_,_,_,_,_,_,_,_,_,_,_,_,_,_,_,_,
_,_,_,_,_,_,_,_,_,_,_,_,_,_,_,_,_,_,_,
_,_,_,_,_,_,_,_,_,_,_,_,_,_,_,_,_,_,_,
_,_,_,_,_,_,_,_,_,_,_,_,L,L,L,L,_,_,_,
_,_,_,_,_,_,_,_,_,_,_,_,_,L,L,M,_,_,_,
_,_,_,_,_,_,_,_,_,_,_,_,_,_,_,_,_,_,_,
_,_,_,_,_,_,_,_,_,_,_,_,_,_,_,_,_,_,_,
_,_,_,_,_,_,L,L,L,L,L,_,_,_,_,_,_,_,_,
_,_,_,_,_,_,M,L,L,L,M,_,_,_,_,_,_,_,_,
_,_,_,_,_,_,_,_,L,_,_,_,_,_,_,_,_,_,_,
_,_,_,_,_,_,_,_,_,_,_,_,_,_,_,_,_,_,_,
_,_,_,_,_,_,_,_,_,_,_,_,_,_,_,_,_,_,_,
_,_,_,_,_,_,_,_,_,_,_,_,_,_,_,_,_,_,_,
_,_,_,_,_,_,_,_,_,_,_,_,_,_,_,_,_,_,_,
_,_,_,_,_,_,_,_,_,_,_,_,_,_,_,_,_,_,_,
_,_,_,_,_,_,_,_,_,_,_,_,_,_,_,_,_,_,_,
_,_,_,_,_,_,_,_,_,_,_,_,_,_,_,_,_,_,_,
_,_,_,_,_,_,_,_,_,_,_,_,_,_,_,_,_,_,_,

_,_,_,_,_,_,_,_,_,_,_,_,_,_,_,_,_,_,_,
_,_,_,_,_,_,_,_,_,_,_,_,_,_,_,_,_,_,_,
_,_,_,_,_,_,_,_,_,_,_,_,_,_,_,_,_,_,_,
_,_,_,_,_,_,_,_,_,_,_,_,_,_,_,_,_,_,_,
_,_,_,_,_,_,_,_,_,_,_,_,_,_,_,_,_,_,_,
_,_,_,_,_,_,_,_,_,_,_,_,_,_,_,_,_,_,_,
_,_,_,_,_,_,_,_,_,_,_,_,_,_,_,_,_,_,_,
_,_,_,_,_,_,_,_,_,_,_,_,_,_,_,_,_,_,_,
_,_,_,_,_,_,_,_,_,_,_,_,_,_,_,_,_,_,_,
_,_,_,_,_,_,_,_,_,_,_,_,_,_,_,_,_,_,_,
_,_,_,_,_,_,_,_,_,_,_,_,_,_,_,_,_,_,_,
_,_,_,_,_,_,_,_,_,_,_,_,_,_,_,_,_,_,_,
_,_,_,_,_,_,_,_,_,_,_,_,_,_,_,_,_,_,_,
_,_,_,_,_,_,_,_,_,_,_,_,_,_,_,_,_,_,_,
_,_,_,_,_,_,_,_,_,_,_,_,_,_,_,_,_,_,_,
_,_,_,_,_,_,_,_,_,_,_,_,_,_,_,_,_,_,_,
_,_,_,_,_,_,_,_,_,_,_,_,_,_,_,_,_,_,_,
_,_,_,_,_,_,_,_,_,_,_,_,_,_,_,_,_,_,_,
_,_,_,_,_,_,_,_,_,_,_,_,_,_,_,_,_,_,_,
_,_,_,_,_,_,_,_,_,_,_,_,_,_,_,_,_,_,_,
_,_,_,_,_,_,_,_,_,_,_,_,_,_,_,_,_,_,_,
_,_,_,_,_,_,_,_,_,_,_,_,_,_,_,_,_,_,_,
_,_,_,_,_,_,_,_,_,_,_,_,_,_,_,_,_,_,_,
_,_,_,_,_,_,_,_,_,_,_,_,_,_,_,_,_,_,_,
_,_,_,_,_,_,_,_,_,_,_,_,_,_,_,_,_,_,_,
_,_,_,_,_,_,_,_,_,_,_,_,_,_,_,_,_,_,_,
_,_,_,_,_,_,_,L,L,L,_,_,_,_,_,_,_,_,_,
_,_,_,_,_,_,_,M,L,M,_,_,_,_,_,_,_,_,_,
_,_,_,_,_,_,_,_,_,_,_,_,_,_,_,_,_,_,_,
_,_,_,_,_,_,_,_,_,_,_,_,_,_,_,_,_,_,_,
_,_,_,_,_,_,_,_,_,_,_,_,_,_,_,_,_,_,_,
_,_,_,_,_,_,_,_,_,_,_,_,_,_,_,_,_,_,_,
_,_,_,_,_,_,_,_,_,_,_,_,_,_,_,_,_,_,_,
_,_,_,_,_,_,_,_,_,_,_,_,_,_,_,_,_,_,_,
_,_,_,_,_,_,_,_,_,_,_,_,_,_,_,_,_,_,_,
_,_,_,_,_,_,_,_,_,_,_,_,_,_,_,_,_,_,_,
_,_,_,_,_,_,_,_,_,_,_,_,_,_,_,_,_,_,_},
yslice_prob = {{ypos = 0, prob = 127}, {ypos = 5, prob = 127}, {ypos = 6, prob = 127}, {ypos = 7, prob = 127},
{ypos = 14, prob = 127}, {ypos = 15, prob = 127}, {ypos = 16, prob = 127}}}
