
local T = {name = "ethereal:sakura_trunk", force_place = true}
local L = {name = "ethereal:sakura_leaves"}
local M = {name = "ethereal:sakura_leaves", prob = 223}

ethereal.sakura_tree = {size = {x=11, y=11, z=11}, data = {
_,_,_,_,_,_,_,_,_,_,_,
_,_,_,_,_,_,_,_,_,_,_,
_,_,_,_,_,_,_,_,_,_,_,
_,_,_,_,_,_,_,_,_,_,_,
_,_,_,_,_,_,_,_,_,_,_,
_,_,_,_,_,_,_,_,_,_,_,
_,_,_,_,_,_,_,_,_,_,_,
_,M,M,_,_,_,_,_,_,_,_,
_,M,M,M,_,M,M,M,_,_,_,
_,_,_,_,_,_,_,_,_,_,_,
_,_,_,_,_,_,_,_,_,_,_,

_,_,_,_,_,_,_,_,_,_,_,
_,_,_,_,_,_,_,_,_,_,_,
_,_,_,_,_,_,_,_,_,_,_,
_,_,_,_,_,_,_,_,_,_,_,
_,_,_,_,_,_,_,_,_,_,_,
_,_,_,_,_,_,_,_,_,_,_,
_,M,M,M,_,M,M,M,_,_,_,
M,L,L,L,L,L,L,L,M,_,_,
M,L,L,L,L,L,L,L,M,_,_,
_,M,M,M,_,M,M,M,_,_,_,
_,_,_,_,_,_,_,_,_,_,_,

_,_,_,_,_,_,_,_,_,_,_,
_,_,_,_,_,_,_,_,_,_,_,
_,_,_,_,_,_,_,_,_,_,_,
_,_,_,_,_,_,_,_,_,_,_,
_,_,_,_,_,_,_,_,_,_,_,
_,_,M,M,M,M,M,_,_,_,_,
_,M,L,L,L,L,L,M,M,_,_,
M,L,T,L,L,L,L,L,L,M,_,
M,L,L,L,L,L,L,L,L,M,_,
_,M,L,M,M,L,L,L,M,_,_,
_,_,_,_,_,M,M,M,_,_,_,

_,_,_,_,_,_,_,_,_,_,_,
_,_,_,_,_,_,_,_,_,_,_,
_,_,_,_,_,_,_,_,_,_,_,
_,_,_,_,_,_,_,_,_,_,_,
_,_,_,M,M,M,M,_,_,_,_,
_,_,M,L,L,L,L,M,M,_,_,
_,M,L,T,L,L,L,L,M,_,_,
_,M,L,L,L,L,T,L,L,M,_,
M,L,L,L,L,L,T,L,L,M,_,
_,M,M,L,L,L,L,L,M,M,_,
_,_,_,M,M,M,M,M,_,_,_,

_,_,_,_,_,_,_,_,_,_,_,
_,_,_,_,_,_,_,_,_,_,_,
_,_,_,_,_,_,_,_,_,_,_,
_,_,_,_,_,_,_,_,_,_,_,
_,_,_,M,M,M,M,M,_,_,_,
_,_,M,L,T,L,L,L,M,_,_,
_,_,M,L,L,T,L,L,L,M,_,
_,M,L,L,L,L,L,L,L,M,_,
_,M,L,L,L,L,L,L,L,L,M,
_,M,L,L,L,L,L,L,L,M,_,
_,_,M,M,M,M,M,M,M,_,_,

_,_,_,_,_,T,_,_,_,_,_,
_,_,_,_,_,T,_,_,_,_,_,
_,_,_,_,_,T,_,_,_,_,_,
_,_,_,_,_,T,_,_,_,_,_,
_,_,_,M,M,T,M,M,_,_,_,
_,_,M,L,L,T,T,L,M,_,_,
_,_,M,L,T,L,L,T,L,M,_,
_,M,L,T,L,L,L,L,T,L,M,
_,M,L,T,L,L,L,L,L,L,M,
_,M,L,L,L,L,L,L,L,L,_,
_,_,M,M,M,M,M,M,M,_,_,

_,_,_,_,_,_,_,_,_,_,_,
_,_,_,_,_,_,_,_,_,_,_,
_,_,_,_,_,_,_,_,_,_,_,
_,_,_,_,_,_,_,_,_,_,_,
_,_,_,M,M,M,M,M,_,_,_,
_,_,M,L,T,L,L,L,M,_,_,
_,_,M,L,L,T,L,L,L,M,_,
_,M,L,L,L,L,L,L,L,M,_,
_,M,L,L,L,L,L,L,L,L,M,
_,M,L,L,L,L,L,L,L,M,_,
_,_,M,M,M,M,M,M,M,_,_,

_,_,_,_,_,_,_,_,_,_,_,
_,_,_,_,_,_,_,_,_,_,_,
_,_,_,_,_,_,_,_,_,_,_,
_,_,_,_,_,_,_,_,_,_,_,
_,_,_,M,M,M,M,_,_,_,_,
_,_,M,L,L,L,L,M,M,_,_,
_,M,L,T,L,L,L,L,M,_,_,
_,M,L,L,L,L,T,L,L,M,_,
M,L,L,L,L,L,T,L,L,M,_,
_,M,M,L,L,L,L,L,M,M,_,
_,_,_,M,M,M,M,M,_,_,_,

_,_,_,_,_,_,_,_,_,_,_,
_,_,_,_,_,_,_,_,_,_,_,
_,_,_,_,_,_,_,_,_,_,_,
_,_,_,_,_,_,_,_,_,_,_,
_,_,_,_,_,_,_,_,_,_,_,
_,_,M,M,M,M,M,_,_,_,_,
_,M,L,L,L,L,L,M,M,_,_,
M,L,T,L,L,L,L,L,L,M,_,
M,L,L,L,L,L,L,L,L,M,_,
_,M,L,M,M,L,L,L,M,_,_,
_,_,_,_,_,M,M,M,_,_,_,

_,_,_,_,_,_,_,_,_,_,_,
_,_,_,_,_,_,_,_,_,_,_,
_,_,_,_,_,_,_,_,_,_,_,
_,_,_,_,_,_,_,_,_,_,_,
_,_,_,_,_,_,_,_,_,_,_,
_,_,_,_,_,_,_,_,_,_,_,
_,M,M,M,_,M,M,M,_,_,_,
M,L,L,L,L,L,L,L,M,_,_,
M,L,L,L,L,L,L,L,M,_,_,
_,M,M,M,_,M,M,M,_,_,_,
_,_,_,_,_,_,_,_,_,_,_,

_,_,_,_,_,_,_,_,_,_,_,
_,_,_,_,_,_,_,_,_,_,_,
_,_,_,_,_,_,_,_,_,_,_,
_,_,_,_,_,_,_,_,_,_,_,
_,_,_,_,_,_,_,_,_,_,_,
_,_,_,_,_,_,_,_,_,_,_,
_,_,_,_,_,_,_,_,_,_,_,
_,M,M,_,_,_,_,_,_,_,_,
_,M,M,M,_,M,M,M,_,_,_,
_,_,_,_,_,_,_,_,_,_,_,
_,_,_,_,_,_,_,_,_,_,_},
yslice_prob = {{ypos = 0, prob = 127}, {ypos = 3, prob = 127}, {ypos = 7, prob = 127}}}
