
local D = {name = "ethereal:dry_dirt_with_fiery_grass", prob = 255}
local d = {name = "ethereal:dry_dirt_with_fiery_grass", prob = 245}
local s = {name = "default:stone"}
local L = {name = "default:lava_source"}
local l = {name = "default:lava_source", prob = 225}
local f = {name = "default:lava_flowing"}
local o = {name = "default:obsidian", prob = 215}

ethereal.volcanol = {size = {x = 15, y = 4, z = 15}, data = {
_,_,_,_,_,_,_,_,_,_,_,_,_,_,_,
_,_,_,_,_,_,_,_,_,_,_,_,_,_,_,
_,_,_,_,_,_,_,_,_,_,_,_,_,_,_,
_,_,_,_,_,_,_,_,_,_,_,_,_,_,_,

_,_,_,d,d,d,d,_,_,d,_,_,_,_,_,
_,_,_,_,_,_,_,_,_,_,_,_,_,_,_,
_,_,_,_,_,_,_,_,_,_,_,_,_,_,_,
_,_,_,_,_,_,_,_,_,_,_,_,_,_,_,

_,_,d,s,s,s,s,d,d,s,d,d,_,_,_,
_,_,_,s,s,s,s,_,_,s,_,_,_,_,_,
_,_,_,_,_,_,_,_,_,_,_,_,_,_,_,
_,_,_,_,_,_,_,_,_,_,_,_,_,_,_,

_,d,s,o,o,o,o,s,s,o,s,s,d,_,_,
_,_,s,f,f,s,f,s,s,f,s,s,_,_,_,
_,_,_,s,s,_,s,_,_,s,_,_,_,_,_,
_,_,_,_,_,_,_,_,_,_,_,_,_,_,_,

d,s,o,s,s,s,s,o,o,s,o,o,s,d,_,
_,s,L,L,L,L,f,s,f,f,L,L,s,_,_,
_,_,s,f,f,s,s,o,s,o,s,s,_,_,_,
_,_,_,o,o,o,_,_,_,o,_,_,_,_,_,

d,s,o,s,o,o,o,s,s,o,s,s,o,s,d,
_,s,f,L,L,L,L,L,L,L,L,L,L,s,_,
_,_,s,f,f,f,f,f,f,L,f,L,s,_,_,
_,_,_,o,_,_,o,o,o,_,o,o,_,_,_,

d,s,o,s,o,s,s,o,o,s,o,s,o,s,d,
_,s,s,L,L,L,L,L,L,L,L,L,L,s,_,
_,_,_,o,f,f,f,f,f,f,f,L,s,_,_,
_,_,_,_,_,_,_,_,_,_,_,o,_,_,_,

_,d,s,o,s,o,s,s,s,s,o,s,o,s,d,
_,_,s,L,L,L,L,L,L,L,L,L,L,s,_,
_,_,s,f,f,f,f,f,f,f,f,L,s,_,_,
_,_,_,o,_,_,_,_,_,_,_,s,_,_,_,

d,s,o,s,o,o,o,o,o,o,s,o,s,d,_,
_,s,L,L,L,L,L,L,L,L,L,L,s,_,_,
_,_,s,f,f,f,f,f,f,f,L,s,_,_,_,
_,_,_,o,_,_,_,_,_,_,_,o,_,_,_,

d,s,o,s,s,s,s,s,s,o,s,o,s,d,_,
_,s,L,L,L,L,L,L,L,L,L,L,s,_,_,
_,_,s,f,f,f,f,L,L,f,L,s,_,_,_,
_,_,_,o,o,_,_,_,o,_,o,_,_,_,_,

_,d,s,o,o,o,o,o,o,s,o,s,d,_,_,
_,_,s,s,L,f,f,f,f,L,L,s,_,_,_,
_,_,_,s,s,s,s,s,s,f,s,_,_,_,_,
_,_,_,_,s,o,o,o,_,s,_,_,_,_,_,

_,_,d,s,s,s,s,s,s,o,s,d,_,_,_,
_,_,_,s,s,s,s,s,s,L,s,_,_,_,_,
_,_,_,_,_,_,_,_,_,s,_,_,_,_,_,
_,_,_,_,_,_,_,_,_,_,_,_,_,_,_,

_,_,_,d,d,d,d,d,d,s,s,d,_,_,_,
_,_,_,_,_,_,_,_,_,s,s,_,_,_,_,
_,_,_,_,_,_,_,_,_,_,_,_,_,_,_,
_,_,_,_,_,_,_,_,_,_,_,_,_,_,_,

_,_,_,_,_,_,_,_,_,d,d,_,_,_,_,
_,_,_,_,_,_,_,_,_,_,_,_,_,_,_,
_,_,_,_,_,_,_,_,_,_,_,_,_,_,_,
_,_,_,_,_,_,_,_,_,_,_,_,_,_,_,

_,_,_,_,_,_,_,_,_,_,_,_,_,_,_,
_,_,_,_,_,_,_,_,_,_,_,_,_,_,_,
_,_,_,_,_,_,_,_,_,_,_,_,_,_,_,
_,_,_,_,_,_,_,_,_,_,_,_,_,_,_},
yslice_prob = {{ypos = 0, prob = 127}, {ypos = 1, prob = 127}, {ypos = 2, prob = 127}}}

ethereal.volcanom = {size = {x = 6, y = 2, z = 6}, data = {
_,_,s,_,_,_,
_,_,_,_,_,_,

_,s,l,s,_,_,
_,_,s,D,_,_,

_,s,l,l,s,_,
_,s,_,_,s,_,

s,l,l,l,s,_,
_,s,_,_,D,_,

_,D,l,l,D,D,
_,_,s,D,_,_,

_,_,D,D,D,_,
_,_,_,_,_,_},
yslice_prob = {{ypos = 0, prob = 127}}}
