
local L = {name = "ethereal:willow_twig"}
local M = {name = "ethereal:willow_twig", prob = 223}
local T = {name = "ethereal:willow_trunk", force_place = true}
local t = {name = "ethereal:willow_trunk", prob = 127, force_place = true}
local U = {name = "ethereal:willow_trunk", param2 = 7, force_place = true}
local u = {name = "ethereal:willow_trunk", prob = 127, param2 = 7, force_place = true}
local V = {name = "ethereal:willow_trunk", param2 = 9, force_place = true}
local v = {name = "ethereal:willow_trunk", prob = 127, param2 = 9, force_place = true}
local W = {name = "ethereal:willow_trunk", param2 = 12, force_place = true}
local w = {name = "ethereal:willow_trunk", prob = 127, param2 = 12, force_place = true}
local X = {name = "ethereal:willow_trunk", param2 = 18, force_place = true}
local x = {name = "ethereal:willow_trunk", prob = 127, param2 = 18, force_place = true}

ethereal.willow = {size = {x = 7, y = 11, z = 7}, data = {
_,_,_,_,_,_,_,
_,_,_,_,_,_,_,
_,_,_,_,_,_,_,
_,L,_,_,_,_,_,
_,L,_,L,_,_,_,
_,L,L,L,_,L,_,
_,L,L,L,L,L,_,
_,L,L,L,L,L,_,
_,_,L,L,L,_,_,
_,_,_,_,_,_,_,
_,_,_,_,_,_,_,

_,_,_,_,_,_,_,
_,_,_,_,_,_,_,
_,_,_,_,_,_,_,
_,_,_,_,_,_,L,
L,_,_,_,_,_,L,
L,_,_,_,_,_,L,
L,L,_,L,_,L,L,
L,L,L,L,L,L,L,
_,L,L,L,L,L,_,
_,_,L,L,L,_,_,
_,_,_,_,_,_,_,

_,_,T,t,t,_,_,
_,_,T,_,_,_,_,
_,_,t,_,_,_,_,
_,_,_,_,_,_,_,
_,_,_,_,_,_,_,
_,_,_,_,_,_,L,
L,_,_,_,_,_,L,
L,L,L,L,L,L,L,
L,L,L,L,L,L,L,
_,L,L,L,L,L,_,
_,_,_,L,_,_,_,

_,_,t,T,T,_,_,
_,_,_,T,T,_,_,
L,_,_,T,t,_,_,
L,_,_,T,_,_,_,
L,_,_,T,_,_,L,
L,_,_,T,_,_,L,
L,L,_,T,_,L,L,
L,L,L,T,L,L,L,
L,L,L,L,L,L,L,
_,L,L,L,L,L,_,
_,_,L,L,L,_,_,

_,_,t,T,t,_,_,
_,_,_,T,_,_,_,
_,_,_,t,_,_,L,
_,_,_,_,_,_,L,
L,_,_,_,_,_,L,
L,_,_,_,_,_,L,
L,_,_,_,_,_,L,
L,L,L,L,L,L,L,
L,L,L,L,L,L,L,
_,L,L,L,L,L,_,
_,_,_,L,_,_,_,

_,_,_,_,_,_,_,
_,_,_,_,_,_,_,
_,_,_,_,_,_,_,
L,_,_,_,_,_,_,
L,_,_,_,_,_,_,
L,_,_,_,_,_,L,
L,L,_,L,_,L,L,
L,L,L,L,L,L,L,
_,L,L,L,L,L,_,
_,_,L,L,L,_,_,
_,_,_,_,_,_,_,

_,_,_,_,_,_,_,
_,_,_,_,_,_,_,
_,_,_,_,_,_,_,
_,_,_,_,L,_,_,
_,_,L,_,L,L,_,
_,L,L,L,L,L,_,
_,L,L,L,L,L,_,
_,L,L,L,L,L,_,
_,_,L,L,L,_,_,
_,_,_,_,_,_,_,
_,_,_,_,_,_,_},
yslice_prob = {{ypos = 7, prob = 127}}}

ethereal.willow2 = {size = {x = 12, y = 14, z = 12}, data = {
_,_,_,_,_,_,_,_,_,_,_,_,
_,_,_,_,_,_,_,_,_,_,_,_,
_,_,_,_,_,_,_,_,_,_,_,_,
_,_,_,_,_,_,_,_,_,_,_,_,
_,_,_,_,_,_,_,_,_,_,_,_,
_,_,_,_,_,_,_,_,_,_,_,_,
_,_,_,M,_,_,_,_,M,_,_,_,
_,_,_,M,_,_,_,_,M,_,_,_,
_,_,_,_,_,M,_,_,_,_,_,_,
_,_,_,_,_,M,_,_,_,_,_,_,
_,_,_,_,_,_,_,_,_,_,_,_,
_,_,_,_,_,_,_,_,_,_,_,_,
_,_,_,_,_,_,_,_,_,_,_,_,
_,_,_,_,_,_,_,_,_,_,_,_,

_,_,_,_,_,_,_,_,_,_,_,_,
_,_,_,_,_,_,_,_,_,_,_,_,
_,_,_,_,_,_,_,_,_,_,_,_,
_,_,_,_,_,_,_,_,_,_,_,_,
_,_,M,_,_,_,_,_,_,M,_,_,
_,_,L,_,_,_,_,_,_,L,_,_,
_,M,L,L,_,M,_,_,L,L,M,_,
_,M,L,L,L,L,_,L,L,L,M,_,
_,_,_,L,L,L,L,_,L,_,_,_,
_,_,_,_,L,L,L,_,_,_,_,_,
_,_,_,_,_,L,_,_,_,_,_,_,
_,_,_,_,_,_,_,_,_,_,_,_,
_,_,_,_,_,_,_,_,_,_,_,_,
_,_,_,_,_,_,_,_,_,_,_,_,

_,_,_,v,_,_,_,_,_,_,_,_,
_,_,_,_,_,_,_,_,_,_,_,_,
_,_,_,_,_,_,_,_,_,_,_,_,
_,_,M,_,_,_,_,_,_,M,_,_,
_,M,L,_,M,_,_,M,_,L,M,_,
_,L,L,L,L,M,_,L,L,L,L,_,
_,L,L,L,L,L,M,L,L,L,L,_,
_,L,L,L,L,L,L,L,L,L,L,_,
_,_,L,L,L,L,L,L,L,L,_,_,
_,_,_,L,L,L,L,L,L,_,_,_,
_,_,_,_,L,L,L,_,_,_,_,_,
_,_,_,_,_,L,_,_,_,_,_,_,
_,_,_,_,_,_,_,_,_,_,_,_,
_,_,_,_,_,_,_,_,_,_,_,_,

_,_,x,X,X,X,_,_,v,_,_,_,
_,_,_,_,_,_,_,_,_,_,_,_,
_,_,_,_,_,_,_,_,_,_,_,_,
_,_,_,_,_,_,_,_,_,_,_,_,
_,_,_,_,_,_,_,_,_,_,_,_,
_,_,L,L,_,_,_,_,L,L,_,_,
M,L,L,L,_,_,_,M,L,L,L,M,
M,L,L,T,L,L,L,L,T,L,L,M,
_,L,L,L,L,L,L,L,L,L,L,_,
_,_,L,L,L,T,L,L,L,L,_,_,
_,_,_,L,L,L,L,L,_,_,_,_,
_,_,_,_,L,L,L,_,_,_,_,_,
_,_,_,_,_,_,_,_,_,_,_,_,
_,_,_,_,_,_,_,_,_,_,_,_,

_,_,_,_,_,T,_,_,V,_,_,_,
_,_,_,_,_,T,_,_,_,_,_,_,
_,_,_,_,_,_,_,_,_,_,_,_,
_,_,_,M,_,_,_,_,_,_,_,_,
_,_,M,L,_,_,_,_,_,M,_,_,
_,_,L,L,L,_,_,_,_,L,_,_,
_,_,L,L,T,_,_,T,M,L,_,_,
_,L,L,L,L,_,L,L,L,L,L,_,
_,_,L,L,L,T,L,L,L,L,_,_,
_,_,_,L,L,L,L,L,L,L,_,_,
_,_,_,L,L,L,L,L,L,_,_,_,
_,_,_,_,L,L,L,L,_,_,_,_,
_,_,_,_,_,L,L,_,_,_,_,_,
_,_,_,_,_,_,_,_,_,_,_,_,

_,_,_,_,_,T,T,W,W,w,_,_,
_,_,_,_,_,T,T,_,_,_,_,_,
_,_,_,_,_,T,T,_,_,_,_,_,
_,_,_,_,_,T,T,_,_,_,_,_,
_,_,L,L,L,T,T,_,_,_,_,_,
_,L,L,L,L,T,T,_,_,M,_,_,
_,L,L,L,L,T,T,_,_,M,_,_,
_,_,L,L,L,T,T,L,L,M,_,_,
_,_,_,L,M,T,M,L,L,L,L,_,
_,_,M,L,L,T,L,L,L,L,L,_,
_,_,M,L,L,L,L,L,L,L,_,_,
_,_,_,L,L,L,L,L,L,_,_,_,
_,_,_,_,L,L,L,L,_,_,_,_,
_,_,_,_,_,_,L,_,_,_,_,_,

_,_,x,X,X,T,T,T,_,_,_,_,
_,_,_,_,_,T,T,T,_,_,_,_,
_,_,M,_,_,T,T,_,_,_,_,_,
_,M,L,_,_,T,T,_,_,M,_,_,
_,L,L,L,_,T,T,_,_,L,_,_,
M,L,L,L,T,T,T,T,_,L,_,_,
M,L,L,T,L,T,T,L,L,L,L,_,
_,L,L,L,L,T,T,L,L,L,L,_,
_,_,L,L,L,T,T,T,L,L,L,M,
_,_,M,L,L,L,T,L,T,L,L,M,
_,_,M,L,L,L,T,L,L,L,L,_,
_,_,_,M,L,L,L,L,L,L,_,_,
_,_,_,_,L,L,L,L,L,_,_,_,
_,_,_,_,_,L,L,L,_,_,_,_,

_,_,_,_,_,T,_,_,_,_,_,_,
_,_,_,_,_,T,_,_,_,_,_,_,
_,_,_,_,_,_,_,_,_,_,_,_,
_,_,_,_,_,_,_,_,_,_,_,_,
_,_,L,L,L,_,L,_,L,L,_,_,
_,L,L,L,L,T,L,L,L,L,L,M,
_,L,L,L,L,L,L,L,T,L,L,M,
_,_,L,L,L,L,L,L,L,L,L,_,
_,_,L,L,M,L,M,L,L,L,L,_,
_,_,L,M,T,L,L,L,L,L,L,_,
_,L,L,L,L,L,L,L,L,L,_,_,
_,_,L,L,L,L,L,L,L,_,_,_,
_,_,_,L,_,L,L,L,_,_,_,_,
_,_,_,_,_,_,L,_,_,_,_,_,

_,_,_,_,_,U,_,_,_,_,_,_,
_,_,_,_,_,_,_,_,_,_,_,_,
_,_,_,_,_,_,_,_,_,M,_,_,
_,_,_,M,_,_,_,M,_,L,M,_,
_,_,_,L,L,L,L,L,L,L,L,_,
_,_,L,L,L,L,L,L,L,L,L,_,
_,_,L,L,L,T,L,L,L,L,L,_,
_,_,_,L,L,L,L,L,L,L,_,_,
_,_,L,L,L,L,L,L,L,L,_,_,
M,L,L,L,M,M,L,L,L,L,_,_,
M,L,L,T,L,M,L,L,L,_,_,_,
_,L,L,L,L,L,L,L,_,_,_,_,
_,_,L,L,L,_,L,_,_,_,_,_,
_,_,_,_,_,_,_,_,_,_,_,_,

_,_,_,_,_,W,W,w,_,_,_,_,
_,_,_,_,_,_,_,_,_,_,_,_,
_,_,_,_,_,M,_,_,_,_,_,_,
_,_,_,_,_,L,_,_,_,M,_,_,
_,_,_,_,L,L,L,_,_,L,_,_,
_,_,_,L,L,L,L,L,L,L,M,_,
_,_,M,L,L,L,L,L,L,L,M,_,
_,M,L,_,L,L,L,_,L,_,_,_,
_,L,L,L,L,L,_,_,M,_,_,_,
_,L,L,L,L,M,_,_,M,_,_,_,
_,L,L,L,L,M,M,_,_,_,_,_,
_,_,L,L,L,_,M,_,_,_,_,_,
_,_,_,L,_,_,_,_,_,_,_,_,
_,_,_,_,_,_,_,_,_,_,_,_,

_,_,_,_,_,_,u,_,_,_,_,_,
_,_,_,_,_,_,_,_,_,_,_,_,
_,_,_,_,_,_,_,_,_,_,_,_,
_,_,_,_,_,M,_,_,_,_,_,_,
_,_,_,_,_,L,_,_,_,_,_,_,
_,_,_,_,L,L,L,_,M,_,_,_,
_,_,_,_,L,L,L,_,M,_,_,_,
_,_,M,_,_,L,_,_,_,_,_,_,
_,_,L,_,_,_,_,_,_,_,_,_,
_,M,L,L,_,_,_,_,_,_,_,_,
_,M,L,L,L,_,_,_,_,_,_,_,
_,_,_,L,_,_,_,_,_,_,_,_,
_,_,_,_,_,_,_,_,_,_,_,_,
_,_,_,_,_,_,_,_,_,_,_,_,

_,_,_,_,_,_,_,_,_,_,_,_,
_,_,_,_,_,_,_,_,_,_,_,_,
_,_,_,_,_,_,_,_,_,_,_,_,
_,_,_,_,_,_,_,_,_,_,_,_,
_,_,_,_,_,_,_,_,_,_,_,_,
_,_,_,_,_,M,_,_,_,_,_,_,
_,_,_,_,_,M,_,_,_,_,_,_,
_,_,_,_,_,_,_,_,_,_,_,_,
_,_,_,_,_,_,_,_,_,_,_,_,
_,_,_,M,_,_,_,_,_,_,_,_,
_,_,_,M,_,_,_,_,_,_,_,_,
_,_,_,_,_,_,_,_,_,_,_,_,
_,_,_,_,_,_,_,_,_,_,_,_,
_,_,_,_,_,_,_,_,_,_,_,_},
yslice_prob = {{ypos = 0, prob = 127}, {ypos = 1, prob = 127}}}
