
local T = {name = "ethereal:yellow_trunk", force_place = true}
local B = {name = "ethereal:yellow_trunk", prob = 127, force_place = true}
local L = {name = "ethereal:yellowleaves"}
local A = {name = "ethereal:golden_apple", prob = 115}

ethereal.yellowtree = {size = {x = 9, y = 19, z = 9}, data = {
_,_,_,_,_,_,_,_,_,
_,_,_,_,_,_,_,_,_,
_,_,_,_,_,_,_,_,_,
_,_,_,_,_,_,_,_,_,
_,_,_,_,_,_,_,_,_,
_,_,_,_,_,_,_,_,_,
_,_,_,_,_,_,_,_,_,
_,_,_,_,_,_,_,_,_,
_,_,_,_,_,_,_,_,_,
_,_,_,_,_,_,_,_,_,
_,_,_,_,_,_,_,_,_,
_,_,_,_,_,_,_,_,_,
_,_,_,_,A,_,_,_,_,
_,_,_,_,L,_,_,_,_,
_,_,_,_,_,_,_,_,_,
_,_,_,_,_,_,_,_,_,
_,_,_,_,_,_,_,_,_,
_,_,_,_,_,_,_,_,_,
_,_,_,_,_,_,_,_,_,

_,_,_,_,_,_,_,_,_,
_,_,_,_,_,_,_,_,_,
_,_,_,_,_,_,_,_,_,
_,_,_,_,_,_,_,_,_,
_,_,_,_,_,_,_,_,_,
_,_,_,_,_,_,_,_,_,
_,_,_,_,_,_,_,_,_,
_,_,_,_,_,_,_,_,_,
_,_,_,_,_,_,_,_,_,
_,_,_,_,_,_,_,_,_,
_,_,_,_,_,_,_,_,_,
_,_,_,_,_,_,_,_,_,
_,_,_,A,_,A,_,_,_,
_,_,_,L,T,L,_,_,_,
_,_,_,_,L,_,_,_,_,
_,_,_,_,_,_,_,_,_,
_,_,_,_,A,_,_,_,_,
_,_,_,_,L,_,_,_,_,
_,_,_,_,_,_,_,_,_,

_,_,_,_,_,_,_,_,_,
_,_,_,_,_,_,_,_,_,
_,_,_,_,_,_,_,_,_,
_,_,_,_,_,_,_,_,_,
_,_,_,_,_,_,_,_,_,
_,_,_,_,_,_,_,_,_,
_,_,_,_,_,_,_,_,_,
_,_,_,_,_,_,_,_,_,
_,_,_,_,_,_,_,_,_,
_,_,_,_,_,_,_,_,_,
_,_,_,_,_,_,_,_,_,
_,_,_,_,_,_,_,_,_,
_,_,_,A,B,A,_,_,_,
_,_,_,L,T,L,_,_,_,
_,_,_,_,L,_,_,_,_,
_,_,_,_,_,_,_,_,_,
_,_,_,A,_,A,_,_,_,
_,_,_,L,T,L,_,_,_,
_,_,_,_,L,_,_,_,_,

_,_,_,_,_,_,_,_,_,
_,_,_,_,_,_,_,_,_,
_,_,_,_,_,_,_,_,_,
_,_,_,_,_,_,_,_,_,
_,_,_,_,T,_,_,_,_,
_,_,_,_,_,_,_,_,_,
_,_,_,_,_,_,_,_,_,
_,_,_,_,_,_,_,_,_,
_,_,_,_,T,A,_,_,_,
_,_,_,_,_,L,A,A,_,
_,_,_,A,_,_,L,L,_,
_,A,A,L,_,A,_,_,_,
_,L,L,L,T,L,_,_,_,
_,_,_,_,_,L,A,A,_,
_,_,_,A,_,_,L,L,_,
_,A,A,L,_,_,_,_,_,
_,L,L,A,B,A,_,_,_,
_,_,_,L,T,L,_,_,_,
_,_,_,_,L,_,_,_,_,

_,_,_,_,T,_,_,_,_,
_,_,_,_,T,_,_,_,_,
_,_,_,_,T,_,_,_,_,
_,_,_,T,T,_,_,_,_,
_,_,_,_,T,_,_,_,_,
_,_,_,_,T,T,_,_,_,
_,_,_,_,T,_,_,_,_,
_,_,_,T,T,_,_,_,_,
_,_,_,_,T,_,_,_,_,
_,_,_,_,T,T,B,_,A,
_,_,_,_,T,_,T,T,L,
A,_,B,T,T,_,L,L,_,
L,T,T,_,T,_,_,_,_,
_,L,L,_,T,T,B,_,A,
_,_,_,_,T,L,T,T,L,
A,_,B,T,T,L,L,L,_,
L,T,T,L,T,L,_,_,_,
_,L,L,_,L,_,_,_,_,
_,_,_,_,_,_,_,_,_,

_,_,_,_,_,_,_,_,_,
_,_,_,_,_,_,_,_,_,
_,_,_,_,_,_,_,_,_,
_,_,_,_,_,_,_,_,_,
_,_,_,_,_,_,_,_,_,
_,_,_,_,_,_,_,_,_,
_,_,_,_,T,_,_,_,_,
_,_,_,_,_,_,_,_,_,
_,_,_,_,_,A,_,_,_,
_,_,_,A,_,L,A,A,_,
_,_,_,L,T,L,L,L,_,
_,A,A,L,_,_,_,_,_,
_,L,L,_,_,A,_,_,_,
_,_,_,A,_,L,A,A,_,
_,_,_,L,T,L,L,L,_,
_,A,A,L,L,_,_,_,_,
_,L,L,_,L,_,_,_,_,
_,_,_,_,_,_,_,_,_,
_,_,_,_,_,_,_,_,_,

_,_,_,_,_,_,_,_,_,
_,_,_,_,_,_,_,_,_,
_,_,_,_,_,_,_,_,_,
_,_,_,_,_,_,_,_,_,
_,_,_,_,_,_,_,_,_,
_,_,_,_,_,_,_,_,_,
_,_,_,_,_,_,_,_,_,
_,_,_,_,_,_,_,_,_,
_,_,_,_,_,_,_,_,_,
_,_,_,_,_,_,_,_,_,
_,_,_,A,B,A,_,_,_,
_,_,_,L,T,L,_,_,_,
_,_,_,_,L,_,_,_,_,
_,_,_,_,_,_,_,_,_,
_,_,_,A,B,A,_,_,_,
_,_,_,L,T,L,_,_,_,
_,_,_,_,L,_,_,_,_,
_,_,_,_,_,_,_,_,_,
_,_,_,_,_,_,_,_,_,

_,_,_,_,_,_,_,_,_,
_,_,_,_,_,_,_,_,_,
_,_,_,_,_,_,_,_,_,
_,_,_,_,_,_,_,_,_,
_,_,_,_,_,_,_,_,_,
_,_,_,_,_,_,_,_,_,
_,_,_,_,_,_,_,_,_,
_,_,_,_,_,_,_,_,_,
_,_,_,_,_,_,_,_,_,
_,_,_,_,_,_,_,_,_,
_,_,_,A,_,A,_,_,_,
_,_,_,L,T,L,_,_,_,
_,_,_,_,L,_,_,_,_,
_,_,_,_,_,_,_,_,_,
_,_,_,A,_,A,_,_,_,
_,_,_,L,T,L,_,_,_,
_,_,_,_,L,_,_,_,_,
_,_,_,_,_,_,_,_,_,
_,_,_,_,_,_,_,_,_,

_,_,_,_,_,_,_,_,_,
_,_,_,_,_,_,_,_,_,
_,_,_,_,_,_,_,_,_,
_,_,_,_,_,_,_,_,_,
_,_,_,_,_,_,_,_,_,
_,_,_,_,_,_,_,_,_,
_,_,_,_,_,_,_,_,_,
_,_,_,_,_,_,_,_,_,
_,_,_,_,_,_,_,_,_,
_,_,_,_,_,_,_,_,_,
_,_,_,_,A,_,_,_,_,
_,_,_,_,L,_,_,_,_,
_,_,_,_,_,_,_,_,_,
_,_,_,_,_,_,_,_,_,
_,_,_,_,A,_,_,_,_,
_,_,_,_,L,_,_,_,_,
_,_,_,_,_,_,_,_,_,
_,_,_,_,_,_,_,_,_,
_,_,_,_,_,_,_,_,_},
yslice_prob = {{ypos = 0, prob = 254}, {ypos = 3, prob = 254}, {ypos = 5, prob = 254}}}
